Workbook

Sheet OpeningDebtors
A1: Sales Date | B1: Customer Name | C1: Sales Invoice Number or reference | E1: Sales Description | G1: =SUM(G5:G300) -> 0 | H1: =SUM(H5:H300) -> 0 | I1: =SUM(I5:I300) -> 0 | K1: For your information only. Enter How Paid e.g. Cash, Cheque etc., | L1: =SUM(L5:L300) -> 0 | M1: =SUM(M5:M300) -> 0 | N1: =TODAY() -> 45397 | P1: =SUM(P5:P300) -> 0
G2: Sales Value including Vat | H2: =Apr!H2 -> 20 | I2: Sales Net of Vat | L2: Receipts from Customers | P2: Sub contractors only
H3: Vat Output | L3: Actual amount received | M3: Sales Value not yet received | N3: Number of Days Outstanding | P3: CIS Tax Deducted | Q3: CIS Certificate reference
H5: =IF(H$4>0,(IF(G5<>0,G5*H$4/100," ")),IF(G5<>0,G5*H$2/(100+H$2)," ")) | I5: =IF((G5<>0),G5-H5," ") | M5: =IF(G5<>0,G5-L5," ") | N5: =IF((G5-L5)<>0,N$1-A5," ")
H6: =IF(H$4>0,(IF(G6<>0,G6*H$4/100," ")),IF(G6<>0,G6*H$2/(100+H$2)," ")) | I6: =IF((G6<>0),G6-H6," ") | M6: =IF(G6<>0,G6-L6," ") | N6: =IF((G6-L6)<>0,N$1-A6," ")
H7: =IF(H$4>0,(IF(G7<>0,G7*H$4/100," ")),IF(G7<>0,G7*H$2/(100+H$2)," ")) | I7: =IF((G7<>0),G7-H7," ") | M7: =IF(G7<>0,G7-L7," ") | N7: =IF((G7-L7)<>0,N$1-A7," ")
H8: =IF(H$4>0,(IF(G8<>0,G8*H$4/100," ")),IF(G8<>0,G8*H$2/(100+H$2)," ")) | I8: =IF((G8<>0),G8-H8," ") | M8: =IF(G8<>0,G8-L8," ") | N8: =IF((G8-L8)<>0,N$1-A8," ")
H9: =IF(H$4>0,(IF(G9<>0,G9*H$4/100," ")),IF(G9<>0,G9*H$2/(100+H$2)," ")) | I9: =IF((G9<>0),G9-H9," ") | M9: =IF(G9<>0,G9-L9," ") | N9: =IF((G9-L9)<>0,N$1-A9," ")
H10: =IF(H$4>0,(IF(G10<>0,G10*H$4/100," ")),IF(G10<>0,G10*H$2/(100+H$2)," ")) | I10: =IF((G10<>0),G10-H10," ") | M10: =IF(G10<>0,G10-L10," ") | N10: =IF((G10-L10)<>0,N$1-A10," ")
H11: =IF(H$4>0,(IF(G11<>0,G11*H$4/100," ")),IF(G11<>0,G11*H$2/(100+H$2)," ")) | I11: =IF((G11<>0),G11-H11," ") | M11: =IF(G11<>0,G11-L11," ") | N11: =IF((G11-L11)<>0,N$1-A11," ")
H12: =IF(H$4>0,(IF(G12<>0,G12*H$4/100," ")),IF(G12<>0,G12*H$2/(100+H$2)," ")) | I12: =IF((G12<>0),G12-H12," ") | M12: =IF(G12<>0,G12-L12," ") | N12: =IF((G12-L12)<>0,N$1-A12," ")
H13: =IF(H$4>0,(IF(G13<>0,G13*H$4/100," ")),IF(G13<>0,G13*H$2/(100+H$2)," ")) | I13: =IF((G13<>0),G13-H13," ") | M13: =IF(G13<>0,G13-L13," ") | N13: =IF((G13-L13)<>0,N$1-A13," ")
H14: =IF(H$4>0,(IF(G14<>0,G14*H$4/100," ")),IF(G14<>0,G14*H$2/(100+H$2)," ")) | I14: =IF((G14<>0),G14-H14," ") | M14: =IF(G14<>0,G14-L14," ") | N14: =IF((G14-L14)<>0,N$1-A14," ")
H15: =IF(H$4>0,(IF(G15<>0,G15*H$4/100," ")),IF(G15<>0,G15*H$2/(100+H$2)," ")) | I15: =IF((G15<>0),G15-H15," ") | M15: =IF(G15<>0,G15-L15," ") | N15: =IF((G15-L15)<>0,N$1-A15," ")
H16: =IF(H$4>0,(IF(G16<>0,G16*H$4/100," ")),IF(G16<>0,G16*H$2/(100+H$2)," ")) | I16: =IF((G16<>0),G16-H16," ") | M16: =IF(G16<>0,G16-L16," ") | N16: =IF((G16-L16)<>0,N$1-A16," ")
... H300: =IF(H$4>0,(IF(G300<>0,G300*H$4/100," ")),IF(G300<>0,G300*H$2/(100+H$2)," ")) | I300: =IF((G300<>0),G300-H300," ") | M300: =IF(G300<>0,G300-L300," ") | N300: =IF((G300-L300)<>0,N$1-A300," ")

Sheet Apr
A1: =G1-H1-SUM(P1:AA1) -> 0 | B1: Check Total | C1: Sales Mileage | D1: =SUM(D5:D300) -> 0 | E1: Sales Description | F1: Enter Expense Code Letter | G1: =SUM(G5:G300) -> 0 | H1: =SUM(H5:H300) -> 0 | I1: =SUM(I5:I300) -> 0 | K1: For your information only. Enter How Paid e.g. Cash, Cheque etc., | L1: =SUM(L5:L300) -> 0 | M1: =SUM(M5:M300) -> 0 | N1: =TODAY() -> 45397 | P1: =SUM(P5:P300) -> 0 | Q1: =SUM(Q5:Q300) -> 0 | R1: =SUM(R5:R300) -> 0 | S1: =SUM(S5:S300) -> 0 | T1: =SUM(T5:T300) -> 0 | U1: =SUM(U5:U300) -> 0 | V1: =SUM(V5:V300) -> 0 | W1: =SUM(W5:W300) -> 0 | ... AB1: =SUM(AB5:AB300) -> 0 | AC1: =AB1 -> 0
A2: Sales Date | B2: Customer Name | C2: Sales Invoice Number or reference | D2: Sales Mileage | G2: Sales Value including Vat | H2: 20 | I2: Sales Net of Vat | L2: Receipts from Customers | P2: Sales Net of Vat | X2: Other Income | Y2: Investment Grants | Z2: Bad Debts written off | AA2: =AA1 -> 0 | AB2: Sub contractors only
H3: Vat Output | L3: Actual amount received | M3: Sales Value not yet received | N3: Number of Days Outstanding | P3: Product A Sales | Q3: Product B Sales | R3: Product C Sales | S3: Product 4 Sales | T3: Product 5 Sales | U3: Product 6 Sales | V3: Product 7 Sales | W3: Product 8 Sales | AA3: Sale of Fixed Assets | AB3: CIS Tax Deducted | AC3: CIS Certificate reference
P4: A | Q4: B | R4: C | S4: 4 | T4: 5 | U4: 6 | V4: 7 | W4: 8 | X4: D | Y4: G | Z4: O | AA4: FS
F5: =IF((G5<>0),"Enter Letter"," ") | H5: =IF(H$4>0,(IF(G5<>0,G5*H$4/100," ")),IF(G5<>0,G5*H$2/(100+H$2)," ")) | I5: =IF((G5<>0),G5-H5," ") | M5: =IF(G5<>0,G5-L5," ") | N5: =IF((G5-L5)<>0,N$1-A5," ") | P5: =IF((F5="a"),I5," ") | Q5: =IF((F5="b"),I5," ") | R5: =IF((F5="c"),I5," ") | S5: =IF((F5=S$4),I5," ") | T5: =IF((F5=T$4),I5," ") | U5: =IF((F5=U$4),I5," ") | V5: =IF((F5=V$4),I5," ") | W5: =IF((F5=W$4),I5," ") | X5: =IF((F5="d"),I5," ") | Y5: =IF((F5="g"),I5," ") | Z5: =IF((F5="o"),I5," ") | AA5: =IF((F5="FS"),I5," ")
F6: =IF((G6<>0),"Enter Letter"," ") | H6: =IF(H$4>0,(IF(G6<>0,G6*H$4/100," ")),IF(G6<>0,G6*H$2/(100+H$2)," ")) | I6: =IF((G6<>0),G6-H6," ") | M6: =IF(G6<>0,G6-L6," ") | N6: =IF((G6-L6)<>0,N$1-A6," ") | P6: =IF((F6="a"),I6," ") | Q6: =IF((F6="b"),I6," ") | R6: =IF((F6="c"),I6," ") | S6: =IF((F6=S$4),I6," ") | T6: =IF((F6=T$4),I6," ") | U6: =IF((F6=U$4),I6," ") | V6: =IF((F6=V$4),I6," ") | W6: =IF((F6=W$4),I6," ") | X6: =IF((F6="d"),I6," ") | Y6: =IF((F6="g"),I6," ") | Z6: =IF((F6="o"),I6," ") | AA6: =IF((F6="FS"),I6," ")
F7: =IF((G7<>0),"Enter Letter"," ") | H7: =IF(H$4>0,(IF(G7<>0,G7*H$4/100," ")),IF(G7<>0,G7*H$2/(100+H$2)," ")) | I7: =IF((G7<>0),G7-H7," ") | M7: =IF(G7<>0,G7-L7," ") | N7: =IF((G7-L7)<>0,N$1-A7," ") | P7: =IF((F7="a"),I7," ") | Q7: =IF((F7="b"),I7," ") | R7: =IF((F7="c"),I7," ") | S7: =IF((F7=S$4),I7," ") | T7: =IF((F7=T$4),I7," ") | U7: =IF((F7=U$4),I7," ") | V7: =IF((F7=V$4),I7," ") | W7: =IF((F7=W$4),I7," ") | X7: =IF((F7="d"),I7," ") | Y7: =IF((F7="g"),I7," ") | Z7: =IF((F7="o"),I7," ") | AA7: =IF((F7="FS"),I7," ")
F8: =IF((G8<>0),"Enter Letter"," ") | H8: =IF(H$4>0,(IF(G8<>0,G8*H$4/100," ")),IF(G8<>0,G8*H$2/(100+H$2)," ")) | I8: =IF((G8<>0),G8-H8," ") | M8: =IF(G8<>0,G8-L8," ") | N8: =IF((G8-L8)<>0,N$1-A8," ") | P8: =IF((F8="a"),I8," ") | Q8: =IF((F8="b"),I8," ") | R8: =IF((F8="c"),I8," ") | S8: =IF((F8=S$4),I8," ") | T8: =IF((F8=T$4),I8," ") | U8: =IF((F8=U$4),I8," ") | V8: =IF((F8=V$4),I8," ") | W8: =IF((F8=W$4),I8," ") | X8: =IF((F8="d"),I8," ") | Y8: =IF((F8="g"),I8," ") | Z8: =IF((F8="o"),I8," ") | AA8: =IF((F8="FS"),I8," ")
F9: =IF((G9<>0),"Enter Letter"," ") | H9: =IF(H$4>0,(IF(G9<>0,G9*H$4/100," ")),IF(G9<>0,G9*H$2/(100+H$2)," ")) | I9: =IF((G9<>0),G9-H9," ") | M9: =IF(G9<>0,G9-L9," ") | N9: =IF((G9-L9)<>0,N$1-A9," ") | P9: =IF((F9="a"),I9," ") | Q9: =IF((F9="b"),I9," ") | R9: =IF((F9="c"),I9," ") | S9: =IF((F9=S$4),I9," ") | T9: =IF((F9=T$4),I9," ") | U9: =IF((F9=U$4),I9," ") | V9: =IF((F9=V$4),I9," ") | W9: =IF((F9=W$4),I9," ") | X9: =IF((F9="d"),I9," ") | Y9: =IF((F9="g"),I9," ") | Z9: =IF((F9="o"),I9," ") | AA9: =IF((F9="FS"),I9," ")
F10: =IF((G10<>0),"Enter Letter"," ") | H10: =IF(H$4>0,(IF(G10<>0,G10*H$4/100," ")),IF(G10<>0,G10*H$2/(100+H$2)," ")) | I10: =IF((G10<>0),G10-H10," ") | M10: =IF(G10<>0,G10-L10," ") | N10: =IF((G10-L10)<>0,N$1-A10," ") | P10: =IF((F10="a"),I10," ") | Q10: =IF((F10="b"),I10," ") | R10: =IF((F10="c"),I10," ") | S10: =IF((F10=S$4),I10," ") | T10: =IF((F10=T$4),I10," ") | U10: =IF((F10=U$4),I10," ") | V10: =IF((F10=V$4),I10," ") | W10: =IF((F10=W$4),I10," ") | X10: =IF((F10="d"),I10," ") | Y10: =IF((F10="g"),I10," ") | Z10: =IF((F10="o"),I10," ") | AA10: =IF((F10="FS"),I10," ")
F11: =IF((G11<>0),"Enter Letter"," ") | H11: =IF(H$4>0,(IF(G11<>0,G11*H$4/100," ")),IF(G11<>0,G11*H$2/(100+H$2)," ")) | I11: =IF((G11<>0),G11-H11," ") | M11: =IF(G11<>0,G11-L11," ") | N11: =IF((G11-L11)<>0,N$1-A11," ") | P11: =IF((F11="a"),I11," ") | Q11: =IF((F11="b"),I11," ") | R11: =IF((F11="c"),I11," ") | S11: =IF((F11=S$4),I11," ") | T11: =IF((F11=T$4),I11," ") | U11: =IF((F11=U$4),I11," ") | V11: =IF((F11=V$4),I11," ") | W11: =IF((F11=W$4),I11," ") | X11: =IF((F11="d"),I11," ") | Y11: =IF((F11="g"),I11," ") | Z11: =IF((F11="o"),I11," ") | AA11: =IF((F11="FS"),I11," ")
F12: =IF((G12<>0),"Enter Letter"," ") | H12: =IF(H$4>0,(IF(G12<>0,G12*H$4/100," ")),IF(G12<>0,G12*H$2/(100+H$2)," ")) | I12: =IF((G12<>0),G12-H12," ") | M12: =IF(G12<>0,G12-L12," ") | N12: =IF((G12-L12)<>0,N$1-A12," ") | P12: =IF((F12="a"),I12," ") | Q12: =IF((F12="b"),I12," ") | R12: =IF((F12="c"),I12," ") | S12: =IF((F12=S$4),I12," ") | T12: =IF((F12=T$4),I12," ") | U12: =IF((F12=U$4),I12," ") | V12: =IF((F12=V$4),I12," ") | W12: =IF((F12=W$4),I12," ") | X12: =IF((F12="d"),I12," ") | Y12: =IF((F12="g"),I12," ") | Z12: =IF((F12="o"),I12," ") | AA12: =IF((F12="FS"),I12," ")
F13: =IF((G13<>0),"Enter Letter"," ") | H13: =IF(H$4>0,(IF(G13<>0,G13*H$4/100," ")),IF(G13<>0,G13*H$2/(100+H$2)," ")) | I13: =IF((G13<>0),G13-H13," ") | M13: =IF(G13<>0,G13-L13," ") | N13: =IF((G13-L13)<>0,N$1-A13," ") | P13: =IF((F13="a"),I13," ") | Q13: =IF((F13="b"),I13," ") | R13: =IF((F13="c"),I13," ") | S13: =IF((F13=S$4),I13," ") | T13: =IF((F13=T$4),I13," ") | U13: =IF((F13=U$4),I13," ") | V13: =IF((F13=V$4),I13," ") | W13: =IF((F13=W$4),I13," ") | X13: =IF((F13="d"),I13," ") | Y13: =IF((F13="g"),I13," ") | Z13: =IF((F13="o"),I13," ") | AA13: =IF((F13="FS"),I13," ")
F14: =IF((G14<>0),"Enter Letter"," ") | H14: =IF(H$4>0,(IF(G14<>0,G14*H$4/100," ")),IF(G14<>0,G14*H$2/(100+H$2)," ")) | I14: =IF((G14<>0),G14-H14," ") | M14: =IF(G14<>0,G14-L14," ") | N14: =IF((G14-L14)<>0,N$1-A14," ") | P14: =IF((F14="a"),I14," ") | Q14: =IF((F14="b"),I14," ") | R14: =IF((F14="c"),I14," ") | S14: =IF((F14=S$4),I14," ") | T14: =IF((F14=T$4),I14," ") | U14: =IF((F14=U$4),I14," ") | V14: =IF((F14=V$4),I14," ") | W14: =IF((F14=W$4),I14," ") | X14: =IF((F14="d"),I14," ") | Y14: =IF((F14="g"),I14," ") | Z14: =IF((F14="o"),I14," ") | AA14: =IF((F14="FS"),I14," ")
F15: =IF((G15<>0),"Enter Letter"," ") | H15: =IF(H$4>0,(IF(G15<>0,G15*H$4/100," ")),IF(G15<>0,G15*H$2/(100+H$2)," ")) | I15: =IF((G15<>0),G15-H15," ") | M15: =IF(G15<>0,G15-L15," ") | N15: =IF((G15-L15)<>0,N$1-A15," ") | P15: =IF((F15="a"),I15," ") | Q15: =IF((F15="b"),I15," ") | R15: =IF((F15="c"),I15," ") | S15: =IF((F15=S$4),I15," ") | T15: =IF((F15=T$4),I15," ") | U15: =IF((F15=U$4),I15," ") | V15: =IF((F15=V$4),I15," ") | W15: =IF((F15=W$4),I15," ") | X15: =IF((F15="d"),I15," ") | Y15: =IF((F15="g"),I15," ") | Z15: =IF((F15="o"),I15," ") | AA15: =IF((F15="FS"),I15," ")
F16: =IF((G16<>0),"Enter Letter"," ") | H16: =IF(H$4>0,(IF(G16<>0,G16*H$4/100," ")),IF(G16<>0,G16*H$2/(100+H$2)," ")) | I16: =IF((G16<>0),G16-H16," ") | M16: =IF(G16<>0,G16-L16," ") | N16: =IF((G16-L16)<>0,N$1-A16," ") | P16: =IF((F16="a"),I16," ") | Q16: =IF((F16="b"),I16," ") | R16: =IF((F16="c"),I16," ") | S16: =IF((F16=S$4),I16," ") | T16: =IF((F16=T$4),I16," ") | U16: =IF((F16=U$4),I16," ") | V16: =IF((F16=V$4),I16," ") | W16: =IF((F16=W$4),I16," ") | X16: =IF((F16="d"),I16," ") | Y16: =IF((F16="g"),I16," ") | Z16: =IF((F16="o"),I16," ") | AA16: =IF((F16="FS"),I16," ")
... F300: =IF((G300<>0),"Enter Letter"," ") | H300: =IF(H$4>0,(IF(G300<>0,G300*H$4/100," ")),IF(G300<>0,G300*H$2/(100+H$2)," ")) | I300: =IF((G300<>0),G300-H300," ") | M300: =IF(G300<>0,G300-L300," ") | N300: =IF((G300-L300)<>0,N$1-A300," ") | P300: =IF((F300="a"),I300," ") | Q300: =IF((F300="b"),I300," ") | R300: =IF((F300="c"),I300," ") | S300: =IF((F300=S$4),I300," ") | T300: =IF((F300=T$4),I300," ") | U300: =IF((F300=U$4),I300," ") | V300: =IF((F300=V$4),I300," ") | W300: =IF((F300=W$4),I300," ") | X300: =IF((F300="d"),I300," ") | Y300: =IF((F300="g"),I300," ") | Z300: =IF((F300="o"),I300," ") | AA300: =IF((F300="FS"),I300," ")

Sheet May
A1: =G1-H1-SUM(P1:AA1) -> 0 | B1: Check Total | C1: Sales Mileage | D1: =SUM(D5:D300) -> 0 | E1: Sales Description | F1: Enter Expense Code Letter | G1: =SUM(G5:G300) -> 0 | H1: =SUM(H5:H300) -> 0 | I1: =SUM(I5:I300) -> 0 | K1: For your information only. Enter How Paid e.g. Cash, Cheque etc., | L1: =SUM(L5:L300) -> 0 | M1: =SUM(M5:M300) -> 0 | N1: =TODAY() -> 45397 | P1: =SUM(P5:P300) -> 0 | Q1: =SUM(Q5:Q300) -> 0 | R1: =SUM(R5:R300) -> 0 | S1: =SUM(S5:S300) -> 0 | T1: =SUM(T5:T300) -> 0 | U1: =SUM(U5:U300) -> 0 | V1: =SUM(V5:V300) -> 0 | W1: =SUM(W5:W300) -> 0 | ... AB1: =SUM(AB5:AB300) -> 0 | AC1: =AB1+Apr!AC1 -> 0
A2: Sales Date | B2: Customer Name | C2: Sales Invoice Number or reference | D2: Sales Mileage | G2: Sales Value including Vat | H2: =Apr!H2 -> 20 | I2: Sales Net of Vat | L2: Receipts from Customers | P2: Sales Net of Vat | X2: Other Income | Y2: Investment Grants | Z2: Bad Debts written off | AA2: =AA1+Apr!AA2 -> 0 | AB2: Sub contractors only
H3: Vat Output | L3: Actual amount received | M3: Sales Value not yet received | N3: Number of Days Outstanding | P3: =Apr!P3 -> Product A Sales | Q3: =Apr!Q3 -> Product B Sales | R3: =Apr!R3 -> Product C Sales | S3: =Apr!S3 -> Product 4 Sales | T3: =Apr!T3 -> Product 5 Sales | U3: =Apr!U3 -> Product 6 Sales | V3: =Apr!V3 -> Product 7 Sales | W3: =Apr!W3 -> Product 8 Sales | AA3: Sale of Fixed Assets | AB3: CIS Tax Deducted | AC3: CIS Certificate reference
H4: =Apr!H4 -> 0 | P4: =Apr!P4 -> A | Q4: =Apr!Q4 -> B | R4: =Apr!R4 -> C | S4: =Apr!S4 -> 4 | T4: =Apr!T4 -> 5 | U4: =Apr!U4 -> 6 | V4: =Apr!V4 -> 7 | W4: =Apr!W4 -> 8 | X4: D | Y4: G | Z4: O | AA4: FS
F5: =IF((G5<>0),"Enter Letter"," ") | H5: =IF(H$4>0,(IF(G5<>0,G5*H$4/100," ")),IF(G5<>0,G5*H$2/(100+H$2)," ")) | I5: =IF((G5<>0),G5-H5," ") | M5: =IF(G5<>0,G5-L5," ") | N5: =IF((G5-L5)<>0,N$1-A5," ") | P5: =IF((F5="a"),I5," ") | Q5: =IF((F5="b"),I5," ") | R5: =IF((F5="c"),I5," ") | S5: =IF((F5=S$4),I5," ") | T5: =IF((F5=T$4),I5," ") | U5: =IF((F5=U$4),I5," ") | V5: =IF((F5=V$4),I5," ") | W5: =IF((F5=W$4),I5," ") | X5: =IF((F5="d"),I5," ") | Y5: =IF((F5="g"),I5," ") | Z5: =IF((F5="o"),I5," ") | AA5: =IF((F5="FS"),I5," ")
F6: =IF((G6<>0),"Enter Letter"," ") | H6: =IF(H$4>0,(IF(G6<>0,G6*H$4/100," ")),IF(G6<>0,G6*H$2/(100+H$2)," ")) | I6: =IF((G6<>0),G6-H6," ") | M6: =IF(G6<>0,G6-L6," ") | N6: =IF((G6-L6)<>0,N$1-A6," ") | P6: =IF((F6="a"),I6," ") | Q6: =IF((F6="b"),I6," ") | R6: =IF((F6="c"),I6," ") | S6: =IF((F6=S$4),I6," ") | T6: =IF((F6=T$4),I6," ") | U6: =IF((F6=U$4),I6," ") | V6: =IF((F6=V$4),I6," ") | W6: =IF((F6=W$4),I6," ") | X6: =IF((F6="d"),I6," ") | Y6: =IF((F6="g"),I6," ") | Z6: =IF((F6="o"),I6," ") | AA6: =IF((F6="FS"),I6," ")
F7: =IF((G7<>0),"Enter Letter"," ") | H7: =IF(H$4>0,(IF(G7<>0,G7*H$4/100," ")),IF(G7<>0,G7*H$2/(100+H$2)," ")) | I7: =IF((G7<>0),G7-H7," ") | M7: =IF(G7<>0,G7-L7," ") | N7: =IF((G7-L7)<>0,N$1-A7," ") | P7: =IF((F7="a"),I7," ") | Q7: =IF((F7="b"),I7," ") | R7: =IF((F7="c"),I7," ") | S7: =IF((F7=S$4),I7," ") | T7: =IF((F7=T$4),I7," ") | U7: =IF((F7=U$4),I7," ") | V7: =IF((F7=V$4),I7," ") | W7: =IF((F7=W$4),I7," ") | X7: =IF((F7="d"),I7," ") | Y7: =IF((F7="g"),I7," ") | Z7: =IF((F7="o"),I7," ") | AA7: =IF((F7="FS"),I7," ")
F8: =IF((G8<>0),"Enter Letter"," ") | H8: =IF(H$4>0,(IF(G8<>0,G8*H$4/100," ")),IF(G8<>0,G8*H$2/(100+H$2)," ")) | I8: =IF((G8<>0),G8-H8," ") | M8: =IF(G8<>0,G8-L8," ") | N8: =IF((G8-L8)<>0,N$1-A8," ") | P8: =IF((F8="a"),I8," ") | Q8: =IF((F8="b"),I8," ") | R8: =IF((F8="c"),I8," ") | S8: =IF((F8=S$4),I8," ") | T8: =IF((F8=T$4),I8," ") | U8: =IF((F8=U$4),I8," ") | V8: =IF((F8=V$4),I8," ") | W8: =IF((F8=W$4),I8," ") | X8: =IF((F8="d"),I8," ") | Y8: =IF((F8="g"),I8," ") | Z8: =IF((F8="o"),I8," ") | AA8: =IF((F8="FS"),I8," ")
F9: =IF((G9<>0),"Enter Letter"," ") | H9: =IF(H$4>0,(IF(G9<>0,G9*H$4/100," ")),IF(G9<>0,G9*H$2/(100+H$2)," ")) | I9: =IF((G9<>0),G9-H9," ") | M9: =IF(G9<>0,G9-L9," ") | N9: =IF((G9-L9)<>0,N$1-A9," ") | P9: =IF((F9="a"),I9," ") | Q9: =IF((F9="b"),I9," ") | R9: =IF((F9="c"),I9," ") | S9: =IF((F9=S$4),I9," ") | T9: =IF((F9=T$4),I9," ") | U9: =IF((F9=U$4),I9," ") | V9: =IF((F9=V$4),I9," ") | W9: =IF((F9=W$4),I9," ") | X9: =IF((F9="d"),I9," ") | Y9: =IF((F9="g"),I9," ") | Z9: =IF((F9="o"),I9," ") | AA9: =IF((F9="FS"),I9," ")
F10: =IF((G10<>0),"Enter Letter"," ") | H10: =IF(H$4>0,(IF(G10<>0,G10*H$4/100," ")),IF(G10<>0,G10*H$2/(100+H$2)," ")) | I10: =IF((G10<>0),G10-H10," ") | M10: =IF(G10<>0,G10-L10," ") | N10: =IF((G10-L10)<>0,N$1-A10," ") | P10: =IF((F10="a"),I10," ") | Q10: =IF((F10="b"),I10," ") | R10: =IF((F10="c"),I10," ") | S10: =IF((F10=S$4),I10," ") | T10: =IF((F10=T$4),I10," ") | U10: =IF((F10=U$4),I10," ") | V10: =IF((F10=V$4),I10," ") | W10: =IF((F10=W$4),I10," ") | X10: =IF((F10="d"),I10," ") | Y10: =IF((F10="g"),I10," ") | Z10: =IF((F10="o"),I10," ") | AA10: =IF((F10="FS"),I10," ")
F11: =IF((G11<>0),"Enter Letter"," ") | H11: =IF(H$4>0,(IF(G11<>0,G11*H$4/100," ")),IF(G11<>0,G11*H$2/(100+H$2)," ")) | I11: =IF((G11<>0),G11-H11," ") | M11: =IF(G11<>0,G11-L11," ") | N11: =IF((G11-L11)<>0,N$1-A11," ") | P11: =IF((F11="a"),I11," ") | Q11: =IF((F11="b"),I11," ") | R11: =IF((F11="c"),I11," ") | S11: =IF((F11=S$4),I11," ") | T11: =IF((F11=T$4),I11," ") | U11: =IF((F11=U$4),I11," ") | V11: =IF((F11=V$4),I11," ") | W11: =IF((F11=W$4),I11," ") | X11: =IF((F11="d"),I11," ") | Y11: =IF((F11="g"),I11," ") | Z11: =IF((F11="o"),I11," ") | AA11: =IF((F11="FS"),I11," ")
F12: =IF((G12<>0),"Enter Letter"," ") | H12: =IF(H$4>0,(IF(G12<>0,G12*H$4/100," ")),IF(G12<>0,G12*H$2/(100+H$2)," ")) | I12: =IF((G12<>0),G12-H12," ") | M12: =IF(G12<>0,G12-L12," ") | N12: =IF((G12-L12)<>0,N$1-A12," ") | P12: =IF((F12="a"),I12," ") | Q12: =IF((F12="b"),I12," ") | R12: =IF((F12="c"),I12," ") | S12: =IF((F12=S$4),I12," ") | T12: =IF((F12=T$4),I12," ") | U12: =IF((F12=U$4),I12," ") | V12: =IF((F12=V$4),I12," ") | W12: =IF((F12=W$4),I12," ") | X12: =IF((F12="d"),I12," ") | Y12: =IF((F12="g"),I12," ") | Z12: =IF((F12="o"),I12," ") | AA12: =IF((F12="FS"),I12," ")
F13: =IF((G13<>0),"Enter Letter"," ") | H13: =IF(H$4>0,(IF(G13<>0,G13*H$4/100," ")),IF(G13<>0,G13*H$2/(100+H$2)," ")) | I13: =IF((G13<>0),G13-H13," ") | M13: =IF(G13<>0,G13-L13," ") | N13: =IF((G13-L13)<>0,N$1-A13," ") | P13: =IF((F13="a"),I13," ") | Q13: =IF((F13="b"),I13," ") | R13: =IF((F13="c"),I13," ") | S13: =IF((F13=S$4),I13," ") | T13: =IF((F13=T$4),I13," ") | U13: =IF((F13=U$4),I13," ") | V13: =IF((F13=V$4),I13," ") | W13: =IF((F13=W$4),I13," ") | X13: =IF((F13="d"),I13," ") | Y13: =IF((F13="g"),I13," ") | Z13: =IF((F13="o"),I13," ") | AA13: =IF((F13="FS"),I13," ")
F14: =IF((G14<>0),"Enter Letter"," ") | H14: =IF(H$4>0,(IF(G14<>0,G14*H$4/100," ")),IF(G14<>0,G14*H$2/(100+H$2)," ")) | I14: =IF((G14<>0),G14-H14," ") | M14: =IF(G14<>0,G14-L14," ") | N14: =IF((G14-L14)<>0,N$1-A14," ") | P14: =IF((F14="a"),I14," ") | Q14: =IF((F14="b"),I14," ") | R14: =IF((F14="c"),I14," ") | S14: =IF((F14=S$4),I14," ") | T14: =IF((F14=T$4),I14," ") | U14: =IF((F14=U$4),I14," ") | V14: =IF((F14=V$4),I14," ") | W14: =IF((F14=W$4),I14," ") | X14: =IF((F14="d"),I14," ") | Y14: =IF((F14="g"),I14," ") | Z14: =IF((F14="o"),I14," ") | AA14: =IF((F14="FS"),I14," ")
F15: =IF((G15<>0),"Enter Letter"," ") | H15: =IF(H$4>0,(IF(G15<>0,G15*H$4/100," ")),IF(G15<>0,G15*H$2/(100+H$2)," ")) | I15: =IF((G15<>0),G15-H15," ") | M15: =IF(G15<>0,G15-L15," ") | N15: =IF((G15-L15)<>0,N$1-A15," ") | P15: =IF((F15="a"),I15," ") | Q15: =IF((F15="b"),I15," ") | R15: =IF((F15="c"),I15," ") | S15: =IF((F15=S$4),I15," ") | T15: =IF((F15=T$4),I15," ") | U15: =IF((F15=U$4),I15," ") | V15: =IF((F15=V$4),I15," ") | W15: =IF((F15=W$4),I15," ") | X15: =IF((F15="d"),I15," ") | Y15: =IF((F15="g"),I15," ") | Z15: =IF((F15="o"),I15," ") | AA15: =IF((F15="FS"),I15," ")
F16: =IF((G16<>0),"Enter Letter"," ") | H16: =IF(H$4>0,(IF(G16<>0,G16*H$4/100," ")),IF(G16<>0,G16*H$2/(100+H$2)," ")) | I16: =IF((G16<>0),G16-H16," ") | M16: =IF(G16<>0,G16-L16," ") | N16: =IF((G16-L16)<>0,N$1-A16," ") | P16: =IF((F16="a"),I16," ") | Q16: =IF((F16="b"),I16," ") | R16: =IF((F16="c"),I16," ") | S16: =IF((F16=S$4),I16," ") | T16: =IF((F16=T$4),I16," ") | U16: =IF((F16=U$4),I16," ") | V16: =IF((F16=V$4),I16," ") | W16: =IF((F16=W$4),I16," ") | X16: =IF((F16="d"),I16," ") | Y16: =IF((F16="g"),I16," ") | Z16: =IF((F16="o"),I16," ") | AA16: =IF((F16="FS"),I16," ")
... F300: =IF((G300<>0),"Enter Letter"," ") | H300: =IF(H$4>0,(IF(G300<>0,G300*H$4/100," ")),IF(G300<>0,G300*H$2/(100+H$2)," ")) | I300: =IF((G300<>0),G300-H300," ") | M300: =IF(G300<>0,G300-L300," ") | N300: =IF((G300-L300)<>0,N$1-A300," ") | P300: =IF((F300="a"),I300," ") | Q300: =IF((F300="b"),I300," ") | R300: =IF((F300="c"),I300," ") | S300: =IF((F300=S$4),I300," ") | T300: =IF((F300=T$4),I300," ") | U300: =IF((F300=U$4),I300," ") | V300: =IF((F300=V$4),I300," ") | W300: =IF((F300=W$4),I300," ") | X300: =IF((F300="d"),I300," ") | Y300: =IF((F300="g"),I300," ") | Z300: =IF((F300="o"),I300," ") | AA300: =IF((F300="FS"),I300," ")

Sheet Jun
A1: =G1-H1-SUM(P1:AA1) -> 0 | B1: Check Total | C1: Sales Mileage | D1: =SUM(D5:D300) -> 0 | E1: Sales Description | F1: Enter Expense Code Letter | G1: =SUM(G5:G300) -> 0 | H1: =SUM(H5:H300) -> 0 | I1: =SUM(I5:I300) -> 0 | K1: For your information only. Enter How Paid e.g. Cash, Cheque etc., | L1: =SUM(L5:L300) -> 0 | M1: =SUM(M5:M300) -> 0 | N1: =TODAY() -> 45397 | P1: =SUM(P5:P300) -> 0 | Q1: =SUM(Q5:Q300) -> 0 | R1: =SUM(R5:R300) -> 0 | S1: =SUM(S5:S300) -> 0 | T1: =SUM(T5:T300) -> 0 | U1: =SUM(U5:U300) -> 0 | V1: =SUM(V5:V300) -> 0 | W1: =SUM(W5:W300) -> 0 | ... AB1: =SUM(AB5:AB300) -> 0 | AC1: =AB1+May!AC1 -> 0
A2: Sales Date | B2: Customer Name | C2: Sales Invoice Number or reference | D2: Sales Mileage | G2: Sales Value including Vat | H2: =May!H2 -> 20 | I2: Sales Net of Vat | L2: Receipts from Customers | P2: Sales Net of Vat | X2: Other Income | Y2: Investment Grants | Z2: Bad Debts written off | AA2: =AA1+May!AA2 -> 0 | AB2: Sub contractors only
H3: Vat Output | L3: Actual amount received | M3: Sales Value not yet received | N3: Number of Days Outstanding | P3: =Apr!P3 -> Product A Sales | Q3: =Apr!Q3 -> Product B Sales | R3: =Apr!R3 -> Product C Sales | S3: =Apr!S3 -> Product 4 Sales | T3: =Apr!T3 -> Product 5 Sales | U3: =Apr!U3 -> Product 6 Sales | V3: =Apr!V3 -> Product 7 Sales | W3: =Apr!W3 -> Product 8 Sales | AA3: Sale of Fixed Assets | AB3: CIS Tax Deducted | AC3: CIS Certificate reference
H4: =May!H4 -> 0 | P4: =Apr!P4 -> A | Q4: =Apr!Q4 -> B | R4: =Apr!R4 -> C | S4: =Apr!S4 -> 4 | T4: =Apr!T4 -> 5 | U4: =Apr!U4 -> 6 | V4: =Apr!V4 -> 7 | W4: =Apr!W4 -> 8 | X4: D | Y4: G | Z4: O | AA4: FS
F5: =IF((G5<>0),"Enter Letter"," ") | H5: =IF(H$4>0,(IF(G5<>0,G5*H$4/100," ")),IF(G5<>0,G5*H$2/(100+H$2)," ")) | I5: =IF((G5<>0),G5-H5," ") | M5: =IF(G5<>0,G5-L5," ") | N5: =IF((G5-L5)<>0,N$1-A5," ") | P5: =IF((F5="a"),I5," ") | Q5: =IF((F5="b"),I5," ") | R5: =IF((F5="c"),I5," ") | S5: =IF((F5=S$4),I5," ") | T5: =IF((F5=T$4),I5," ") | U5: =IF((F5=U$4),I5," ") | V5: =IF((F5=V$4),I5," ") | W5: =IF((F5=W$4),I5," ") | X5: =IF((F5="d"),I5," ") | Y5: =IF((F5="g"),I5," ") | Z5: =IF((F5="o"),I5," ") | AA5: =IF((F5="FS"),I5," ")
F6: =IF((G6<>0),"Enter Letter"," ") | H6: =IF(H$4>0,(IF(G6<>0,G6*H$4/100," ")),IF(G6<>0,G6*H$2/(100+H$2)," ")) | I6: =IF((G6<>0),G6-H6," ") | M6: =IF(G6<>0,G6-L6," ") | N6: =IF((G6-L6)<>0,N$1-A6," ") | P6: =IF((F6="a"),I6," ") | Q6: =IF((F6="b"),I6," ") | R6: =IF((F6="c"),I6," ") | S6: =IF((F6=S$4),I6," ") | T6: =IF((F6=T$4),I6," ") | U6: =IF((F6=U$4),I6," ") | V6: =IF((F6=V$4),I6," ") | W6: =IF((F6=W$4),I6," ") | X6: =IF((F6="d"),I6," ") | Y6: =IF((F6="g"),I6," ") | Z6: =IF((F6="o"),I6," ") | AA6: =IF((F6="FS"),I6," ")
F7: =IF((G7<>0),"Enter Letter"," ") | H7: =IF(H$4>0,(IF(G7<>0,G7*H$4/100," ")),IF(G7<>0,G7*H$2/(100+H$2)," ")) | I7: =IF((G7<>0),G7-H7," ") | M7: =IF(G7<>0,G7-L7," ") | N7: =IF((G7-L7)<>0,N$1-A7," ") | P7: =IF((F7="a"),I7," ") | Q7: =IF((F7="b"),I7," ") | R7: =IF((F7="c"),I7," ") | S7: =IF((F7=S$4),I7," ") | T7: =IF((F7=T$4),I7," ") | U7: =IF((F7=U$4),I7," ") | V7: =IF((F7=V$4),I7," ") | W7: =IF((F7=W$4),I7," ") | X7: =IF((F7="d"),I7," ") | Y7: =IF((F7="g"),I7," ") | Z7: =IF((F7="o"),I7," ") | AA7: =IF((F7="FS"),I7," ")
F8: =IF((G8<>0),"Enter Letter"," ") | H8: =IF(H$4>0,(IF(G8<>0,G8*H$4/100," ")),IF(G8<>0,G8*H$2/(100+H$2)," ")) | I8: =IF((G8<>0),G8-H8," ") | M8: =IF(G8<>0,G8-L8," ") | N8: =IF((G8-L8)<>0,N$1-A8," ") | P8: =IF((F8="a"),I8," ") | Q8: =IF((F8="b"),I8," ") | R8: =IF((F8="c"),I8," ") | S8: =IF((F8=S$4),I8," ") | T8: =IF((F8=T$4),I8," ") | U8: =IF((F8=U$4),I8," ") | V8: =IF((F8=V$4),I8," ") | W8: =IF((F8=W$4),I8," ") | X8: =IF((F8="d"),I8," ") | Y8: =IF((F8="g"),I8," ") | Z8: =IF((F8="o"),I8," ") | AA8: =IF((F8="FS"),I8," ")
F9: =IF((G9<>0),"Enter Letter"," ") | H9: =IF(H$4>0,(IF(G9<>0,G9*H$4/100," ")),IF(G9<>0,G9*H$2/(100+H$2)," ")) | I9: =IF((G9<>0),G9-H9," ") | M9: =IF(G9<>0,G9-L9," ") | N9: =IF((G9-L9)<>0,N$1-A9," ") | P9: =IF((F9="a"),I9," ") | Q9: =IF((F9="b"),I9," ") | R9: =IF((F9="c"),I9," ") | S9: =IF((F9=S$4),I9," ") | T9: =IF((F9=T$4),I9," ") | U9: =IF((F9=U$4),I9," ") | V9: =IF((F9=V$4),I9," ") | W9: =IF((F9=W$4),I9," ") | X9: =IF((F9="d"),I9," ") | Y9: =IF((F9="g"),I9," ") | Z9: =IF((F9="o"),I9," ") | AA9: =IF((F9="FS"),I9," ")
F10: =IF((G10<>0),"Enter Letter"," ") | H10: =IF(H$4>0,(IF(G10<>0,G10*H$4/100," ")),IF(G10<>0,G10*H$2/(100+H$2)," ")) | I10: =IF((G10<>0),G10-H10," ") | M10: =IF(G10<>0,G10-L10," ") | N10: =IF((G10-L10)<>0,N$1-A10," ") | P10: =IF((F10="a"),I10," ") | Q10: =IF((F10="b"),I10," ") | R10: =IF((F10="c"),I10," ") | S10: =IF((F10=S$4),I10," ") | T10: =IF((F10=T$4),I10," ") | U10: =IF((F10=U$4),I10," ") | V10: =IF((F10=V$4),I10," ") | W10: =IF((F10=W$4),I10," ") | X10: =IF((F10="d"),I10," ") | Y10: =IF((F10="g"),I10," ") | Z10: =IF((F10="o"),I10," ") | AA10: =IF((F10="FS"),I10," ")
F11: =IF((G11<>0),"Enter Letter"," ") | H11: =IF(H$4>0,(IF(G11<>0,G11*H$4/100," ")),IF(G11<>0,G11*H$2/(100+H$2)," ")) | I11: =IF((G11<>0),G11-H11," ") | M11: =IF(G11<>0,G11-L11," ") | N11: =IF((G11-L11)<>0,N$1-A11," ") | P11: =IF((F11="a"),I11," ") | Q11: =IF((F11="b"),I11," ") | R11: =IF((F11="c"),I11," ") | S11: =IF((F11=S$4),I11," ") | T11: =IF((F11=T$4),I11," ") | U11: =IF((F11=U$4),I11," ") | V11: =IF((F11=V$4),I11," ") | W11: =IF((F11=W$4),I11," ") | X11: =IF((F11="d"),I11," ") | Y11: =IF((F11="g"),I11," ") | Z11: =IF((F11="o"),I11," ") | AA11: =IF((F11="FS"),I11," ")
F12: =IF((G12<>0),"Enter Letter"," ") | H12: =IF(H$4>0,(IF(G12<>0,G12*H$4/100," ")),IF(G12<>0,G12*H$2/(100+H$2)," ")) | I12: =IF((G12<>0),G12-H12," ") | M12: =IF(G12<>0,G12-L12," ") | N12: =IF((G12-L12)<>0,N$1-A12," ") | P12: =IF((F12="a"),I12," ") | Q12: =IF((F12="b"),I12," ") | R12: =IF((F12="c"),I12," ") | S12: =IF((F12=S$4),I12," ") | T12: =IF((F12=T$4),I12," ") | U12: =IF((F12=U$4),I12," ") | V12: =IF((F12=V$4),I12," ") | W12: =IF((F12=W$4),I12," ") | X12: =IF((F12="d"),I12," ") | Y12: =IF((F12="g"),I12," ") | Z12: =IF((F12="o"),I12," ") | AA12: =IF((F12="FS"),I12," ")
F13: =IF((G13<>0),"Enter Letter"," ") | H13: =IF(H$4>0,(IF(G13<>0,G13*H$4/100," ")),IF(G13<>0,G13*H$2/(100+H$2)," ")) | I13: =IF((G13<>0),G13-H13," ") | M13: =IF(G13<>0,G13-L13," ") | N13: =IF((G13-L13)<>0,N$1-A13," ") | P13: =IF((F13="a"),I13," ") | Q13: =IF((F13="b"),I13," ") | R13: =IF((F13="c"),I13," ") | S13: =IF((F13=S$4),I13," ") | T13: =IF((F13=T$4),I13," ") | U13: =IF((F13=U$4),I13," ") | V13: =IF((F13=V$4),I13," ") | W13: =IF((F13=W$4),I13," ") | X13: =IF((F13="d"),I13," ") | Y13: =IF((F13="g"),I13," ") | Z13: =IF((F13="o"),I13," ") | AA13: =IF((F13="FS"),I13," ")
F14: =IF((G14<>0),"Enter Letter"," ") | H14: =IF(H$4>0,(IF(G14<>0,G14*H$4/100," ")),IF(G14<>0,G14*H$2/(100+H$2)," ")) | I14: =IF((G14<>0),G14-H14," ") | M14: =IF(G14<>0,G14-L14," ") | N14: =IF((G14-L14)<>0,N$1-A14," ") | P14: =IF((F14="a"),I14," ") | Q14: =IF((F14="b"),I14," ") | R14: =IF((F14="c"),I14," ") | S14: =IF((F14=S$4),I14," ") | T14: =IF((F14=T$4),I14," ") | U14: =IF((F14=U$4),I14," ") | V14: =IF((F14=V$4),I14," ") | W14: =IF((F14=W$4),I14," ") | X14: =IF((F14="d"),I14," ") | Y14: =IF((F14="g"),I14," ") | Z14: =IF((F14="o"),I14," ") | AA14: =IF((F14="FS"),I14," ")
F15: =IF((G15<>0),"Enter Letter"," ") | H15: =IF(H$4>0,(IF(G15<>0,G15*H$4/100," ")),IF(G15<>0,G15*H$2/(100+H$2)," ")) | I15: =IF((G15<>0),G15-H15," ") | M15: =IF(G15<>0,G15-L15," ") | N15: =IF((G15-L15)<>0,N$1-A15," ") | P15: =IF((F15="a"),I15," ") | Q15: =IF((F15="b"),I15," ") | R15: =IF((F15="c"),I15," ") | S15: =IF((F15=S$4),I15," ") | T15: =IF((F15=T$4),I15," ") | U15: =IF((F15=U$4),I15," ") | V15: =IF((F15=V$4),I15," ") | W15: =IF((F15=W$4),I15," ") | X15: =IF((F15="d"),I15," ") | Y15: =IF((F15="g"),I15," ") | Z15: =IF((F15="o"),I15," ") | AA15: =IF((F15="FS"),I15," ")
F16: =IF((G16<>0),"Enter Letter"," ") | H16: =IF(H$4>0,(IF(G16<>0,G16*H$4/100," ")),IF(G16<>0,G16*H$2/(100+H$2)," ")) | I16: =IF((G16<>0),G16-H16," ") | M16: =IF(G16<>0,G16-L16," ") | N16: =IF((G16-L16)<>0,N$1-A16," ") | P16: =IF((F16="a"),I16," ") | Q16: =IF((F16="b"),I16," ") | R16: =IF((F16="c"),I16," ") | S16: =IF((F16=S$4),I16," ") | T16: =IF((F16=T$4),I16," ") | U16: =IF((F16=U$4),I16," ") | V16: =IF((F16=V$4),I16," ") | W16: =IF((F16=W$4),I16," ") | X16: =IF((F16="d"),I16," ") | Y16: =IF((F16="g"),I16," ") | Z16: =IF((F16="o"),I16," ") | AA16: =IF((F16="FS"),I16," ")
... F300: =IF((G300<>0),"Enter Letter"," ") | H300: =IF(H$4>0,(IF(G300<>0,G300*H$4/100," ")),IF(G300<>0,G300*H$2/(100+H$2)," ")) | I300: =IF((G300<>0),G300-H300," ") | M300: =IF(G300<>0,G300-L300," ") | N300: =IF((G300-L300)<>0,N$1-A300," ") | P300: =IF((F300="a"),I300," ") | Q300: =IF((F300="b"),I300," ") | R300: =IF((F300="c"),I300," ") | S300: =IF((F300=S$4),I300," ") | T300: =IF((F300=T$4),I300," ") | U300: =IF((F300=U$4),I300," ") | V300: =IF((F300=V$4),I300," ") | W300: =IF((F300=W$4),I300," ") | X300: =IF((F300="d"),I300," ") | Y300: =IF((F300="g"),I300," ") | Z300: =IF((F300="o"),I300," ") | AA300: =IF((F300="FS"),I300," ")

Sheet Jul
A1: =G1-H1-SUM(P1:AA1) -> 0 | B1: Check Total | C1: Sales Mileage | D1: =SUM(D5:D300) -> 0 | E1: Sales Description | F1: Enter Expense Code Letter | G1: =SUM(G5:G300) -> 0 | H1: =SUM(H5:H300) -> 0 | I1: =SUM(I5:I300) -> 0 | K1: For your information only. Enter How Paid e.g. Cash, Cheque etc., | L1: =SUM(L5:L300) -> 0 | M1: =SUM(M5:M300) -> 0 | N1: =TODAY() -> 45397 | P1: =SUM(P5:P300) -> 0 | Q1: =SUM(Q5:Q300) -> 0 | R1: =SUM(R5:R300) -> 0 | S1: =SUM(S5:S300) -> 0 | T1: =SUM(T5:T300) -> 0 | U1: =SUM(U5:U300) -> 0 | V1: =SUM(V5:V300) -> 0 | W1: =SUM(W5:W300) -> 0 | ... AB1: =SUM(AB5:AB300) -> 0 | AC1: =AB1+Jun!AC1 -> 0
A2: Sales Date | B2: Customer Name | C2: Sales Invoice Number or reference | D2: Sales Mileage | G2: Sales Value including Vat | H2: =Jun!H2 -> 20 | I2: Sales Net of Vat | L2: Receipts from Customers | P2: Sales Net of Vat | X2: Other Income | Y2: Investment Grants | Z2: Bad Debts written off | AA2: =AA1+Jun!AA2 -> 0 | AB2: Sub contractors only
H3: Vat Output | L3: Actual amount received | M3: Sales Value not yet received | N3: Number of Days Outstanding | P3: =Apr!P3 -> Product A Sales | Q3: =Apr!Q3 -> Product B Sales | R3: =Apr!R3 -> Product C Sales | S3: =Apr!S3 -> Product 4 Sales | T3: =Apr!T3 -> Product 5 Sales | U3: =Apr!U3 -> Product 6 Sales | V3: =Apr!V3 -> Product 7 Sales | W3: =Apr!W3 -> Product 8 Sales | AA3: Sale of Fixed Assets | AB3: CIS Tax Deducted | AC3: CIS Certificate reference
H4: =Jun!H4 -> 0 | P4: =Apr!P4 -> A | Q4: =Apr!Q4 -> B | R4: =Apr!R4 -> C | S4: =Apr!S4 -> 4 | T4: =Apr!T4 -> 5 | U4: =Apr!U4 -> 6 | V4: =Apr!V4 -> 7 | W4: =Apr!W4 -> 8 | X4: D | Y4: G | Z4: O | AA4: FS
F5: =IF((G5<>0),"Enter Letter"," ") | H5: =IF(H$4>0,(IF(G5<>0,G5*H$4/100," ")),IF(G5<>0,G5*H$2/(100+H$2)," ")) | I5: =IF((G5<>0),G5-H5," ") | M5: =IF(G5<>0,G5-L5," ") | N5: =IF((G5-L5)<>0,N$1-A5," ") | P5: =IF((F5="a"),I5," ") | Q5: =IF((F5="b"),I5," ") | R5: =IF((F5="c"),I5," ") | S5: =IF((F5=S$4),I5," ") | T5: =IF((F5=T$4),I5," ") | U5: =IF((F5=U$4),I5," ") | V5: =IF((F5=V$4),I5," ") | W5: =IF((F5=W$4),I5," ") | X5: =IF((F5="d"),I5," ") | Y5: =IF((F5="g"),I5," ") | Z5: =IF((F5="o"),I5," ") | AA5: =IF((F5="FS"),I5," ")
F6: =IF((G6<>0),"Enter Letter"," ") | H6: =IF(H$4>0,(IF(G6<>0,G6*H$4/100," ")),IF(G6<>0,G6*H$2/(100+H$2)," ")) | I6: =IF((G6<>0),G6-H6," ") | M6: =IF(G6<>0,G6-L6," ") | N6: =IF((G6-L6)<>0,N$1-A6," ") | P6: =IF((F6="a"),I6," ") | Q6: =IF((F6="b"),I6," ") | R6: =IF((F6="c"),I6," ") | S6: =IF((F6=S$4),I6," ") | T6: =IF((F6=T$4),I6," ") | U6: =IF((F6=U$4),I6," ") | V6: =IF((F6=V$4),I6," ") | W6: =IF((F6=W$4),I6," ") | X6: =IF((F6="d"),I6," ") | Y6: =IF((F6="g"),I6," ") | Z6: =IF((F6="o"),I6," ") | AA6: =IF((F6="FS"),I6," ")
F7: =IF((G7<>0),"Enter Letter"," ") | H7: =IF(H$4>0,(IF(G7<>0,G7*H$4/100," ")),IF(G7<>0,G7*H$2/(100+H$2)," ")) | I7: =IF((G7<>0),G7-H7," ") | M7: =IF(G7<>0,G7-L7," ") | N7: =IF((G7-L7)<>0,N$1-A7," ") | P7: =IF((F7="a"),I7," ") | Q7: =IF((F7="b"),I7," ") | R7: =IF((F7="c"),I7," ") | S7: =IF((F7=S$4),I7," ") | T7: =IF((F7=T$4),I7," ") | U7: =IF((F7=U$4),I7," ") | V7: =IF((F7=V$4),I7," ") | W7: =IF((F7=W$4),I7," ") | X7: =IF((F7="d"),I7," ") | Y7: =IF((F7="g"),I7," ") | Z7: =IF((F7="o"),I7," ") | AA7: =IF((F7="FS"),I7," ")
F8: =IF((G8<>0),"Enter Letter"," ") | H8: =IF(H$4>0,(IF(G8<>0,G8*H$4/100," ")),IF(G8<>0,G8*H$2/(100+H$2)," ")) | I8: =IF((G8<>0),G8-H8," ") | M8: =IF(G8<>0,G8-L8," ") | N8: =IF((G8-L8)<>0,N$1-A8," ") | P8: =IF((F8="a"),I8," ") | Q8: =IF((F8="b"),I8," ") | R8: =IF((F8="c"),I8," ") | S8: =IF((F8=S$4),I8," ") | T8: =IF((F8=T$4),I8," ") | U8: =IF((F8=U$4),I8," ") | V8: =IF((F8=V$4),I8," ") | W8: =IF((F8=W$4),I8," ") | X8: =IF((F8="d"),I8," ") | Y8: =IF((F8="g"),I8," ") | Z8: =IF((F8="o"),I8," ") | AA8: =IF((F8="FS"),I8," ")
F9: =IF((G9<>0),"Enter Letter"," ") | H9: =IF(H$4>0,(IF(G9<>0,G9*H$4/100," ")),IF(G9<>0,G9*H$2/(100+H$2)," ")) | I9: =IF((G9<>0),G9-H9," ") | M9: =IF(G9<>0,G9-L9," ") | N9: =IF((G9-L9)<>0,N$1-A9," ") | P9: =IF((F9="a"),I9," ") | Q9: =IF((F9="b"),I9," ") | R9: =IF((F9="c"),I9," ") | S9: =IF((F9=S$4),I9," ") | T9: =IF((F9=T$4),I9," ") | U9: =IF((F9=U$4),I9," ") | V9: =IF((F9=V$4),I9," ") | W9: =IF((F9=W$4),I9," ") | X9: =IF((F9="d"),I9," ") | Y9: =IF((F9="g"),I9," ") | Z9: =IF((F9="o"),I9," ") | AA9: =IF((F9="FS"),I9," ")
F10: =IF((G10<>0),"Enter Letter"," ") | H10: =IF(H$4>0,(IF(G10<>0,G10*H$4/100," ")),IF(G10<>0,G10*H$2/(100+H$2)," ")) | I10: =IF((G10<>0),G10-H10," ") | M10: =IF(G10<>0,G10-L10," ") | N10: =IF((G10-L10)<>0,N$1-A10," ") | P10: =IF((F10="a"),I10," ") | Q10: =IF((F10="b"),I10," ") | R10: =IF((F10="c"),I10," ") | S10: =IF((F10=S$4),I10," ") | T10: =IF((F10=T$4),I10," ") | U10: =IF((F10=U$4),I10," ") | V10: =IF((F10=V$4),I10," ") | W10: =IF((F10=W$4),I10," ") | X10: =IF((F10="d"),I10," ") | Y10: =IF((F10="g"),I10," ") | Z10: =IF((F10="o"),I10," ") | AA10: =IF((F10="FS"),I10," ")
F11: =IF((G11<>0),"Enter Letter"," ") | H11: =IF(H$4>0,(IF(G11<>0,G11*H$4/100," ")),IF(G11<>0,G11*H$2/(100+H$2)," ")) | I11: =IF((G11<>0),G11-H11," ") | M11: =IF(G11<>0,G11-L11," ") | N11: =IF((G11-L11)<>0,N$1-A11," ") | P11: =IF((F11="a"),I11," ") | Q11: =IF((F11="b"),I11," ") | R11: =IF((F11="c"),I11," ") | S11: =IF((F11=S$4),I11," ") | T11: =IF((F11=T$4),I11," ") | U11: =IF((F11=U$4),I11," ") | V11: =IF((F11=V$4),I11," ") | W11: =IF((F11=W$4),I11," ") | X11: =IF((F11="d"),I11," ") | Y11: =IF((F11="g"),I11," ") | Z11: =IF((F11="o"),I11," ") | AA11: =IF((F11="FS"),I11," ")
F12: =IF((G12<>0),"Enter Letter"," ") | H12: =IF(H$4>0,(IF(G12<>0,G12*H$4/100," ")),IF(G12<>0,G12*H$2/(100+H$2)," ")) | I12: =IF((G12<>0),G12-H12," ") | M12: =IF(G12<>0,G12-L12," ") | N12: =IF((G12-L12)<>0,N$1-A12," ") | P12: =IF((F12="a"),I12," ") | Q12: =IF((F12="b"),I12," ") | R12: =IF((F12="c"),I12," ") | S12: =IF((F12=S$4),I12," ") | T12: =IF((F12=T$4),I12," ") | U12: =IF((F12=U$4),I12," ") | V12: =IF((F12=V$4),I12," ") | W12: =IF((F12=W$4),I12," ") | X12: =IF((F12="d"),I12," ") | Y12: =IF((F12="g"),I12," ") | Z12: =IF((F12="o"),I12," ") | AA12: =IF((F12="FS"),I12," ")
F13: =IF((G13<>0),"Enter Letter"," ") | H13: =IF(H$4>0,(IF(G13<>0,G13*H$4/100," ")),IF(G13<>0,G13*H$2/(100+H$2)," ")) | I13: =IF((G13<>0),G13-H13," ") | M13: =IF(G13<>0,G13-L13," ") | N13: =IF((G13-L13)<>0,N$1-A13," ") | P13: =IF((F13="a"),I13," ") | Q13: =IF((F13="b"),I13," ") | R13: =IF((F13="c"),I13," ") | S13: =IF((F13=S$4),I13," ") | T13: =IF((F13=T$4),I13," ") | U13: =IF((F13=U$4),I13," ") | V13: =IF((F13=V$4),I13," ") | W13: =IF((F13=W$4),I13," ") | X13: =IF((F13="d"),I13," ") | Y13: =IF((F13="g"),I13," ") | Z13: =IF((F13="o"),I13," ") | AA13: =IF((F13="FS"),I13," ")
F14: =IF((G14<>0),"Enter Letter"," ") | H14: =IF(H$4>0,(IF(G14<>0,G14*H$4/100," ")),IF(G14<>0,G14*H$2/(100+H$2)," ")) | I14: =IF((G14<>0),G14-H14," ") | M14: =IF(G14<>0,G14-L14," ") | N14: =IF((G14-L14)<>0,N$1-A14," ") | P14: =IF((F14="a"),I14," ") | Q14: =IF((F14="b"),I14," ") | R14: =IF((F14="c"),I14," ") | S14: =IF((F14=S$4),I14," ") | T14: =IF((F14=T$4),I14," ") | U14: =IF((F14=U$4),I14," ") | V14: =IF((F14=V$4),I14," ") | W14: =IF((F14=W$4),I14," ") | X14: =IF((F14="d"),I14," ") | Y14: =IF((F14="g"),I14," ") | Z14: =IF((F14="o"),I14," ") | AA14: =IF((F14="FS"),I14," ")
F15: =IF((G15<>0),"Enter Letter"," ") | H15: =IF(H$4>0,(IF(G15<>0,G15*H$4/100," ")),IF(G15<>0,G15*H$2/(100+H$2)," ")) | I15: =IF((G15<>0),G15-H15," ") | M15: =IF(G15<>0,G15-L15," ") | N15: =IF((G15-L15)<>0,N$1-A15," ") | P15: =IF((F15="a"),I15," ") | Q15: =IF((F15="b"),I15," ") | R15: =IF((F15="c"),I15," ") | S15: =IF((F15=S$4),I15," ") | T15: =IF((F15=T$4),I15," ") | U15: =IF((F15=U$4),I15," ") | V15: =IF((F15=V$4),I15," ") | W15: =IF((F15=W$4),I15," ") | X15: =IF((F15="d"),I15," ") | Y15: =IF((F15="g"),I15," ") | Z15: =IF((F15="o"),I15," ") | AA15: =IF((F15="FS"),I15," ")
F16: =IF((G16<>0),"Enter Letter"," ") | H16: =IF(H$4>0,(IF(G16<>0,G16*H$4/100," ")),IF(G16<>0,G16*H$2/(100+H$2)," ")) | I16: =IF((G16<>0),G16-H16," ") | M16: =IF(G16<>0,G16-L16," ") | N16: =IF((G16-L16)<>0,N$1-A16," ") | P16: =IF((F16="a"),I16," ") | Q16: =IF((F16="b"),I16," ") | R16: =IF((F16="c"),I16," ") | S16: =IF((F16=S$4),I16," ") | T16: =IF((F16=T$4),I16," ") | U16: =IF((F16=U$4),I16," ") | V16: =IF((F16=V$4),I16," ") | W16: =IF((F16=W$4),I16," ") | X16: =IF((F16="d"),I16," ") | Y16: =IF((F16="g"),I16," ") | Z16: =IF((F16="o"),I16," ") | AA16: =IF((F16="FS"),I16," ")
... F300: =IF((G300<>0),"Enter Letter"," ") | H300: =IF(H$4>0,(IF(G300<>0,G300*H$4/100," ")),IF(G300<>0,G300*H$2/(100+H$2)," ")) | I300: =IF((G300<>0),G300-H300," ") | M300: =IF(G300<>0,G300-L300," ") | N300: =IF((G300-L300)<>0,N$1-A300," ") | P300: =IF((F300="a"),I300," ") | Q300: =IF((F300="b"),I300," ") | R300: =IF((F300="c"),I300," ") | S300: =IF((F300=S$4),I300," ") | T300: =IF((F300=T$4),I300," ") | U300: =IF((F300=U$4),I300," ") | V300: =IF((F300=V$4),I300," ") | W300: =IF((F300=W$4),I300," ") | X300: =IF((F300="d"),I300," ") | Y300: =IF((F300="g"),I300," ") | Z300: =IF((F300="o"),I300," ") | AA300: =IF((F300="FS"),I300," ")

Sheet Aug
A1: =G1-H1-SUM(P1:AA1) -> 0 | B1: Check Total | C1: Sales Mileage | D1: =SUM(D5:D300) -> 0 | E1: Sales Description | F1: Enter Expense Code Letter | G1: =SUM(G5:G300) -> 0 | H1: =SUM(H5:H300) -> 0 | I1: =SUM(I5:I300) -> 0 | K1: For your information only. Enter How Paid e.g. Cash, Cheque etc., | L1: =SUM(L5:L300) -> 0 | M1: =SUM(M5:M300) -> 0 | N1: =TODAY() -> 45397 | P1: =SUM(P5:P300) -> 0 | Q1: =SUM(Q5:Q300) -> 0 | R1: =SUM(R5:R300) -> 0 | S1: =SUM(S5:S300) -> 0 | T1: =SUM(T5:T300) -> 0 | U1: =SUM(U5:U300) -> 0 | V1: =SUM(V5:V300) -> 0 | W1: =SUM(W5:W300) -> 0 | ... AB1: =SUM(AB5:AB300) -> 0 | AC1: =AB1+Jul!AC1 -> 0
A2: Sales Date | B2: Customer Name | C2: Sales Invoice Number or reference | D2: Sales Mileage | G2: Sales Value including Vat | H2: =Jul!H2 -> 20 | I2: Sales Net of Vat | L2: Receipts from Customers | P2: Sales Net of Vat | X2: Other Income | Y2: Investment Grants | Z2: Bad Debts written off | AA2: =AA1+Jul!AA2 -> 0 | AB2: Sub contractors only
H3: Vat Output | L3: Actual amount received | M3: Sales Value not yet received | N3: Number of Days Outstanding | P3: =Apr!P3 -> Product A Sales | Q3: =Apr!Q3 -> Product B Sales | R3: =Apr!R3 -> Product C Sales | S3: =Apr!S3 -> Product 4 Sales | T3: =Apr!T3 -> Product 5 Sales | U3: =Apr!U3 -> Product 6 Sales | V3: =Apr!V3 -> Product 7 Sales | W3: =Apr!W3 -> Product 8 Sales | AA3: Sale of Fixed Assets | AB3: CIS Tax Deducted | AC3: CIS Certificate reference
H4: =Jul!H4 -> 0 | P4: =Apr!P4 -> A | Q4: =Apr!Q4 -> B | R4: =Apr!R4 -> C | S4: =Apr!S4 -> 4 | T4: =Apr!T4 -> 5 | U4: =Apr!U4 -> 6 | V4: =Apr!V4 -> 7 | W4: =Apr!W4 -> 8 | X4: D | Y4: G | Z4: O | AA4: FS
F5: =IF((G5<>0),"Enter Letter"," ") | H5: =IF(H$4>0,(IF(G5<>0,G5*H$4/100," ")),IF(G5<>0,G5*H$2/(100+H$2)," ")) | I5: =IF((G5<>0),G5-H5," ") | M5: =IF(G5<>0,G5-L5," ") | N5: =IF((G5-L5)<>0,N$1-A5," ") | P5: =IF((F5="a"),I5," ") | Q5: =IF((F5="b"),I5," ") | R5: =IF((F5="c"),I5," ") | S5: =IF((F5=S$4),I5," ") | T5: =IF((F5=T$4),I5," ") | U5: =IF((F5=U$4),I5," ") | V5: =IF((F5=V$4),I5," ") | W5: =IF((F5=W$4),I5," ") | X5: =IF((F5="d"),I5," ") | Y5: =IF((F5="g"),I5," ") | Z5: =IF((F5="o"),I5," ") | AA5: =IF((F5="FS"),I5," ")
F6: =IF((G6<>0),"Enter Letter"," ") | H6: =IF(H$4>0,(IF(G6<>0,G6*H$4/100," ")),IF(G6<>0,G6*H$2/(100+H$2)," ")) | I6: =IF((G6<>0),G6-H6," ") | M6: =IF(G6<>0,G6-L6," ") | N6: =IF((G6-L6)<>0,N$1-A6," ") | P6: =IF((F6="a"),I6," ") | Q6: =IF((F6="b"),I6," ") | R6: =IF((F6="c"),I6," ") | S6: =IF((F6=S$4),I6," ") | T6: =IF((F6=T$4),I6," ") | U6: =IF((F6=U$4),I6," ") | V6: =IF((F6=V$4),I6," ") | W6: =IF((F6=W$4),I6," ") | X6: =IF((F6="d"),I6," ") | Y6: =IF((F6="g"),I6," ") | Z6: =IF((F6="o"),I6," ") | AA6: =IF((F6="FS"),I6," ")
F7: =IF((G7<>0),"Enter Letter"," ") | H7: =IF(H$4>0,(IF(G7<>0,G7*H$4/100," ")),IF(G7<>0,G7*H$2/(100+H$2)," ")) | I7: =IF((G7<>0),G7-H7," ") | M7: =IF(G7<>0,G7-L7," ") | N7: =IF((G7-L7)<>0,N$1-A7," ") | P7: =IF((F7="a"),I7," ") | Q7: =IF((F7="b"),I7," ") | R7: =IF((F7="c"),I7," ") | S7: =IF((F7=S$4),I7," ") | T7: =IF((F7=T$4),I7," ") | U7: =IF((F7=U$4),I7," ") | V7: =IF((F7=V$4),I7," ") | W7: =IF((F7=W$4),I7," ") | X7: =IF((F7="d"),I7," ") | Y7: =IF((F7="g"),I7," ") | Z7: =IF((F7="o"),I7," ") | AA7: =IF((F7="FS"),I7," ")
F8: =IF((G8<>0),"Enter Letter"," ") | H8: =IF(H$4>0,(IF(G8<>0,G8*H$4/100," ")),IF(G8<>0,G8*H$2/(100+H$2)," ")) | I8: =IF((G8<>0),G8-H8," ") | M8: =IF(G8<>0,G8-L8," ") | N8: =IF((G8-L8)<>0,N$1-A8," ") | P8: =IF((F8="a"),I8," ") | Q8: =IF((F8="b"),I8," ") | R8: =IF((F8="c"),I8," ") | S8: =IF((F8=S$4),I8," ") | T8: =IF((F8=T$4),I8," ") | U8: =IF((F8=U$4),I8," ") | V8: =IF((F8=V$4),I8," ") | W8: =IF((F8=W$4),I8," ") | X8: =IF((F8="d"),I8," ") | Y8: =IF((F8="g"),I8," ") | Z8: =IF((F8="o"),I8," ") | AA8: =IF((F8="FS"),I8," ")
F9: =IF((G9<>0),"Enter Letter"," ") | H9: =IF(H$4>0,(IF(G9<>0,G9*H$4/100," ")),IF(G9<>0,G9*H$2/(100+H$2)," ")) | I9: =IF((G9<>0),G9-H9," ") | M9: =IF(G9<>0,G9-L9," ") | N9: =IF((G9-L9)<>0,N$1-A9," ") | P9: =IF((F9="a"),I9," ") | Q9: =IF((F9="b"),I9," ") | R9: =IF((F9="c"),I9," ") | S9: =IF((F9=S$4),I9," ") | T9: =IF((F9=T$4),I9," ") | U9: =IF((F9=U$4),I9," ") | V9: =IF((F9=V$4),I9," ") | W9: =IF((F9=W$4),I9," ") | X9: =IF((F9="d"),I9," ") | Y9: =IF((F9="g"),I9," ") | Z9: =IF((F9="o"),I9," ") | AA9: =IF((F9="FS"),I9," ")
F10: =IF((G10<>0),"Enter Letter"," ") | H10: =IF(H$4>0,(IF(G10<>0,G10*H$4/100," ")),IF(G10<>0,G10*H$2/(100+H$2)," ")) | I10: =IF((G10<>0),G10-H10," ") | M10: =IF(G10<>0,G10-L10," ") | N10: =IF((G10-L10)<>0,N$1-A10," ") | P10: =IF((F10="a"),I10," ") | Q10: =IF((F10="b"),I10," ") | R10: =IF((F10="c"),I10," ") | S10: =IF((F10=S$4),I10," ") | T10: =IF((F10=T$4),I10," ") | U10: =IF((F10=U$4),I10," ") | V10: =IF((F10=V$4),I10," ") | W10: =IF((F10=W$4),I10," ") | X10: =IF((F10="d"),I10," ") | Y10: =IF((F10="g"),I10," ") | Z10: =IF((F10="o"),I10," ") | AA10: =IF((F10="FS"),I10," ")
F11: =IF((G11<>0),"Enter Letter"," ") | H11: =IF(H$4>0,(IF(G11<>0,G11*H$4/100," ")),IF(G11<>0,G11*H$2/(100+H$2)," ")) | I11: =IF((G11<>0),G11-H11," ") | M11: =IF(G11<>0,G11-L11," ") | N11: =IF((G11-L11)<>0,N$1-A11," ") | P11: =IF((F11="a"),I11," ") | Q11: =IF((F11="b"),I11," ") | R11: =IF((F11="c"),I11," ") | S11: =IF((F11=S$4),I11," ") | T11: =IF((F11=T$4),I11," ") | U11: =IF((F11=U$4),I11," ") | V11: =IF((F11=V$4),I11," ") | W11: =IF((F11=W$4),I11," ") | X11: =IF((F11="d"),I11," ") | Y11: =IF((F11="g"),I11," ") | Z11: =IF((F11="o"),I11," ") | AA11: =IF((F11="FS"),I11," ")
F12: =IF((G12<>0),"Enter Letter"," ") | H12: =IF(H$4>0,(IF(G12<>0,G12*H$4/100," ")),IF(G12<>0,G12*H$2/(100+H$2)," ")) | I12: =IF((G12<>0),G12-H12," ") | M12: =IF(G12<>0,G12-L12," ") | N12: =IF((G12-L12)<>0,N$1-A12," ") | P12: =IF((F12="a"),I12," ") | Q12: =IF((F12="b"),I12," ") | R12: =IF((F12="c"),I12," ") | S12: =IF((F12=S$4),I12," ") | T12: =IF((F12=T$4),I12," ") | U12: =IF((F12=U$4),I12," ") | V12: =IF((F12=V$4),I12," ") | W12: =IF((F12=W$4),I12," ") | X12: =IF((F12="d"),I12," ") | Y12: =IF((F12="g"),I12," ") | Z12: =IF((F12="o"),I12," ") | AA12: =IF((F12="FS"),I12," ")
F13: =IF((G13<>0),"Enter Letter"," ") | H13: =IF(H$4>0,(IF(G13<>0,G13*H$4/100," ")),IF(G13<>0,G13*H$2/(100+H$2)," ")) | I13: =IF((G13<>0),G13-H13," ") | M13: =IF(G13<>0,G13-L13," ") | N13: =IF((G13-L13)<>0,N$1-A13," ") | P13: =IF((F13="a"),I13," ") | Q13: =IF((F13="b"),I13," ") | R13: =IF((F13="c"),I13," ") | S13: =IF((F13=S$4),I13," ") | T13: =IF((F13=T$4),I13," ") | U13: =IF((F13=U$4),I13," ") | V13: =IF((F13=V$4),I13," ") | W13: =IF((F13=W$4),I13," ") | X13: =IF((F13="d"),I13," ") | Y13: =IF((F13="g"),I13," ") | Z13: =IF((F13="o"),I13," ") | AA13: =IF((F13="FS"),I13," ")
F14: =IF((G14<>0),"Enter Letter"," ") | H14: =IF(H$4>0,(IF(G14<>0,G14*H$4/100," ")),IF(G14<>0,G14*H$2/(100+H$2)," ")) | I14: =IF((G14<>0),G14-H14," ") | M14: =IF(G14<>0,G14-L14," ") | N14: =IF((G14-L14)<>0,N$1-A14," ") | P14: =IF((F14="a"),I14," ") | Q14: =IF((F14="b"),I14," ") | R14: =IF((F14="c"),I14," ") | S14: =IF((F14=S$4),I14," ") | T14: =IF((F14=T$4),I14," ") | U14: =IF((F14=U$4),I14," ") | V14: =IF((F14=V$4),I14," ") | W14: =IF((F14=W$4),I14," ") | X14: =IF((F14="d"),I14," ") | Y14: =IF((F14="g"),I14," ") | Z14: =IF((F14="o"),I14," ") | AA14: =IF((F14="FS"),I14," ")
F15: =IF((G15<>0),"Enter Letter"," ") | H15: =IF(H$4>0,(IF(G15<>0,G15*H$4/100," ")),IF(G15<>0,G15*H$2/(100+H$2)," ")) | I15: =IF((G15<>0),G15-H15," ") | M15: =IF(G15<>0,G15-L15," ") | N15: =IF((G15-L15)<>0,N$1-A15," ") | P15: =IF((F15="a"),I15," ") | Q15: =IF((F15="b"),I15," ") | R15: =IF((F15="c"),I15," ") | S15: =IF((F15=S$4),I15," ") | T15: =IF((F15=T$4),I15," ") | U15: =IF((F15=U$4),I15," ") | V15: =IF((F15=V$4),I15," ") | W15: =IF((F15=W$4),I15," ") | X15: =IF((F15="d"),I15," ") | Y15: =IF((F15="g"),I15," ") | Z15: =IF((F15="o"),I15," ") | AA15: =IF((F15="FS"),I15," ")
F16: =IF((G16<>0),"Enter Letter"," ") | H16: =IF(H$4>0,(IF(G16<>0,G16*H$4/100," ")),IF(G16<>0,G16*H$2/(100+H$2)," ")) | I16: =IF((G16<>0),G16-H16," ") | M16: =IF(G16<>0,G16-L16," ") | N16: =IF((G16-L16)<>0,N$1-A16," ") | P16: =IF((F16="a"),I16," ") | Q16: =IF((F16="b"),I16," ") | R16: =IF((F16="c"),I16," ") | S16: =IF((F16=S$4),I16," ") | T16: =IF((F16=T$4),I16," ") | U16: =IF((F16=U$4),I16," ") | V16: =IF((F16=V$4),I16," ") | W16: =IF((F16=W$4),I16," ") | X16: =IF((F16="d"),I16," ") | Y16: =IF((F16="g"),I16," ") | Z16: =IF((F16="o"),I16," ") | AA16: =IF((F16="FS"),I16," ")
... F300: =IF((G300<>0),"Enter Letter"," ") | H300: =IF(H$4>0,(IF(G300<>0,G300*H$4/100," ")),IF(G300<>0,G300*H$2/(100+H$2)," ")) | I300: =IF((G300<>0),G300-H300," ") | M300: =IF(G300<>0,G300-L300," ") | N300: =IF((G300-L300)<>0,N$1-A300," ") | P300: =IF((F300="a"),I300," ") | Q300: =IF((F300="b"),I300," ") | R300: =IF((F300="c"),I300," ") | S300: =IF((F300=S$4),I300," ") | T300: =IF((F300=T$4),I300," ") | U300: =IF((F300=U$4),I300," ") | V300: =IF((F300=V$4),I300," ") | W300: =IF((F300=W$4),I300," ") | X300: =IF((F300="d"),I300," ") | Y300: =IF((F300="g"),I300," ") | Z300: =IF((F300="o"),I300," ") | AA300: =IF((F300="FS"),I300," ")

Sheet Sep
A1: =G1-H1-SUM(P1:AA1) -> 0 | B1: Check Total | C1: Sales Mileage | D1: =SUM(D5:D300) -> 0 | E1: Sales Description | F1: Enter Expense Code Letter | G1: =SUM(G5:G300) -> 0 | H1: =SUM(H5:H300) -> 0 | I1: =SUM(I5:I300) -> 0 | K1: For your information only. Enter How Paid e.g. Cash, Cheque etc., | L1: =SUM(L5:L300) -> 0 | M1: =SUM(M5:M300) -> 0 | N1: =TODAY() -> 45397 | P1: =SUM(P5:P300) -> 0 | Q1: =SUM(Q5:Q300) -> 0 | R1: =SUM(R5:R300) -> 0 | S1: =SUM(S5:S300) -> 0 | T1: =SUM(T5:T300) -> 0 | U1: =SUM(U5:U300) -> 0 | V1: =SUM(V5:V300) -> 0 | W1: =SUM(W5:W300) -> 0 | ... AB1: =SUM(AB5:AB300) -> 0 | AC1: =AB1+Aug!AC1 -> 0
A2: Sales Date | B2: Customer Name | C2: Sales Invoice Number or reference | D2: Sales Mileage | G2: Sales Value including Vat | H2: =Aug!H2 -> 20 | I2: Sales Net of Vat | L2: Receipts from Customers | P2: Sales Net of Vat | X2: Other Income | Y2: Investment Grants | Z2: Bad Debts written off | AA2: =AA1+Aug!AA2 -> 0 | AB2: Sub contractors only
H3: Vat Output | L3: Actual amount received | M3: Sales Value not yet received | N3: Number of Days Outstanding | P3: =Apr!P3 -> Product A Sales | Q3: =Apr!Q3 -> Product B Sales | R3: =Apr!R3 -> Product C Sales | S3: =Apr!S3 -> Product 4 Sales | T3: =Apr!T3 -> Product 5 Sales | U3: =Apr!U3 -> Product 6 Sales | V3: =Apr!V3 -> Product 7 Sales | W3: =Apr!W3 -> Product 8 Sales | AA3: Sale of Fixed Assets | AB3: CIS Tax Deducted | AC3: CIS Certificate reference
H4: =Aug!H4 -> 0 | P4: =Apr!P4 -> A | Q4: =Apr!Q4 -> B | R4: =Apr!R4 -> C | S4: =Apr!S4 -> 4 | T4: =Apr!T4 -> 5 | U4: =Apr!U4 -> 6 | V4: =Apr!V4 -> 7 | W4: =Apr!W4 -> 8 | X4: D | Y4: G | Z4: O | AA4: FS
F5: =IF((G5<>0),"Enter Letter"," ") | H5: =IF(H$4>0,(IF(G5<>0,G5*H$4/100," ")),IF(G5<>0,G5*H$2/(100+H$2)," ")) | I5: =IF((G5<>0),G5-H5," ") | M5: =IF(G5<>0,G5-L5," ") | N5: =IF((G5-L5)<>0,N$1-A5," ") | P5: =IF((F5="a"),I5," ") | Q5: =IF((F5="b"),I5," ") | R5: =IF((F5="c"),I5," ") | S5: =IF((F5=S$4),I5," ") | T5: =IF((F5=T$4),I5," ") | U5: =IF((F5=U$4),I5," ") | V5: =IF((F5=V$4),I5," ") | W5: =IF((F5=W$4),I5," ") | X5: =IF((F5="d"),I5," ") | Y5: =IF((F5="g"),I5," ") | Z5: =IF((F5="o"),I5," ") | AA5: =IF((F5="FS"),I5," ")
F6: =IF((G6<>0),"Enter Letter"," ") | H6: =IF(H$4>0,(IF(G6<>0,G6*H$4/100," ")),IF(G6<>0,G6*H$2/(100+H$2)," ")) | I6: =IF((G6<>0),G6-H6," ") | M6: =IF(G6<>0,G6-L6," ") | N6: =IF((G6-L6)<>0,N$1-A6," ") | P6: =IF((F6="a"),I6," ") | Q6: =IF((F6="b"),I6," ") | R6: =IF((F6="c"),I6," ") | S6: =IF((F6=S$4),I6," ") | T6: =IF((F6=T$4),I6," ") | U6: =IF((F6=U$4),I6," ") | V6: =IF((F6=V$4),I6," ") | W6: =IF((F6=W$4),I6," ") | X6: =IF((F6="d"),I6," ") | Y6: =IF((F6="g"),I6," ") | Z6: =IF((F6="o"),I6," ") | AA6: =IF((F6="FS"),I6," ")
F7: =IF((G7<>0),"Enter Letter"," ") | H7: =IF(H$4>0,(IF(G7<>0,G7*H$4/100," ")),IF(G7<>0,G7*H$2/(100+H$2)," ")) | I7: =IF((G7<>0),G7-H7," ") | M7: =IF(G7<>0,G7-L7," ") | N7: =IF((G7-L7)<>0,N$1-A7," ") | P7: =IF((F7="a"),I7," ") | Q7: =IF((F7="b"),I7," ") | R7: =IF((F7="c"),I7," ") | S7: =IF((F7=S$4),I7," ") | T7: =IF((F7=T$4),I7," ") | U7: =IF((F7=U$4),I7," ") | V7: =IF((F7=V$4),I7," ") | W7: =IF((F7=W$4),I7," ") | X7: =IF((F7="d"),I7," ") | Y7: =IF((F7="g"),I7," ") | Z7: =IF((F7="o"),I7," ") | AA7: =IF((F7="FS"),I7," ")
F8: =IF((G8<>0),"Enter Letter"," ") | H8: =IF(H$4>0,(IF(G8<>0,G8*H$4/100," ")),IF(G8<>0,G8*H$2/(100+H$2)," ")) | I8: =IF((G8<>0),G8-H8," ") | M8: =IF(G8<>0,G8-L8," ") | N8: =IF((G8-L8)<>0,N$1-A8," ") | P8: =IF((F8="a"),I8," ") | Q8: =IF((F8="b"),I8," ") | R8: =IF((F8="c"),I8," ") | S8: =IF((F8=S$4),I8," ") | T8: =IF((F8=T$4),I8," ") | U8: =IF((F8=U$4),I8," ") | V8: =IF((F8=V$4),I8," ") | W8: =IF((F8=W$4),I8," ") | X8: =IF((F8="d"),I8," ") | Y8: =IF((F8="g"),I8," ") | Z8: =IF((F8="o"),I8," ") | AA8: =IF((F8="FS"),I8," ")
F9: =IF((G9<>0),"Enter Letter"," ") | H9: =IF(H$4>0,(IF(G9<>0,G9*H$4/100," ")),IF(G9<>0,G9*H$2/(100+H$2)," ")) | I9: =IF((G9<>0),G9-H9," ") | M9: =IF(G9<>0,G9-L9," ") | N9: =IF((G9-L9)<>0,N$1-A9," ") | P9: =IF((F9="a"),I9," ") | Q9: =IF((F9="b"),I9," ") | R9: =IF((F9="c"),I9," ") | S9: =IF((F9=S$4),I9," ") | T9: =IF((F9=T$4),I9," ") | U9: =IF((F9=U$4),I9," ") | V9: =IF((F9=V$4),I9," ") | W9: =IF((F9=W$4),I9," ") | X9: =IF((F9="d"),I9," ") | Y9: =IF((F9="g"),I9," ") | Z9: =IF((F9="o"),I9," ") | AA9: =IF((F9="FS"),I9," ")
F10: =IF((G10<>0),"Enter Letter"," ") | H10: =IF(H$4>0,(IF(G10<>0,G10*H$4/100," ")),IF(G10<>0,G10*H$2/(100+H$2)," ")) | I10: =IF((G10<>0),G10-H10," ") | M10: =IF(G10<>0,G10-L10," ") | N10: =IF((G10-L10)<>0,N$1-A10," ") | P10: =IF((F10="a"),I10," ") | Q10: =IF((F10="b"),I10," ") | R10: =IF((F10="c"),I10," ") | S10: =IF((F10=S$4),I10," ") | T10: =IF((F10=T$4),I10," ") | U10: =IF((F10=U$4),I10," ") | V10: =IF((F10=V$4),I10," ") | W10: =IF((F10=W$4),I10," ") | X10: =IF((F10="d"),I10," ") | Y10: =IF((F10="g"),I10," ") | Z10: =IF((F10="o"),I10," ") | AA10: =IF((F10="FS"),I10," ")
F11: =IF((G11<>0),"Enter Letter"," ") | H11: =IF(H$4>0,(IF(G11<>0,G11*H$4/100," ")),IF(G11<>0,G11*H$2/(100+H$2)," ")) | I11: =IF((G11<>0),G11-H11," ") | M11: =IF(G11<>0,G11-L11," ") | N11: =IF((G11-L11)<>0,N$1-A11," ") | P11: =IF((F11="a"),I11," ") | Q11: =IF((F11="b"),I11," ") | R11: =IF((F11="c"),I11," ") | S11: =IF((F11=S$4),I11," ") | T11: =IF((F11=T$4),I11," ") | U11: =IF((F11=U$4),I11," ") | V11: =IF((F11=V$4),I11," ") | W11: =IF((F11=W$4),I11," ") | X11: =IF((F11="d"),I11," ") | Y11: =IF((F11="g"),I11," ") | Z11: =IF((F11="o"),I11," ") | AA11: =IF((F11="FS"),I11," ")
F12: =IF((G12<>0),"Enter Letter"," ") | H12: =IF(H$4>0,(IF(G12<>0,G12*H$4/100," ")),IF(G12<>0,G12*H$2/(100+H$2)," ")) | I12: =IF((G12<>0),G12-H12," ") | M12: =IF(G12<>0,G12-L12," ") | N12: =IF((G12-L12)<>0,N$1-A12," ") | P12: =IF((F12="a"),I12," ") | Q12: =IF((F12="b"),I12," ") | R12: =IF((F12="c"),I12," ") | S12: =IF((F12=S$4),I12," ") | T12: =IF((F12=T$4),I12," ") | U12: =IF((F12=U$4),I12," ") | V12: =IF((F12=V$4),I12," ") | W12: =IF((F12=W$4),I12," ") | X12: =IF((F12="d"),I12," ") | Y12: =IF((F12="g"),I12," ") | Z12: =IF((F12="o"),I12," ") | AA12: =IF((F12="FS"),I12," ")
F13: =IF((G13<>0),"Enter Letter"," ") | H13: =IF(H$4>0,(IF(G13<>0,G13*H$4/100," ")),IF(G13<>0,G13*H$2/(100+H$2)," ")) | I13: =IF((G13<>0),G13-H13," ") | M13: =IF(G13<>0,G13-L13," ") | N13: =IF((G13-L13)<>0,N$1-A13," ") | P13: =IF((F13="a"),I13," ") | Q13: =IF((F13="b"),I13," ") | R13: =IF((F13="c"),I13," ") | S13: =IF((F13=S$4),I13," ") | T13: =IF((F13=T$4),I13," ") | U13: =IF((F13=U$4),I13," ") | V13: =IF((F13=V$4),I13," ") | W13: =IF((F13=W$4),I13," ") | X13: =IF((F13="d"),I13," ") | Y13: =IF((F13="g"),I13," ") | Z13: =IF((F13="o"),I13," ") | AA13: =IF((F13="FS"),I13," ")
F14: =IF((G14<>0),"Enter Letter"," ") | H14: =IF(H$4>0,(IF(G14<>0,G14*H$4/100," ")),IF(G14<>0,G14*H$2/(100+H$2)," ")) | I14: =IF((G14<>0),G14-H14," ") | M14: =IF(G14<>0,G14-L14," ") | N14: =IF((G14-L14)<>0,N$1-A14," ") | P14: =IF((F14="a"),I14," ") | Q14: =IF((F14="b"),I14," ") | R14: =IF((F14="c"),I14," ") | S14: =IF((F14=S$4),I14," ") | T14: =IF((F14=T$4),I14," ") | U14: =IF((F14=U$4),I14," ") | V14: =IF((F14=V$4),I14," ") | W14: =IF((F14=W$4),I14," ") | X14: =IF((F14="d"),I14," ") | Y14: =IF((F14="g"),I14," ") | Z14: =IF((F14="o"),I14," ") | AA14: =IF((F14="FS"),I14," ")
F15: =IF((G15<>0),"Enter Letter"," ") | H15: =IF(H$4>0,(IF(G15<>0,G15*H$4/100," ")),IF(G15<>0,G15*H$2/(100+H$2)," ")) | I15: =IF((G15<>0),G15-H15," ") | M15: =IF(G15<>0,G15-L15," ") | N15: =IF((G15-L15)<>0,N$1-A15," ") | P15: =IF((F15="a"),I15," ") | Q15: =IF((F15="b"),I15," ") | R15: =IF((F15="c"),I15," ") | S15: =IF((F15=S$4),I15," ") | T15: =IF((F15=T$4),I15," ") | U15: =IF((F15=U$4),I15," ") | V15: =IF((F15=V$4),I15," ") | W15: =IF((F15=W$4),I15," ") | X15: =IF((F15="d"),I15," ") | Y15: =IF((F15="g"),I15," ") | Z15: =IF((F15="o"),I15," ") | AA15: =IF((F15="FS"),I15," ")
F16: =IF((G16<>0),"Enter Letter"," ") | H16: =IF(H$4>0,(IF(G16<>0,G16*H$4/100," ")),IF(G16<>0,G16*H$2/(100+H$2)," ")) | I16: =IF((G16<>0),G16-H16," ") | M16: =IF(G16<>0,G16-L16," ") | N16: =IF((G16-L16)<>0,N$1-A16," ") | P16: =IF((F16="a"),I16," ") | Q16: =IF((F16="b"),I16," ") | R16: =IF((F16="c"),I16," ") | S16: =IF((F16=S$4),I16," ") | T16: =IF((F16=T$4),I16," ") | U16: =IF((F16=U$4),I16," ") | V16: =IF((F16=V$4),I16," ") | W16: =IF((F16=W$4),I16," ") | X16: =IF((F16="d"),I16," ") | Y16: =IF((F16="g"),I16," ") | Z16: =IF((F16="o"),I16," ") | AA16: =IF((F16="FS"),I16," ")
... F300: =IF((G300<>0),"Enter Letter"," ") | H300: =IF(H$4>0,(IF(G300<>0,G300*H$4/100," ")),IF(G300<>0,G300*H$2/(100+H$2)," ")) | I300: =IF((G300<>0),G300-H300," ") | M300: =IF(G300<>0,G300-L300," ") | N300: =IF((G300-L300)<>0,N$1-A300," ") | P300: =IF((F300="a"),I300," ") | Q300: =IF((F300="b"),I300," ") | R300: =IF((F300="c"),I300," ") | S300: =IF((F300=S$4),I300," ") | T300: =IF((F300=T$4),I300," ") | U300: =IF((F300=U$4),I300," ") | V300: =IF((F300=V$4),I300," ") | W300: =IF((F300=W$4),I300," ") | X300: =IF((F300="d"),I300," ") | Y300: =IF((F300="g"),I300," ") | Z300: =IF((F300="o"),I300," ") | AA300: =IF((F300="FS"),I300," ")

Sheet Oct
A1: =G1-H1-SUM(P1:AA1) -> 0 | B1: Check Total | C1: Sales Mileage | D1: =SUM(D5:D300) -> 0 | E1: Sales Description | F1: Enter Expense Code Letter | G1: =SUM(G5:G300) -> 0 | H1: =SUM(H5:H300) -> 0 | I1: =SUM(I5:I300) -> 0 | K1: For your information only. Enter How Paid e.g. Cash, Cheque etc., | L1: =SUM(L5:L300) -> 0 | M1: =SUM(M5:M300) -> 0 | N1: =TODAY() -> 45397 | P1: =SUM(P5:P300) -> 0 | Q1: =SUM(Q5:Q300) -> 0 | R1: =SUM(R5:R300) -> 0 | S1: =SUM(S5:S300) -> 0 | T1: =SUM(T5:T300) -> 0 | U1: =SUM(U5:U300) -> 0 | V1: =SUM(V5:V300) -> 0 | W1: =SUM(W5:W300) -> 0 | ... AB1: =SUM(AB5:AB300) -> 0 | AC1: =AB1+Sep!AC1 -> 0
A2: Sales Date | B2: Customer Name | C2: Sales Invoice Number or reference | D2: Sales Mileage | G2: Sales Value including Vat | H2: =Sep!H2 -> 20 | I2: Sales Net of Vat | L2: Receipts from Customers | P2: Sales Net of Vat | X2: Other Income | Y2: Investment Grants | Z2: Bad Debts written off | AA2: =AA1+Sep!AA2 -> 0 | AB2: Sub contractors only
H3: Vat Output | L3: Actual amount received | M3: Sales Value not yet received | N3: Number of Days Outstanding | P3: =Apr!P3 -> Product A Sales | Q3: =Apr!Q3 -> Product B Sales | R3: =Apr!R3 -> Product C Sales | S3: =Apr!S3 -> Product 4 Sales | T3: =Apr!T3 -> Product 5 Sales | U3: =Apr!U3 -> Product 6 Sales | V3: =Apr!V3 -> Product 7 Sales | W3: =Apr!W3 -> Product 8 Sales | AA3: Sale of Fixed Assets | AB3: CIS Tax Deducted | AC3: CIS Certificate reference
H4: =Sep!H4 -> 0 | P4: =Apr!P4 -> A | Q4: =Apr!Q4 -> B | R4: =Apr!R4 -> C | S4: =Apr!S4 -> 4 | T4: =Apr!T4 -> 5 | U4: =Apr!U4 -> 6 | V4: =Apr!V4 -> 7 | W4: =Apr!W4 -> 8 | X4: D | Y4: G | Z4: O | AA4: FS
F5: =IF((G5<>0),"Enter Letter"," ") | H5: =IF(H$4>0,(IF(G5<>0,G5*H$4/100," ")),IF(G5<>0,G5*H$2/(100+H$2)," ")) | I5: =IF((G5<>0),G5-H5," ") | M5: =IF(G5<>0,G5-L5," ") | N5: =IF((G5-L5)<>0,N$1-A5," ") | P5: =IF((F5="a"),I5," ") | Q5: =IF((F5="b"),I5," ") | R5: =IF((F5="c"),I5," ") | S5: =IF((F5=S$4),I5," ") | T5: =IF((F5=T$4),I5," ") | U5: =IF((F5=U$4),I5," ") | V5: =IF((F5=V$4),I5," ") | W5: =IF((F5=W$4),I5," ") | X5: =IF((F5="d"),I5," ") | Y5: =IF((F5="g"),I5," ") | Z5: =IF((F5="o"),I5," ") | AA5: =IF((F5="FS"),I5," ")
F6: =IF((G6<>0),"Enter Letter"," ") | H6: =IF(H$4>0,(IF(G6<>0,G6*H$4/100," ")),IF(G6<>0,G6*H$2/(100+H$2)," ")) | I6: =IF((G6<>0),G6-H6," ") | M6: =IF(G6<>0,G6-L6," ") | N6: =IF((G6-L6)<>0,N$1-A6," ") | P6: =IF((F6="a"),I6," ") | Q6: =IF((F6="b"),I6," ") | R6: =IF((F6="c"),I6," ") | S6: =IF((F6=S$4),I6," ") | T6: =IF((F6=T$4),I6," ") | U6: =IF((F6=U$4),I6," ") | V6: =IF((F6=V$4),I6," ") | W6: =IF((F6=W$4),I6," ") | X6: =IF((F6="d"),I6," ") | Y6: =IF((F6="g"),I6," ") | Z6: =IF((F6="o"),I6," ") | AA6: =IF((F6="FS"),I6," ")
F7: =IF((G7<>0),"Enter Letter"," ") | H7: =IF(H$4>0,(IF(G7<>0,G7*H$4/100," ")),IF(G7<>0,G7*H$2/(100+H$2)," ")) | I7: =IF((G7<>0),G7-H7," ") | M7: =IF(G7<>0,G7-L7," ") | N7: =IF((G7-L7)<>0,N$1-A7," ") | P7: =IF((F7="a"),I7," ") | Q7: =IF((F7="b"),I7," ") | R7: =IF((F7="c"),I7," ") | S7: =IF((F7=S$4),I7," ") | T7: =IF((F7=T$4),I7," ") | U7: =IF((F7=U$4),I7," ") | V7: =IF((F7=V$4),I7," ") | W7: =IF((F7=W$4),I7," ") | X7: =IF((F7="d"),I7," ") | Y7: =IF((F7="g"),I7," ") | Z7: =IF((F7="o"),I7," ") | AA7: =IF((F7="FS"),I7," ")
