Workbook

Sheet OpeningDebtors
A1: Opening Debtors Balance | C1: =IF([1]OpenAccounts!$E$16>0,[1]OpenAccounts!$E$16,0) -> 0 | D1: Total in C1 should equal F1 | F1: =SUM(F5:F300) -> 0 | G1: =SUM(G5:G300) -> 0 | H1: =SUM(H5:H300) -> 0 | J1: For your information only. Enter How Paid e.g. Cash, Cheque etc., | K1: =SUM(K5:K300) -> 0 | L1: =SUM(L5:L300) -> 0 | M1: =TODAY() -> 45751 | O1: =SUM(O5:O300) -> 0
A2: Sales Date | B2: Customer Name | C2: Sales Invoice Number or reference | D2: Sales Description | F2: Sales Value including Vat | G2: ='Month 01'!G2 -> 20 | H2: Sales Net of Vat | K2: Receipts from Customers | O2: Sub contractors only
G3: Vat Output | K3: Actual amount received | L3: Sales Value not yet received | M3: Number of Days Outstanding | O3: CIS Tax Deducted | P3: CIS Certificate reference
G4: ='Month 01'!G4 -> 0
G5: =IF(G$4>0,(IF(F5<>0,F5*G$4/100," ")),IF(F5<>0,F5*G$2/(100+G$2)," ")) | H5: =IF((F5<>0),F5-G5," ") | L5: =IF(F5<>0,F5-K5," ") | M5: =IF((F5-K5)<>0,M$1-A5," ")
G6: =IF(G$4>0,(IF(F6<>0,F6*G$4/100," ")),IF(F6<>0,F6*G$2/(100+G$2)," ")) | H6: =IF((F6<>0),F6-G6," ") | L6: =IF(F6<>0,F6-K6," ") | M6: =IF((F6-K6)<>0,M$1-A6," ")
G7: =IF(G$4>0,(IF(F7<>0,F7*G$4/100," ")),IF(F7<>0,F7*G$2/(100+G$2)," ")) | H7: =IF((F7<>0),F7-G7," ") | L7: =IF(F7<>0,F7-K7," ") | M7: =IF((F7-K7)<>0,M$1-A7," ")
G8: =IF(G$4>0,(IF(F8<>0,F8*G$4/100," ")),IF(F8<>0,F8*G$2/(100+G$2)," ")) | H8: =IF((F8<>0),F8-G8," ") | L8: =IF(F8<>0,F8-K8," ") | M8: =IF((F8-K8)<>0,M$1-A8," ")
G9: =IF(G$4>0,(IF(F9<>0,F9*G$4/100," ")),IF(F9<>0,F9*G$2/(100+G$2)," ")) | H9: =IF((F9<>0),F9-G9," ") | L9: =IF(F9<>0,F9-K9," ") | M9: =IF((F9-K9)<>0,M$1-A9," ")
G10: =IF(G$4>0,(IF(F10<>0,F10*G$4/100," ")),IF(F10<>0,F10*G$2/(100+G$2)," ")) | H10: =IF((F10<>0),F10-G10," ") | L10: =IF(F10<>0,F10-K10," ") | M10: =IF((F10-K10)<>0,M$1-A10," ")
G11: =IF(G$4>0,(IF(F11<>0,F11*G$4/100," ")),IF(F11<>0,F11*G$2/(100+G$2)," ")) | H11: =IF((F11<>0),F11-G11," ") | L11: =IF(F11<>0,F11-K11," ") | M11: =IF((F11-K11)<>0,M$1-A11," ")
G12: =IF(G$4>0,(IF(F12<>0,F12*G$4/100," ")),IF(F12<>0,F12*G$2/(100+G$2)," ")) | H12: =IF((F12<>0),F12-G12," ") | L12: =IF(F12<>0,F12-K12," ") | M12: =IF((F12-K12)<>0,M$1-A12," ")
G13: =IF(G$4>0,(IF(F13<>0,F13*G$4/100," ")),IF(F13<>0,F13*G$2/(100+G$2)," ")) | H13: =IF((F13<>0),F13-G13," ") | L13: =IF(F13<>0,F13-K13," ") | M13: =IF((F13-K13)<>0,M$1-A13," ")
G14: =IF(G$4>0,(IF(F14<>0,F14*G$4/100," ")),IF(F14<>0,F14*G$2/(100+G$2)," ")) | H14: =IF((F14<>0),F14-G14," ") | L14: =IF(F14<>0,F14-K14," ") | M14: =IF((F14-K14)<>0,M$1-A14," ")
G15: =IF(G$4>0,(IF(F15<>0,F15*G$4/100," ")),IF(F15<>0,F15*G$2/(100+G$2)," ")) | H15: =IF((F15<>0),F15-G15," ") | L15: =IF(F15<>0,F15-K15," ") | M15: =IF((F15-K15)<>0,M$1-A15," ")
G16: =IF(G$4>0,(IF(F16<>0,F16*G$4/100," ")),IF(F16<>0,F16*G$2/(100+G$2)," ")) | H16: =IF((F16<>0),F16-G16," ") | L16: =IF(F16<>0,F16-K16," ") | M16: =IF((F16-K16)<>0,M$1-A16," ")
... G300: =IF(G$4>0,(IF(F300<>0,F300*G$4/100," ")),IF(F300<>0,F300*G$2/(100+G$2)," ")) | H300: =IF((F300<>0),F300-G300," ") | L300: =IF(F300<>0,F300-K300," ") | M300: =IF((F300-K300)<>0,M$1-A300," ")

Sheet Month 01
A1: =F1-G1-SUM(O1:U1) -> 0 | B1: Check Total | C1: Sales Invoice Number or reference | D1: Total for Month | F1: =SUM(F5:F300) -> 0 | G1: =SUM(G5:G300) -> 0 | H1: =SUM(H5:H300) -> 0 | J1: For your information only. Enter How Paid e.g. Cash, Cheque etc., | K1: =SUM(K5:K300) -> 0 | L1: =SUM(L5:L300) -> 0 | M1: =TODAY() -> 45751 | O1: =SUM(O5:O300) -> 0 | P1: =SUM(P5:P300) -> 0 | Q1: =SUM(Q5:Q300) -> 0 | R1: =SUM(R5:R300) -> 0 | S1: =SUM(S5:S300) -> 0 | T1: =SUM(T5:T300) -> 0 | U1: =SUM(U5:U300) -> 0 | V1: =SUM(V5:V300) -> 0
A2: Sales Date | B2: Customer Name | D2: Sales Description | E2: Enter Expense Code Letter | F2: Sales Value including Vat | G2: =[1]Admin!$M$19 -> 20 | H2: Sales Net of Vat | K2: Receipts from Customers | O2: Sales Net of Vat | R2: Other Income | S2: Investment Grants | T2: Bad Debts written off | U2: Sale of Fixed Assets | V2: Sub contractors only
G3: Vat Output | K3: Actual amount received | L3: Sales Value not yet received | M3: Number of Days Outstanding | O3: Product A | P3: Product B | Q3: Product C | V3: CIS Tax Deducted | W3: CIS Certificate reference
O4: A | P4: B | Q4: C | R4: D | S4: G | T4: O | U4: FS
E5: =IF((F5<>0),"Enter Letter"," ") | G5: =IF(G$4>0,(IF(F5<>0,F5*G$4/100," ")),IF(F5<>0,F5*G$2/(100+G$2)," ")) | H5: =IF((F5<>0),F5-G5," ") | L5: =IF(F5<>0,F5-K5," ") | M5: =IF((F5-K5)<>0,M$1-A5," ") | O5: =IF((E5="a"),H5," ") | P5: =IF((E5="b"),H5," ") | Q5: =IF((E5="c"),H5," ") | R5: =IF((E5="d"),H5," ") | S5: =IF((E5="g"),H5," ") | T5: =IF((E5="o"),H5," ") | U5: =IF((E5="FS"),H5," ")
E6: =IF((F6<>0),"Enter Letter"," ") | G6: =IF(G$4>0,(IF(F6<>0,F6*G$4/100," ")),IF(F6<>0,F6*G$2/(100+G$2)," ")) | H6: =IF((F6<>0),F6-G6," ") | L6: =IF(F6<>0,F6-K6," ") | M6: =IF((F6-K6)<>0,M$1-A6," ") | O6: =IF((E6="a"),H6," ") | P6: =IF((E6="b"),H6," ") | Q6: =IF((E6="c"),H6," ") | R6: =IF((E6="d"),H6," ") | S6: =IF((E6="g"),H6," ") | T6: =IF((E6="o"),H6," ") | U6: =IF((E6="FS"),H6," ")
E7: =IF((F7<>0),"Enter Letter"," ") | G7: =IF(G$4>0,(IF(F7<>0,F7*G$4/100," ")),IF(F7<>0,F7*G$2/(100+G$2)," ")) | H7: =IF((F7<>0),F7-G7," ") | L7: =IF(F7<>0,F7-K7," ") | M7: =IF((F7-K7)<>0,M$1-A7," ") | O7: =IF((E7="a"),H7," ") | P7: =IF((E7="b"),H7," ") | Q7: =IF((E7="c"),H7," ") | R7: =IF((E7="d"),H7," ") | S7: =IF((E7="g"),H7," ") | T7: =IF((E7="o"),H7," ") | U7: =IF((E7="FS"),H7," ")
E8: =IF((F8<>0),"Enter Letter"," ") | G8: =IF(G$4>0,(IF(F8<>0,F8*G$4/100," ")),IF(F8<>0,F8*G$2/(100+G$2)," ")) | H8: =IF((F8<>0),F8-G8," ") | L8: =IF(F8<>0,F8-K8," ") | M8: =IF((F8-K8)<>0,M$1-A8," ") | O8: =IF((E8="a"),H8," ") | P8: =IF((E8="b"),H8," ") | Q8: =IF((E8="c"),H8," ") | R8: =IF((E8="d"),H8," ") | S8: =IF((E8="g"),H8," ") | T8: =IF((E8="o"),H8," ") | U8: =IF((E8="FS"),H8," ")
E9: =IF((F9<>0),"Enter Letter"," ") | G9: =IF(G$4>0,(IF(F9<>0,F9*G$4/100," ")),IF(F9<>0,F9*G$2/(100+G$2)," ")) | H9: =IF((F9<>0),F9-G9," ") | L9: =IF(F9<>0,F9-K9," ") | M9: =IF((F9-K9)<>0,M$1-A9," ") | O9: =IF((E9="a"),H9," ") | P9: =IF((E9="b"),H9," ") | Q9: =IF((E9="c"),H9," ") | R9: =IF((E9="d"),H9," ") | S9: =IF((E9="g"),H9," ") | T9: =IF((E9="o"),H9," ") | U9: =IF((E9="FS"),H9," ")
E10: =IF((F10<>0),"Enter Letter"," ") | G10: =IF(G$4>0,(IF(F10<>0,F10*G$4/100," ")),IF(F10<>0,F10*G$2/(100+G$2)," ")) | H10: =IF((F10<>0),F10-G10," ") | L10: =IF(F10<>0,F10-K10," ") | M10: =IF((F10-K10)<>0,M$1-A10," ") | O10: =IF((E10="a"),H10," ") | P10: =IF((E10="b"),H10," ") | Q10: =IF((E10="c"),H10," ") | R10: =IF((E10="d"),H10," ") | S10: =IF((E10="g"),H10," ") | T10: =IF((E10="o"),H10," ") | U10: =IF((E10="FS"),H10," ")
E11: =IF((F11<>0),"Enter Letter"," ") | G11: =IF(G$4>0,(IF(F11<>0,F11*G$4/100," ")),IF(F11<>0,F11*G$2/(100+G$2)," ")) | H11: =IF((F11<>0),F11-G11," ") | L11: =IF(F11<>0,F11-K11," ") | M11: =IF((F11-K11)<>0,M$1-A11," ") | O11: =IF((E11="a"),H11," ") | P11: =IF((E11="b"),H11," ") | Q11: =IF((E11="c"),H11," ") | R11: =IF((E11="d"),H11," ") | S11: =IF((E11="g"),H11," ") | T11: =IF((E11="o"),H11," ") | U11: =IF((E11="FS"),H11," ")
E12: =IF((F12<>0),"Enter Letter"," ") | G12: =IF(G$4>0,(IF(F12<>0,F12*G$4/100," ")),IF(F12<>0,F12*G$2/(100+G$2)," ")) | H12: =IF((F12<>0),F12-G12," ") | L12: =IF(F12<>0,F12-K12," ") | M12: =IF((F12-K12)<>0,M$1-A12," ") | O12: =IF((E12="a"),H12," ") | P12: =IF((E12="b"),H12," ") | Q12: =IF((E12="c"),H12," ") | R12: =IF((E12="d"),H12," ") | S12: =IF((E12="g"),H12," ") | T12: =IF((E12="o"),H12," ") | U12: =IF((E12="FS"),H12," ")
E13: =IF((F13<>0),"Enter Letter"," ") | G13: =IF(G$4>0,(IF(F13<>0,F13*G$4/100," ")),IF(F13<>0,F13*G$2/(100+G$2)," ")) | H13: =IF((F13<>0),F13-G13," ") | L13: =IF(F13<>0,F13-K13," ") | M13: =IF((F13-K13)<>0,M$1-A13," ") | O13: =IF((E13="a"),H13," ") | P13: =IF((E13="b"),H13," ") | Q13: =IF((E13="c"),H13," ") | R13: =IF((E13="d"),H13," ") | S13: =IF((E13="g"),H13," ") | T13: =IF((E13="o"),H13," ") | U13: =IF((E13="FS"),H13," ")
E14: =IF((F14<>0),"Enter Letter"," ") | G14: =IF(G$4>0,(IF(F14<>0,F14*G$4/100," ")),IF(F14<>0,F14*G$2/(100+G$2)," ")) | H14: =IF((F14<>0),F14-G14," ") | L14: =IF(F14<>0,F14-K14," ") | M14: =IF((F14-K14)<>0,M$1-A14," ") | O14: =IF((E14="a"),H14," ") | P14: =IF((E14="b"),H14," ") | Q14: =IF((E14="c"),H14," ") | R14: =IF((E14="d"),H14," ") | S14: =IF((E14="g"),H14," ") | T14: =IF((E14="o"),H14," ") | U14: =IF((E14="FS"),H14," ")
E15: =IF((F15<>0),"Enter Letter"," ") | G15: =IF(G$4>0,(IF(F15<>0,F15*G$4/100," ")),IF(F15<>0,F15*G$2/(100+G$2)," ")) | H15: =IF((F15<>0),F15-G15," ") | L15: =IF(F15<>0,F15-K15," ") | M15: =IF((F15-K15)<>0,M$1-A15," ") | O15: =IF((E15="a"),H15," ") | P15: =IF((E15="b"),H15," ") | Q15: =IF((E15="c"),H15," ") | R15: =IF((E15="d"),H15," ") | S15: =IF((E15="g"),H15," ") | T15: =IF((E15="o"),H15," ") | U15: =IF((E15="FS"),H15," ")
E16: =IF((F16<>0),"Enter Letter"," ") | G16: =IF(G$4>0,(IF(F16<>0,F16*G$4/100," ")),IF(F16<>0,F16*G$2/(100+G$2)," ")) | H16: =IF((F16<>0),F16-G16," ") | L16: =IF(F16<>0,F16-K16," ") | M16: =IF((F16-K16)<>0,M$1-A16," ") | O16: =IF((E16="a"),H16," ") | P16: =IF((E16="b"),H16," ") | Q16: =IF((E16="c"),H16," ") | R16: =IF((E16="d"),H16," ") | S16: =IF((E16="g"),H16," ") | T16: =IF((E16="o"),H16," ") | U16: =IF((E16="FS"),H16," ")
... E300: =IF((F300<>0),"Enter Letter"," ") | G300: =IF(G$4>0,(IF(F300<>0,F300*G$4/100," ")),IF(F300<>0,F300*G$2/(100+G$2)," ")) | H300: =IF((F300<>0),F300-G300," ") | L300: =IF(F300<>0,F300-K300," ") | M300: =IF((F300-K300)<>0,M$1-A300," ") | O300: =IF((E300="a"),H300," ") | P300: =IF((E300="b"),H300," ") | Q300: =IF((E300="c"),H300," ") | R300: =IF((E300="d"),H300," ") | S300: =IF((E300="g"),H300," ") | T300: =IF((E300="o"),H300," ") | U300: =IF((E300="FS"),H300," ")

Sheet Month 02
A1: =F1-G1-SUM(O1:U1) -> 0 | B1: Check Total | C1: Sales Invoice Number or reference | D1: Total for Month | F1: =SUM(F5:F300) -> 0 | G1: =SUM(G5:G300) -> 0 | H1: =SUM(H5:H300) -> 0 | J1: For your information only. Enter How Paid e.g. Cash, Cheque etc., | K1: =SUM(K5:K300) -> 0 | L1: =SUM(L5:L300) -> 0 | M1: =TODAY() -> 45751 | O1: =SUM(O5:O300) -> 0 | P1: =SUM(P5:P300) -> 0 | Q1: =SUM(Q5:Q300) -> 0 | R1: =SUM(R5:R300) -> 0 | S1: =SUM(S5:S300) -> 0 | T1: =SUM(T5:T300) -> 0 | U1: =SUM(U5:U300) -> 0 | V1: =SUM(V5:V300) -> 0
A2: Sales Date | B2: Customer Name | D2: Sales Description | E2: Enter Expense Code Letter | F2: Sales Value including Vat | G2: ='Month 01'!G2 -> 20 | H2: Sales Net of Vat | K2: Receipts from Customers | O2: Sales Net of Vat | R2: Other Income | S2: Investment Grants | T2: Bad Debts written off | U2: Sale of Fixed Assets | V2: Sub contractors only
G3: Vat Output | K3: Actual amount received | L3: Sales Value not yet received | M3: Number of Days Outstanding | O3: Product A | P3: Product B | Q3: Product C | V3: CIS Tax Deducted | W3: CIS Certificate reference
G4: ='Month 01'!G4 -> 0 | O4: A | P4: B | Q4: C | R4: D | S4: G | T4: O | U4: FS
E5: =IF((F5<>0),"Enter Letter"," ") | G5: =IF(G$4>0,(IF(F5<>0,F5*G$4/100," ")),IF(F5<>0,F5*G$2/(100+G$2)," ")) | H5: =IF((F5<>0),F5-G5," ") | L5: =IF(F5<>0,F5-K5," ") | M5: =IF((F5-K5)<>0,M$1-A5," ") | O5: =IF((E5="a"),H5," ") | P5: =IF((E5="b"),H5," ") | Q5: =IF((E5="c"),H5," ") | R5: =IF((E5="d"),H5," ") | S5: =IF((E5="g"),H5," ") | T5: =IF((E5="o"),H5," ") | U5: =IF((E5="FS"),H5," ")
E6: =IF((F6<>0),"Enter Letter"," ") | G6: =IF(G$4>0,(IF(F6<>0,F6*G$4/100," ")),IF(F6<>0,F6*G$2/(100+G$2)," ")) | H6: =IF((F6<>0),F6-G6," ") | L6: =IF(F6<>0,F6-K6," ") | M6: =IF((F6-K6)<>0,M$1-A6," ") | O6: =IF((E6="a"),H6," ") | P6: =IF((E6="b"),H6," ") | Q6: =IF((E6="c"),H6," ") | R6: =IF((E6="d"),H6," ") | S6: =IF((E6="g"),H6," ") | T6: =IF((E6="o"),H6," ") | U6: =IF((E6="FS"),H6," ")
E7: =IF((F7<>0),"Enter Letter"," ") | G7: =IF(G$4>0,(IF(F7<>0,F7*G$4/100," ")),IF(F7<>0,F7*G$2/(100+G$2)," ")) | H7: =IF((F7<>0),F7-G7," ") | L7: =IF(F7<>0,F7-K7," ") | M7: =IF((F7-K7)<>0,M$1-A7," ") | O7: =IF((E7="a"),H7," ") | P7: =IF((E7="b"),H7," ") | Q7: =IF((E7="c"),H7," ") | R7: =IF((E7="d"),H7," ") | S7: =IF((E7="g"),H7," ") | T7: =IF((E7="o"),H7," ") | U7: =IF((E7="FS"),H7," ")
E8: =IF((F8<>0),"Enter Letter"," ") | G8: =IF(G$4>0,(IF(F8<>0,F8*G$4/100," ")),IF(F8<>0,F8*G$2/(100+G$2)," ")) | H8: =IF((F8<>0),F8-G8," ") | L8: =IF(F8<>0,F8-K8," ") | M8: =IF((F8-K8)<>0,M$1-A8," ") | O8: =IF((E8="a"),H8," ") | P8: =IF((E8="b"),H8," ") | Q8: =IF((E8="c"),H8," ") | R8: =IF((E8="d"),H8," ") | S8: =IF((E8="g"),H8," ") | T8: =IF((E8="o"),H8," ") | U8: =IF((E8="FS"),H8," ")
E9: =IF((F9<>0),"Enter Letter"," ") | G9: =IF(G$4>0,(IF(F9<>0,F9*G$4/100," ")),IF(F9<>0,F9*G$2/(100+G$2)," ")) | H9: =IF((F9<>0),F9-G9," ") | L9: =IF(F9<>0,F9-K9," ") | M9: =IF((F9-K9)<>0,M$1-A9," ") | O9: =IF((E9="a"),H9," ") | P9: =IF((E9="b"),H9," ") | Q9: =IF((E9="c"),H9," ") | R9: =IF((E9="d"),H9," ") | S9: =IF((E9="g"),H9," ") | T9: =IF((E9="o"),H9," ") | U9: =IF((E9="FS"),H9," ")
E10: =IF((F10<>0),"Enter Letter"," ") | G10: =IF(G$4>0,(IF(F10<>0,F10*G$4/100," ")),IF(F10<>0,F10*G$2/(100+G$2)," ")) | H10: =IF((F10<>0),F10-G10," ") | L10: =IF(F10<>0,F10-K10," ") | M10: =IF((F10-K10)<>0,M$1-A10," ") | O10: =IF((E10="a"),H10," ") | P10: =IF((E10="b"),H10," ") | Q10: =IF((E10="c"),H10," ") | R10: =IF((E10="d"),H10," ") | S10: =IF((E10="g"),H10," ") | T10: =IF((E10="o"),H10," ") | U10: =IF((E10="FS"),H10," ")
E11: =IF((F11<>0),"Enter Letter"," ") | G11: =IF(G$4>0,(IF(F11<>0,F11*G$4/100," ")),IF(F11<>0,F11*G$2/(100+G$2)," ")) | H11: =IF((F11<>0),F11-G11," ") | L11: =IF(F11<>0,F11-K11," ") | M11: =IF((F11-K11)<>0,M$1-A11," ") | O11: =IF((E11="a"),H11," ") | P11: =IF((E11="b"),H11," ") | Q11: =IF((E11="c"),H11," ") | R11: =IF((E11="d"),H11," ") | S11: =IF((E11="g"),H11," ") | T11: =IF((E11="o"),H11," ") | U11: =IF((E11="FS"),H11," ")
E12: =IF((F12<>0),"Enter Letter"," ") | G12: =IF(G$4>0,(IF(F12<>0,F12*G$4/100," ")),IF(F12<>0,F12*G$2/(100+G$2)," ")) | H12: =IF((F12<>0),F12-G12," ") | L12: =IF(F12<>0,F12-K12," ") | M12: =IF((F12-K12)<>0,M$1-A12," ") | O12: =IF((E12="a"),H12," ") | P12: =IF((E12="b"),H12," ") | Q12: =IF((E12="c"),H12," ") | R12: =IF((E12="d"),H12," ") | S12: =IF((E12="g"),H12," ") | T12: =IF((E12="o"),H12," ") | U12: =IF((E12="FS"),H12," ")
E13: =IF((F13<>0),"Enter Letter"," ") | G13: =IF(G$4>0,(IF(F13<>0,F13*G$4/100," ")),IF(F13<>0,F13*G$2/(100+G$2)," ")) | H13: =IF((F13<>0),F13-G13," ") | L13: =IF(F13<>0,F13-K13," ") | M13: =IF((F13-K13)<>0,M$1-A13," ") | O13: =IF((E13="a"),H13," ") | P13: =IF((E13="b"),H13," ") | Q13: =IF((E13="c"),H13," ") | R13: =IF((E13="d"),H13," ") | S13: =IF((E13="g"),H13," ") | T13: =IF((E13="o"),H13," ") | U13: =IF((E13="FS"),H13," ")
E14: =IF((F14<>0),"Enter Letter"," ") | G14: =IF(G$4>0,(IF(F14<>0,F14*G$4/100," ")),IF(F14<>0,F14*G$2/(100+G$2)," ")) | H14: =IF((F14<>0),F14-G14," ") | L14: =IF(F14<>0,F14-K14," ") | M14: =IF((F14-K14)<>0,M$1-A14," ") | O14: =IF((E14="a"),H14," ") | P14: =IF((E14="b"),H14," ") | Q14: =IF((E14="c"),H14," ") | R14: =IF((E14="d"),H14," ") | S14: =IF((E14="g"),H14," ") | T14: =IF((E14="o"),H14," ") | U14: =IF((E14="FS"),H14," ")
E15: =IF((F15<>0),"Enter Letter"," ") | G15: =IF(G$4>0,(IF(F15<>0,F15*G$4/100," ")),IF(F15<>0,F15*G$2/(100+G$2)," ")) | H15: =IF((F15<>0),F15-G15," ") | L15: =IF(F15<>0,F15-K15," ") | M15: =IF((F15-K15)<>0,M$1-A15," ") | O15: =IF((E15="a"),H15," ") | P15: =IF((E15="b"),H15," ") | Q15: =IF((E15="c"),H15," ") | R15: =IF((E15="d"),H15," ") | S15: =IF((E15="g"),H15," ") | T15: =IF((E15="o"),H15," ") | U15: =IF((E15="FS"),H15," ")
E16: =IF((F16<>0),"Enter Letter"," ") | G16: =IF(G$4>0,(IF(F16<>0,F16*G$4/100," ")),IF(F16<>0,F16*G$2/(100+G$2)," ")) | H16: =IF((F16<>0),F16-G16," ") | L16: =IF(F16<>0,F16-K16," ") | M16: =IF((F16-K16)<>0,M$1-A16," ") | O16: =IF((E16="a"),H16," ") | P16: =IF((E16="b"),H16," ") | Q16: =IF((E16="c"),H16," ") | R16: =IF((E16="d"),H16," ") | S16: =IF((E16="g"),H16," ") | T16: =IF((E16="o"),H16," ") | U16: =IF((E16="FS"),H16," ")
... E300: =IF((F300<>0),"Enter Letter"," ") | G300: =IF(G$4>0,(IF(F300<>0,F300*G$4/100," ")),IF(F300<>0,F300*G$2/(100+G$2)," ")) | H300: =IF((F300<>0),F300-G300," ") | L300: =IF(F300<>0,F300-K300," ") | M300: =IF((F300-K300)<>0,M$1-A300," ") | O300: =IF((E300="a"),H300," ") | P300: =IF((E300="b"),H300," ") | Q300: =IF((E300="c"),H300," ") | R300: =IF((E300="d"),H300," ") | S300: =IF((E300="g"),H300," ") | T300: =IF((E300="o"),H300," ") | U300: =IF((E300="FS"),H300," ")

Sheet Month 03
A1: =F1-G1-SUM(O1:U1) -> 0 | B1: Check Total | C1: Sales Invoice Number or reference | D1: Total for Month | F1: =SUM(F5:F300) -> 0 | G1: =SUM(G5:G300) -> 0 | H1: =SUM(H5:H300) -> 0 | J1: For your information only. Enter How Paid e.g. Cash, Cheque etc., | K1: =SUM(K5:K300) -> 0 | L1: =SUM(L5:L300) -> 0 | M1: =TODAY() -> 45751 | O1: =SUM(O5:O300) -> 0 | P1: =SUM(P5:P300) -> 0 | Q1: =SUM(Q5:Q300) -> 0 | R1: =SUM(R5:R300) -> 0 | S1: =SUM(S5:S300) -> 0 | T1: =SUM(T5:T300) -> 0 | U1: =SUM(U5:U300) -> 0 | V1: =SUM(V5:V300) -> 0
A2: Sales Date | B2: Customer Name | D2: Sales Description | E2: Enter Expense Code Letter | F2: Sales Value including Vat | G2: ='Month 02'!G2 -> 20 | H2: Sales Net of Vat | K2: Receipts from Customers | O2: Sales Net of Vat | R2: Other Income | S2: Investment Grants | T2: Bad Debts written off | U2: Sale of Fixed Assets | V2: Sub contractors only
G3: Vat Output | K3: Actual amount received | L3: Sales Value not yet received | M3: Number of Days Outstanding | O3: Product A | P3: Product B | Q3: Product C | V3: CIS Tax Deducted | W3: CIS Certificate reference
G4: ='Month 02'!G4 -> 0 | O4: A | P4: B | Q4: C | R4: D | S4: G | T4: O | U4: FS
E5: =IF((F5<>0),"Enter Letter"," ") | G5: =IF(G$4>0,(IF(F5<>0,F5*G$4/100," ")),IF(F5<>0,F5*G$2/(100+G$2)," ")) | H5: =IF((F5<>0),F5-G5," ") | L5: =IF(F5<>0,F5-K5," ") | M5: =IF((F5-K5)<>0,M$1-A5," ") | O5: =IF((E5="a"),H5," ") | P5: =IF((E5="b"),H5," ") | Q5: =IF((E5="c"),H5," ") | R5: =IF((E5="d"),H5," ") | S5: =IF((E5="g"),H5," ") | T5: =IF((E5="o"),H5," ") | U5: =IF((E5="FS"),H5," ")
E6: =IF((F6<>0),"Enter Letter"," ") | G6: =IF(G$4>0,(IF(F6<>0,F6*G$4/100," ")),IF(F6<>0,F6*G$2/(100+G$2)," ")) | H6: =IF((F6<>0),F6-G6," ") | L6: =IF(F6<>0,F6-K6," ") | M6: =IF((F6-K6)<>0,M$1-A6," ") | O6: =IF((E6="a"),H6," ") | P6: =IF((E6="b"),H6," ") | Q6: =IF((E6="c"),H6," ") | R6: =IF((E6="d"),H6," ") | S6: =IF((E6="g"),H6," ") | T6: =IF((E6="o"),H6," ") | U6: =IF((E6="FS"),H6," ")
E7: =IF((F7<>0),"Enter Letter"," ") | G7: =IF(G$4>0,(IF(F7<>0,F7*G$4/100," ")),IF(F7<>0,F7*G$2/(100+G$2)," ")) | H7: =IF((F7<>0),F7-G7," ") | L7: =IF(F7<>0,F7-K7," ") | M7: =IF((F7-K7)<>0,M$1-A7," ") | O7: =IF((E7="a"),H7," ") | P7: =IF((E7="b"),H7," ") | Q7: =IF((E7="c"),H7," ") | R7: =IF((E7="d"),H7," ") | S7: =IF((E7="g"),H7," ") | T7: =IF((E7="o"),H7," ") | U7: =IF((E7="FS"),H7," ")
E8: =IF((F8<>0),"Enter Letter"," ") | G8: =IF(G$4>0,(IF(F8<>0,F8*G$4/100," ")),IF(F8<>0,F8*G$2/(100+G$2)," ")) | H8: =IF((F8<>0),F8-G8," ") | L8: =IF(F8<>0,F8-K8," ") | M8: =IF((F8-K8)<>0,M$1-A8," ") | O8: =IF((E8="a"),H8," ") | P8: =IF((E8="b"),H8," ") | Q8: =IF((E8="c"),H8," ") | R8: =IF((E8="d"),H8," ") | S8: =IF((E8="g"),H8," ") | T8: =IF((E8="o"),H8," ") | U8: =IF((E8="FS"),H8," ")
E9: =IF((F9<>0),"Enter Letter"," ") | G9: =IF(G$4>0,(IF(F9<>0,F9*G$4/100," ")),IF(F9<>0,F9*G$2/(100+G$2)," ")) | H9: =IF((F9<>0),F9-G9," ") | L9: =IF(F9<>0,F9-K9," ") | M9: =IF((F9-K9)<>0,M$1-A9," ") | O9: =IF((E9="a"),H9," ") | P9: =IF((E9="b"),H9," ") | Q9: =IF((E9="c"),H9," ") | R9: =IF((E9="d"),H9," ") | S9: =IF((E9="g"),H9," ") | T9: =IF((E9="o"),H9," ") | U9: =IF((E9="FS"),H9," ")
E10: =IF((F10<>0),"Enter Letter"," ") | G10: =IF(G$4>0,(IF(F10<>0,F10*G$4/100," ")),IF(F10<>0,F10*G$2/(100+G$2)," ")) | H10: =IF((F10<>0),F10-G10," ") | L10: =IF(F10<>0,F10-K10," ") | M10: =IF((F10-K10)<>0,M$1-A10," ") | O10: =IF((E10="a"),H10," ") | P10: =IF((E10="b"),H10," ") | Q10: =IF((E10="c"),H10," ") | R10: =IF((E10="d"),H10," ") | S10: =IF((E10="g"),H10," ") | T10: =IF((E10="o"),H10," ") | U10: =IF((E10="FS"),H10," ")
E11: =IF((F11<>0),"Enter Letter"," ") | G11: =IF(G$4>0,(IF(F11<>0,F11*G$4/100," ")),IF(F11<>0,F11*G$2/(100+G$2)," ")) | H11: =IF((F11<>0),F11-G11," ") | L11: =IF(F11<>0,F11-K11," ") | M11: =IF((F11-K11)<>0,M$1-A11," ") | O11: =IF((E11="a"),H11," ") | P11: =IF((E11="b"),H11," ") | Q11: =IF((E11="c"),H11," ") | R11: =IF((E11="d"),H11," ") | S11: =IF((E11="g"),H11," ") | T11: =IF((E11="o"),H11," ") | U11: =IF((E11="FS"),H11," ")
E12: =IF((F12<>0),"Enter Letter"," ") | G12: =IF(G$4>0,(IF(F12<>0,F12*G$4/100," ")),IF(F12<>0,F12*G$2/(100+G$2)," ")) | H12: =IF((F12<>0),F12-G12," ") | L12: =IF(F12<>0,F12-K12," ") | M12: =IF((F12-K12)<>0,M$1-A12," ") | O12: =IF((E12="a"),H12," ") | P12: =IF((E12="b"),H12," ") | Q12: =IF((E12="c"),H12," ") | R12: =IF((E12="d"),H12," ") | S12: =IF((E12="g"),H12," ") | T12: =IF((E12="o"),H12," ") | U12: =IF((E12="FS"),H12," ")
E13: =IF((F13<>0),"Enter Letter"," ") | G13: =IF(G$4>0,(IF(F13<>0,F13*G$4/100," ")),IF(F13<>0,F13*G$2/(100+G$2)," ")) | H13: =IF((F13<>0),F13-G13," ") | L13: =IF(F13<>0,F13-K13," ") | M13: =IF((F13-K13)<>0,M$1-A13," ") | O13: =IF((E13="a"),H13," ") | P13: =IF((E13="b"),H13," ") | Q13: =IF((E13="c"),H13," ") | R13: =IF((E13="d"),H13," ") | S13: =IF((E13="g"),H13," ") | T13: =IF((E13="o"),H13," ") | U13: =IF((E13="FS"),H13," ")
E14: =IF((F14<>0),"Enter Letter"," ") | G14: =IF(G$4>0,(IF(F14<>0,F14*G$4/100," ")),IF(F14<>0,F14*G$2/(100+G$2)," ")) | H14: =IF((F14<>0),F14-G14," ") | L14: =IF(F14<>0,F14-K14," ") | M14: =IF((F14-K14)<>0,M$1-A14," ") | O14: =IF((E14="a"),H14," ") | P14: =IF((E14="b"),H14," ") | Q14: =IF((E14="c"),H14," ") | R14: =IF((E14="d"),H14," ") | S14: =IF((E14="g"),H14," ") | T14: =IF((E14="o"),H14," ") | U14: =IF((E14="FS"),H14," ")
E15: =IF((F15<>0),"Enter Letter"," ") | G15: =IF(G$4>0,(IF(F15<>0,F15*G$4/100," ")),IF(F15<>0,F15*G$2/(100+G$2)," ")) | H15: =IF((F15<>0),F15-G15," ") | L15: =IF(F15<>0,F15-K15," ") | M15: =IF((F15-K15)<>0,M$1-A15," ") | O15: =IF((E15="a"),H15," ") | P15: =IF((E15="b"),H15," ") | Q15: =IF((E15="c"),H15," ") | R15: =IF((E15="d"),H15," ") | S15: =IF((E15="g"),H15," ") | T15: =IF((E15="o"),H15," ") | U15: =IF((E15="FS"),H15," ")
E16: =IF((F16<>0),"Enter Letter"," ") | G16: =IF(G$4>0,(IF(F16<>0,F16*G$4/100," ")),IF(F16<>0,F16*G$2/(100+G$2)," ")) | H16: =IF((F16<>0),F16-G16," ") | L16: =IF(F16<>0,F16-K16," ") | M16: =IF((F16-K16)<>0,M$1-A16," ") | O16: =IF((E16="a"),H16," ") | P16: =IF((E16="b"),H16," ") | Q16: =IF((E16="c"),H16," ") | R16: =IF((E16="d"),H16," ") | S16: =IF((E16="g"),H16," ") | T16: =IF((E16="o"),H16," ") | U16: =IF((E16="FS"),H16," ")
... E300: =IF((F300<>0),"Enter Letter"," ") | G300: =IF(G$4>0,(IF(F300<>0,F300*G$4/100," ")),IF(F300<>0,F300*G$2/(100+G$2)," ")) | H300: =IF((F300<>0),F300-G300," ") | L300: =IF(F300<>0,F300-K300," ") | M300: =IF((F300-K300)<>0,M$1-A300," ") | O300: =IF((E300="a"),H300," ") | P300: =IF((E300="b"),H300," ") | Q300: =IF((E300="c"),H300," ") | R300: =IF((E300="d"),H300," ") | S300: =IF((E300="g"),H300," ") | T300: =IF((E300="o"),H300," ") | U300: =IF((E300="FS"),H300," ")

Sheet Month 04
A1: =F1-G1-SUM(O1:U1) -> 0 | B1: Check Total | C1: Sales Invoice Number or reference | D1: Total for Month | F1: =SUM(F5:F300) -> 0 | G1: =SUM(G5:G300) -> 0 | H1: =SUM(H5:H300) -> 0 | J1: For your information only. Enter How Paid e.g. Cash, Cheque etc., | K1: =SUM(K5:K300) -> 0 | L1: =SUM(L5:L300) -> 0 | M1: =TODAY() -> 45751 | O1: =SUM(O5:O300) -> 0 | P1: =SUM(P5:P300) -> 0 | Q1: =SUM(Q5:Q300) -> 0 | R1: =SUM(R5:R300) -> 0 | S1: =SUM(S5:S300) -> 0 | T1: =SUM(T5:T300) -> 0 | U1: =SUM(U5:U300) -> 0 | V1: =SUM(V5:V300) -> 0
A2: Sales Date | B2: Customer Name | D2: Sales Description | E2: Enter Expense Code Letter | F2: Sales Value including Vat | G2: ='Month 03'!G2 -> 20 | H2: Sales Net of Vat | K2: Receipts from Customers | O2: Sales Net of Vat | R2: Other Income | S2: Investment Grants | T2: Bad Debts written off | U2: Sale of Fixed Assets | V2: Sub contractors only
G3: Vat Output | K3: Actual amount received | L3: Sales Value not yet received | M3: Number of Days Outstanding | O3: Product A | P3: Product B | Q3: Product C | V3: CIS Tax Deducted | W3: CIS Certificate reference
G4: ='Month 03'!G4 -> 0 | O4: A | P4: B | Q4: C | R4: D | S4: G | T4: O | U4: FS
E5: =IF((F5<>0),"Enter Letter"," ") | G5: =IF(G$4>0,(IF(F5<>0,F5*G$4/100," ")),IF(F5<>0,F5*G$2/(100+G$2)," ")) | H5: =IF((F5<>0),F5-G5," ") | L5: =IF(F5<>0,F5-K5," ") | M5: =IF((F5-K5)<>0,M$1-A5," ") | O5: =IF((E5="a"),H5," ") | P5: =IF((E5="b"),H5," ") | Q5: =IF((E5="c"),H5," ") | R5: =IF((E5="d"),H5," ") | S5: =IF((E5="g"),H5," ") | T5: =IF((E5="o"),H5," ") | U5: =IF((E5="FS"),H5," ")
E6: =IF((F6<>0),"Enter Letter"," ") | G6: =IF(G$4>0,(IF(F6<>0,F6*G$4/100," ")),IF(F6<>0,F6*G$2/(100+G$2)," ")) | H6: =IF((F6<>0),F6-G6," ") | L6: =IF(F6<>0,F6-K6," ") | M6: =IF((F6-K6)<>0,M$1-A6," ") | O6: =IF((E6="a"),H6," ") | P6: =IF((E6="b"),H6," ") | Q6: =IF((E6="c"),H6," ") | R6: =IF((E6="d"),H6," ") | S6: =IF((E6="g"),H6," ") | T6: =IF((E6="o"),H6," ") | U6: =IF((E6="FS"),H6," ")
E7: =IF((F7<>0),"Enter Letter"," ") | G7: =IF(G$4>0,(IF(F7<>0,F7*G$4/100," ")),IF(F7<>0,F7*G$2/(100+G$2)," ")) | H7: =IF((F7<>0),F7-G7," ") | L7: =IF(F7<>0,F7-K7," ") | M7: =IF((F7-K7)<>0,M$1-A7," ") | O7: =IF((E7="a"),H7," ") | P7: =IF((E7="b"),H7," ") | Q7: =IF((E7="c"),H7," ") | R7: =IF((E7="d"),H7," ") | S7: =IF((E7="g"),H7," ") | T7: =IF((E7="o"),H7," ") | U7: =IF((E7="FS"),H7," ")
E8: =IF((F8<>0),"Enter Letter"," ") | G8: =IF(G$4>0,(IF(F8<>0,F8*G$4/100," ")),IF(F8<>0,F8*G$2/(100+G$2)," ")) | H8: =IF((F8<>0),F8-G8," ") | L8: =IF(F8<>0,F8-K8," ") | M8: =IF((F8-K8)<>0,M$1-A8," ") | O8: =IF((E8="a"),H8," ") | P8: =IF((E8="b"),H8," ") | Q8: =IF((E8="c"),H8," ") | R8: =IF((E8="d"),H8," ") | S8: =IF((E8="g"),H8," ") | T8: =IF((E8="o"),H8," ") | U8: =IF((E8="FS"),H8," ")
E9: =IF((F9<>0),"Enter Letter"," ") | G9: =IF(G$4>0,(IF(F9<>0,F9*G$4/100," ")),IF(F9<>0,F9*G$2/(100+G$2)," ")) | H9: =IF((F9<>0),F9-G9," ") | L9: =IF(F9<>0,F9-K9," ") | M9: =IF((F9-K9)<>0,M$1-A9," ") | O9: =IF((E9="a"),H9," ") | P9: =IF((E9="b"),H9," ") | Q9: =IF((E9="c"),H9," ") | R9: =IF((E9="d"),H9," ") | S9: =IF((E9="g"),H9," ") | T9: =IF((E9="o"),H9," ") | U9: =IF((E9="FS"),H9," ")
E10: =IF((F10<>0),"Enter Letter"," ") | G10: =IF(G$4>0,(IF(F10<>0,F10*G$4/100," ")),IF(F10<>0,F10*G$2/(100+G$2)," ")) | H10: =IF((F10<>0),F10-G10," ") | L10: =IF(F10<>0,F10-K10," ") | M10: =IF((F10-K10)<>0,M$1-A10," ") | O10: =IF((E10="a"),H10," ") | P10: =IF((E10="b"),H10," ") | Q10: =IF((E10="c"),H10," ") | R10: =IF((E10="d"),H10," ") | S10: =IF((E10="g"),H10," ") | T10: =IF((E10="o"),H10," ") | U10: =IF((E10="FS"),H10," ")
E11: =IF((F11<>0),"Enter Letter"," ") | G11: =IF(G$4>0,(IF(F11<>0,F11*G$4/100," ")),IF(F11<>0,F11*G$2/(100+G$2)," ")) | H11: =IF((F11<>0),F11-G11," ") | L11: =IF(F11<>0,F11-K11," ") | M11: =IF((F11-K11)<>0,M$1-A11," ") | O11: =IF((E11="a"),H11," ") | P11: =IF((E11="b"),H11," ") | Q11: =IF((E11="c"),H11," ") | R11: =IF((E11="d"),H11," ") | S11: =IF((E11="g"),H11," ") | T11: =IF((E11="o"),H11," ") | U11: =IF((E11="FS"),H11," ")
E12: =IF((F12<>0),"Enter Letter"," ") | G12: =IF(G$4>0,(IF(F12<>0,F12*G$4/100," ")),IF(F12<>0,F12*G$2/(100+G$2)," ")) | H12: =IF((F12<>0),F12-G12," ") | L12: =IF(F12<>0,F12-K12," ") | M12: =IF((F12-K12)<>0,M$1-A12," ") | O12: =IF((E12="a"),H12," ") | P12: =IF((E12="b"),H12," ") | Q12: =IF((E12="c"),H12," ") | R12: =IF((E12="d"),H12," ") | S12: =IF((E12="g"),H12," ") | T12: =IF((E12="o"),H12," ") | U12: =IF((E12="FS"),H12," ")
E13: =IF((F13<>0),"Enter Letter"," ") | G13: =IF(G$4>0,(IF(F13<>0,F13*G$4/100," ")),IF(F13<>0,F13*G$2/(100+G$2)," ")) | H13: =IF((F13<>0),F13-G13," ") | L13: =IF(F13<>0,F13-K13," ") | M13: =IF((F13-K13)<>0,M$1-A13," ") | O13: =IF((E13="a"),H13," ") | P13: =IF((E13="b"),H13," ") | Q13: =IF((E13="c"),H13," ") | R13: =IF((E13="d"),H13," ") | S13: =IF((E13="g"),H13," ") | T13: =IF((E13="o"),H13," ") | U13: =IF((E13="FS"),H13," ")
E14: =IF((F14<>0),"Enter Letter"," ") | G14: =IF(G$4>0,(IF(F14<>0,F14*G$4/100," ")),IF(F14<>0,F14*G$2/(100+G$2)," ")) | H14: =IF((F14<>0),F14-G14," ") | L14: =IF(F14<>0,F14-K14," ") | M14: =IF((F14-K14)<>0,M$1-A14," ") | O14: =IF((E14="a"),H14," ") | P14: =IF((E14="b"),H14," ") | Q14: =IF((E14="c"),H14," ") | R14: =IF((E14="d"),H14," ") | S14: =IF((E14="g"),H14," ") | T14: =IF((E14="o"),H14," ") | U14: =IF((E14="FS"),H14," ")
E15: =IF((F15<>0),"Enter Letter"," ") | G15: =IF(G$4>0,(IF(F15<>0,F15*G$4/100," ")),IF(F15<>0,F15*G$2/(100+G$2)," ")) | H15: =IF((F15<>0),F15-G15," ") | L15: =IF(F15<>0,F15-K15," ") | M15: =IF((F15-K15)<>0,M$1-A15," ") | O15: =IF((E15="a"),H15," ") | P15: =IF((E15="b"),H15," ") | Q15: =IF((E15="c"),H15," ") | R15: =IF((E15="d"),H15," ") | S15: =IF((E15="g"),H15," ") | T15: =IF((E15="o"),H15," ") | U15: =IF((E15="FS"),H15," ")
E16: =IF((F16<>0),"Enter Letter"," ") | G16: =IF(G$4>0,(IF(F16<>0,F16*G$4/100," ")),IF(F16<>0,F16*G$2/(100+G$2)," ")) | H16: =IF((F16<>0),F16-G16," ") | L16: =IF(F16<>0,F16-K16," ") | M16: =IF((F16-K16)<>0,M$1-A16," ") | O16: =IF((E16="a"),H16," ") | P16: =IF((E16="b"),H16," ") | Q16: =IF((E16="c"),H16," ") | R16: =IF((E16="d"),H16," ") | S16: =IF((E16="g"),H16," ") | T16: =IF((E16="o"),H16," ") | U16: =IF((E16="FS"),H16," ")
... E300: =IF((F300<>0),"Enter Letter"," ") | G300: =IF(G$4>0,(IF(F300<>0,F300*G$4/100," ")),IF(F300<>0,F300*G$2/(100+G$2)," ")) | H300: =IF((F300<>0),F300-G300," ") | L300: =IF(F300<>0,F300-K300," ") | M300: =IF((F300-K300)<>0,M$1-A300," ") | O300: =IF((E300="a"),H300," ") | P300: =IF((E300="b"),H300," ") | Q300: =IF((E300="c"),H300," ") | R300: =IF((E300="d"),H300," ") | S300: =IF((E300="g"),H300," ") | T300: =IF((E300="o"),H300," ") | U300: =IF((E300="FS"),H300," ")

Sheet Month 05
A1: =F1-G1-SUM(O1:U1) -> 0 | B1: Check Total | C1: Sales Invoice Number or reference | D1: Total for Month | F1: =SUM(F5:F300) -> 0 | G1: =SUM(G5:G300) -> 0 | H1: =SUM(H5:H300) -> 0 | J1: For your information only. Enter How Paid e.g. Cash, Cheque etc., | K1: =SUM(K5:K300) -> 0 | L1: =SUM(L5:L300) -> 0 | M1: =TODAY() -> 45751 | O1: =SUM(O5:O300) -> 0 | P1: =SUM(P5:P300) -> 0 | Q1: =SUM(Q5:Q300) -> 0 | R1: =SUM(R5:R300) -> 0 | S1: =SUM(S5:S300) -> 0 | T1: =SUM(T5:T300) -> 0 | U1: =SUM(U5:U300) -> 0 | V1: =SUM(V5:V300) -> 0
A2: Sales Date | B2: Customer Name | D2: Sales Description | E2: Enter Expense Code Letter | F2: Sales Value including Vat | G2: ='Month 04'!G2 -> 20 | H2: Sales Net of Vat | K2: Receipts from Customers | O2: Sales Net of Vat | R2: Other Income | S2: Investment Grants | T2: Bad Debts written off | U2: Sale of Fixed Assets | V2: Sub contractors only
G3: Vat Output | K3: Actual amount received | L3: Sales Value not yet received | M3: Number of Days Outstanding | O3: Product A | P3: Product B | Q3: Product C | V3: CIS Tax Deducted | W3: CIS Certificate reference
G4: ='Month 04'!G4 -> 0 | O4: A | P4: B | Q4: C | R4: D | S4: G | T4: O | U4: FS
E5: =IF((F5<>0),"Enter Letter"," ") | G5: =IF(G$4>0,(IF(F5<>0,F5*G$4/100," ")),IF(F5<>0,F5*G$2/(100+G$2)," ")) | H5: =IF((F5<>0),F5-G5," ") | L5: =IF(F5<>0,F5-K5," ") | M5: =IF((F5-K5)<>0,M$1-A5," ") | O5: =IF((E5="a"),H5," ") | P5: =IF((E5="b"),H5," ") | Q5: =IF((E5="c"),H5," ") | R5: =IF((E5="d"),H5," ") | S5: =IF((E5="g"),H5," ") | T5: =IF((E5="o"),H5," ") | U5: =IF((E5="FS"),H5," ")
E6: =IF((F6<>0),"Enter Letter"," ") | G6: =IF(G$4>0,(IF(F6<>0,F6*G$4/100," ")),IF(F6<>0,F6*G$2/(100+G$2)," ")) | H6: =IF((F6<>0),F6-G6," ") | L6: =IF(F6<>0,F6-K6," ") | M6: =IF((F6-K6)<>0,M$1-A6," ") | O6: =IF((E6="a"),H6," ") | P6: =IF((E6="b"),H6," ") | Q6: =IF((E6="c"),H6," ") | R6: =IF((E6="d"),H6," ") | S6: =IF((E6="g"),H6," ") | T6: =IF((E6="o"),H6," ") | U6: =IF((E6="FS"),H6," ")
E7: =IF((F7<>0),"Enter Letter"," ") | G7: =IF(G$4>0,(IF(F7<>0,F7*G$4/100," ")),IF(F7<>0,F7*G$2/(100+G$2)," ")) | H7: =IF((F7<>0),F7-G7," ") | L7: =IF(F7<>0,F7-K7," ") | M7: =IF((F7-K7)<>0,M$1-A7," ") | O7: =IF((E7="a"),H7," ") | P7: =IF((E7="b"),H7," ") | Q7: =IF((E7="c"),H7," ") | R7: =IF((E7="d"),H7," ") | S7: =IF((E7="g"),H7," ") | T7: =IF((E7="o"),H7," ") | U7: =IF((E7="FS"),H7," ")
E8: =IF((F8<>0),"Enter Letter"," ") | G8: =IF(G$4>0,(IF(F8<>0,F8*G$4/100," ")),IF(F8<>0,F8*G$2/(100+G$2)," ")) | H8: =IF((F8<>0),F8-G8," ") | L8: =IF(F8<>0,F8-K8," ") | M8: =IF((F8-K8)<>0,M$1-A8," ") | O8: =IF((E8="a"),H8," ") | P8: =IF((E8="b"),H8," ") | Q8: =IF((E8="c"),H8," ") | R8: =IF((E8="d"),H8," ") | S8: =IF((E8="g"),H8," ") | T8: =IF((E8="o"),H8," ") | U8: =IF((E8="FS"),H8," ")
E9: =IF((F9<>0),"Enter Letter"," ") | G9: =IF(G$4>0,(IF(F9<>0,F9*G$4/100," ")),IF(F9<>0,F9*G$2/(100+G$2)," ")) | H9: =IF((F9<>0),F9-G9," ") | L9: =IF(F9<>0,F9-K9," ") | M9: =IF((F9-K9)<>0,M$1-A9," ") | O9: =IF((E9="a"),H9," ") | P9: =IF((E9="b"),H9," ") | Q9: =IF((E9="c"),H9," ") | R9: =IF((E9="d"),H9," ") | S9: =IF((E9="g"),H9," ") | T9: =IF((E9="o"),H9," ") | U9: =IF((E9="FS"),H9," ")
E10: =IF((F10<>0),"Enter Letter"," ") | G10: =IF(G$4>0,(IF(F10<>0,F10*G$4/100," ")),IF(F10<>0,F10*G$2/(100+G$2)," ")) | H10: =IF((F10<>0),F10-G10," ") | L10: =IF(F10<>0,F10-K10," ") | M10: =IF((F10-K10)<>0,M$1-A10," ") | O10: =IF((E10="a"),H10," ") | P10: =IF((E10="b"),H10," ") | Q10: =IF((E10="c"),H10," ") | R10: =IF((E10="d"),H10," ") | S10: =IF((E10="g"),H10," ") | T10: =IF((E10="o"),H10," ") | U10: =IF((E10="FS"),H10," ")
E11: =IF((F11<>0),"Enter Letter"," ") | G11: =IF(G$4>0,(IF(F11<>0,F11*G$4/100," ")),IF(F11<>0,F11*G$2/(100+G$2)," ")) | H11: =IF((F11<>0),F11-G11," ") | L11: =IF(F11<>0,F11-K11," ") | M11: =IF((F11-K11)<>0,M$1-A11," ") | O11: =IF((E11="a"),H11," ") | P11: =IF((E11="b"),H11," ") | Q11: =IF((E11="c"),H11," ") | R11: =IF((E11="d"),H11," ") | S11: =IF((E11="g"),H11," ") | T11: =IF((E11="o"),H11," ") | U11: =IF((E11="FS"),H11," ")
E12: =IF((F12<>0),"Enter Letter"," ") | G12: =IF(G$4>0,(IF(F12<>0,F12*G$4/100," ")),IF(F12<>0,F12*G$2/(100+G$2)," ")) | H12: =IF((F12<>0),F12-G12," ") | L12: =IF(F12<>0,F12-K12," ") | M12: =IF((F12-K12)<>0,M$1-A12," ") | O12: =IF((E12="a"),H12," ") | P12: =IF((E12="b"),H12," ") | Q12: =IF((E12="c"),H12," ") | R12: =IF((E12="d"),H12," ") | S12: =IF((E12="g"),H12," ") | T12: =IF((E12="o"),H12," ") | U12: =IF((E12="FS"),H12," ")
E13: =IF((F13<>0),"Enter Letter"," ") | G13: =IF(G$4>0,(IF(F13<>0,F13*G$4/100," ")),IF(F13<>0,F13*G$2/(100+G$2)," ")) | H13: =IF((F13<>0),F13-G13," ") | L13: =IF(F13<>0,F13-K13," ") | M13: =IF((F13-K13)<>0,M$1-A13," ") | O13: =IF((E13="a"),H13," ") | P13: =IF((E13="b"),H13," ") | Q13: =IF((E13="c"),H13," ") | R13: =IF((E13="d"),H13," ") | S13: =IF((E13="g"),H13," ") | T13: =IF((E13="o"),H13," ") | U13: =IF((E13="FS"),H13," ")
E14: =IF((F14<>0),"Enter Letter"," ") | G14: =IF(G$4>0,(IF(F14<>0,F14*G$4/100," ")),IF(F14<>0,F14*G$2/(100+G$2)," ")) | H14: =IF((F14<>0),F14-G14," ") | L14: =IF(F14<>0,F14-K14," ") | M14: =IF((F14-K14)<>0,M$1-A14," ") | O14: =IF((E14="a"),H14," ") | P14: =IF((E14="b"),H14," ") | Q14: =IF((E14="c"),H14," ") | R14: =IF((E14="d"),H14," ") | S14: =IF((E14="g"),H14," ") | T14: =IF((E14="o"),H14," ") | U14: =IF((E14="FS"),H14," ")
E15: =IF((F15<>0),"Enter Letter"," ") | G15: =IF(G$4>0,(IF(F15<>0,F15*G$4/100," ")),IF(F15<>0,F15*G$2/(100+G$2)," ")) | H15: =IF((F15<>0),F15-G15," ") | L15: =IF(F15<>0,F15-K15," ") | M15: =IF((F15-K15)<>0,M$1-A15," ") | O15: =IF((E15="a"),H15," ") | P15: =IF((E15="b"),H15," ") | Q15: =IF((E15="c"),H15," ") | R15: =IF((E15="d"),H15," ") | S15: =IF((E15="g"),H15," ") | T15: =IF((E15="o"),H15," ") | U15: =IF((E15="FS"),H15," ")
E16: =IF((F16<>0),"Enter Letter"," ") | G16: =IF(G$4>0,(IF(F16<>0,F16*G$4/100," ")),IF(F16<>0,F16*G$2/(100+G$2)," ")) | H16: =IF((F16<>0),F16-G16," ") | L16: =IF(F16<>0,F16-K16," ") | M16: =IF((F16-K16)<>0,M$1-A16," ") | O16: =IF((E16="a"),H16," ") | P16: =IF((E16="b"),H16," ") | Q16: =IF((E16="c"),H16," ") | R16: =IF((E16="d"),H16," ") | S16: =IF((E16="g"),H16," ") | T16: =IF((E16="o"),H16," ") | U16: =IF((E16="FS"),H16," ")
... E300: =IF((F300<>0),"Enter Letter"," ") | G300: =IF(G$4>0,(IF(F300<>0,F300*G$4/100," ")),IF(F300<>0,F300*G$2/(100+G$2)," ")) | H300: =IF((F300<>0),F300-G300," ") | L300: =IF(F300<>0,F300-K300," ") | M300: =IF((F300-K300)<>0,M$1-A300," ") | O300: =IF((E300="a"),H300," ") | P300: =IF((E300="b"),H300," ") | Q300: =IF((E300="c"),H300," ") | R300: =IF((E300="d"),H300," ") | S300: =IF((E300="g"),H300," ") | T300: =IF((E300="o"),H300," ") | U300: =IF((E300="FS"),H300," ")

Sheet Month 06
A1: =F1-G1-SUM(O1:U1) -> 0 | B1: Check Total | C1: Sales Invoice Number or reference | D1: Total for Month | F1: =SUM(F5:F300) -> 0 | G1: =SUM(G5:G300) -> 0 | H1: =SUM(H5:H300) -> 0 | J1: For your information only. Enter How Paid e.g. Cash, Cheque etc., | K1: =SUM(K5:K300) -> 0 | L1: =SUM(L5:L300) -> 0 | M1: =TODAY() -> 45751 | O1: =SUM(O5:O300) -> 0 | P1: =SUM(P5:P300) -> 0 | Q1: =SUM(Q5:Q300) -> 0 | R1: =SUM(R5:R300) -> 0 | S1: =SUM(S5:S300) -> 0 | T1: =SUM(T5:T300) -> 0 | U1: =SUM(U5:U300) -> 0 | V1: =SUM(V5:V300) -> 0
A2: Sales Date | B2: Customer Name | D2: Sales Description | E2: Enter Expense Code Letter | F2: Sales Value including Vat | G2: ='Month 05'!G2 -> 20 | H2: Sales Net of Vat | K2: Receipts from Customers | O2: Sales Net of Vat | R2: Other Income | S2: Investment Grants | T2: Bad Debts written off | U2: Sale of Fixed Assets | V2: Sub contractors only
G3: Vat Output | K3: Actual amount received | L3: Sales Value not yet received | M3: Number of Days Outstanding | O3: Product A | P3: Product B | Q3: Product C | V3: CIS Tax Deducted | W3: CIS Certificate reference
G4: ='Month 05'!G4 -> 0 | O4: A | P4: B | Q4: C | R4: D | S4: G | T4: O | U4: FS
E5: =IF((F5<>0),"Enter Letter"," ") | G5: =IF(G$4>0,(IF(F5<>0,F5*G$4/100," ")),IF(F5<>0,F5*G$2/(100+G$2)," ")) | H5: =IF((F5<>0),F5-G5," ") | L5: =IF(F5<>0,F5-K5," ") | M5: =IF((F5-K5)<>0,M$1-A5," ") | O5: =IF((E5="a"),H5," ") | P5: =IF((E5="b"),H5," ") | Q5: =IF((E5="c"),H5," ") | R5: =IF((E5="d"),H5," ") | S5: =IF((E5="g"),H5," ") | T5: =IF((E5="o"),H5," ") | U5: =IF((E5="FS"),H5," ")
E6: =IF((F6<>0),"Enter Letter"," ") | G6: =IF(G$4>0,(IF(F6<>0,F6*G$4/100," ")),IF(F6<>0,F6*G$2/(100+G$2)," ")) | H6: =IF((F6<>0),F6-G6," ") | L6: =IF(F6<>0,F6-K6," ") | M6: =IF((F6-K6)<>0,M$1-A6," ") | O6: =IF((E6="a"),H6," ") | P6: =IF((E6="b"),H6," ") | Q6: =IF((E6="c"),H6," ") | R6: =IF((E6="d"),H6," ") | S6: =IF((E6="g"),H6," ") | T6: =IF((E6="o"),H6," ") | U6: =IF((E6="FS"),H6," ")
E7: =IF((F7<>0),"Enter Letter"," ") | G7: =IF(G$4>0,(IF(F7<>0,F7*G$4/100," ")),IF(F7<>0,F7*G$2/(100+G$2)," ")) | H7: =IF((F7<>0),F7-G7," ") | L7: =IF(F7<>0,F7-K7," ") | M7: =IF((F7-K7)<>0,M$1-A7," ") | O7: =IF((E7="a"),H7," ") | P7: =IF((E7="b"),H7," ") | Q7: =IF((E7="c"),H7," ") | R7: =IF((E7="d"),H7," ") | S7: =IF((E7="g"),H7," ") | T7: =IF((E7="o"),H7," ") | U7: =IF((E7="FS"),H7," ")
E8: =IF((F8<>0),"Enter Letter"," ") | G8: =IF(G$4>0,(IF(F8<>0,F8*G$4/100," ")),IF(F8<>0,F8*G$2/(100+G$2)," ")) | H8: =IF((F8<>0),F8-G8," ") | L8: =IF(F8<>0,F8-K8," ") | M8: =IF((F8-K8)<>0,M$1-A8," ") | O8: =IF((E8="a"),H8," ") | P8: =IF((E8="b"),H8," ") | Q8: =IF((E8="c"),H8," ") | R8: =IF((E8="d"),H8," ") | S8: =IF((E8="g"),H8," ") | T8: =IF((E8="o"),H8," ") | U8: =IF((E8="FS"),H8," ")
E9: =IF((F9<>0),"Enter Letter"," ") | G9: =IF(G$4>0,(IF(F9<>0,F9*G$4/100," ")),IF(F9<>0,F9*G$2/(100+G$2)," ")) | H9: =IF((F9<>0),F9-G9," ") | L9: =IF(F9<>0,F9-K9," ") | M9: =IF((F9-K9)<>0,M$1-A9," ") | O9: =IF((E9="a"),H9," ") | P9: =IF((E9="b"),H9," ") | Q9: =IF((E9="c"),H9," ") | R9: =IF((E9="d"),H9," ") | S9: =IF((E9="g"),H9," ") | T9: =IF((E9="o"),H9," ") | U9: =IF((E9="FS"),H9," ")
E10: =IF((F10<>0),"Enter Letter"," ") | G10: =IF(G$4>0,(IF(F10<>0,F10*G$4/100," ")),IF(F10<>0,F10*G$2/(100+G$2)," ")) | H10: =IF((F10<>0),F10-G10," ") | L10: =IF(F10<>0,F10-K10," ") | M10: =IF((F10-K10)<>0,M$1-A10," ") | O10: =IF((E10="a"),H10," ") | P10: =IF((E10="b"),H10," ") | Q10: =IF((E10="c"),H10," ") | R10: =IF((E10="d"),H10," ") | S10: =IF((E10="g"),H10," ") | T10: =IF((E10="o"),H10," ") | U10: =IF((E10="FS"),H10," ")
E11: =IF((F11<>0),"Enter Letter"," ") | G11: =IF(G$4>0,(IF(F11<>0,F11*G$4/100," ")),IF(F11<>0,F11*G$2/(100+G$2)," ")) | H11: =IF((F11<>0),F11-G11," ") | L11: =IF(F11<>0,F11-K11," ") | M11: =IF((F11-K11)<>0,M$1-A11," ") | O11: =IF((E11="a"),H11," ") | P11: =IF((E11="b"),H11," ") | Q11: =IF((E11="c"),H11," ") | R11: =IF((E11="d"),H11," ") | S11: =IF((E11="g"),H11," ") | T11: =IF((E11="o"),H11," ") | U11: =IF((E11="FS"),H11," ")
E12: =IF((F12<>0),"Enter Letter"," ") | G12: =IF(G$4>0,(IF(F12<>0,F12*G$4/100," ")),IF(F12<>0,F12*G$2/(100+G$2)," ")) | H12: =IF((F12<>0),F12-G12," ") | L12: =IF(F12<>0,F12-K12," ") | M12: =IF((F12-K12)<>0,M$1-A12," ") | O12: =IF((E12="a"),H12," ") | P12: =IF((E12="b"),H12," ") | Q12: =IF((E12="c"),H12," ") | R12: =IF((E12="d"),H12," ") | S12: =IF((E12="g"),H12," ") | T12: =IF((E12="o"),H12," ") | U12: =IF((E12="FS"),H12," ")
E13: =IF((F13<>0),"Enter Letter"," ") | G13: =IF(G$4>0,(IF(F13<>0,F13*G$4/100," ")),IF(F13<>0,F13*G$2/(100+G$2)," ")) | H13: =IF((F13<>0),F13-G13," ") | L13: =IF(F13<>0,F13-K13," ") | M13: =IF((F13-K13)<>0,M$1-A13," ") | O13: =IF((E13="a"),H13," ") | P13: =IF((E13="b"),H13," ") | Q13: =IF((E13="c"),H13," ") | R13: =IF((E13="d"),H13," ") | S13: =IF((E13="g"),H13," ") | T13: =IF((E13="o"),H13," ") | U13: =IF((E13="FS"),H13," ")
E14: =IF((F14<>0),"Enter Letter"," ") | G14: =IF(G$4>0,(IF(F14<>0,F14*G$4/100," ")),IF(F14<>0,F14*G$2/(100+G$2)," ")) | H14: =IF((F14<>0),F14-G14," ") | L14: =IF(F14<>0,F14-K14," ") | M14: =IF((F14-K14)<>0,M$1-A14," ") | O14: =IF((E14="a"),H14," ") | P14: =IF((E14="b"),H14," ") | Q14: =IF((E14="c"),H14," ") | R14: =IF((E14="d"),H14," ") | S14: =IF((E14="g"),H14," ") | T14: =IF((E14="o"),H14," ") | U14: =IF((E14="FS"),H14," ")
E15: =IF((F15<>0),"Enter Letter"," ") | G15: =IF(G$4>0,(IF(F15<>0,F15*G$4/100," ")),IF(F15<>0,F15*G$2/(100+G$2)," ")) | H15: =IF((F15<>0),F15-G15," ") | L15: =IF(F15<>0,F15-K15," ") | M15: =IF((F15-K15)<>0,M$1-A15," ") | O15: =IF((E15="a"),H15," ") | P15: =IF((E15="b"),H15," ") | Q15: =IF((E15="c"),H15," ") | R15: =IF((E15="d"),H15," ") | S15: =IF((E15="g"),H15," ") | T15: =IF((E15="o"),H15," ") | U15: =IF((E15="FS"),H15," ")
E16: =IF((F16<>0),"Enter Letter"," ") | G16: =IF(G$4>0,(IF(F16<>0,F16*G$4/100," ")),IF(F16<>0,F16*G$2/(100+G$2)," ")) | H16: =IF((F16<>0),F16-G16," ") | L16: =IF(F16<>0,F16-K16," ") | M16: =IF((F16-K16)<>0,M$1-A16," ") | O16: =IF((E16="a"),H16," ") | P16: =IF((E16="b"),H16," ") | Q16: =IF((E16="c"),H16," ") | R16: =IF((E16="d"),H16," ") | S16: =IF((E16="g"),H16," ") | T16: =IF((E16="o"),H16," ") | U16: =IF((E16="FS"),H16," ")
... E300: =IF((F300<>0),"Enter Letter"," ") | G300: =IF(G$4>0,(IF(F300<>0,F300*G$4/100," ")),IF(F300<>0,F300*G$2/(100+G$2)," ")) | H300: =IF((F300<>0),F300-G300," ") | L300: =IF(F300<>0,F300-K300," ") | M300: =IF((F300-K300)<>0,M$1-A300," ") | O300: =IF((E300="a"),H300," ") | P300: =IF((E300="b"),H300," ") | Q300: =IF((E300="c"),H300," ") | R300: =IF((E300="d"),H300," ") | S300: =IF((E300="g"),H300," ") | T300: =IF((E300="o"),H300," ") | U300: =IF((E300="FS"),H300," ")

Sheet Month 07
A1: =F1-G1-SUM(O1:U1) -> 0 | B1: Check Total | C1: Sales Invoice Number or reference | D1: Total for Month | F1: =SUM(F5:F300) -> 0 | G1: =SUM(G5:G300) -> 0 | H1: =SUM(H5:H300) -> 0 | J1: For your information only. Enter How Paid e.g. Cash, Cheque etc., | K1: =SUM(K5:K300) -> 0 | L1: =SUM(L5:L300) -> 0 | M1: =TODAY() -> 45751 | O1: =SUM(O5:O300) -> 0 | P1: =SUM(P5:P300) -> 0 | Q1: =SUM(Q5:Q300) -> 0 | R1: =SUM(R5:R300) -> 0 | S1: =SUM(S5:S300) -> 0 | T1: =SUM(T5:T300) -> 0 | U1: =SUM(U5:U300) -> 0 | V1: =SUM(V5:V300) -> 0
A2: Sales Date | B2: Customer Name | D2: Sales Description | E2: Enter Expense Code Letter | F2: Sales Value including Vat | G2: ='Month 06'!G2 -> 20 | H2: Sales Net of Vat | K2: Receipts from Customers | O2: Sales Net of Vat | R2: Other Income | S2: Investment Grants | T2: Bad Debts written off | U2: Sale of Fixed Assets | V2: Sub contractors only
G3: Vat Output | K3: Actual amount received | L3: Sales Value not yet received | M3: Number of Days Outstanding | O3: Product A | P3: Product B | Q3: Product C | V3: CIS Tax Deducted | W3: CIS Certificate reference
G4: ='Month 06'!G4 -> 0 | O4: A | P4: B | Q4: C | R4: D | S4: G | T4: O | U4: FS
E5: =IF((F5<>0),"Enter Letter"," ") | G5: =IF(G$4>0,(IF(F5<>0,F5*G$4/100," ")),IF(F5<>0,F5*G$2/(100+G$2)," ")) | H5: =IF((F5<>0),F5-G5," ") | L5: =IF(F5<>0,F5-K5," ") | M5: =IF((F5-K5)<>0,M$1-A5," ") | O5: =IF((E5="a"),H5," ") | P5: =IF((E5="b"),H5," ") | Q5: =IF((E5="c"),H5," ") | R5: =IF((E5="d"),H5," ") | S5: =IF((E5="g"),H5," ") | T5: =IF((E5="o"),H5," ") | U5: =IF((E5="FS"),H5," ")
E6: =IF((F6<>0),"Enter Letter"," ") | G6: =IF(G$4>0,(IF(F6<>0,F6*G$4/100," ")),IF(F6<>0,F6*G$2/(100+G$2)," ")) | H6: =IF((F6<>0),F6-G6," ") | L6: =IF(F6<>0,F6-K6," ") | M6: =IF((F6-K6)<>0,M$1-A6," ") | O6: =IF((E6="a"),H6," ") | P6: =IF((E6="b"),H6," ") | Q6: =IF((E6="c"),H6," ") | R6: =IF((E6="d"),H6," ") | S6: =IF((E6="g"),H6," ") | T6: =IF((E6="o"),H6," ") | U6: =IF((E6="FS"),H6," ")
E7: =IF((F7<>0),"Enter Letter"," ") | G7: =IF(G$4>0,(IF(F7<>0,F7*G$4/100," ")),IF(F7<>0,F7*G$2/(100+G$2)," ")) | H7: =IF((F7<>0),F7-G7," ") | L7: =IF(F7<>0,F7-K7," ") | M7: =IF((F7-K7)<>0,M$1-A7," ") | O7: =IF((E7="a"),H7," ") | P7: =IF((E7="b"),H7," ") | Q7: =IF((E7="c"),H7," ") | R7: =IF((E7="d"),H7," ") | S7: =IF((E7="g"),H7," ") | T7: =IF((E7="o"),H7," ") | U7: =IF((E7="FS"),H7," ")
E8: =IF((F8<>0),"Enter Letter"," ") | G8: =IF(G$4>0,(IF(F8<>0,F8*G$4/100," ")),IF(F8<>0,F8*G$2/(100+G$2)," ")) | H8: =IF((F8<>0),F8-G8," ") | L8: =IF(F8<>0,F8-K8," ") | M8: =IF((F8-K8)<>0,M$1-A8," ") | O8: =IF((E8="a"),H8," ") | P8: =IF((E8="b"),H8," ") | Q8: =IF((E8="c"),H8," ") | R8: =IF((E8="d"),H8," ") | S8: =IF((E8="g"),H8," ") | T8: =IF((E8="o"),H8," ") | U8: =IF((E8="FS"),H8," ")
E9: =IF((F9<>0),"Enter Letter"," ") | G9: =IF(G$4>0,(IF(F9<>0,F9*G$4/100," ")),IF(F9<>0,F9*G$2/(100+G$2)," ")) | H9: =IF((F9<>0),F9-G9," ") | L9: =IF(F9<>0,F9-K9," ") | M9: =IF((F9-K9)<>0,M$1-A9," ") | O9: =IF((E9="a"),H9," ") | P9: =IF((E9="b"),H9," ") | Q9: =IF((E9="c"),H9," ") | R9: =IF((E9="d"),H9," ") | S9: =IF((E9="g"),H9," ") | T9: =IF((E9="o"),H9," ") | U9: =IF((E9="FS"),H9," ")
E10: =IF((F10<>0),"Enter Letter"," ") | G10: =IF(G$4>0,(IF(F10<>0,F10*G$4/100," ")),IF(F10<>0,F10*G$2/(100+G$2)," ")) | H10: =IF((F10<>0),F10-G10," ") | L10: =IF(F10<>0,F10-K10," ") | M10: =IF((F10-K10)<>0,M$1-A10," ") | O10: =IF((E10="a"),H10," ") | P10: =IF((E10="b"),H10," ") | Q10: =IF((E10="c"),H10," ") | R10: =IF((E10="d"),H10," ") | S10: =IF((E10="g"),H10," ") | T10: =IF((E10="o"),H10," ") | U10: =IF((E10="FS"),H10," ")
E11: =IF((F11<>0),"Enter Letter"," ") | G11: =IF(G$4>0,(IF(F11<>0,F11*G$4/100," ")),IF(F11<>0,F11*G$2/(100+G$2)," ")) | H11: =IF((F11<>0),F11-G11," ") | L11: =IF(F11<>0,F11-K11," ") | M11: =IF((F11-K11)<>0,M$1-A11," ") | O11: =IF((E11="a"),H11," ") | P11: =IF((E11="b"),H11," ") | Q11: =IF((E11="c"),H11," ") | R11: =IF((E11="d"),H11," ") | S11: =IF((E11="g"),H11," ") | T11: =IF((E11="o"),H11," ") | U11: =IF((E11="FS"),H11," ")
E12: =IF((F12<>0),"Enter Letter"," ") | G12: =IF(G$4>0,(IF(F12<>0,F12*G$4/100," ")),IF(F12<>0,F12*G$2/(100+G$2)," ")) | H12: =IF((F12<>0),F12-G12," ") | L12: =IF(F12<>0,F12-K12," ") | M12: =IF((F12-K12)<>0,M$1-A12," ") | O12: =IF((E12="a"),H12," ") | P12: =IF((E12="b"),H12," ") | Q12: =IF((E12="c"),H12," ") | R12: =IF((E12="d"),H12," ") | S12: =IF((E12="g"),H12," ") | T12: =IF((E12="o"),H12," ") | U12: =IF((E12="FS"),H12," ")
E13: =IF((F13<>0),"Enter Letter"," ") | G13: =IF(G$4>0,(IF(F13<>0,F13*G$4/100," ")),IF(F13<>0,F13*G$2/(100+G$2)," ")) | H13: =IF((F13<>0),F13-G13," ") | L13: =IF(F13<>0,F13-K13," ") | M13: =IF((F13-K13)<>0,M$1-A13," ") | O13: =IF((E13="a"),H13," ") | P13: =IF((E13="b"),H13," ") | Q13: =IF((E13="c"),H13," ") | R13: =IF((E13="d"),H13," ") | S13: =IF((E13="g"),H13," ") | T13: =IF((E13="o"),H13," ") | U13: =IF((E13="FS"),H13," ")
E14: =IF((F14<>0),"Enter Letter"," ") | G14: =IF(G$4>0,(IF(F14<>0,F14*G$4/100," ")),IF(F14<>0,F14*G$2/(100+G$2)," ")) | H14: =IF((F14<>0),F14-G14," ") | L14: =IF(F14<>0,F14-K14," ") | M14: =IF((F14-K14)<>0,M$1-A14," ") | O14: =IF((E14="a"),H14," ") | P14: =IF((E14="b"),H14," ") | Q14: =IF((E14="c"),H14," ") | R14: =IF((E14="d"),H14," ") | S14: =IF((E14="g"),H14," ") | T14: =IF((E14="o"),H14," ") | U14: =IF((E14="FS"),H14," ")
E15: =IF((F15<>0),"Enter Letter"," ") | G15: =IF(G$4>0,(IF(F15<>0,F15*G$4/100," ")),IF(F15<>0,F15*G$2/(100+G$2)," ")) | H15: =IF((F15<>0),F15-G15," ") | L15: =IF(F15<>0,F15-K15," ") | M15: =IF((F15-K15)<>0,M$1-A15," ") | O15: =IF((E15="a"),H15," ") | P15: =IF((E15="b"),H15," ") | Q15: =IF((E15="c"),H15," ") | R15: =IF((E15="d"),H15," ") | S15: =IF((E15="g"),H15," ") | T15: =IF((E15="o"),H15," ") | U15: =IF((E15="FS"),H15," ")
E16: =IF((F16<>0),"Enter Letter"," ") | G16: =IF(G$4>0,(IF(F16<>0,F16*G$4/100," ")),IF(F16<>0,F16*G$2/(100+G$2)," ")) | H16: =IF((F16<>0),F16-G16," ") | L16: =IF(F16<>0,F16-K16," ") | M16: =IF((F16-K16)<>0,M$1-A16," ") | O16: =IF((E16="a"),H16," ") | P16: =IF((E16="b"),H16," ") | Q16: =IF((E16="c"),H16," ") | R16: =IF((E16="d"),H16," ") | S16: =IF((E16="g"),H16," ") | T16: =IF((E16="o"),H16," ") | U16: =IF((E16="FS"),H16," ")
... E300: =IF((F300<>0),"Enter Letter"," ") | G300: =IF(G$4>0,(IF(F300<>0,F300*G$4/100," ")),IF(F300<>0,F300*G$2/(100+G$2)," ")) | H300: =IF((F300<>0),F300-G300," ") | L300: =IF(F300<>0,F300-K300," ") | M300: =IF((F300-K300)<>0,M$1-A300," ") | O300: =IF((E300="a"),H300," ") | P300: =IF((E300="b"),H300," ") | Q300: =IF((E300="c"),H300," ") | R300: =IF((E300="d"),H300," ") | S300: =IF((E300="g"),H300," ") | T300: =IF((E300="o"),H300," ") | U300: =IF((E300="FS"),H300," ")

Sheet Month 08
A1: =F1-G1-SUM(O1:U1) -> 0 | B1: Check Total | C1: Sales Invoice Number or reference | D1: Total for Month | F1: =SUM(F5:F300) -> 0 | G1: =SUM(G5:G300) -> 0 | H1: =SUM(H5:H300) -> 0 | J1: For your information only. Enter How Paid e.g. Cash, Cheque etc., | K1: =SUM(K5:K300) -> 0 | L1: =SUM(L5:L300) -> 0 | M1: =TODAY() -> 45751 | O1: =SUM(O5:O300) -> 0 | P1: =SUM(P5:P300) -> 0 | Q1: =SUM(Q5:Q300) -> 0 | R1: =SUM(R5:R300) -> 0 | S1: =SUM(S5:S300) -> 0 | T1: =SUM(T5:T300) -> 0 | U1: =SUM(U5:U300) -> 0 | V1: =SUM(V5:V300) -> 0
A2: Sales Date | B2: Customer Name | D2: Sales Description | E2: Enter Expense Code Letter | F2: Sales Value including Vat | G2: ='Month 07'!G2 -> 20 | H2: Sales Net of Vat | K2: Receipts from Customers | O2: Sales Net of Vat | R2: Other Income | S2: Investment Grants | T2: Bad Debts written off | U2: Sale of Fixed Assets | V2: Sub contractors only
G3: Vat Output | K3: Actual amount received | L3: Sales Value not yet received | M3: Number of Days Outstanding | O3: Product A | P3: Product B | Q3: Product C | V3: CIS Tax Deducted | W3: CIS Certificate reference
G4: ='Month 07'!G4 -> 0 | O4: A | P4: B | Q4: C | R4: D | S4: G | T4: O | U4: FS
E5: =IF((F5<>0),"Enter Letter"," ") | G5: =IF(G$4>0,(IF(F5<>0,F5*G$4/100," ")),IF(F5<>0,F5*G$2/(100+G$2)," ")) | H5: =IF((F5<>0),F5-G5," ") | L5: =IF(F5<>0,F5-K5," ") | M5: =IF((F5-K5)<>0,M$1-A5," ") | O5: =IF((E5="a"),H5," ") | P5: =IF((E5="b"),H5," ") | Q5: =IF((E5="c"),H5," ") | R5: =IF((E5="d"),H5," ") | S5: =IF((E5="g"),H5," ") | T5: =IF((E5="o"),H5," ") | U5: =IF((E5="FS"),H5," ")
E6: =IF((F6<>0),"Enter Letter"," ") | G6: =IF(G$4>0,(IF(F6<>0,F6*G$4/100," ")),IF(F6<>0,F6*G$2/(100+G$2)," ")) | H6: =IF((F6<>0),F6-G6," ") | L6: =IF(F6<>0,F6-K6," ") | M6: =IF((F6-K6)<>0,M$1-A6," ") | O6: =IF((E6="a"),H6," ") | P6: =IF((E6="b"),H6," ") | Q6: =IF((E6="c"),H6," ") | R6: =IF((E6="d"),H6," ") | S6: =IF((E6="g"),H6," ") | T6: =IF((E6="o"),H6," ") | U6: =IF((E6="FS"),H6," ")
E7: =IF((F7<>0),"Enter Letter"," ") | G7: =IF(G$4>0,(IF(F7<>0,F7*G$4/100," ")),IF(F7<>0,F7*G$2/(100+G$2)," ")) | H7: =IF((F7<>0),F7-G7," ") | L7: =IF(F7<>0,F7-K7," ") | M7: =IF((F7-K7)<>0,M$1-A7," ") | O7: =IF((E7="a"),H7," ") | P7: =IF((E7="b"),H7," ") | Q7: =IF((E7="c"),H7," ") | R7: =IF((E7="d"),H7," ") | S7: =IF((E7="g"),H7," ") | T7: =IF((E7="o"),H7," ") | U7: =IF((E7="FS"),H7," ")
E8: =IF((F8<>0),"Enter Letter"," ") | G8: =IF(G$4>0,(IF(F8<>0,F8*G$4/100," ")),IF(F8<>0,F8*G$2/(100+G$2)," ")) | H8: =IF((F8<>0),F8-G8," ") | L8: =IF(F8<>0,F8-K8," ") | M8: =IF((F8-K8)<>0,M$1-A8," ") | O8: =IF((E8="a"),H8," ") | P8: =IF((E8="b"),H8," ") | Q8: =IF((E8="c"),H8," ") | R8: =IF((E8="d"),H8," ") | S8: =IF((E8="g"),H8," ") | T8: =IF((E8="o"),H8," ") | U8: =IF((E8="FS"),H8," ")
E9: =IF((F9<>0),"Enter Letter"," ") | G9: =IF(G$4>0,(IF(F9<>0,F9*G$4/100," ")),IF(F9<>0,F9*G$2/(100+G$2)," ")) | H9: =IF((F9<>0),F9-G9," ") | L9: =IF(F9<>0,F9-K9," ") | M9: =IF((F9-K9)<>0,M$1-A9," ") | O9: =IF((E9="a"),H9," ") | P9: =IF((E9="b"),H9," ") | Q9: =IF((E9="c"),H9," ") | R9: =IF((E9="d"),H9," ") | S9: =IF((E9="g"),H9," ") | T9: =IF((E9="o"),H9," ") | U9: =IF((E9="FS"),H9," ")
E10: =IF((F10<>0),"Enter Letter"," ") | G10: =IF(G$4>0,(IF(F10<>0,F10*G$4/100," ")),IF(F10<>0,F10*G$2/(100+G$2)," ")) | H10: =IF((F10<>0),F10-G10," ") | L10: =IF(F10<>0,F10-K10," ") | M10: =IF((F10-K10)<>0,M$1-A10," ") | O10: =IF((E10="a"),H10," ") | P10: =IF((E10="b"),H10," ") | Q10: =IF((E10="c"),H10," ") | R10: =IF((E10="d"),H10," ") | S10: =IF((E10="g"),H10," ") | T10: =IF((E10="o"),H10," ") | U10: =IF((E10="FS"),H10," ")
E11: =IF((F11<>0),"Enter Letter"," ") | G11: =IF(G$4>0,(IF(F11<>0,F11*G$4/100," ")),IF(F11<>0,F11*G$2/(100+G$2)," ")) | H11: =IF((F11<>0),F11-G11," ") | L11: =IF(F11<>0,F11-K11," ") | M11: =IF((F11-K11)<>0,M$1-A11," ") | O11: =IF((E11="a"),H11," ") | P11: =IF((E11="b"),H11," ") | Q11: =IF((E11="c"),H11," ") | R11: =IF((E11="d"),H11," ") | S11: =IF((E11="g"),H11," ") | T11: =IF((E11="o"),H11," ") | U11: =IF((E11="FS"),H11," ")
E12: =IF((F12<>0),"Enter Letter"," ") | G12: =IF(G$4>0,(IF(F12<>0,F12*G$4/100," ")),IF(F12<>0,F12*G$2/(100+G$2)," ")) | H12: =IF((F12<>0),F12-G12," ") | L12: =IF(F12<>0,F12-K12," ") | M12: =IF((F12-K12)<>0,M$1-A12," ") | O12: =IF((E12="a"),H12," ") | P12: =IF((E12="b"),H12," ") | Q12: =IF((E12="c"),H12," ") | R12: =IF((E12="d"),H12," ") | S12: =IF((E12="g"),H12," ") | T12: =IF((E12="o"),H12," ") | U12: =IF((E12="FS"),H12," ")
E13: =IF((F13<>0),"Enter Letter"," ") | G13: =IF(G$4>0,(IF(F13<>0,F13*G$4/100," ")),IF(F13<>0,F13*G$2/(100+G$2)," ")) | H13: =IF((F13<>0),F13-G13," ") | L13: =IF(F13<>0,F13-K13," ") | M13: =IF((F13-K13)<>0,M$1-A13," ") | O13: =IF((E13="a"),H13," ") | P13: =IF((E13="b"),H13," ") | Q13: =IF((E13="c"),H13," ") | R13: =IF((E13="d"),H13," ") | S13: =IF((E13="g"),H13," ") | T13: =IF((E13="o"),H13," ") | U13: =IF((E13="FS"),H13," ")
E14: =IF((F14<>0),"Enter Letter"," ") | G14: =IF(G$4>0,(IF(F14<>0,F14*G$4/100," ")),IF(F14<>0,F14*G$2/(100+G$2)," ")) | H14: =IF((F14<>0),F14-G14," ") | L14: =IF(F14<>0,F14-K14," ") | M14: =IF((F14-K14)<>0,M$1-A14," ") | O14: =IF((E14="a"),H14," ") | P14: =IF((E14="b"),H14," ") | Q14: =IF((E14="c"),H14," ") | R14: =IF((E14="d"),H14," ") | S14: =IF((E14="g"),H14," ") | T14: =IF((E14="o"),H14," ") | U14: =IF((E14="FS"),H14," ")
E15: =IF((F15<>0),"Enter Letter"," ") | G15: =IF(G$4>0,(IF(F15<>0,F15*G$4/100," ")),IF(F15<>0,F15*G$2/(100+G$2)," ")) | H15: =IF((F15<>0),F15-G15," ") | L15: =IF(F15<>0,F15-K15," ") | M15: =IF((F15-K15)<>0,M$1-A15," ") | O15: =IF((E15="a"),H15," ") | P15: =IF((E15="b"),H15," ") | Q15: =IF((E15="c"),H15," ") | R15: =IF((E15="d"),H15," ") | S15: =IF((E15="g"),H15," ") | T15: =IF((E15="o"),H15," ") | U15: =IF((E15="FS"),H15," ")
E16: =IF((F16<>0),"Enter Letter"," ") | G16: =IF(G$4>0,(IF(F16<>0,F16*G$4/100," ")),IF(F16<>0,F16*G$2/(100+G$2)," ")) | H16: =IF((F16<>0),F16-G16," ") | L16: =IF(F16<>0,F16-K16," ") | M16: =IF((F16-K16)<>0,M$1-A16," ") | O16: =IF((E16="a"),H16," ") | P16: =IF((E16="b"),H16," ") | Q16: =IF((E16="c"),H16," ") | R16: =IF((E16="d"),H16," ") | S16: =IF((E16="g"),H16," ") | T16: =IF((E16="o"),H16," ") | U16: =IF((E16="FS"),H16," ")
... E300: =IF((F300<>0),"Enter Letter"," ") | G300: =IF(G$4>0,(IF(F300<>0,F300*G$4/100," ")),IF(F300<>0,F300*G$2/(100+G$2)," ")) | H300: =IF((F300<>0),F300-G300," ") | L300: =IF(F300<>0,F300-K300," ") | M300: =IF((F300-K300)<>0,M$1-A300," ") | O300: =IF((E300="a"),H300," ") | P300: =IF((E300="b"),H300," ") | Q300: =IF((E300="c"),H300," ") | R300: =IF((E300="d"),H300," ") | S300: =IF((E300="g"),H300," ") | T300: =IF((E300="o"),H300," ") | U300: =IF((E300="FS"),H300," ")

Sheet Month 09
A1: =F1-G1-SUM(O1:U1) -> 0 | B1: Check Total | C1: Sales Invoice Number or reference | D1: Total for Month | F1: =SUM(F5:F300) -> 0 | G1: =SUM(G5:G300) -> 0 | H1: =SUM(H5:H300) -> 0 | J1: For your information only. Enter How Paid e.g. Cash, Cheque etc., | K1: =SUM(K5:K300) -> 0 | L1: =SUM(L5:L300) -> 0 | M1: =TODAY() -> 45751 | O1: =SUM(O5:O300) -> 0 | P1: =SUM(P5:P300) -> 0 | Q1: =SUM(Q5:Q300) -> 0 | R1: =SUM(R5:R300) -> 0 | S1: =SUM(S5:S300) -> 0 | T1: =SUM(T5:T300) -> 0 | U1: =SUM(U5:U300) -> 0 | V1: =SUM(V5:V300) -> 0
A2: Sales Date | B2: Customer Name | D2: Sales Description | E2: Enter Expense Code Letter | F2: Sales Value including Vat | G2: ='Month 08'!G2 -> 20 | H2: Sales Net of Vat | K2: Receipts from Customers | O2: Sales Net of Vat | R2: Other Income | S2: Investment Grants | T2: Bad Debts written off | U2: Sale of Fixed Assets | V2: Sub contractors only
G3: Vat Output | K3: Actual amount received | L3: Sales Value not yet received | M3: Number of Days Outstanding | O3: Product A | P3: Product B | Q3: Product C | V3: CIS Tax Deducted | W3: CIS Certificate reference
G4: ='Month 08'!G4 -> 0 | O4: A | P4: B | Q4: C | R4: D | S4: G | T4: O | U4: FS
E5: =IF((F5<>0),"Enter Letter"," ") | G5: =IF(G$4>0,(IF(F5<>0,F5*G$4/100," ")),IF(F5<>0,F5*G$2/(100+G$2)," ")) | H5: =IF((F5<>0),F5-G5," ") | L5: =IF(F5<>0,F5-K5," ") | M5: =IF((F5-K5)<>0,M$1-A5," ") | O5: =IF((E5="a"),H5," ") | P5: =IF((E5="b"),H5," ") | Q5: =IF((E5="c"),H5," ") | R5: =IF((E5="d"),H5," ") | S5: =IF((E5="g"),H5," ") | T5: =IF((E5="o"),H5," ") | U5: =IF((E5="FS"),H5," ")
E6: =IF((F6<>0),"Enter Letter"," ") | G6: =IF(G$4>0,(IF(F6<>0,F6*G$4/100," ")),IF(F6<>0,F6*G$2/(100+G$2)," ")) | H6: =IF((F6<>0),F6-G6," ") | L6: =IF(F6<>0,F6-K6," ") | M6: =IF((F6-K6)<>0,M$1-A6," ") | O6: =IF((E6="a"),H6," ") | P6: =IF((E6="b"),H6," ") | Q6: =IF((E6="c"),H6," ") | R6: =IF((E6="d"),H6," ") | S6: =IF((E6="g"),H6," ") | T6: =IF((E6="o"),H6," ") | U6: =IF((E6="FS"),H6," ")
E7: =IF((F7<>0),"Enter Letter"," ") | G7: =IF(G$4>0,(IF(F7<>0,F7*G$4/100," ")),IF(F7<>0,F7*G$2/(100+G$2)," ")) | H7: =IF((F7<>0),F7-G7," ") | L7: =IF(F7<>0,F7-K7," ") | M7: =IF((F7-K7)<>0,M$1-A7," ") | O7: =IF((E7="a"),H7," ") | P7: =IF((E7="b"),H7," ") | Q7: =IF((E7="c"),H7," ") | R7: =IF((E7="d"),H7," ") | S7: =IF((E7="g"),H7," ") | T7: =IF((E7="o"),H7," ") | U7: =IF((E7="FS"),H7," ")
E8: =IF((F8<>0),"Enter Letter"," ") | G8: =IF(G$4>0,(IF(F8<>0,F8*G$4/100," ")),IF(F8<>0,F8*G$2/(100+G$2)," ")) | H8: =IF((F8<>0),F8-G8," ") | L8: =IF(F8<>0,F8-K8," ") | M8: =IF((F8-K8)<>0,M$1-A8," ") | O8: =IF((E8="a"),H8," ") | P8: =IF((E8="b"),H8," ") | Q8: =IF((E8="c"),H8," ") | R8: =IF((E8="d"),H8," ") | S8: =IF((E8="g"),H8," ") | T8: =IF((E8="o"),H8," ") | U8: =IF((E8="FS"),H8," ")
E9: =IF((F9<>0),"Enter Letter"," ") | G9: =IF(G$4>0,(IF(F9<>0,F9*G$4/100," ")),IF(F9<>0,F9*G$2/(100+G$2)," ")) | H9: =IF((F9<>0),F9-G9," ") | L9: =IF(F9<>0,F9-K9," ") | M9: =IF((F9-K9)<>0,M$1-A9," ") | O9: =IF((E9="a"),H9," ") | P9: =IF((E9="b"),H9," ") | Q9: =IF((E9="c"),H9," ") | R9: =IF((E9="d"),H9," ") | S9: =IF((E9="g"),H9," ") | T9: =IF((E9="o"),H9," ") | U9: =IF((E9="FS"),H9," ")
E10: =IF((F10<>0),"Enter Letter"," ") | G10: =IF(G$4>0,(IF(F10<>0,F10*G$4/100," ")),IF(F10<>0,F10*G$2/(100+G$2)," ")) | H10: =IF((F10<>0),F10-G10," ") | L10: =IF(F10<>0,F10-K10," ") | M10: =IF((F10-K10)<>0,M$1-A10," ") | O10: =IF((E10="a"),H10," ") | P10: =IF((E10="b"),H10," ") | Q10: =IF((E10="c"),H10," ") | R10: =IF((E10="d"),H10," ") | S10: =IF((E10="g"),H10," ") | T10: =IF((E10="o"),H10," ") | U10: =IF((E10="FS"),H10," ")
