Workbook

Sheet Jun
B1: < Opening Bank Balance | C1: =[1]Admin!$B$9 -> 45748 | D1: Totals > | E1: =F1-SUM(G1:Q1) -> 0 | F1: =SUM(F6:F200) -> 500 | G1: =SUM(G6:G200) -> 0 | H1: =SUM(H6:H200) -> 0 | I1: =SUM(I6:I200) -> 0 | J1: =SUM(J6:J200) -> 0 | K1: =SUM(K6:K200) -> 0 | L1: =SUM(L6:L200) -> 0 | M1: =SUM(M6:M200) -> 0 | ... Q1: =SUM(Q6:Q200) -> 500 | S1: =IF(W1=0," ","Check all payment code letters entered") | V1: Totals > | W1: =X1-SUM(Y1:AN1) -> 0 | X1: =SUM(X6:X200) -> 0 | Y1: =SUM(Y6:Y200) -> 0 | Z1: =SUM(Z6:Z200) -> 0 | AA1: =SUM(AA6:AA200) -> 0 | AB1: =SUM(AB6:AB200) -> 0 | AC1: =SUM(AC6:AC200) -> 0 | AD1: =SUM(AD6:AD200) -> 0 | AE1: =SUM(AE6:AE200) -> 0 | ... AN1: =SUM(AN6:AN200) -> 0
A2: =A1+F1-X1 -> 500 | B2: < Closing Bank Balance | C2: =[1]Admin!$B$10 -> 45777 | D2: Deposit Bank Reference | E2: Enter Code Letters | F2: COMPANY CREDIT CARD STATEMENT RECEIPTS | S2: =IF(E1=0," ","Check all Receipts Code Letters entered") | U2: Enter Purchase Invoice No. | V2: Cheque number Direct Debit | W2: Enter Code Letters | X2: COMPANY CREDIT CARD STATEMENT PAYMENTS
B3: < Statement Bank Balance | C3: =C2 -> 45777 | F3: Amounts received from each Source | G3: Transfers From Current | H3: Transfers From Savings | I3: Transfers From Cash | J3: Amount Received Debtors | K3: Interest Received | L3: Long Term Debtor | M3: Long Term Creditor | N3: HMRC Vat Refunded | O3: HMRC CIS Refunded | P3: Directors Loan Account | Q3: Bank Contra items | X3: Amounts Paid by invoice number | Y3: Transfers To Current | Z3: Transfers To Savings | AA3: Transfers To Cash | AB3: Amount Paid Creditors | AC3: Net Wages Paid | AD3: Bank Charges Paid | AE3: Interest Paid | AF3: Long Term Debtor | AG3: Long Term Creditor | AH3: HMRC Paye Payments | AI3: HMRC Vat Payments | AJ3: HMRC CIS Payments | AK3: HMRC Corp Tax Payment | AL3: Dividends Paid | AM3: Directors Loan Account | AN3: Bank Contra items
A4: =A2-A3 -> 500 | B4: =IF(A4=0,"< Bank - Statement Balance"," Reconcile Bank Statement") -> Reconcile Bank Statement | S4: Payment Date | T4: Suppliers paid
A5: Date | B5: Source of Funds Received | C5: Sales Invoice | G5: BB | H5: BS | I5: BC | J5: DR | K5: K | L5: LDR | M5: LCR | N5: RV | O5: RC | P5: DL | Q5: X | Y5: BB | Z5: BS | AA5: BC | AB5: CR | AC5: W | AD5: B | AE5: J | AF5: LDR | AG5: LCR | AH5: RP | AI5: RV | AJ5: RC | AK5: RT | AL5: DV | AM5: DL | AN5: X
A6: 45838 | B6: Payment from current | E6: X | F6: 500 | G6: =IF(E6="BB",F6," ") | H6: =IF(E6="BS",F6," ") | I6: =IF(E6="BC",F6," ") | J6: =IF(E6="DR",F6," ") | K6: =IF(E6="K",F6," ") | L6: =IF(E6="LDR",F6," ") | M6: =IF(E6="LCR",F6," ") | N6: =IF(E6="RV",F6," ") | O6: =IF(E6="RC",F6," ") | P6: =IF(E6="DL",F6," ") | Q6: =IF(E6="X",F6," ") -> 500 | W6: =IF(X6<>0,"Enter Code"," ") | Y6: =IF(W6="BB",X6," ") | Z6: =IF(W6="BS",X6," ") | AA6: =IF(W6="BC",X6," ") | AB6: =IF(W6="CR",X6," ") | AC6: =IF(W6="W",X6," ") | AD6: =IF(W6="B",X6," ") | AE6: =IF(W6="J",X6," ") | AF6: =IF(W6="LDR",X6," ") | AG6: =IF(W6="LCR",X6," ") | AH6: =IF(W6="RP",X6," ") | AI6: =IF(W6="RV",X6," ") | AJ6: =IF(W6="RC",X6," ") | AK6: =IF(W6="RT",X6," ") | AL6: =IF(W6="DV",X6," ") | AM6: =IF(W6="DL",X6," ") | AN6: =IF(W6="X",X6," ")
G7: =IF(E7="BB",F7," ") | H7: =IF(E7="BS",F7," ") | I7: =IF(E7="BC",F7," ") | J7: =IF(E7="DR",F7," ") | K7: =IF(E7="K",F7," ") | L7: =IF(E7="LDR",F7," ") | M7: =IF(E7="LCR",F7," ") | N7: =IF(E7="RV",F7," ") | O7: =IF(E7="RC",F7," ") | P7: =IF(E7="DL",F7," ") | Q7: =IF(E7="X",F7," ") | W7: =IF(X7<>0,"Enter Code"," ") | Y7: =IF(W7="BB",X7," ") | Z7: =IF(W7="BS",X7," ") | AA7: =IF(W7="BC",X7," ") | AB7: =IF(W7="CR",X7," ") | AC7: =IF(W7="W",X7," ") | AD7: =IF(W7="B",X7," ") | AE7: =IF(W7="J",X7," ") | AF7: =IF(W7="LDR",X7," ") | AG7: =IF(W7="LCR",X7," ") | AH7: =IF(W7="RP",X7," ") | AI7: =IF(W7="RV",X7," ") | AJ7: =IF(W7="RC",X7," ") | AK7: =IF(W7="RT",X7," ") | AL7: =IF(W7="DV",X7," ") | AM7: =IF(W7="DL",X7," ") | AN7: =IF(W7="X",X7," ")
G8: =IF(E8="BB",F8," ") | H8: =IF(E8="BS",F8," ") | I8: =IF(E8="BC",F8," ") | J8: =IF(E8="DR",F8," ") | K8: =IF(E8="K",F8," ") | L8: =IF(E8="LDR",F8," ") | M8: =IF(E8="LCR",F8," ") | N8: =IF(E8="RV",F8," ") | O8: =IF(E8="RC",F8," ") | P8: =IF(E8="DL",F8," ") | Q8: =IF(E8="X",F8," ") | W8: =IF(X8<>0,"Enter Code"," ") | Y8: =IF(W8="BB",X8," ") | Z8: =IF(W8="BS",X8," ") | AA8: =IF(W8="BC",X8," ") | AB8: =IF(W8="CR",X8," ") | AC8: =IF(W8="W",X8," ") | AD8: =IF(W8="B",X8," ") | AE8: =IF(W8="J",X8," ") | AF8: =IF(W8="LDR",X8," ") | AG8: =IF(W8="LCR",X8," ") | AH8: =IF(W8="RP",X8," ") | AI8: =IF(W8="RV",X8," ") | AJ8: =IF(W8="RC",X8," ") | AK8: =IF(W8="RT",X8," ") | AL8: =IF(W8="DV",X8," ") | AM8: =IF(W8="DL",X8," ") | AN8: =IF(W8="X",X8," ")
G9: =IF(E9="BB",F9," ") | H9: =IF(E9="BS",F9," ") | I9: =IF(E9="BC",F9," ") | J9: =IF(E9="DR",F9," ") | K9: =IF(E9="K",F9," ") | L9: =IF(E9="LDR",F9," ") | M9: =IF(E9="LCR",F9," ") | N9: =IF(E9="RV",F9," ") | O9: =IF(E9="RC",F9," ") | P9: =IF(E9="DL",F9," ") | Q9: =IF(E9="X",F9," ") | W9: =IF(X9<>0,"Enter Code"," ") | Y9: =IF(W9="BB",X9," ") | Z9: =IF(W9="BS",X9," ") | AA9: =IF(W9="BC",X9," ") | AB9: =IF(W9="CR",X9," ") | AC9: =IF(W9="W",X9," ") | AD9: =IF(W9="B",X9," ") | AE9: =IF(W9="J",X9," ") | AF9: =IF(W9="LDR",X9," ") | AG9: =IF(W9="LCR",X9," ") | AH9: =IF(W9="RP",X9," ") | AI9: =IF(W9="RV",X9," ") | AJ9: =IF(W9="RC",X9," ") | AK9: =IF(W9="RT",X9," ") | AL9: =IF(W9="DV",X9," ") | AM9: =IF(W9="DL",X9," ") | AN9: =IF(W9="X",X9," ")
G10: =IF(E10="BB",F10," ") | H10: =IF(E10="BS",F10," ") | I10: =IF(E10="BC",F10," ") | J10: =IF(E10="DR",F10," ") | K10: =IF(E10="K",F10," ") | L10: =IF(E10="LDR",F10," ") | M10: =IF(E10="LCR",F10," ") | N10: =IF(E10="RV",F10," ") | O10: =IF(E10="RC",F10," ") | P10: =IF(E10="DL",F10," ") | Q10: =IF(E10="X",F10," ") | W10: =IF(X10<>0,"Enter Code"," ") | Y10: =IF(W10="BB",X10," ") | Z10: =IF(W10="BS",X10," ") | AA10: =IF(W10="BC",X10," ") | AB10: =IF(W10="CR",X10," ") | AC10: =IF(W10="W",X10," ") | AD10: =IF(W10="B",X10," ") | AE10: =IF(W10="J",X10," ") | AF10: =IF(W10="LDR",X10," ") | AG10: =IF(W10="LCR",X10," ") | AH10: =IF(W10="RP",X10," ") | AI10: =IF(W10="RV",X10," ") | AJ10: =IF(W10="RC",X10," ") | AK10: =IF(W10="RT",X10," ") | AL10: =IF(W10="DV",X10," ") | AM10: =IF(W10="DL",X10," ") | AN10: =IF(W10="X",X10," ")
G11: =IF(E11="BB",F11," ") | H11: =IF(E11="BS",F11," ") | I11: =IF(E11="BC",F11," ") | J11: =IF(E11="DR",F11," ") | K11: =IF(E11="K",F11," ") | L11: =IF(E11="LDR",F11," ") | M11: =IF(E11="LCR",F11," ") | N11: =IF(E11="RV",F11," ") | O11: =IF(E11="RC",F11," ") | P11: =IF(E11="DL",F11," ") | Q11: =IF(E11="X",F11," ") | W11: =IF(X11<>0,"Enter Code"," ") | Y11: =IF(W11="BB",X11," ") | Z11: =IF(W11="BS",X11," ") | AA11: =IF(W11="BC",X11," ") | AB11: =IF(W11="CR",X11," ") | AC11: =IF(W11="W",X11," ") | AD11: =IF(W11="B",X11," ") | AE11: =IF(W11="J",X11," ") | AF11: =IF(W11="LDR",X11," ") | AG11: =IF(W11="LCR",X11," ") | AH11: =IF(W11="RP",X11," ") | AI11: =IF(W11="RV",X11," ") | AJ11: =IF(W11="RC",X11," ") | AK11: =IF(W11="RT",X11," ") | AL11: =IF(W11="DV",X11," ") | AM11: =IF(W11="DL",X11," ") | AN11: =IF(W11="X",X11," ")
G12: =IF(E12="BB",F12," ") | H12: =IF(E12="BS",F12," ") | I12: =IF(E12="BC",F12," ") | J12: =IF(E12="DR",F12," ") | K12: =IF(E12="K",F12," ") | L12: =IF(E12="LDR",F12," ") | M12: =IF(E12="LCR",F12," ") | N12: =IF(E12="RV",F12," ") | O12: =IF(E12="RC",F12," ") | P12: =IF(E12="DL",F12," ") | Q12: =IF(E12="X",F12," ") | W12: =IF(X12<>0,"Enter Code"," ") | Y12: =IF(W12="BB",X12," ") | Z12: =IF(W12="BS",X12," ") | AA12: =IF(W12="BC",X12," ") | AB12: =IF(W12="CR",X12," ") | AC12: =IF(W12="W",X12," ") | AD12: =IF(W12="B",X12," ") | AE12: =IF(W12="J",X12," ") | AF12: =IF(W12="LDR",X12," ") | AG12: =IF(W12="LCR",X12," ") | AH12: =IF(W12="RP",X12," ") | AI12: =IF(W12="RV",X12," ") | AJ12: =IF(W12="RC",X12," ") | AK12: =IF(W12="RT",X12," ") | AL12: =IF(W12="DV",X12," ") | AM12: =IF(W12="DL",X12," ") | AN12: =IF(W12="X",X12," ")
G13: =IF(E13="BB",F13," ") | H13: =IF(E13="BS",F13," ") | I13: =IF(E13="BC",F13," ") | J13: =IF(E13="DR",F13," ") | K13: =IF(E13="K",F13," ") | L13: =IF(E13="LDR",F13," ") | M13: =IF(E13="LCR",F13," ") | N13: =IF(E13="RV",F13," ") | O13: =IF(E13="RC",F13," ") | P13: =IF(E13="DL",F13," ") | Q13: =IF(E13="X",F13," ") | W13: =IF(X13<>0,"Enter Code"," ") | Y13: =IF(W13="BB",X13," ") | Z13: =IF(W13="BS",X13," ") | AA13: =IF(W13="BC",X13," ") | AB13: =IF(W13="CR",X13," ") | AC13: =IF(W13="W",X13," ") | AD13: =IF(W13="B",X13," ") | AE13: =IF(W13="J",X13," ") | AF13: =IF(W13="LDR",X13," ") | AG13: =IF(W13="LCR",X13," ") | AH13: =IF(W13="RP",X13," ") | AI13: =IF(W13="RV",X13," ") | AJ13: =IF(W13="RC",X13," ") | AK13: =IF(W13="RT",X13," ") | AL13: =IF(W13="DV",X13," ") | AM13: =IF(W13="DL",X13," ") | AN13: =IF(W13="X",X13," ")
G14: =IF(E14="BB",F14," ") | H14: =IF(E14="BS",F14," ") | I14: =IF(E14="BC",F14," ") | J14: =IF(E14="DR",F14," ") | K14: =IF(E14="K",F14," ") | L14: =IF(E14="LDR",F14," ") | M14: =IF(E14="LCR",F14," ") | N14: =IF(E14="RV",F14," ") | O14: =IF(E14="RC",F14," ") | P14: =IF(E14="DL",F14," ") | Q14: =IF(E14="X",F14," ") | W14: =IF(X14<>0,"Enter Code"," ") | Y14: =IF(W14="BB",X14," ") | Z14: =IF(W14="BS",X14," ") | AA14: =IF(W14="BC",X14," ") | AB14: =IF(W14="CR",X14," ") | AC14: =IF(W14="W",X14," ") | AD14: =IF(W14="B",X14," ") | AE14: =IF(W14="J",X14," ") | AF14: =IF(W14="LDR",X14," ") | AG14: =IF(W14="LCR",X14," ") | AH14: =IF(W14="RP",X14," ") | AI14: =IF(W14="RV",X14," ") | AJ14: =IF(W14="RC",X14," ") | AK14: =IF(W14="RT",X14," ") | AL14: =IF(W14="DV",X14," ") | AM14: =IF(W14="DL",X14," ") | AN14: =IF(W14="X",X14," ")
G15: =IF(E15="BB",F15," ") | H15: =IF(E15="BS",F15," ") | I15: =IF(E15="BC",F15," ") | J15: =IF(E15="DR",F15," ") | K15: =IF(E15="K",F15," ") | L15: =IF(E15="LDR",F15," ") | M15: =IF(E15="LCR",F15," ") | N15: =IF(E15="RV",F15," ") | O15: =IF(E15="RC",F15," ") | P15: =IF(E15="DL",F15," ") | Q15: =IF(E15="X",F15," ") | W15: =IF(X15<>0,"Enter Code"," ") | Y15: =IF(W15="BB",X15," ") | Z15: =IF(W15="BS",X15," ") | AA15: =IF(W15="BC",X15," ") | AB15: =IF(W15="CR",X15," ") | AC15: =IF(W15="W",X15," ") | AD15: =IF(W15="B",X15," ") | AE15: =IF(W15="J",X15," ") | AF15: =IF(W15="LDR",X15," ") | AG15: =IF(W15="LCR",X15," ") | AH15: =IF(W15="RP",X15," ") | AI15: =IF(W15="RV",X15," ") | AJ15: =IF(W15="RC",X15," ") | AK15: =IF(W15="RT",X15," ") | AL15: =IF(W15="DV",X15," ") | AM15: =IF(W15="DL",X15," ") | AN15: =IF(W15="X",X15," ")
G16: =IF(E16="BB",F16," ") | H16: =IF(E16="BS",F16," ") | I16: =IF(E16="BC",F16," ") | J16: =IF(E16="DR",F16," ") | K16: =IF(E16="K",F16," ") | L16: =IF(E16="LDR",F16," ") | M16: =IF(E16="LCR",F16," ") | N16: =IF(E16="RV",F16," ") | O16: =IF(E16="RC",F16," ") | P16: =IF(E16="DL",F16," ") | Q16: =IF(E16="X",F16," ") | W16: =IF(X16<>0,"Enter Code"," ") | Y16: =IF(W16="BB",X16," ") | Z16: =IF(W16="BS",X16," ") | AA16: =IF(W16="BC",X16," ") | AB16: =IF(W16="CR",X16," ") | AC16: =IF(W16="W",X16," ") | AD16: =IF(W16="B",X16," ") | AE16: =IF(W16="J",X16," ") | AF16: =IF(W16="LDR",X16," ") | AG16: =IF(W16="LCR",X16," ") | AH16: =IF(W16="RP",X16," ") | AI16: =IF(W16="RV",X16," ") | AJ16: =IF(W16="RC",X16," ") | AK16: =IF(W16="RT",X16," ") | AL16: =IF(W16="DV",X16," ") | AM16: =IF(W16="DL",X16," ") | AN16: =IF(W16="X",X16," ")
G17: =IF(E17="BB",F17," ") | H17: =IF(E17="BS",F17," ") | I17: =IF(E17="BC",F17," ") | J17: =IF(E17="DR",F17," ") | K17: =IF(E17="K",F17," ") | L17: =IF(E17="LDR",F17," ") | M17: =IF(E17="LCR",F17," ") | N17: =IF(E17="RV",F17," ") | O17: =IF(E17="RC",F17," ") | P17: =IF(E17="DL",F17," ") | Q17: =IF(E17="X",F17," ") | W17: =IF(X17<>0,"Enter Code"," ") | Y17: =IF(W17="BB",X17," ") | Z17: =IF(W17="BS",X17," ") | AA17: =IF(W17="BC",X17," ") | AB17: =IF(W17="CR",X17," ") | AC17: =IF(W17="W",X17," ") | AD17: =IF(W17="B",X17," ") | AE17: =IF(W17="J",X17," ") | AF17: =IF(W17="LDR",X17," ") | AG17: =IF(W17="LCR",X17," ") | AH17: =IF(W17="RP",X17," ") | AI17: =IF(W17="RV",X17," ") | AJ17: =IF(W17="RC",X17," ") | AK17: =IF(W17="RT",X17," ") | AL17: =IF(W17="DV",X17," ") | AM17: =IF(W17="DL",X17," ") | AN17: =IF(W17="X",X17," ")
G18: =IF(E18="BB",F18," ") | H18: =IF(E18="BS",F18," ") | I18: =IF(E18="BC",F18," ") | J18: =IF(E18="DR",F18," ") | K18: =IF(E18="K",F18," ") | L18: =IF(E18="LDR",F18," ") | M18: =IF(E18="LCR",F18," ") | N18: =IF(E18="RV",F18," ") | O18: =IF(E18="RC",F18," ") | P18: =IF(E18="DL",F18," ") | Q18: =IF(E18="X",F18," ") | W18: =IF(X18<>0,"Enter Code"," ") | Y18: =IF(W18="BB",X18," ") | Z18: =IF(W18="BS",X18," ") | AA18: =IF(W18="BC",X18," ") | AB18: =IF(W18="CR",X18," ") | AC18: =IF(W18="W",X18," ") | AD18: =IF(W18="B",X18," ") | AE18: =IF(W18="J",X18," ") | AF18: =IF(W18="LDR",X18," ") | AG18: =IF(W18="LCR",X18," ") | AH18: =IF(W18="RP",X18," ") | AI18: =IF(W18="RV",X18," ") | AJ18: =IF(W18="RC",X18," ") | AK18: =IF(W18="RT",X18," ") | AL18: =IF(W18="DV",X18," ") | AM18: =IF(W18="DL",X18," ") | AN18: =IF(W18="X",X18," ")
... G69: =IF(E69="BB",F69," ") | H69: =IF(E69="BS",F69," ") | I69: =IF(E69="BC",F69," ") | J69: =IF(E69="DR",F69," ") | K69: =IF(E69="K",F69," ") | L69: =IF(E69="LDR",F69," ") | M69: =IF(E69="LCR",F69," ") | N69: =IF(E69="RV",F69," ") | O69: =IF(E69="RC",F69," ") | P69: =IF(E69="DL",F69," ") | Q69: =IF(E69="X",F69," ") | W69: =IF(X69<>0,"Enter Code"," ") | Y69: =IF(W69="BB",X69," ") | Z69: =IF(W69="BS",X69," ") | AA69: =IF(W69="BC",X69," ") | AB69: =IF(W69="CR",X69," ") | AC69: =IF(W69="W",X69," ") | AD69: =IF(W69="B",X69," ") | AE69: =IF(W69="J",X69," ") | AF69: =IF(W69="LDR",X69," ") | AG69: =IF(W69="LCR",X69," ") | AH69: =IF(W69="RP",X69," ") | AI69: =IF(W69="RV",X69," ") | AJ69: =IF(W69="RC",X69," ") | AK69: =IF(W69="RT",X69," ") | AL69: =IF(W69="DV",X69," ") | AM69: =IF(W69="DL",X69," ") | AN69: =IF(W69="X",X69," ")
E70: =IF(F70<>0,"Enter Code"," ") | G70: =IF(E70="BB",F70," ") | H70: =IF(E70="BS",F70," ") | I70: =IF(E70="BC",F70," ") | J70: =IF(E70="DR",F70," ") | K70: =IF(E70="K",F70," ") | L70: =IF(E70="LDR",F70," ") | M70: =IF(E70="LCR",F70," ") | N70: =IF(E70="RV",F70," ") | O70: =IF(E70="RC",F70," ") | P70: =IF(E70="DL",F70," ") | Q70: =IF(E70="X",F70," ") | W70: =IF(X70<>0,"Enter Code"," ") | Y70: =IF(W70="BB",X70," ") | Z70: =IF(W70="BS",X70," ") | AA70: =IF(W70="BC",X70," ") | AB70: =IF(W70="CR",X70," ") | AC70: =IF(W70="W",X70," ") | AD70: =IF(W70="B",X70," ") | AE70: =IF(W70="J",X70," ") | AF70: =IF(W70="LDR",X70," ") | AG70: =IF(W70="LCR",X70," ") | AH70: =IF(W70="RP",X70," ") | AI70: =IF(W70="RV",X70," ") | AJ70: =IF(W70="RC",X70," ") | AK70: =IF(W70="RT",X70," ") | AL70: =IF(W70="DV",X70," ") | AM70: =IF(W70="DL",X70," ") | AN70: =IF(W70="X",X70," ")
E71: =IF(F71<>0,"Enter Code"," ") | G71: =IF(E71="BB",F71," ") | H71: =IF(E71="BS",F71," ") | I71: =IF(E71="BC",F71," ") | J71: =IF(E71="DR",F71," ") | K71: =IF(E71="K",F71," ") | L71: =IF(E71="LDR",F71," ") | M71: =IF(E71="LCR",F71," ") | N71: =IF(E71="RV",F71," ") | O71: =IF(E71="RC",F71," ") | P71: =IF(E71="DL",F71," ") | Q71: =IF(E71="X",F71," ") | W71: =IF(X71<>0,"Enter Code"," ") | Y71: =IF(W71="BB",X71," ") | Z71: =IF(W71="BS",X71," ") | AA71: =IF(W71="BC",X71," ") | AB71: =IF(W71="CR",X71," ") | AC71: =IF(W71="W",X71," ") | AD71: =IF(W71="B",X71," ") | AE71: =IF(W71="J",X71," ") | AF71: =IF(W71="LDR",X71," ") | AG71: =IF(W71="LCR",X71," ") | AH71: =IF(W71="RP",X71," ") | AI71: =IF(W71="RV",X71," ") | AJ71: =IF(W71="RC",X71," ") | AK71: =IF(W71="RT",X71," ") | AL71: =IF(W71="DV",X71," ") | AM71: =IF(W71="DL",X71," ") | AN71: =IF(W71="X",X71," ")
E72: =IF(F72<>0,"Enter Code"," ") | G72: =IF(E72="BB",F72," ") | H72: =IF(E72="BS",F72," ") | I72: =IF(E72="BC",F72," ") | J72: =IF(E72="DR",F72," ") | K72: =IF(E72="K",F72," ") | L72: =IF(E72="LDR",F72," ") | M72: =IF(E72="LCR",F72," ") | N72: =IF(E72="RV",F72," ") | O72: =IF(E72="RC",F72," ") | P72: =IF(E72="DL",F72," ") | Q72: =IF(E72="X",F72," ") | W72: =IF(X72<>0,"Enter Code"," ") | Y72: =IF(W72="BB",X72," ") | Z72: =IF(W72="BS",X72," ") | AA72: =IF(W72="BC",X72," ") | AB72: =IF(W72="CR",X72," ") | AC72: =IF(W72="W",X72," ") | AD72: =IF(W72="B",X72," ") | AE72: =IF(W72="J",X72," ") | AF72: =IF(W72="LDR",X72," ") | AG72: =IF(W72="LCR",X72," ") | AH72: =IF(W72="RP",X72," ") | AI72: =IF(W72="RV",X72," ") | AJ72: =IF(W72="RC",X72," ") | AK72: =IF(W72="RT",X72," ") | AL72: =IF(W72="DV",X72," ") | AM72: =IF(W72="DL",X72," ") | AN72: =IF(W72="X",X72," ")
E73: =IF(F73<>0,"Enter Code"," ") | G73: =IF(E73="BB",F73," ") | H73: =IF(E73="BS",F73," ") | I73: =IF(E73="BC",F73," ") | J73: =IF(E73="DR",F73," ") | K73: =IF(E73="K",F73," ") | L73: =IF(E73="LDR",F73," ") | M73: =IF(E73="LCR",F73," ") | N73: =IF(E73="RV",F73," ") | O73: =IF(E73="RC",F73," ") | P73: =IF(E73="DL",F73," ") | Q73: =IF(E73="X",F73," ") | W73: =IF(X73<>0,"Enter Code"," ") | Y73: =IF(W73="BB",X73," ") | Z73: =IF(W73="BS",X73," ") | AA73: =IF(W73="BC",X73," ") | AB73: =IF(W73="CR",X73," ") | AC73: =IF(W73="W",X73," ") | AD73: =IF(W73="B",X73," ") | AE73: =IF(W73="J",X73," ") | AF73: =IF(W73="LDR",X73," ") | AG73: =IF(W73="LCR",X73," ") | AH73: =IF(W73="RP",X73," ") | AI73: =IF(W73="RV",X73," ") | AJ73: =IF(W73="RC",X73," ") | AK73: =IF(W73="RT",X73," ") | AL73: =IF(W73="DV",X73," ") | AM73: =IF(W73="DL",X73," ") | AN73: =IF(W73="X",X73," ")
E74: =IF(F74<>0,"Enter Code"," ") | G74: =IF(E74="BB",F74," ") | H74: =IF(E74="BS",F74," ") | I74: =IF(E74="BC",F74," ") | J74: =IF(E74="DR",F74," ") | K74: =IF(E74="K",F74," ") | L74: =IF(E74="LDR",F74," ") | M74: =IF(E74="LCR",F74," ") | N74: =IF(E74="RV",F74," ") | O74: =IF(E74="RC",F74," ") | P74: =IF(E74="DL",F74," ") | Q74: =IF(E74="X",F74," ") | W74: =IF(X74<>0,"Enter Code"," ") | Y74: =IF(W74="BB",X74," ") | Z74: =IF(W74="BS",X74," ") | AA74: =IF(W74="BC",X74," ") | AB74: =IF(W74="CR",X74," ") | AC74: =IF(W74="W",X74," ") | AD74: =IF(W74="B",X74," ") | AE74: =IF(W74="J",X74," ") | AF74: =IF(W74="LDR",X74," ") | AG74: =IF(W74="LCR",X74," ") | AH74: =IF(W74="RP",X74," ") | AI74: =IF(W74="RV",X74," ") | AJ74: =IF(W74="RC",X74," ") | AK74: =IF(W74="RT",X74," ") | AL74: =IF(W74="DV",X74," ") | AM74: =IF(W74="DL",X74," ") | AN74: =IF(W74="X",X74," ")
E75: =IF(F75<>0,"Enter Code"," ") | G75: =IF(E75="BB",F75," ") | H75: =IF(E75="BS",F75," ") | I75: =IF(E75="BC",F75," ") | J75: =IF(E75="DR",F75," ") | K75: =IF(E75="K",F75," ") | L75: =IF(E75="LDR",F75," ") | M75: =IF(E75="LCR",F75," ") | N75: =IF(E75="RV",F75," ") | O75: =IF(E75="RC",F75," ") | P75: =IF(E75="DL",F75," ") | Q75: =IF(E75="X",F75," ") | W75: =IF(X75<>0,"Enter Code"," ") | Y75: =IF(W75="BB",X75," ") | Z75: =IF(W75="BS",X75," ") | AA75: =IF(W75="BC",X75," ") | AB75: =IF(W75="CR",X75," ") | AC75: =IF(W75="W",X75," ") | AD75: =IF(W75="B",X75," ") | AE75: =IF(W75="J",X75," ") | AF75: =IF(W75="LDR",X75," ") | AG75: =IF(W75="LCR",X75," ") | AH75: =IF(W75="RP",X75," ") | AI75: =IF(W75="RV",X75," ") | AJ75: =IF(W75="RC",X75," ") | AK75: =IF(W75="RT",X75," ") | AL75: =IF(W75="DV",X75," ") | AM75: =IF(W75="DL",X75," ") | AN75: =IF(W75="X",X75," ")
E76: =IF(F76<>0,"Enter Code"," ") | G76: =IF(E76="BB",F76," ") | H76: =IF(E76="BS",F76," ") | I76: =IF(E76="BC",F76," ") | J76: =IF(E76="DR",F76," ") | K76: =IF(E76="K",F76," ") | L76: =IF(E76="LDR",F76," ") | M76: =IF(E76="LCR",F76," ") | N76: =IF(E76="RV",F76," ") | O76: =IF(E76="RC",F76," ") | P76: =IF(E76="DL",F76," ") | Q76: =IF(E76="X",F76," ") | W76: =IF(X76<>0,"Enter Code"," ") | Y76: =IF(W76="BB",X76," ") | Z76: =IF(W76="BS",X76," ") | AA76: =IF(W76="BC",X76," ") | AB76: =IF(W76="CR",X76," ") | AC76: =IF(W76="W",X76," ") | AD76: =IF(W76="B",X76," ") | AE76: =IF(W76="J",X76," ") | AF76: =IF(W76="LDR",X76," ") | AG76: =IF(W76="LCR",X76," ") | AH76: =IF(W76="RP",X76," ") | AI76: =IF(W76="RV",X76," ") | AJ76: =IF(W76="RC",X76," ") | AK76: =IF(W76="RT",X76," ") | AL76: =IF(W76="DV",X76," ") | AM76: =IF(W76="DL",X76," ") | AN76: =IF(W76="X",X76," ")
E77: =IF(F77<>0,"Enter Code"," ") | G77: =IF(E77="BB",F77," ") | H77: =IF(E77="BS",F77," ") | I77: =IF(E77="BC",F77," ") | J77: =IF(E77="DR",F77," ") | K77: =IF(E77="K",F77," ") | L77: =IF(E77="LDR",F77," ") | M77: =IF(E77="LCR",F77," ") | N77: =IF(E77="RV",F77," ") | O77: =IF(E77="RC",F77," ") | P77: =IF(E77="DL",F77," ") | Q77: =IF(E77="X",F77," ") | W77: =IF(X77<>0,"Enter Code"," ") | Y77: =IF(W77="BB",X77," ") | Z77: =IF(W77="BS",X77," ") | AA77: =IF(W77="BC",X77," ") | AB77: =IF(W77="CR",X77," ") | AC77: =IF(W77="W",X77," ") | AD77: =IF(W77="B",X77," ") | AE77: =IF(W77="J",X77," ") | AF77: =IF(W77="LDR",X77," ") | AG77: =IF(W77="LCR",X77," ") | AH77: =IF(W77="RP",X77," ") | AI77: =IF(W77="RV",X77," ") | AJ77: =IF(W77="RC",X77," ") | AK77: =IF(W77="RT",X77," ") | AL77: =IF(W77="DV",X77," ") | AM77: =IF(W77="DL",X77," ") | AN77: =IF(W77="X",X77," ")
E78: =IF(F78<>0,"Enter Code"," ") | G78: =IF(E78="BB",F78," ") | H78: =IF(E78="BS",F78," ") | I78: =IF(E78="BC",F78," ") | J78: =IF(E78="DR",F78," ") | K78: =IF(E78="K",F78," ") | L78: =IF(E78="LDR",F78," ") | M78: =IF(E78="LCR",F78," ") | N78: =IF(E78="RV",F78," ") | O78: =IF(E78="RC",F78," ") | P78: =IF(E78="DL",F78," ") | Q78: =IF(E78="X",F78," ") | W78: =IF(X78<>0,"Enter Code"," ") | Y78: =IF(W78="BB",X78," ") | Z78: =IF(W78="BS",X78," ") | AA78: =IF(W78="BC",X78," ") | AB78: =IF(W78="CR",X78," ") | AC78: =IF(W78="W",X78," ") | AD78: =IF(W78="B",X78," ") | AE78: =IF(W78="J",X78," ") | AF78: =IF(W78="LDR",X78," ") | AG78: =IF(W78="LCR",X78," ") | AH78: =IF(W78="RP",X78," ") | AI78: =IF(W78="RV",X78," ") | AJ78: =IF(W78="RC",X78," ") | AK78: =IF(W78="RT",X78," ") | AL78: =IF(W78="DV",X78," ") | AM78: =IF(W78="DL",X78," ") | AN78: =IF(W78="X",X78," ")
E79: =IF(F79<>0,"Enter Code"," ") | G79: =IF(E79="BB",F79," ") | H79: =IF(E79="BS",F79," ") | I79: =IF(E79="BC",F79," ") | J79: =IF(E79="DR",F79," ") | K79: =IF(E79="K",F79," ") | L79: =IF(E79="LDR",F79," ") | M79: =IF(E79="LCR",F79," ") | N79: =IF(E79="RV",F79," ") | O79: =IF(E79="RC",F79," ") | P79: =IF(E79="DL",F79," ") | Q79: =IF(E79="X",F79," ") | W79: =IF(X79<>0,"Enter Code"," ") | Y79: =IF(W79="BB",X79," ") | Z79: =IF(W79="BS",X79," ") | AA79: =IF(W79="BC",X79," ") | AB79: =IF(W79="CR",X79," ") | AC79: =IF(W79="W",X79," ") | AD79: =IF(W79="B",X79," ") | AE79: =IF(W79="J",X79," ") | AF79: =IF(W79="LDR",X79," ") | AG79: =IF(W79="LCR",X79," ") | AH79: =IF(W79="RP",X79," ") | AI79: =IF(W79="RV",X79," ") | AJ79: =IF(W79="RC",X79," ") | AK79: =IF(W79="RT",X79," ") | AL79: =IF(W79="DV",X79," ") | AM79: =IF(W79="DL",X79," ") | AN79: =IF(W79="X",X79," ")
E80: =IF(F80<>0,"Enter Code"," ") | G80: =IF(E80="BB",F80," ") | H80: =IF(E80="BS",F80," ") | I80: =IF(E80="BC",F80," ") | J80: =IF(E80="DR",F80," ") | K80: =IF(E80="K",F80," ") | L80: =IF(E80="LDR",F80," ") | M80: =IF(E80="LCR",F80," ") | N80: =IF(E80="RV",F80," ") | O80: =IF(E80="RC",F80," ") | P80: =IF(E80="DL",F80," ") | Q80: =IF(E80="X",F80," ") | W80: =IF(X80<>0,"Enter Code"," ") | Y80: =IF(W80="BB",X80," ") | Z80: =IF(W80="BS",X80," ") | AA80: =IF(W80="BC",X80," ") | AB80: =IF(W80="CR",X80," ") | AC80: =IF(W80="W",X80," ") | AD80: =IF(W80="B",X80," ") | AE80: =IF(W80="J",X80," ") | AF80: =IF(W80="LDR",X80," ") | AG80: =IF(W80="LCR",X80," ") | AH80: =IF(W80="RP",X80," ") | AI80: =IF(W80="RV",X80," ") | AJ80: =IF(W80="RC",X80," ") | AK80: =IF(W80="RT",X80," ") | AL80: =IF(W80="DV",X80," ") | AM80: =IF(W80="DL",X80," ") | AN80: =IF(W80="X",X80," ")
E81: =IF(F81<>0,"Enter Code"," ") | G81: =IF(E81="BB",F81," ") | H81: =IF(E81="BS",F81," ") | I81: =IF(E81="BC",F81," ") | J81: =IF(E81="DR",F81," ") | K81: =IF(E81="K",F81," ") | L81: =IF(E81="LDR",F81," ") | M81: =IF(E81="LCR",F81," ") | N81: =IF(E81="RV",F81," ") | O81: =IF(E81="RC",F81," ") | P81: =IF(E81="DL",F81," ") | Q81: =IF(E81="X",F81," ") | W81: =IF(X81<>0,"Enter Code"," ") | Y81: =IF(W81="BB",X81," ") | Z81: =IF(W81="BS",X81," ") | AA81: =IF(W81="BC",X81," ") | AB81: =IF(W81="CR",X81," ") | AC81: =IF(W81="W",X81," ") | AD81: =IF(W81="B",X81," ") | AE81: =IF(W81="J",X81," ") | AF81: =IF(W81="LDR",X81," ") | AG81: =IF(W81="LCR",X81," ") | AH81: =IF(W81="RP",X81," ") | AI81: =IF(W81="RV",X81," ") | AJ81: =IF(W81="RC",X81," ") | AK81: =IF(W81="RT",X81," ") | AL81: =IF(W81="DV",X81," ") | AM81: =IF(W81="DL",X81," ") | AN81: =IF(W81="X",X81," ")
... E200: =IF(F200<>0,"Enter Code"," ") | G200: =IF(E200="BB",F200," ") | H200: =IF(E200="BS",F200," ") | I200: =IF(E200="BC",F200," ") | J200: =IF(E200="DR",F200," ") | K200: =IF(E200="K",F200," ") | L200: =IF(E200="LDR",F200," ") | M200: =IF(E200="LCR",F200," ") | N200: =IF(E200="RV",F200," ") | O200: =IF(E200="RC",F200," ") | P200: =IF(E200="DL",F200," ") | Q200: =IF(E200="X",F200," ") | W200: =IF(X200<>0,"Enter Code"," ") | Y200: =IF(W200="BB",X200," ") | Z200: =IF(W200="BS",X200," ") | AA200: =IF(W200="BC",X200," ") | AB200: =IF(W200="CR",X200," ") | AC200: =IF(W200="W",X200," ") | AD200: =IF(W200="B",X200," ") | AE200: =IF(W200="J",X200," ") | AF200: =IF(W200="LDR",X200," ") | AG200: =IF(W200="LCR",X200," ") | AH200: =IF(W200="RP",X200," ") | AI200: =IF(W200="RV",X200," ") | AJ200: =IF(W200="RC",X200," ") | AK200: =IF(W200="RT",X200," ") | AL200: =IF(W200="DV",X200," ") | AM200: =IF(W200="DL",X200," ") | AN200: =IF(W200="X",X200," ")

Sheet Jul
A1: =Jun!A2 -> 500 | B1: < Opening Bank Balance | C1: =[1]Admin!$B$11 -> 45778 | D1: Totals > | E1: =F1-SUM(G1:Q1) -> -45858 | F1: =SUM(F6:F200) -> 0 | G1: =SUM(G6:G200) -> 0 | H1: =SUM(H6:H200) -> 0 | I1: =SUM(I6:I200) -> 0 | J1: =SUM(J6:J200) -> 0 | K1: =SUM(K6:K200) -> 0 | L1: =SUM(L6:L200) -> 0 | M1: =SUM(M6:M200) -> 0 | ... Q1: =SUM(Q6:Q200) -> 0 | S1: =IF(W1=0," ","Check all payment code letters entered") | V1: Totals > | W1: =X1-SUM(Y1:AN1) -> 0 | X1: =SUM(X6:X200) -> 0 | Y1: =SUM(Y6:Y200) -> 0 | Z1: =SUM(Z6:Z200) -> 0 | AA1: =SUM(AA6:AA200) -> 0 | AB1: =SUM(AB6:AB200) -> 0 | AC1: =SUM(AC6:AC200) -> 0 | AD1: =SUM(AD6:AD200) -> 0 | AE1: =SUM(AE6:AE200) -> 0 | ... AN1: =SUM(AN6:AN200) -> 0
A2: =A1+F1-X1 -> 500 | B2: < Closing Bank Balance | C2: =[1]Admin!$B$12 -> 45808 | D2: Deposit Bank Reference | E2: Enter Code Letters | F2: COMPANY CREDIT CARD STATEMENT RECEIPTS | S2: =IF(E1=0," ","Check all Receipts Code Letters entered") -> Check all Receipts Code Letters entered | U2: Enter Purchase Invoice No. | V2: Cheque number Direct Debit | W2: Enter Code Letters | X2: COMPANY CREDIT CARD STATEMENT PAYMENTS
B3: < Statement Bank Balance | C3: =C2 -> 45808 | F3: Amounts received from each Source | G3: Transfers From Current | H3: Transfers From Savings | I3: Transfers From Cash | J3: Amount Received Debtors | K3: Interest Received | L3: Long Term Debtor | M3: Long Term Creditor | N3: HMRC Vat Refunded | O3: HMRC CIS Refunded | P3: Directors Loan Account | Q3: Bank Contra items | X3: Amounts Paid by invoice number | Y3: Transfers To Current | Z3: Transfers To Savings | AA3: Transfers To Cash | AB3: Amount Paid Creditors | AC3: Net Wages Paid | AD3: Bank Charges Paid | AE3: Interest Paid | AF3: Long Term Debtor | AG3: Long Term Creditor | AH3: HMRC Paye Payments | AI3: HMRC Vat Payments | AJ3: HMRC CIS Payments | AK3: HMRC Corp Tax Payment | AL3: Dividends Paid | AM3: Directors Loan Account | AN3: Bank Contra items
A4: =A2-A3 -> 500 | B4: =IF(A4=0,"< Bank - Statement Balance"," Reconcile Bank Statement") -> Reconcile Bank Statement | S4: Payment Date | T4: Suppliers paid
A5: Date | B5: Source of Funds Received | C5: Sales Invoice | G5: BB | H5: BS | I5: BC | J5: DR | K5: K | L5: LDR | M5: LCR | N5: RV | O5: RC | P5: DL | Q5: X | Y5: BB | Z5: BS | AA5: BC | AB5: CR | AC5: W | AD5: B | AE5: J | AF5: LDR | AG5: LCR | AH5: RP | AI5: RV | AJ5: RC | AK5: RT | AL5: DV | AM5: DL | AN5: X
E6: =IF(F6<>0,"Enter Code"," ") | G6: =IF(E6="BB",F6," ") | H6: =IF(E6="BS",F6," ") | I6: =IF(E6="BC",F6," ") | J6: =IF(E6="DR",F6," ") | K6: =IF(E6="K",F6," ") | L6: =IF(E6="LDR",F6," ") | M6: =IF(E6="LCR",F6," ") | N6: =IF(E6="RV",F6," ") | O6: =IF(E6="RC",F6," ") | P6: 45858 | Q6: HSBC | S6: B | T6: 35 | W6: =IF(X6<>0,"Enter Code"," ") | Y6: =IF(W6="BB",X6," ") | Z6: =IF(W6="BS",X6," ") | AA6: =IF(W6="BC",X6," ") | AB6: =IF(W6="CR",X6," ") | AC6: =IF(W6="W",X6," ") | AD6: =IF(W6="B",X6," ") | AE6: =IF(W6="J",X6," ") | AF6: =IF(W6="LDR",X6," ") | AG6: =IF(W6="LCR",X6," ") | AH6: =IF(W6="RP",X6," ") | AI6: =IF(W6="RV",X6," ") | AJ6: =IF(W6="RC",X6," ") | AK6: =IF(W6="RT",X6," ") | AL6: =IF(W6="DV",X6," ") | AM6: =IF(W6="DL",X6," ") | AN6: =IF(W6="X",X6," ")
E7: =IF(F7<>0,"Enter Code"," ") | G7: =IF(E7="BB",F7," ") | H7: =IF(E7="BS",F7," ") | I7: =IF(E7="BC",F7," ") | J7: =IF(E7="DR",F7," ") | K7: =IF(E7="K",F7," ") | L7: =IF(E7="LDR",F7," ") | M7: =IF(E7="LCR",F7," ") | N7: =IF(E7="RV",F7," ") | O7: =IF(E7="RC",F7," ") | W7: =IF(X7<>0,"Enter Code"," ") | Y7: =IF(W7="BB",X7," ") | Z7: =IF(W7="BS",X7," ") | AA7: =IF(W7="BC",X7," ") | AB7: =IF(W7="CR",X7," ") | AC7: =IF(W7="W",X7," ") | AD7: =IF(W7="B",X7," ") | AE7: =IF(W7="J",X7," ") | AF7: =IF(W7="LDR",X7," ") | AG7: =IF(W7="LCR",X7," ") | AH7: =IF(W7="RP",X7," ") | AI7: =IF(W7="RV",X7," ") | AJ7: =IF(W7="RC",X7," ") | AK7: =IF(W7="RT",X7," ") | AL7: =IF(W7="DV",X7," ") | AM7: =IF(W7="DL",X7," ") | AN7: =IF(W7="X",X7," ")
E8: =IF(F8<>0,"Enter Code"," ") | G8: =IF(E8="BB",F8," ") | H8: =IF(E8="BS",F8," ") | I8: =IF(E8="BC",F8," ") | J8: =IF(E8="DR",F8," ") | K8: =IF(E8="K",F8," ") | L8: =IF(E8="LDR",F8," ") | M8: =IF(E8="LCR",F8," ") | N8: =IF(E8="RV",F8," ") | O8: =IF(E8="RC",F8," ") | W8: =IF(X8<>0,"Enter Code"," ") | Y8: =IF(W8="BB",X8," ") | Z8: =IF(W8="BS",X8," ") | AA8: =IF(W8="BC",X8," ") | AB8: =IF(W8="CR",X8," ") | AC8: =IF(W8="W",X8," ") | AD8: =IF(W8="B",X8," ") | AE8: =IF(W8="J",X8," ") | AF8: =IF(W8="LDR",X8," ") | AG8: =IF(W8="LCR",X8," ") | AH8: =IF(W8="RP",X8," ") | AI8: =IF(W8="RV",X8," ") | AJ8: =IF(W8="RC",X8," ") | AK8: =IF(W8="RT",X8," ") | AL8: =IF(W8="DV",X8," ") | AM8: =IF(W8="DL",X8," ") | AN8: =IF(W8="X",X8," ")
E9: =IF(F9<>0,"Enter Code"," ") | G9: =IF(E9="BB",F9," ") | H9: =IF(E9="BS",F9," ") | I9: =IF(E9="BC",F9," ") | J9: =IF(E9="DR",F9," ") | K9: =IF(E9="K",F9," ") | L9: =IF(E9="LDR",F9," ") | M9: =IF(E9="LCR",F9," ") | N9: =IF(E9="RV",F9," ") | O9: =IF(E9="RC",F9," ") | W9: =IF(X9<>0,"Enter Code"," ") | Y9: =IF(W9="BB",X9," ") | Z9: =IF(W9="BS",X9," ") | AA9: =IF(W9="BC",X9," ") | AB9: =IF(W9="CR",X9," ") | AC9: =IF(W9="W",X9," ") | AD9: =IF(W9="B",X9," ") | AE9: =IF(W9="J",X9," ") | AF9: =IF(W9="LDR",X9," ") | AG9: =IF(W9="LCR",X9," ") | AH9: =IF(W9="RP",X9," ") | AI9: =IF(W9="RV",X9," ") | AJ9: =IF(W9="RC",X9," ") | AK9: =IF(W9="RT",X9," ") | AL9: =IF(W9="DV",X9," ") | AM9: =IF(W9="DL",X9," ") | AN9: =IF(W9="X",X9," ")
E10: =IF(F10<>0,"Enter Code"," ") | G10: =IF(E10="BB",F10," ") | H10: =IF(E10="BS",F10," ") | I10: =IF(E10="BC",F10," ") | J10: =IF(E10="DR",F10," ") | K10: =IF(E10="K",F10," ") | L10: =IF(E10="LDR",F10," ") | M10: =IF(E10="LCR",F10," ") | N10: =IF(E10="RV",F10," ") | O10: =IF(E10="RC",F10," ") | W10: =IF(X10<>0,"Enter Code"," ") | Y10: =IF(W10="BB",X10," ") | Z10: =IF(W10="BS",X10," ") | AA10: =IF(W10="BC",X10," ") | AB10: =IF(W10="CR",X10," ") | AC10: =IF(W10="W",X10," ") | AD10: =IF(W10="B",X10," ") | AE10: =IF(W10="J",X10," ") | AF10: =IF(W10="LDR",X10," ") | AG10: =IF(W10="LCR",X10," ") | AH10: =IF(W10="RP",X10," ") | AI10: =IF(W10="RV",X10," ") | AJ10: =IF(W10="RC",X10," ") | AK10: =IF(W10="RT",X10," ") | AL10: =IF(W10="DV",X10," ") | AM10: =IF(W10="DL",X10," ") | AN10: =IF(W10="X",X10," ")
E11: =IF(F11<>0,"Enter Code"," ") | G11: =IF(E11="BB",F11," ") | H11: =IF(E11="BS",F11," ") | I11: =IF(E11="BC",F11," ") | J11: =IF(E11="DR",F11," ") | K11: =IF(E11="K",F11," ") | L11: =IF(E11="LDR",F11," ") | M11: =IF(E11="LCR",F11," ") | N11: =IF(E11="RV",F11," ") | O11: =IF(E11="RC",F11," ") | W11: =IF(X11<>0,"Enter Code"," ") | Y11: =IF(W11="BB",X11," ") | Z11: =IF(W11="BS",X11," ") | AA11: =IF(W11="BC",X11," ") | AB11: =IF(W11="CR",X11," ") | AC11: =IF(W11="W",X11," ") | AD11: =IF(W11="B",X11," ") | AE11: =IF(W11="J",X11," ") | AF11: =IF(W11="LDR",X11," ") | AG11: =IF(W11="LCR",X11," ") | AH11: =IF(W11="RP",X11," ") | AI11: =IF(W11="RV",X11," ") | AJ11: =IF(W11="RC",X11," ") | AK11: =IF(W11="RT",X11," ") | AL11: =IF(W11="DV",X11," ") | AM11: =IF(W11="DL",X11," ") | AN11: =IF(W11="X",X11," ")
E12: =IF(F12<>0,"Enter Code"," ") | G12: =IF(E12="BB",F12," ") | H12: =IF(E12="BS",F12," ") | I12: =IF(E12="BC",F12," ") | J12: =IF(E12="DR",F12," ") | K12: =IF(E12="K",F12," ") | L12: =IF(E12="LDR",F12," ") | M12: =IF(E12="LCR",F12," ") | N12: =IF(E12="RV",F12," ") | O12: =IF(E12="RC",F12," ") | W12: =IF(X12<>0,"Enter Code"," ") | Y12: =IF(W12="BB",X12," ") | Z12: =IF(W12="BS",X12," ") | AA12: =IF(W12="BC",X12," ") | AB12: =IF(W12="CR",X12," ") | AC12: =IF(W12="W",X12," ") | AD12: =IF(W12="B",X12," ") | AE12: =IF(W12="J",X12," ") | AF12: =IF(W12="LDR",X12," ") | AG12: =IF(W12="LCR",X12," ") | AH12: =IF(W12="RP",X12," ") | AI12: =IF(W12="RV",X12," ") | AJ12: =IF(W12="RC",X12," ") | AK12: =IF(W12="RT",X12," ") | AL12: =IF(W12="DV",X12," ") | AM12: =IF(W12="DL",X12," ") | AN12: =IF(W12="X",X12," ")
E13: =IF(F13<>0,"Enter Code"," ") | G13: =IF(E13="BB",F13," ") | H13: =IF(E13="BS",F13," ") | I13: =IF(E13="BC",F13," ") | J13: =IF(E13="DR",F13," ") | K13: =IF(E13="K",F13," ") | L13: =IF(E13="LDR",F13," ") | M13: =IF(E13="LCR",F13," ") | N13: =IF(E13="RV",F13," ") | O13: =IF(E13="RC",F13," ") | W13: =IF(X13<>0,"Enter Code"," ") | Y13: =IF(W13="BB",X13," ") | Z13: =IF(W13="BS",X13," ") | AA13: =IF(W13="BC",X13," ") | AB13: =IF(W13="CR",X13," ") | AC13: =IF(W13="W",X13," ") | AD13: =IF(W13="B",X13," ") | AE13: =IF(W13="J",X13," ") | AF13: =IF(W13="LDR",X13," ") | AG13: =IF(W13="LCR",X13," ") | AH13: =IF(W13="RP",X13," ") | AI13: =IF(W13="RV",X13," ") | AJ13: =IF(W13="RC",X13," ") | AK13: =IF(W13="RT",X13," ") | AL13: =IF(W13="DV",X13," ") | AM13: =IF(W13="DL",X13," ") | AN13: =IF(W13="X",X13," ")
E14: =IF(F14<>0,"Enter Code"," ") | G14: =IF(E14="BB",F14," ") | H14: =IF(E14="BS",F14," ") | I14: =IF(E14="BC",F14," ") | J14: =IF(E14="DR",F14," ") | K14: =IF(E14="K",F14," ") | L14: =IF(E14="LDR",F14," ") | M14: =IF(E14="LCR",F14," ") | N14: =IF(E14="RV",F14," ") | O14: =IF(E14="RC",F14," ") | W14: =IF(X14<>0,"Enter Code"," ") | Y14: =IF(W14="BB",X14," ") | Z14: =IF(W14="BS",X14," ") | AA14: =IF(W14="BC",X14," ") | AB14: =IF(W14="CR",X14," ") | AC14: =IF(W14="W",X14," ") | AD14: =IF(W14="B",X14," ") | AE14: =IF(W14="J",X14," ") | AF14: =IF(W14="LDR",X14," ") | AG14: =IF(W14="LCR",X14," ") | AH14: =IF(W14="RP",X14," ") | AI14: =IF(W14="RV",X14," ") | AJ14: =IF(W14="RC",X14," ") | AK14: =IF(W14="RT",X14," ") | AL14: =IF(W14="DV",X14," ") | AM14: =IF(W14="DL",X14," ") | AN14: =IF(W14="X",X14," ")
E15: =IF(F15<>0,"Enter Code"," ") | G15: =IF(E15="BB",F15," ") | H15: =IF(E15="BS",F15," ") | I15: =IF(E15="BC",F15," ") | J15: =IF(E15="DR",F15," ") | K15: =IF(E15="K",F15," ") | L15: =IF(E15="LDR",F15," ") | M15: =IF(E15="LCR",F15," ") | N15: =IF(E15="RV",F15," ") | O15: =IF(E15="RC",F15," ") | W15: =IF(X15<>0,"Enter Code"," ") | Y15: =IF(W15="BB",X15," ") | Z15: =IF(W15="BS",X15," ") | AA15: =IF(W15="BC",X15," ") | AB15: =IF(W15="CR",X15," ") | AC15: =IF(W15="W",X15," ") | AD15: =IF(W15="B",X15," ") | AE15: =IF(W15="J",X15," ") | AF15: =IF(W15="LDR",X15," ") | AG15: =IF(W15="LCR",X15," ") | AH15: =IF(W15="RP",X15," ") | AI15: =IF(W15="RV",X15," ") | AJ15: =IF(W15="RC",X15," ") | AK15: =IF(W15="RT",X15," ") | AL15: =IF(W15="DV",X15," ") | AM15: =IF(W15="DL",X15," ") | AN15: =IF(W15="X",X15," ")
E16: =IF(F16<>0,"Enter Code"," ") | G16: =IF(E16="BB",F16," ") | H16: =IF(E16="BS",F16," ") | I16: =IF(E16="BC",F16," ") | J16: =IF(E16="DR",F16," ") | K16: =IF(E16="K",F16," ") | L16: =IF(E16="LDR",F16," ") | M16: =IF(E16="LCR",F16," ") | N16: =IF(E16="RV",F16," ") | O16: =IF(E16="RC",F16," ") | W16: =IF(X16<>0,"Enter Code"," ") | Y16: =IF(W16="BB",X16," ") | Z16: =IF(W16="BS",X16," ") | AA16: =IF(W16="BC",X16," ") | AB16: =IF(W16="CR",X16," ") | AC16: =IF(W16="W",X16," ") | AD16: =IF(W16="B",X16," ") | AE16: =IF(W16="J",X16," ") | AF16: =IF(W16="LDR",X16," ") | AG16: =IF(W16="LCR",X16," ") | AH16: =IF(W16="RP",X16," ") | AI16: =IF(W16="RV",X16," ") | AJ16: =IF(W16="RC",X16," ") | AK16: =IF(W16="RT",X16," ") | AL16: =IF(W16="DV",X16," ") | AM16: =IF(W16="DL",X16," ") | AN16: =IF(W16="X",X16," ")
E17: =IF(F17<>0,"Enter Code"," ") | G17: =IF(E17="BB",F17," ") | H17: =IF(E17="BS",F17," ") | I17: =IF(E17="BC",F17," ") | J17: =IF(E17="DR",F17," ") | K17: =IF(E17="K",F17," ") | L17: =IF(E17="LDR",F17," ") | M17: =IF(E17="LCR",F17," ") | N17: =IF(E17="RV",F17," ") | O17: =IF(E17="RC",F17," ") | W17: =IF(X17<>0,"Enter Code"," ") | Y17: =IF(W17="BB",X17," ") | Z17: =IF(W17="BS",X17," ") | AA17: =IF(W17="BC",X17," ") | AB17: =IF(W17="CR",X17," ") | AC17: =IF(W17="W",X17," ") | AD17: =IF(W17="B",X17," ") | AE17: =IF(W17="J",X17," ") | AF17: =IF(W17="LDR",X17," ") | AG17: =IF(W17="LCR",X17," ") | AH17: =IF(W17="RP",X17," ") | AI17: =IF(W17="RV",X17," ") | AJ17: =IF(W17="RC",X17," ") | AK17: =IF(W17="RT",X17," ") | AL17: =IF(W17="DV",X17," ") | AM17: =IF(W17="DL",X17," ") | AN17: =IF(W17="X",X17," ")
E18: =IF(F18<>0,"Enter Code"," ") | G18: =IF(E18="BB",F18," ") | H18: =IF(E18="BS",F18," ") | I18: =IF(E18="BC",F18," ") | J18: =IF(E18="DR",F18," ") | K18: =IF(E18="K",F18," ") | L18: =IF(E18="LDR",F18," ") | M18: =IF(E18="LCR",F18," ") | N18: =IF(E18="RV",F18," ") | O18: =IF(E18="RC",F18," ") | W18: =IF(X18<>0,"Enter Code"," ") | Y18: =IF(W18="BB",X18," ") | Z18: =IF(W18="BS",X18," ") | AA18: =IF(W18="BC",X18," ") | AB18: =IF(W18="CR",X18," ") | AC18: =IF(W18="W",X18," ") | AD18: =IF(W18="B",X18," ") | AE18: =IF(W18="J",X18," ") | AF18: =IF(W18="LDR",X18," ") | AG18: =IF(W18="LCR",X18," ") | AH18: =IF(W18="RP",X18," ") | AI18: =IF(W18="RV",X18," ") | AJ18: =IF(W18="RC",X18," ") | AK18: =IF(W18="RT",X18," ") | AL18: =IF(W18="DV",X18," ") | AM18: =IF(W18="DL",X18," ") | AN18: =IF(W18="X",X18," ")
... E69: =IF(F69<>0,"Enter Code"," ") | G69: =IF(E69="BB",F69," ") | H69: =IF(E69="BS",F69," ") | I69: =IF(E69="BC",F69," ") | J69: =IF(E69="DR",F69," ") | K69: =IF(E69="K",F69," ") | L69: =IF(E69="LDR",F69," ") | M69: =IF(E69="LCR",F69," ") | N69: =IF(E69="RV",F69," ") | O69: =IF(E69="RC",F69," ") | W69: =IF(X69<>0,"Enter Code"," ") | Y69: =IF(W69="BB",X69," ") | Z69: =IF(W69="BS",X69," ") | AA69: =IF(W69="BC",X69," ") | AB69: =IF(W69="CR",X69," ") | AC69: =IF(W69="W",X69," ") | AD69: =IF(W69="B",X69," ") | AE69: =IF(W69="J",X69," ") | AF69: =IF(W69="LDR",X69," ") | AG69: =IF(W69="LCR",X69," ") | AH69: =IF(W69="RP",X69," ") | AI69: =IF(W69="RV",X69," ") | AJ69: =IF(W69="RC",X69," ") | AK69: =IF(W69="RT",X69," ") | AL69: =IF(W69="DV",X69," ") | AM69: =IF(W69="DL",X69," ") | AN69: =IF(W69="X",X69," ")
E70: =IF(F70<>0,"Enter Code"," ") | G70: =IF(E70="BB",F70," ") | H70: =IF(E70="BS",F70," ") | I70: =IF(E70="BC",F70," ") | J70: =IF(E70="DR",F70," ") | K70: =IF(E70="K",F70," ") | L70: =IF(E70="LDR",F70," ") | M70: =IF(E70="LCR",F70," ") | N70: =IF(E70="RV",F70," ") | O70: =IF(E70="RC",F70," ") | P70: =IF(E70="DL",F70," ") | Q70: =IF(E70="X",F70," ") | W70: =IF(X70<>0,"Enter Code"," ") | Y70: =IF(W70="BB",X70," ") | Z70: =IF(W70="BS",X70," ") | AA70: =IF(W70="BC",X70," ") | AB70: =IF(W70="CR",X70," ") | AC70: =IF(W70="W",X70," ") | AD70: =IF(W70="B",X70," ") | AE70: =IF(W70="J",X70," ") | AF70: =IF(W70="LDR",X70," ") | AG70: =IF(W70="LCR",X70," ") | AH70: =IF(W70="RP",X70," ") | AI70: =IF(W70="RV",X70," ") | AJ70: =IF(W70="RC",X70," ") | AK70: =IF(W70="RT",X70," ") | AL70: =IF(W70="DV",X70," ") | AM70: =IF(W70="DL",X70," ") | AN70: =IF(W70="X",X70," ")
E71: =IF(F71<>0,"Enter Code"," ") | G71: =IF(E71="BB",F71," ") | H71: =IF(E71="BS",F71," ") | I71: =IF(E71="BC",F71," ") | J71: =IF(E71="DR",F71," ") | K71: =IF(E71="K",F71," ") | L71: =IF(E71="LDR",F71," ") | M71: =IF(E71="LCR",F71," ") | N71: =IF(E71="RV",F71," ") | O71: =IF(E71="RC",F71," ") | P71: =IF(E71="DL",F71," ") | Q71: =IF(E71="X",F71," ") | W71: =IF(X71<>0,"Enter Code"," ") | Y71: =IF(W71="BB",X71," ") | Z71: =IF(W71="BS",X71," ") | AA71: =IF(W71="BC",X71," ") | AB71: =IF(W71="CR",X71," ") | AC71: =IF(W71="W",X71," ") | AD71: =IF(W71="B",X71," ") | AE71: =IF(W71="J",X71," ") | AF71: =IF(W71="LDR",X71," ") | AG71: =IF(W71="LCR",X71," ") | AH71: =IF(W71="RP",X71," ") | AI71: =IF(W71="RV",X71," ") | AJ71: =IF(W71="RC",X71," ") | AK71: =IF(W71="RT",X71," ") | AL71: =IF(W71="DV",X71," ") | AM71: =IF(W71="DL",X71," ") | AN71: =IF(W71="X",X71," ")
E72: =IF(F72<>0,"Enter Code"," ") | G72: =IF(E72="BB",F72," ") | H72: =IF(E72="BS",F72," ") | I72: =IF(E72="BC",F72," ") | J72: =IF(E72="DR",F72," ") | K72: =IF(E72="K",F72," ") | L72: =IF(E72="LDR",F72," ") | M72: =IF(E72="LCR",F72," ") | N72: =IF(E72="RV",F72," ") | O72: =IF(E72="RC",F72," ") | P72: =IF(E72="DL",F72," ") | Q72: =IF(E72="X",F72," ") | W72: =IF(X72<>0,"Enter Code"," ") | Y72: =IF(W72="BB",X72," ") | Z72: =IF(W72="BS",X72," ") | AA72: =IF(W72="BC",X72," ") | AB72: =IF(W72="CR",X72," ") | AC72: =IF(W72="W",X72," ") | AD72: =IF(W72="B",X72," ") | AE72: =IF(W72="J",X72," ") | AF72: =IF(W72="LDR",X72," ") | AG72: =IF(W72="LCR",X72," ") | AH72: =IF(W72="RP",X72," ") | AI72: =IF(W72="RV",X72," ") | AJ72: =IF(W72="RC",X72," ") | AK72: =IF(W72="RT",X72," ") | AL72: =IF(W72="DV",X72," ") | AM72: =IF(W72="DL",X72," ") | AN72: =IF(W72="X",X72," ")
E73: =IF(F73<>0,"Enter Code"," ") | G73: =IF(E73="BB",F73," ") | H73: =IF(E73="BS",F73," ") | I73: =IF(E73="BC",F73," ") | J73: =IF(E73="DR",F73," ") | K73: =IF(E73="K",F73," ") | L73: =IF(E73="LDR",F73," ") | M73: =IF(E73="LCR",F73," ") | N73: =IF(E73="RV",F73," ") | O73: =IF(E73="RC",F73," ") | P73: =IF(E73="DL",F73," ") | Q73: =IF(E73="X",F73," ") | W73: =IF(X73<>0,"Enter Code"," ") | Y73: =IF(W73="BB",X73," ") | Z73: =IF(W73="BS",X73," ") | AA73: =IF(W73="BC",X73," ") | AB73: =IF(W73="CR",X73," ") | AC73: =IF(W73="W",X73," ") | AD73: =IF(W73="B",X73," ") | AE73: =IF(W73="J",X73," ") | AF73: =IF(W73="LDR",X73," ") | AG73: =IF(W73="LCR",X73," ") | AH73: =IF(W73="RP",X73," ") | AI73: =IF(W73="RV",X73," ") | AJ73: =IF(W73="RC",X73," ") | AK73: =IF(W73="RT",X73," ") | AL73: =IF(W73="DV",X73," ") | AM73: =IF(W73="DL",X73," ") | AN73: =IF(W73="X",X73," ")
E74: =IF(F74<>0,"Enter Code"," ") | G74: =IF(E74="BB",F74," ") | H74: =IF(E74="BS",F74," ") | I74: =IF(E74="BC",F74," ") | J74: =IF(E74="DR",F74," ") | K74: =IF(E74="K",F74," ") | L74: =IF(E74="LDR",F74," ") | M74: =IF(E74="LCR",F74," ") | N74: =IF(E74="RV",F74," ") | O74: =IF(E74="RC",F74," ") | P74: =IF(E74="DL",F74," ") | Q74: =IF(E74="X",F74," ") | W74: =IF(X74<>0,"Enter Code"," ") | Y74: =IF(W74="BB",X74," ") | Z74: =IF(W74="BS",X74," ") | AA74: =IF(W74="BC",X74," ") | AB74: =IF(W74="CR",X74," ") | AC74: =IF(W74="W",X74," ") | AD74: =IF(W74="B",X74," ") | AE74: =IF(W74="J",X74," ") | AF74: =IF(W74="LDR",X74," ") | AG74: =IF(W74="LCR",X74," ") | AH74: =IF(W74="RP",X74," ") | AI74: =IF(W74="RV",X74," ") | AJ74: =IF(W74="RC",X74," ") | AK74: =IF(W74="RT",X74," ") | AL74: =IF(W74="DV",X74," ") | AM74: =IF(W74="DL",X74," ") | AN74: =IF(W74="X",X74," ")
E75: =IF(F75<>0,"Enter Code"," ") | G75: =IF(E75="BB",F75," ") | H75: =IF(E75="BS",F75," ") | I75: =IF(E75="BC",F75," ") | J75: =IF(E75="DR",F75," ") | K75: =IF(E75="K",F75," ") | L75: =IF(E75="LDR",F75," ") | M75: =IF(E75="LCR",F75," ") | N75: =IF(E75="RV",F75," ") | O75: =IF(E75="RC",F75," ") | P75: =IF(E75="DL",F75," ") | Q75: =IF(E75="X",F75," ") | W75: =IF(X75<>0,"Enter Code"," ") | Y75: =IF(W75="BB",X75," ") | Z75: =IF(W75="BS",X75," ") | AA75: =IF(W75="BC",X75," ") | AB75: =IF(W75="CR",X75," ") | AC75: =IF(W75="W",X75," ") | AD75: =IF(W75="B",X75," ") | AE75: =IF(W75="J",X75," ") | AF75: =IF(W75="LDR",X75," ") | AG75: =IF(W75="LCR",X75," ") | AH75: =IF(W75="RP",X75," ") | AI75: =IF(W75="RV",X75," ") | AJ75: =IF(W75="RC",X75," ") | AK75: =IF(W75="RT",X75," ") | AL75: =IF(W75="DV",X75," ") | AM75: =IF(W75="DL",X75," ") | AN75: =IF(W75="X",X75," ")
E76: =IF(F76<>0,"Enter Code"," ") | G76: =IF(E76="BB",F76," ") | H76: =IF(E76="BS",F76," ") | I76: =IF(E76="BC",F76," ") | J76: =IF(E76="DR",F76," ") | K76: =IF(E76="K",F76," ") | L76: =IF(E76="LDR",F76," ") | M76: =IF(E76="LCR",F76," ") | N76: =IF(E76="RV",F76," ") | O76: =IF(E76="RC",F76," ") | P76: =IF(E76="DL",F76," ") | Q76: =IF(E76="X",F76," ") | W76: =IF(X76<>0,"Enter Code"," ") | Y76: =IF(W76="BB",X76," ") | Z76: =IF(W76="BS",X76," ") | AA76: =IF(W76="BC",X76," ") | AB76: =IF(W76="CR",X76," ") | AC76: =IF(W76="W",X76," ") | AD76: =IF(W76="B",X76," ") | AE76: =IF(W76="J",X76," ") | AF76: =IF(W76="LDR",X76," ") | AG76: =IF(W76="LCR",X76," ") | AH76: =IF(W76="RP",X76," ") | AI76: =IF(W76="RV",X76," ") | AJ76: =IF(W76="RC",X76," ") | AK76: =IF(W76="RT",X76," ") | AL76: =IF(W76="DV",X76," ") | AM76: =IF(W76="DL",X76," ") | AN76: =IF(W76="X",X76," ")
E77: =IF(F77<>0,"Enter Code"," ") | G77: =IF(E77="BB",F77," ") | H77: =IF(E77="BS",F77," ") | I77: =IF(E77="BC",F77," ") | J77: =IF(E77="DR",F77," ") | K77: =IF(E77="K",F77," ") | L77: =IF(E77="LDR",F77," ") | M77: =IF(E77="LCR",F77," ") | N77: =IF(E77="RV",F77," ") | O77: =IF(E77="RC",F77," ") | P77: =IF(E77="DL",F77," ") | Q77: =IF(E77="X",F77," ") | W77: =IF(X77<>0,"Enter Code"," ") | Y77: =IF(W77="BB",X77," ") | Z77: =IF(W77="BS",X77," ") | AA77: =IF(W77="BC",X77," ") | AB77: =IF(W77="CR",X77," ") | AC77: =IF(W77="W",X77," ") | AD77: =IF(W77="B",X77," ") | AE77: =IF(W77="J",X77," ") | AF77: =IF(W77="LDR",X77," ") | AG77: =IF(W77="LCR",X77," ") | AH77: =IF(W77="RP",X77," ") | AI77: =IF(W77="RV",X77," ") | AJ77: =IF(W77="RC",X77," ") | AK77: =IF(W77="RT",X77," ") | AL77: =IF(W77="DV",X77," ") | AM77: =IF(W77="DL",X77," ") | AN77: =IF(W77="X",X77," ")
E78: =IF(F78<>0,"Enter Code"," ") | G78: =IF(E78="BB",F78," ") | H78: =IF(E78="BS",F78," ") | I78: =IF(E78="BC",F78," ") | J78: =IF(E78="DR",F78," ") | K78: =IF(E78="K",F78," ") | L78: =IF(E78="LDR",F78," ") | M78: =IF(E78="LCR",F78," ") | N78: =IF(E78="RV",F78," ") | O78: =IF(E78="RC",F78," ") | P78: =IF(E78="DL",F78," ") | Q78: =IF(E78="X",F78," ") | W78: =IF(X78<>0,"Enter Code"," ") | Y78: =IF(W78="BB",X78," ") | Z78: =IF(W78="BS",X78," ") | AA78: =IF(W78="BC",X78," ") | AB78: =IF(W78="CR",X78," ") | AC78: =IF(W78="W",X78," ") | AD78: =IF(W78="B",X78," ") | AE78: =IF(W78="J",X78," ") | AF78: =IF(W78="LDR",X78," ") | AG78: =IF(W78="LCR",X78," ") | AH78: =IF(W78="RP",X78," ") | AI78: =IF(W78="RV",X78," ") | AJ78: =IF(W78="RC",X78," ") | AK78: =IF(W78="RT",X78," ") | AL78: =IF(W78="DV",X78," ") | AM78: =IF(W78="DL",X78," ") | AN78: =IF(W78="X",X78," ")
E79: =IF(F79<>0,"Enter Code"," ") | G79: =IF(E79="BB",F79," ") | H79: =IF(E79="BS",F79," ") | I79: =IF(E79="BC",F79," ") | J79: =IF(E79="DR",F79," ") | K79: =IF(E79="K",F79," ") | L79: =IF(E79="LDR",F79," ") | M79: =IF(E79="LCR",F79," ") | N79: =IF(E79="RV",F79," ") | O79: =IF(E79="RC",F79," ") | P79: =IF(E79="DL",F79," ") | Q79: =IF(E79="X",F79," ") | W79: =IF(X79<>0,"Enter Code"," ") | Y79: =IF(W79="BB",X79," ") | Z79: =IF(W79="BS",X79," ") | AA79: =IF(W79="BC",X79," ") | AB79: =IF(W79="CR",X79," ") | AC79: =IF(W79="W",X79," ") | AD79: =IF(W79="B",X79," ") | AE79: =IF(W79="J",X79," ") | AF79: =IF(W79="LDR",X79," ") | AG79: =IF(W79="LCR",X79," ") | AH79: =IF(W79="RP",X79," ") | AI79: =IF(W79="RV",X79," ") | AJ79: =IF(W79="RC",X79," ") | AK79: =IF(W79="RT",X79," ") | AL79: =IF(W79="DV",X79," ") | AM79: =IF(W79="DL",X79," ") | AN79: =IF(W79="X",X79," ")
E80: =IF(F80<>0,"Enter Code"," ") | G80: =IF(E80="BB",F80," ") | H80: =IF(E80="BS",F80," ") | I80: =IF(E80="BC",F80," ") | J80: =IF(E80="DR",F80," ") | K80: =IF(E80="K",F80," ") | L80: =IF(E80="LDR",F80," ") | M80: =IF(E80="LCR",F80," ") | N80: =IF(E80="RV",F80," ") | O80: =IF(E80="RC",F80," ") | P80: =IF(E80="DL",F80," ") | Q80: =IF(E80="X",F80," ") | W80: =IF(X80<>0,"Enter Code"," ") | Y80: =IF(W80="BB",X80," ") | Z80: =IF(W80="BS",X80," ") | AA80: =IF(W80="BC",X80," ") | AB80: =IF(W80="CR",X80," ") | AC80: =IF(W80="W",X80," ") | AD80: =IF(W80="B",X80," ") | AE80: =IF(W80="J",X80," ") | AF80: =IF(W80="LDR",X80," ") | AG80: =IF(W80="LCR",X80," ") | AH80: =IF(W80="RP",X80," ") | AI80: =IF(W80="RV",X80," ") | AJ80: =IF(W80="RC",X80," ") | AK80: =IF(W80="RT",X80," ") | AL80: =IF(W80="DV",X80," ") | AM80: =IF(W80="DL",X80," ") | AN80: =IF(W80="X",X80," ")
E81: =IF(F81<>0,"Enter Code"," ") | G81: =IF(E81="BB",F81," ") | H81: =IF(E81="BS",F81," ") | I81: =IF(E81="BC",F81," ") | J81: =IF(E81="DR",F81," ") | K81: =IF(E81="K",F81," ") | L81: =IF(E81="LDR",F81," ") | M81: =IF(E81="LCR",F81," ") | N81: =IF(E81="RV",F81," ") | O81: =IF(E81="RC",F81," ") | P81: =IF(E81="DL",F81," ") | Q81: =IF(E81="X",F81," ") | W81: =IF(X81<>0,"Enter Code"," ") | Y81: =IF(W81="BB",X81," ") | Z81: =IF(W81="BS",X81," ") | AA81: =IF(W81="BC",X81," ") | AB81: =IF(W81="CR",X81," ") | AC81: =IF(W81="W",X81," ") | AD81: =IF(W81="B",X81," ") | AE81: =IF(W81="J",X81," ") | AF81: =IF(W81="LDR",X81," ") | AG81: =IF(W81="LCR",X81," ") | AH81: =IF(W81="RP",X81," ") | AI81: =IF(W81="RV",X81," ") | AJ81: =IF(W81="RC",X81," ") | AK81: =IF(W81="RT",X81," ") | AL81: =IF(W81="DV",X81," ") | AM81: =IF(W81="DL",X81," ") | AN81: =IF(W81="X",X81," ")
... E200: =IF(F200<>0,"Enter Code"," ") | G200: =IF(E200="BB",F200," ") | H200: =IF(E200="BS",F200," ") | I200: =IF(E200="BC",F200," ") | J200: =IF(E200="DR",F200," ") | K200: =IF(E200="K",F200," ") | L200: =IF(E200="LDR",F200," ") | M200: =IF(E200="LCR",F200," ") | N200: =IF(E200="RV",F200," ") | O200: =IF(E200="RC",F200," ") | P200: =IF(E200="DL",F200," ") | Q200: =IF(E200="X",F200," ") | W200: =IF(X200<>0,"Enter Code"," ") | Y200: =IF(W200="BB",X200," ") | Z200: =IF(W200="BS",X200," ") | AA200: =IF(W200="BC",X200," ") | AB200: =IF(W200="CR",X200," ") | AC200: =IF(W200="W",X200," ") | AD200: =IF(W200="B",X200," ") | AE200: =IF(W200="J",X200," ") | AF200: =IF(W200="LDR",X200," ") | AG200: =IF(W200="LCR",X200," ") | AH200: =IF(W200="RP",X200," ") | AI200: =IF(W200="RV",X200," ") | AJ200: =IF(W200="RC",X200," ") | AK200: =IF(W200="RT",X200," ") | AL200: =IF(W200="DV",X200," ") | AM200: =IF(W200="DL",X200," ") | AN200: =IF(W200="X",X200," ")

Sheet Aug
A1: =Jul!A2 -> 500 | B1: < Opening Bank Balance | C1: =[1]Admin!$B$13 -> 45809 | D1: Totals > | E1: =F1-SUM(G1:Q1) -> 180 | F1: =SUM(F6:F200) -> 180 | G1: =SUM(G6:G200) -> 0 | H1: =SUM(H6:H200) -> 0 | I1: =SUM(I6:I200) -> 0 | J1: =SUM(J6:J200) -> 0 | K1: =SUM(K6:K200) -> 0 | L1: =SUM(L6:L200) -> 0 | M1: =SUM(M6:M200) -> 0 | ... Q1: =SUM(Q6:Q200) -> 0 | S1: =IF(W1=0," ","Check all payment code letters entered") | V1: Totals > | W1: =X1-SUM(Y1:AN1) -> 0 | X1: =SUM(X6:X200) -> 0 | Y1: =SUM(Y6:Y200) -> 0 | Z1: =SUM(Z6:Z200) -> 0 | AA1: =SUM(AA6:AA200) -> 0 | AB1: =SUM(AB6:AB200) -> 0 | AC1: =SUM(AC6:AC200) -> 0 | AD1: =SUM(AD6:AD200) -> 0 | AE1: =SUM(AE6:AE200) -> 0 | ... AN1: =SUM(AN6:AN200) -> 0
A2: =A1+F1-X1 -> 680 | B2: < Closing Bank Balance | C2: =[1]Admin!$B$14 -> 45838 | D2: Deposit Bank Reference | E2: Enter Code Letters | F2: COMPANY CREDIT CARD STATEMENT RECEIPTS | S2: =IF(E1=0," ","Check all Receipts Code Letters entered") -> Check all Receipts Code Letters entered | U2: Enter Purchase Invoice No. | V2: Cheque number Direct Debit | W2: Enter Code Letters | X2: COMPANY CREDIT CARD STATEMENT PAYMENTS
B3: < Statement Bank Balance | C3: =C2 -> 45838 | F3: Amounts received from each Source | G3: Transfers From Current | H3: Transfers From Savings | I3: Transfers From Cash | J3: Amount Received Debtors | K3: Interest Received | L3: Long Term Debtor | M3: Long Term Creditor | N3: HMRC Vat Refunded | O3: HMRC CIS Refunded | P3: Directors Loan Account | Q3: Bank Contra items | X3: Amounts Paid by invoice number | Y3: Transfers To Current | Z3: Transfers To Savings | AA3: Transfers To Cash | AB3: Amount Paid Creditors | AC3: Net Wages Paid | AD3: Bank Charges Paid | AE3: Interest Paid | AF3: Long Term Debtor | AG3: Long Term Creditor | AH3: HMRC Paye Payments | AI3: HMRC Vat Payments | AJ3: HMRC CIS Payments | AK3: HMRC Corp Tax Payment | AL3: Dividends Paid | AM3: Directors Loan Account | AN3: Bank Contra items
A4: =A2-A3 -> 680 | B4: =IF(A4=0,"< Bank - Statement Balance"," Reconcile Bank Statement") -> Reconcile Bank Statement | S4: Payment Date | T4: Suppliers paid
A5: Date | B5: Source of Funds Received | C5: Sales Invoice | G5: BB | H5: BS | I5: BC | J5: DR | K5: K | L5: LDR | M5: LCR | N5: RV | O5: RC | P5: DL | Q5: X | Y5: BB | Z5: BS | AA5: BC | AB5: CR | AC5: W | AD5: B | AE5: J | AF5: LDR | AG5: LCR | AH5: RP | AI5: RV | AJ5: RC | AK5: RT | AL5: DV | AM5: DL | AN5: X
A6: 45887 | B6: Premier Inn | E6: CR | F6: 180 | G6: =IF(E6="BB",F6," ") | H6: =IF(E6="BS",F6," ") | I6: =IF(E6="BC",F6," ") | J6: =IF(E6="DR",F6," ") | K6: =IF(E6="K",F6," ") | L6: =IF(E6="LDR",F6," ") | M6: =IF(E6="LCR",F6," ") | N6: =IF(E6="RV",F6," ") | O6: =IF(E6="RC",F6," ") | P6: =IF(E6="DL",F6," ") | Q6: =IF(E6="X",F6," ") | W6: =IF(X6<>0,"Enter Code"," ") | Y6: =IF(W6="BB",X6," ") | Z6: =IF(W6="BS",X6," ") | AA6: =IF(W6="BC",X6," ") | AB6: =IF(W6="CR",X6," ") | AC6: =IF(W6="W",X6," ") | AD6: =IF(W6="B",X6," ") | AE6: =IF(W6="J",X6," ") | AF6: =IF(W6="LDR",X6," ") | AG6: =IF(W6="LCR",X6," ") | AH6: =IF(W6="RP",X6," ") | AI6: =IF(W6="RV",X6," ") | AJ6: =IF(W6="RC",X6," ") | AK6: =IF(W6="RT",X6," ") | AL6: =IF(W6="DV",X6," ") | AM6: =IF(W6="DL",X6," ") | AN6: =IF(W6="X",X6," ")
G7: =IF(E7="BB",F7," ") | H7: =IF(E7="BS",F7," ") | I7: =IF(E7="BC",F7," ") | J7: =IF(E7="DR",F7," ") | K7: =IF(E7="K",F7," ") | L7: =IF(E7="LDR",F7," ") | M7: =IF(E7="LCR",F7," ") | N7: =IF(E7="RV",F7," ") | O7: =IF(E7="RC",F7," ") | P7: =IF(E7="DL",F7," ") | Q7: =IF(E7="X",F7," ") | W7: =IF(X7<>0,"Enter Code"," ") | Y7: =IF(W7="BB",X7," ") | Z7: =IF(W7="BS",X7," ") | AA7: =IF(W7="BC",X7," ") | AB7: =IF(W7="CR",X7," ") | AC7: =IF(W7="W",X7," ") | AD7: =IF(W7="B",X7," ") | AE7: =IF(W7="J",X7," ") | AF7: =IF(W7="LDR",X7," ") | AG7: =IF(W7="LCR",X7," ") | AH7: =IF(W7="RP",X7," ") | AI7: =IF(W7="RV",X7," ") | AJ7: =IF(W7="RC",X7," ") | AK7: =IF(W7="RT",X7," ") | AL7: =IF(W7="DV",X7," ") | AM7: =IF(W7="DL",X7," ") | AN7: =IF(W7="X",X7," ")
G8: =IF(E8="BB",F8," ") | H8: =IF(E8="BS",F8," ") | I8: =IF(E8="BC",F8," ") | J8: =IF(E8="DR",F8," ") | K8: =IF(E8="K",F8," ") | L8: =IF(E8="LDR",F8," ") | M8: =IF(E8="LCR",F8," ") | N8: =IF(E8="RV",F8," ") | O8: =IF(E8="RC",F8," ") | P8: =IF(E8="DL",F8," ") | Q8: =IF(E8="X",F8," ") | W8: =IF(X8<>0,"Enter Code"," ") | Y8: =IF(W8="BB",X8," ") | Z8: =IF(W8="BS",X8," ") | AA8: =IF(W8="BC",X8," ") | AB8: =IF(W8="CR",X8," ") | AC8: =IF(W8="W",X8," ") | AD8: =IF(W8="B",X8," ") | AE8: =IF(W8="J",X8," ") | AF8: =IF(W8="LDR",X8," ") | AG8: =IF(W8="LCR",X8," ") | AH8: =IF(W8="RP",X8," ") | AI8: =IF(W8="RV",X8," ") | AJ8: =IF(W8="RC",X8," ") | AK8: =IF(W8="RT",X8," ") | AL8: =IF(W8="DV",X8," ") | AM8: =IF(W8="DL",X8," ") | AN8: =IF(W8="X",X8," ")
G9: =IF(E9="BB",F9," ") | H9: =IF(E9="BS",F9," ") | I9: =IF(E9="BC",F9," ") | J9: =IF(E9="DR",F9," ") | K9: =IF(E9="K",F9," ") | L9: =IF(E9="LDR",F9," ") | M9: =IF(E9="LCR",F9," ") | N9: =IF(E9="RV",F9," ") | O9: =IF(E9="RC",F9," ") | P9: =IF(E9="DL",F9," ") | Q9: =IF(E9="X",F9," ") | W9: =IF(X9<>0,"Enter Code"," ") | Y9: =IF(W9="BB",X9," ") | Z9: =IF(W9="BS",X9," ") | AA9: =IF(W9="BC",X9," ") | AB9: =IF(W9="CR",X9," ") | AC9: =IF(W9="W",X9," ") | AD9: =IF(W9="B",X9," ") | AE9: =IF(W9="J",X9," ") | AF9: =IF(W9="LDR",X9," ") | AG9: =IF(W9="LCR",X9," ") | AH9: =IF(W9="RP",X9," ") | AI9: =IF(W9="RV",X9," ") | AJ9: =IF(W9="RC",X9," ") | AK9: =IF(W9="RT",X9," ") | AL9: =IF(W9="DV",X9," ") | AM9: =IF(W9="DL",X9," ") | AN9: =IF(W9="X",X9," ")
G10: =IF(E10="BB",F10," ") | H10: =IF(E10="BS",F10," ") | I10: =IF(E10="BC",F10," ") | J10: =IF(E10="DR",F10," ") | K10: =IF(E10="K",F10," ") | L10: =IF(E10="LDR",F10," ") | M10: =IF(E10="LCR",F10," ") | N10: =IF(E10="RV",F10," ") | O10: =IF(E10="RC",F10," ") | P10: =IF(E10="DL",F10," ") | Q10: =IF(E10="X",F10," ") | W10: =IF(X10<>0,"Enter Code"," ") | Y10: =IF(W10="BB",X10," ") | Z10: =IF(W10="BS",X10," ") | AA10: =IF(W10="BC",X10," ") | AB10: =IF(W10="CR",X10," ") | AC10: =IF(W10="W",X10," ") | AD10: =IF(W10="B",X10," ") | AE10: =IF(W10="J",X10," ") | AF10: =IF(W10="LDR",X10," ") | AG10: =IF(W10="LCR",X10," ") | AH10: =IF(W10="RP",X10," ") | AI10: =IF(W10="RV",X10," ") | AJ10: =IF(W10="RC",X10," ") | AK10: =IF(W10="RT",X10," ") | AL10: =IF(W10="DV",X10," ") | AM10: =IF(W10="DL",X10," ") | AN10: =IF(W10="X",X10," ")
G11: =IF(E11="BB",F11," ") | H11: =IF(E11="BS",F11," ") | I11: =IF(E11="BC",F11," ") | J11: =IF(E11="DR",F11," ") | K11: =IF(E11="K",F11," ") | L11: =IF(E11="LDR",F11," ") | M11: =IF(E11="LCR",F11," ") | N11: =IF(E11="RV",F11," ") | O11: =IF(E11="RC",F11," ") | P11: =IF(E11="DL",F11," ") | Q11: =IF(E11="X",F11," ") | W11: =IF(X11<>0,"Enter Code"," ") | Y11: =IF(W11="BB",X11," ") | Z11: =IF(W11="BS",X11," ") | AA11: =IF(W11="BC",X11," ") | AB11: =IF(W11="CR",X11," ") | AC11: =IF(W11="W",X11," ") | AD11: =IF(W11="B",X11," ") | AE11: =IF(W11="J",X11," ") | AF11: =IF(W11="LDR",X11," ") | AG11: =IF(W11="LCR",X11," ") | AH11: =IF(W11="RP",X11," ") | AI11: =IF(W11="RV",X11," ") | AJ11: =IF(W11="RC",X11," ") | AK11: =IF(W11="RT",X11," ") | AL11: =IF(W11="DV",X11," ") | AM11: =IF(W11="DL",X11," ") | AN11: =IF(W11="X",X11," ")
G12: =IF(E12="BB",F12," ") | H12: =IF(E12="BS",F12," ") | I12: =IF(E12="BC",F12," ") | J12: =IF(E12="DR",F12," ") | K12: =IF(E12="K",F12," ") | L12: =IF(E12="LDR",F12," ") | M12: =IF(E12="LCR",F12," ") | N12: =IF(E12="RV",F12," ") | O12: =IF(E12="RC",F12," ") | P12: =IF(E12="DL",F12," ") | Q12: =IF(E12="X",F12," ") | W12: =IF(X12<>0,"Enter Code"," ") | Y12: =IF(W12="BB",X12," ") | Z12: =IF(W12="BS",X12," ") | AA12: =IF(W12="BC",X12," ") | AB12: =IF(W12="CR",X12," ") | AC12: =IF(W12="W",X12," ") | AD12: =IF(W12="B",X12," ") | AE12: =IF(W12="J",X12," ") | AF12: =IF(W12="LDR",X12," ") | AG12: =IF(W12="LCR",X12," ") | AH12: =IF(W12="RP",X12," ") | AI12: =IF(W12="RV",X12," ") | AJ12: =IF(W12="RC",X12," ") | AK12: =IF(W12="RT",X12," ") | AL12: =IF(W12="DV",X12," ") | AM12: =IF(W12="DL",X12," ") | AN12: =IF(W12="X",X12," ")
G13: =IF(E13="BB",F13," ") | H13: =IF(E13="BS",F13," ") | I13: =IF(E13="BC",F13," ") | J13: =IF(E13="DR",F13," ") | K13: =IF(E13="K",F13," ") | L13: =IF(E13="LDR",F13," ") | M13: =IF(E13="LCR",F13," ") | N13: =IF(E13="RV",F13," ") | O13: =IF(E13="RC",F13," ") | P13: =IF(E13="DL",F13," ") | Q13: =IF(E13="X",F13," ") | W13: =IF(X13<>0,"Enter Code"," ") | Y13: =IF(W13="BB",X13," ") | Z13: =IF(W13="BS",X13," ") | AA13: =IF(W13="BC",X13," ") | AB13: =IF(W13="CR",X13," ") | AC13: =IF(W13="W",X13," ") | AD13: =IF(W13="B",X13," ") | AE13: =IF(W13="J",X13," ") | AF13: =IF(W13="LDR",X13," ") | AG13: =IF(W13="LCR",X13," ") | AH13: =IF(W13="RP",X13," ") | AI13: =IF(W13="RV",X13," ") | AJ13: =IF(W13="RC",X13," ") | AK13: =IF(W13="RT",X13," ") | AL13: =IF(W13="DV",X13," ") | AM13: =IF(W13="DL",X13," ") | AN13: =IF(W13="X",X13," ")
G14: =IF(E14="BB",F14," ") | H14: =IF(E14="BS",F14," ") | I14: =IF(E14="BC",F14," ") | J14: =IF(E14="DR",F14," ") | K14: =IF(E14="K",F14," ") | L14: =IF(E14="LDR",F14," ") | M14: =IF(E14="LCR",F14," ") | N14: =IF(E14="RV",F14," ") | O14: =IF(E14="RC",F14," ") | P14: =IF(E14="DL",F14," ") | Q14: =IF(E14="X",F14," ") | W14: =IF(X14<>0,"Enter Code"," ") | Y14: =IF(W14="BB",X14," ") | Z14: =IF(W14="BS",X14," ") | AA14: =IF(W14="BC",X14," ") | AB14: =IF(W14="CR",X14," ") | AC14: =IF(W14="W",X14," ") | AD14: =IF(W14="B",X14," ") | AE14: =IF(W14="J",X14," ") | AF14: =IF(W14="LDR",X14," ") | AG14: =IF(W14="LCR",X14," ") | AH14: =IF(W14="RP",X14," ") | AI14: =IF(W14="RV",X14," ") | AJ14: =IF(W14="RC",X14," ") | AK14: =IF(W14="RT",X14," ") | AL14: =IF(W14="DV",X14," ") | AM14: =IF(W14="DL",X14," ") | AN14: =IF(W14="X",X14," ")
