Workbook

Sheet Month 01
A1: EXPENSES CLAIM FORM
A2: Attach all receipts to support the claim for re-imbursement of business expenses incurred
A3: Enter X if vat registered leave blank if not registered or flat rate scheme | G3: x
A5: Name | F5: Vat rate applied | H5: 20
A6: Address | F6: Date From: | G6: 45383
C7: Post Code | F7: Date To: | G7: 45412
A9: Date | B9: Description of Expense | C9: Destination and Purpose | D9: Mileage | E9: Expense Type | F9: Total Claimed | G9: Vat | H9: Net Expense | J9: General Admin | K9: Hotel & Travel | L9: Vehicle or Mileage | M9: Other Expenses
G10: =IF(F10>0,IF(G$3="X",F10*H$5/100/(1+H$5/100)," ")," ") | H10: =IF(F10>0,IF(G10=" ",F10,F10-G10)," ") | J10: =IF(E10="General Admin",H10," ") | K10: =IF(E10="Hotel & Travel",H10," ") | L10: =IF(E10="Vehicle or Mileage",H10," ") | M10: =IF(E10="Other Expenses",H10," ")
G11: =IF(F11>0,IF(G$3="X",F11*H$5/100/(1+H$5/100)," ")," ") | H11: =IF(F11>0,IF(G11=" ",F11,F11-G11)," ") | J11: =IF(E11="General Admin",H11," ") | K11: =IF(E11="Hotel & Travel",H11," ") | L11: =IF(E11="Vehicle or Mileage",H11," ") | M11: =IF(E11="Other Expenses",H11," ")
G12: =IF(F12>0,IF(G$3="X",F12*H$5/100/(1+H$5/100)," ")," ") | H12: =IF(F12>0,IF(G12=" ",F12,F12-G12)," ") | J12: =IF(E12="General Admin",H12," ") | K12: =IF(E12="Hotel & Travel",H12," ") | L12: =IF(E12="Vehicle or Mileage",H12," ") | M12: =IF(E12="Other Expenses",H12," ")
G13: =IF(F13>0,IF(G$3="X",F13*H$5/100/(1+H$5/100)," ")," ") | H13: =IF(F13>0,IF(G13=" ",F13,F13-G13)," ") | J13: =IF(E13="General Admin",H13," ") | K13: =IF(E13="Hotel & Travel",H13," ") | L13: =IF(E13="Vehicle or Mileage",H13," ") | M13: =IF(E13="Other Expenses",H13," ")
G14: =IF(F14>0,IF(G$3="X",F14*H$5/100/(1+H$5/100)," ")," ") | H14: =IF(F14>0,IF(G14=" ",F14,F14-G14)," ") | J14: =IF(E14="General Admin",H14," ") | K14: =IF(E14="Hotel & Travel",H14," ") | L14: =IF(E14="Vehicle or Mileage",H14," ") | M14: =IF(E14="Other Expenses",H14," ")
G15: =IF(F15>0,IF(G$3="X",F15*H$5/100/(1+H$5/100)," ")," ") | H15: =IF(F15>0,IF(G15=" ",F15,F15-G15)," ") | J15: =IF(E15="General Admin",H15," ") | K15: =IF(E15="Hotel & Travel",H15," ") | L15: =IF(E15="Vehicle or Mileage",H15," ") | M15: =IF(E15="Other Expenses",H15," ")
G16: =IF(F16>0,IF(G$3="X",F16*H$5/100/(1+H$5/100)," ")," ") | H16: =IF(F16>0,IF(G16=" ",F16,F16-G16)," ") | J16: =IF(E16="General Admin",H16," ") | K16: =IF(E16="Hotel & Travel",H16," ") | L16: =IF(E16="Vehicle or Mileage",H16," ") | M16: =IF(E16="Other Expenses",H16," ")
G17: =IF(F17>0,IF(G$3="X",F17*H$5/100/(1+H$5/100)," ")," ") | H17: =IF(F17>0,IF(G17=" ",F17,F17-G17)," ") | J17: =IF(E17="General Admin",H17," ") | K17: =IF(E17="Hotel & Travel",H17," ") | L17: =IF(E17="Vehicle or Mileage",H17," ") | M17: =IF(E17="Other Expenses",H17," ")
G18: =IF(F18>0,IF(G$3="X",F18*H$5/100/(1+H$5/100)," ")," ") | H18: =IF(F18>0,IF(G18=" ",F18,F18-G18)," ") | J18: =IF(E18="General Admin",H18," ") | K18: =IF(E18="Hotel & Travel",H18," ") | L18: =IF(E18="Vehicle or Mileage",H18," ") | M18: =IF(E18="Other Expenses",H18," ")
G19: =IF(F19>0,IF(G$3="X",F19*H$5/100/(1+H$5/100)," ")," ") | H19: =IF(F19>0,IF(G19=" ",F19,F19-G19)," ") | J19: =IF(E19="General Admin",H19," ") | K19: =IF(E19="Hotel & Travel",H19," ") | L19: =IF(E19="Vehicle or Mileage",H19," ") | M19: =IF(E19="Other Expenses",H19," ")
G20: =IF(F20>0,IF(G$3="X",F20*H$5/100/(1+H$5/100)," ")," ") | H20: =IF(F20>0,IF(G20=" ",F20,F20-G20)," ") | J20: =IF(E20="General Admin",H20," ") | K20: =IF(E20="Hotel & Travel",H20," ") | L20: =IF(E20="Vehicle or Mileage",H20," ") | M20: =IF(E20="Other Expenses",H20," ")
G21: =IF(F21>0,IF(G$3="X",F21*H$5/100/(1+H$5/100)," ")," ") | H21: =IF(F21>0,IF(G21=" ",F21,F21-G21)," ") | J21: =IF(E21="General Admin",H21," ") | K21: =IF(E21="Hotel & Travel",H21," ") | L21: =IF(E21="Vehicle or Mileage",H21," ") | M21: =IF(E21="Other Expenses",H21," ")
... G29: =IF(F29>0,IF(G$3="X",F29*H$5/100/(1+H$5/100)," ")," ") | H29: =IF(F29>0,IF(G29=" ",F29,F29-G29)," ") | J29: =IF(E29="General Admin",H29," ") | K29: =IF(E29="Hotel & Travel",H29," ") | L29: =IF(E29="Vehicle or Mileage",H29," ") | M29: =IF(E29="Other Expenses",H29," ")
B30: ="Mileage Claim @ "&TEXT(C30*100,0)&"p" -> Mileage Claim @ 45p | C30: 0.45 | D30: =SUM(D10:D29) -> 0 | E30: Vehicle or Mileage | F30: =IF(D30>0,D30*C30," ") | H30: =IF(D30>0,F30-G30," ") | J30: =IF(E30="General Admin",H30," ") | K30: =IF(E30="Hotel & Travel",H30," ") | L30: =IF(E30="Vehicle or Mileage",H30," ") | M30: =IF(E30="Other Expenses",H30," ")
F31: =SUM(F10:F30) -> 0 | G31: =SUM(G10:G30) -> 0 | H31: =SUM(H10:H30) -> 0 | J31: =SUM(J10:J30) -> 0 | K31: =SUM(K10:K30) -> 0 | L31: =SUM(L10:L30) -> 0 | M31: =SUM(M10:M30) -> 0
C33: TOTAL AMOUNT PAYABLE | E33: £ | F33: =F31 -> 0
A35: I confirm the amount claimed has been incurred solely on business and does not include travel expenses from
A36: home to normal place of work, personal or third party expenses
A38: Signed | B38: ……………………………………………………………. | D38: Date | E38: …………………………….
A40: Payment Authorised By | C40: ………………………… | D40: Date | E40: …………………………….
A42: OFFICE USE: Accounting Summary | C42: Reference | D42: Exp01 | G42: Entry Code Letter
A44: =IF(G7>0,G7," ") -> 45412 | B44: =IF(B5>0,B5," ") | D44: Total Purchases | F44: =IF(F31>0,F31," ")
D45: Vat Input | F45: =IF(G31>0,G31," ")
D46: Expense analysis
D47: General Admin | F47: =IF(J31>0,J31," ") | G47: G
D48: Hotel & Travel | F48: =IF(K31>0,K31," ") | G48: H
D49: Vehicle or Mileage | F49: =IF(L31>0,L31," ") | G49: V
B50: Manual analysis required of Other Expenses for accounts | D50: Other Expenses | F50: =IF(M31>0,M31," ") | G50: To be allocated manually

Sheet Month 02
A1: EXPENSES CLAIM FORM
A2: Attach all receipts to support the claim for re-imbursement of business expenses incurred
A3: Enter X if vat registered leave blank if not registered or flat rate scheme | G3: x
A5: Name | B5: =IF('Month 01'!B5:D5>0,'Month 01'!B5:D5,"") | F5: Vat rate applied | H5: ='Month 01'!H5 -> 20
A6: Address | B6: =IF('Month 01'!B6:D6>0,'Month 01'!B6:D6,"") | F6: Date From: | G6: =DATE(YEAR('Month 01'!G6),MONTH('Month 01'!G6)+1,1) -> 45413
B7: =IF('Month 01'!B7>0,'Month 01'!B7,"") | C7: Post Code | D7: =IF('Month 01'!D7>0,'Month 01'!D7,"") | F7: Date To: | G7: =DATE(YEAR(G6),MONTH(G6),DAY(DATE(YEAR(G6),MONTH(G6)+1,1)-1)) -> 45443
A9: Date | B9: Description of Expense | C9: Destination and Purpose | D9: Mileage | E9: Expense Type | F9: Total Claimed | G9: Vat | H9: Net Expense | J9: General Admin | K9: Hotel & Travel | L9: Vehicle or Mileage | M9: Other Expenses
G10: =IF(F10>0,IF(G$3="X",F10*H$5/100/(1+H$5/100)," ")," ") | H10: =IF(F10>0,IF(G10=" ",F10,F10-G10)," ") | J10: =IF(E10="General Admin",H10," ") | K10: =IF(E10="Hotel & Travel",H10," ") | L10: =IF(E10="Vehicle or Mileage",H10," ") | M10: =IF(E10="Other Expenses",H10," ")
G11: =IF(F11>0,IF(G$3="X",F11*H$5/100/(1+H$5/100)," ")," ") | H11: =IF(F11>0,IF(G11=" ",F11,F11-G11)," ") | J11: =IF(E11="General Admin",H11," ") | K11: =IF(E11="Hotel & Travel",H11," ") | L11: =IF(E11="Vehicle or Mileage",H11," ") | M11: =IF(E11="Other Expenses",H11," ")
G12: =IF(F12>0,IF(G$3="X",F12*H$5/100/(1+H$5/100)," ")," ") | H12: =IF(F12>0,IF(G12=" ",F12,F12-G12)," ") | J12: =IF(E12="General Admin",H12," ") | K12: =IF(E12="Hotel & Travel",H12," ") | L12: =IF(E12="Vehicle or Mileage",H12," ") | M12: =IF(E12="Other Expenses",H12," ")
G13: =IF(F13>0,IF(G$3="X",F13*H$5/100/(1+H$5/100)," ")," ") | H13: =IF(F13>0,IF(G13=" ",F13,F13-G13)," ") | J13: =IF(E13="General Admin",H13," ") | K13: =IF(E13="Hotel & Travel",H13," ") | L13: =IF(E13="Vehicle or Mileage",H13," ") | M13: =IF(E13="Other Expenses",H13," ")
G14: =IF(F14>0,IF(G$3="X",F14*H$5/100/(1+H$5/100)," ")," ") | H14: =IF(F14>0,IF(G14=" ",F14,F14-G14)," ") | J14: =IF(E14="General Admin",H14," ") | K14: =IF(E14="Hotel & Travel",H14," ") | L14: =IF(E14="Vehicle or Mileage",H14," ") | M14: =IF(E14="Other Expenses",H14," ")
G15: =IF(F15>0,IF(G$3="X",F15*H$5/100/(1+H$5/100)," ")," ") | H15: =IF(F15>0,IF(G15=" ",F15,F15-G15)," ") | J15: =IF(E15="General Admin",H15," ") | K15: =IF(E15="Hotel & Travel",H15," ") | L15: =IF(E15="Vehicle or Mileage",H15," ") | M15: =IF(E15="Other Expenses",H15," ")
G16: =IF(F16>0,IF(G$3="X",F16*H$5/100/(1+H$5/100)," ")," ") | H16: =IF(F16>0,IF(G16=" ",F16,F16-G16)," ") | J16: =IF(E16="General Admin",H16," ") | K16: =IF(E16="Hotel & Travel",H16," ") | L16: =IF(E16="Vehicle or Mileage",H16," ") | M16: =IF(E16="Other Expenses",H16," ")
G17: =IF(F17>0,IF(G$3="X",F17*H$5/100/(1+H$5/100)," ")," ") | H17: =IF(F17>0,IF(G17=" ",F17,F17-G17)," ") | J17: =IF(E17="General Admin",H17," ") | K17: =IF(E17="Hotel & Travel",H17," ") | L17: =IF(E17="Vehicle or Mileage",H17," ") | M17: =IF(E17="Other Expenses",H17," ")
G18: =IF(F18>0,IF(G$3="X",F18*H$5/100/(1+H$5/100)," ")," ") | H18: =IF(F18>0,IF(G18=" ",F18,F18-G18)," ") | J18: =IF(E18="General Admin",H18," ") | K18: =IF(E18="Hotel & Travel",H18," ") | L18: =IF(E18="Vehicle or Mileage",H18," ") | M18: =IF(E18="Other Expenses",H18," ")
G19: =IF(F19>0,IF(G$3="X",F19*H$5/100/(1+H$5/100)," ")," ") | H19: =IF(F19>0,IF(G19=" ",F19,F19-G19)," ") | J19: =IF(E19="General Admin",H19," ") | K19: =IF(E19="Hotel & Travel",H19," ") | L19: =IF(E19="Vehicle or Mileage",H19," ") | M19: =IF(E19="Other Expenses",H19," ")
G20: =IF(F20>0,IF(G$3="X",F20*H$5/100/(1+H$5/100)," ")," ") | H20: =IF(F20>0,IF(G20=" ",F20,F20-G20)," ") | J20: =IF(E20="General Admin",H20," ") | K20: =IF(E20="Hotel & Travel",H20," ") | L20: =IF(E20="Vehicle or Mileage",H20," ") | M20: =IF(E20="Other Expenses",H20," ")
G21: =IF(F21>0,IF(G$3="X",F21*H$5/100/(1+H$5/100)," ")," ") | H21: =IF(F21>0,IF(G21=" ",F21,F21-G21)," ") | J21: =IF(E21="General Admin",H21," ") | K21: =IF(E21="Hotel & Travel",H21," ") | L21: =IF(E21="Vehicle or Mileage",H21," ") | M21: =IF(E21="Other Expenses",H21," ")
... G29: =IF(F29>0,IF(G$3="X",F29*H$5/100/(1+H$5/100)," ")," ") | H29: =IF(F29>0,IF(G29=" ",F29,F29-G29)," ") | J29: =IF(E29="General Admin",H29," ") | K29: =IF(E29="Hotel & Travel",H29," ") | L29: =IF(E29="Vehicle or Mileage",H29," ") | M29: =IF(E29="Other Expenses",H29," ")
B30: ="Mileage Claim @ "&TEXT(C30*100,0)&"p" -> Mileage Claim @ 45p | C30: ='Month 01'!C30 -> 0.45 | D30: =SUM(D10:D29) -> 0 | E30: Vehicle or Mileage | F30: =IF(D30>0,D30*C30," ") | H30: =IF(D30>0,F30-G30," ") | J30: =IF(E30="General Admin",H30," ") | K30: =IF(E30="Hotel & Travel",H30," ") | L30: =IF(E30="Vehicle or Mileage",H30," ") | M30: =IF(E30="Other Expenses",H30," ")
F31: =SUM(F10:F30) -> 0 | G31: =SUM(G10:G30) -> 0 | H31: =SUM(H10:H30) -> 0 | J31: =SUM(J10:J30) -> 0 | K31: =SUM(K10:K30) -> 0 | L31: =SUM(L10:L30) -> 0 | M31: =SUM(M10:M30) -> 0
C33: TOTAL AMOUNT PAYABLE | E33: £ | F33: =F31 -> 0
A35: I confirm the amount claimed has been incurred solely on business and does not include travel expenses from
A36: home to normal place of work, personal or third party expenses
A38: Signed | B38: ……………………………………………………………. | D38: Date | E38: …………………………….
A40: Payment Authorised By | C40: ………………………… | D40: Date | E40: …………………………….
A42: OFFICE USE: Accounting Summary | C42: Reference | D42: Exp01 | G42: Entry Code Letter
A44: =IF(G7>0,G7," ") -> 45443 | B44: =IF(B5>0,B5," ") | D44: Total Purchases | F44: =IF(F31>0,F31," ")
D45: Vat Input | F45: =IF(G31>0,G31," ")
D46: Expense analysis
D47: General Admin | F47: =IF(J31>0,J31," ") | G47: G
D48: Hotel & Travel | F48: =IF(K31>0,K31," ") | G48: H
D49: Vehicle or Mileage | F49: =IF(L31>0,L31," ") | G49: V
B50: Manual analysis required of Other Expenses for accounts | D50: Other Expenses | F50: =IF(M31>0,M31," ") | G50: To be allocated manually

Sheet Month 03
A1: EXPENSES CLAIM FORM
A2: Attach all receipts to support the claim for re-imbursement of business expenses incurred
A3: Enter X if vat registered leave blank if not registered or flat rate scheme | G3: x
A5: Name | B5: =IF('Month 02'!B5:D5>0,'Month 02'!B5:D5,"") | F5: Vat rate applied | H5: ='Month 02'!H5 -> 20
A6: Address | B6: =IF('Month 02'!B6:D6>0,'Month 02'!B6:D6,"") | F6: Date From: | G6: =DATE(YEAR('Month 02'!G6),MONTH('Month 02'!G6)+1,DAY('Month 02'!G6)) -> 45444
B7: =IF('Month 02'!B7>0,'Month 02'!B7,"") | C7: Post Code | D7: =IF('Month 02'!D7>0,'Month 02'!D7,"") | F7: Date To: | G7: =DATE(YEAR(G6),MONTH(G6),DAY(DATE(YEAR(G6),MONTH(G6)+1,1)-1)) -> 45473
A9: Date | B9: Description of Expense | C9: Destination and Purpose | D9: Mileage | E9: Expense Type | F9: Total Claimed | G9: Vat | H9: Net Expense | J9: General Admin | K9: Hotel & Travel | L9: Vehicle or Mileage | M9: Other Expenses
G10: =IF(F10>0,IF(G$3="X",F10*H$5/100/(1+H$5/100)," ")," ") | H10: =IF(F10>0,IF(G10=" ",F10,F10-G10)," ") | J10: =IF(E10="General Admin",H10," ") | K10: =IF(E10="Hotel & Travel",H10," ") | L10: =IF(E10="Vehicle or Mileage",H10," ") | M10: =IF(E10="Other Expenses",H10," ")
G11: =IF(F11>0,IF(G$3="X",F11*H$5/100/(1+H$5/100)," ")," ") | H11: =IF(F11>0,IF(G11=" ",F11,F11-G11)," ") | J11: =IF(E11="General Admin",H11," ") | K11: =IF(E11="Hotel & Travel",H11," ") | L11: =IF(E11="Vehicle or Mileage",H11," ") | M11: =IF(E11="Other Expenses",H11," ")
G12: =IF(F12>0,IF(G$3="X",F12*H$5/100/(1+H$5/100)," ")," ") | H12: =IF(F12>0,IF(G12=" ",F12,F12-G12)," ") | J12: =IF(E12="General Admin",H12," ") | K12: =IF(E12="Hotel & Travel",H12," ") | L12: =IF(E12="Vehicle or Mileage",H12," ") | M12: =IF(E12="Other Expenses",H12," ")
G13: =IF(F13>0,IF(G$3="X",F13*H$5/100/(1+H$5/100)," ")," ") | H13: =IF(F13>0,IF(G13=" ",F13,F13-G13)," ") | J13: =IF(E13="General Admin",H13," ") | K13: =IF(E13="Hotel & Travel",H13," ") | L13: =IF(E13="Vehicle or Mileage",H13," ") | M13: =IF(E13="Other Expenses",H13," ")
G14: =IF(F14>0,IF(G$3="X",F14*H$5/100/(1+H$5/100)," ")," ") | H14: =IF(F14>0,IF(G14=" ",F14,F14-G14)," ") | J14: =IF(E14="General Admin",H14," ") | K14: =IF(E14="Hotel & Travel",H14," ") | L14: =IF(E14="Vehicle or Mileage",H14," ") | M14: =IF(E14="Other Expenses",H14," ")
G15: =IF(F15>0,IF(G$3="X",F15*H$5/100/(1+H$5/100)," ")," ") | H15: =IF(F15>0,IF(G15=" ",F15,F15-G15)," ") | J15: =IF(E15="General Admin",H15," ") | K15: =IF(E15="Hotel & Travel",H15," ") | L15: =IF(E15="Vehicle or Mileage",H15," ") | M15: =IF(E15="Other Expenses",H15," ")
G16: =IF(F16>0,IF(G$3="X",F16*H$5/100/(1+H$5/100)," ")," ") | H16: =IF(F16>0,IF(G16=" ",F16,F16-G16)," ") | J16: =IF(E16="General Admin",H16," ") | K16: =IF(E16="Hotel & Travel",H16," ") | L16: =IF(E16="Vehicle or Mileage",H16," ") | M16: =IF(E16="Other Expenses",H16," ")
G17: =IF(F17>0,IF(G$3="X",F17*H$5/100/(1+H$5/100)," ")," ") | H17: =IF(F17>0,IF(G17=" ",F17,F17-G17)," ") | J17: =IF(E17="General Admin",H17," ") | K17: =IF(E17="Hotel & Travel",H17," ") | L17: =IF(E17="Vehicle or Mileage",H17," ") | M17: =IF(E17="Other Expenses",H17," ")
G18: =IF(F18>0,IF(G$3="X",F18*H$5/100/(1+H$5/100)," ")," ") | H18: =IF(F18>0,IF(G18=" ",F18,F18-G18)," ") | J18: =IF(E18="General Admin",H18," ") | K18: =IF(E18="Hotel & Travel",H18," ") | L18: =IF(E18="Vehicle or Mileage",H18," ") | M18: =IF(E18="Other Expenses",H18," ")
G19: =IF(F19>0,IF(G$3="X",F19*H$5/100/(1+H$5/100)," ")," ") | H19: =IF(F19>0,IF(G19=" ",F19,F19-G19)," ") | J19: =IF(E19="General Admin",H19," ") | K19: =IF(E19="Hotel & Travel",H19," ") | L19: =IF(E19="Vehicle or Mileage",H19," ") | M19: =IF(E19="Other Expenses",H19," ")
G20: =IF(F20>0,IF(G$3="X",F20*H$5/100/(1+H$5/100)," ")," ") | H20: =IF(F20>0,IF(G20=" ",F20,F20-G20)," ") | J20: =IF(E20="General Admin",H20," ") | K20: =IF(E20="Hotel & Travel",H20," ") | L20: =IF(E20="Vehicle or Mileage",H20," ") | M20: =IF(E20="Other Expenses",H20," ")
G21: =IF(F21>0,IF(G$3="X",F21*H$5/100/(1+H$5/100)," ")," ") | H21: =IF(F21>0,IF(G21=" ",F21,F21-G21)," ") | J21: =IF(E21="General Admin",H21," ") | K21: =IF(E21="Hotel & Travel",H21," ") | L21: =IF(E21="Vehicle or Mileage",H21," ") | M21: =IF(E21="Other Expenses",H21," ")
... G29: =IF(F29>0,IF(G$3="X",F29*H$5/100/(1+H$5/100)," ")," ") | H29: =IF(F29>0,IF(G29=" ",F29,F29-G29)," ") | J29: =IF(E29="General Admin",H29," ") | K29: =IF(E29="Hotel & Travel",H29," ") | L29: =IF(E29="Vehicle or Mileage",H29," ") | M29: =IF(E29="Other Expenses",H29," ")
B30: ="Mileage Claim @ "&TEXT(C30*100,0)&"p" -> Mileage Claim @ 45p | C30: ='Month 02'!C30 -> 0.45 | D30: =SUM(D10:D29) -> 0 | E30: Vehicle or Mileage | F30: =IF(D30>0,D30*C30," ") | H30: =IF(D30>0,F30-G30," ") | J30: =IF(E30="General Admin",H30," ") | K30: =IF(E30="Hotel & Travel",H30," ") | L30: =IF(E30="Vehicle or Mileage",H30," ") | M30: =IF(E30="Other Expenses",H30," ")
F31: =SUM(F10:F30) -> 0 | G31: =SUM(G10:G30) -> 0 | H31: =SUM(H10:H30) -> 0 | J31: =SUM(J10:J30) -> 0 | K31: =SUM(K10:K30) -> 0 | L31: =SUM(L10:L30) -> 0 | M31: =SUM(M10:M30) -> 0
C33: TOTAL AMOUNT PAYABLE | E33: £ | F33: =F31 -> 0
A35: I confirm the amount claimed has been incurred solely on business and does not include travel expenses from
A36: home to normal place of work, personal or third party expenses
A38: Signed | B38: ……………………………………………………………. | D38: Date | E38: …………………………….
A40: Payment Authorised By | C40: ………………………… | D40: Date | E40: …………………………….
A42: OFFICE USE: Accounting Summary | C42: Reference | D42: Exp01 | G42: Entry Code Letter
A44: =IF(G7>0,G7," ") -> 45473 | B44: =IF(B5>0,B5," ") | D44: Total Purchases | F44: =IF(F31>0,F31," ")
D45: Vat Input | F45: =IF(G31>0,G31," ")
D46: Expense analysis
D47: General Admin | F47: =IF(J31>0,J31," ") | G47: G
D48: Hotel & Travel | F48: =IF(K31>0,K31," ") | G48: H
D49: Vehicle or Mileage | F49: =IF(L31>0,L31," ") | G49: V
B50: Manual analysis required of Other Expenses for accounts | D50: Other Expenses | F50: =IF(M31>0,M31," ") | G50: To be allocated manually

Sheet Month 04
A1: EXPENSES CLAIM FORM
A2: Attach all receipts to support the claim for re-imbursement of business expenses incurred
A3: Enter X if vat registered leave blank if not registered or flat rate scheme | G3: x
A5: Name | B5: =IF('Month 03'!B5:D5>0,'Month 03'!B5:D5,"") | F5: Vat rate applied | H5: ='Month 03'!H5 -> 20
A6: Address | B6: =IF('Month 03'!B6:D6>0,'Month 03'!B6:D6,"") | F6: Date From: | G6: =DATE(YEAR('Month 03'!G6),MONTH('Month 03'!G6)+1,1) -> 45474
B7: =IF('Month 03'!B7>0,'Month 03'!B7,"") | C7: Post Code | D7: =IF('Month 03'!D7>0,'Month 03'!D7,"") | F7: Date To: | G7: =DATE(YEAR(G6),MONTH(G6),DAY(DATE(YEAR(G6),MONTH(G6)+1,1)-1)) -> 45504
A9: Date | B9: Description of Expense | C9: Destination and Purpose | D9: Mileage | E9: Expense Type | F9: Total Claimed | G9: Vat | H9: Net Expense | J9: General Admin | K9: Hotel & Travel | L9: Vehicle or Mileage | M9: Other Expenses
G10: =IF(F10>0,IF(G$3="X",F10*H$5/100/(1+H$5/100)," ")," ") | H10: =IF(F10>0,IF(G10=" ",F10,F10-G10)," ") | J10: =IF(E10="General Admin",H10," ") | K10: =IF(E10="Hotel & Travel",H10," ") | L10: =IF(E10="Vehicle or Mileage",H10," ") | M10: =IF(E10="Other Expenses",H10," ")
G11: =IF(F11>0,IF(G$3="X",F11*H$5/100/(1+H$5/100)," ")," ") | H11: =IF(F11>0,IF(G11=" ",F11,F11-G11)," ") | J11: =IF(E11="General Admin",H11," ") | K11: =IF(E11="Hotel & Travel",H11," ") | L11: =IF(E11="Vehicle or Mileage",H11," ") | M11: =IF(E11="Other Expenses",H11," ")
G12: =IF(F12>0,IF(G$3="X",F12*H$5/100/(1+H$5/100)," ")," ") | H12: =IF(F12>0,IF(G12=" ",F12,F12-G12)," ") | J12: =IF(E12="General Admin",H12," ") | K12: =IF(E12="Hotel & Travel",H12," ") | L12: =IF(E12="Vehicle or Mileage",H12," ") | M12: =IF(E12="Other Expenses",H12," ")
G13: =IF(F13>0,IF(G$3="X",F13*H$5/100/(1+H$5/100)," ")," ") | H13: =IF(F13>0,IF(G13=" ",F13,F13-G13)," ") | J13: =IF(E13="General Admin",H13," ") | K13: =IF(E13="Hotel & Travel",H13," ") | L13: =IF(E13="Vehicle or Mileage",H13," ") | M13: =IF(E13="Other Expenses",H13," ")
G14: =IF(F14>0,IF(G$3="X",F14*H$5/100/(1+H$5/100)," ")," ") | H14: =IF(F14>0,IF(G14=" ",F14,F14-G14)," ") | J14: =IF(E14="General Admin",H14," ") | K14: =IF(E14="Hotel & Travel",H14," ") | L14: =IF(E14="Vehicle or Mileage",H14," ") | M14: =IF(E14="Other Expenses",H14," ")
G15: =IF(F15>0,IF(G$3="X",F15*H$5/100/(1+H$5/100)," ")," ") | H15: =IF(F15>0,IF(G15=" ",F15,F15-G15)," ") | J15: =IF(E15="General Admin",H15," ") | K15: =IF(E15="Hotel & Travel",H15," ") | L15: =IF(E15="Vehicle or Mileage",H15," ") | M15: =IF(E15="Other Expenses",H15," ")
G16: =IF(F16>0,IF(G$3="X",F16*H$5/100/(1+H$5/100)," ")," ") | H16: =IF(F16>0,IF(G16=" ",F16,F16-G16)," ") | J16: =IF(E16="General Admin",H16," ") | K16: =IF(E16="Hotel & Travel",H16," ") | L16: =IF(E16="Vehicle or Mileage",H16," ") | M16: =IF(E16="Other Expenses",H16," ")
G17: =IF(F17>0,IF(G$3="X",F17*H$5/100/(1+H$5/100)," ")," ") | H17: =IF(F17>0,IF(G17=" ",F17,F17-G17)," ") | J17: =IF(E17="General Admin",H17," ") | K17: =IF(E17="Hotel & Travel",H17," ") | L17: =IF(E17="Vehicle or Mileage",H17," ") | M17: =IF(E17="Other Expenses",H17," ")
G18: =IF(F18>0,IF(G$3="X",F18*H$5/100/(1+H$5/100)," ")," ") | H18: =IF(F18>0,IF(G18=" ",F18,F18-G18)," ") | J18: =IF(E18="General Admin",H18," ") | K18: =IF(E18="Hotel & Travel",H18," ") | L18: =IF(E18="Vehicle or Mileage",H18," ") | M18: =IF(E18="Other Expenses",H18," ")
G19: =IF(F19>0,IF(G$3="X",F19*H$5/100/(1+H$5/100)," ")," ") | H19: =IF(F19>0,IF(G19=" ",F19,F19-G19)," ") | J19: =IF(E19="General Admin",H19," ") | K19: =IF(E19="Hotel & Travel",H19," ") | L19: =IF(E19="Vehicle or Mileage",H19," ") | M19: =IF(E19="Other Expenses",H19," ")
G20: =IF(F20>0,IF(G$3="X",F20*H$5/100/(1+H$5/100)," ")," ") | H20: =IF(F20>0,IF(G20=" ",F20,F20-G20)," ") | J20: =IF(E20="General Admin",H20," ") | K20: =IF(E20="Hotel & Travel",H20," ") | L20: =IF(E20="Vehicle or Mileage",H20," ") | M20: =IF(E20="Other Expenses",H20," ")
G21: =IF(F21>0,IF(G$3="X",F21*H$5/100/(1+H$5/100)," ")," ") | H21: =IF(F21>0,IF(G21=" ",F21,F21-G21)," ") | J21: =IF(E21="General Admin",H21," ") | K21: =IF(E21="Hotel & Travel",H21," ") | L21: =IF(E21="Vehicle or Mileage",H21," ") | M21: =IF(E21="Other Expenses",H21," ")
... G29: =IF(F29>0,IF(G$3="X",F29*H$5/100/(1+H$5/100)," ")," ") | H29: =IF(F29>0,IF(G29=" ",F29,F29-G29)," ") | J29: =IF(E29="General Admin",H29," ") | K29: =IF(E29="Hotel & Travel",H29," ") | L29: =IF(E29="Vehicle or Mileage",H29," ") | M29: =IF(E29="Other Expenses",H29," ")
B30: ="Mileage Claim @ "&TEXT(C30*100,0)&"p" -> Mileage Claim @ 45p | C30: ='Month 03'!C30 -> 0.45 | D30: =SUM(D10:D29) -> 0 | E30: Vehicle or Mileage | F30: =IF(D30>0,D30*C30," ") | H30: =IF(D30>0,F30-G30," ") | J30: =IF(E30="General Admin",H30," ") | K30: =IF(E30="Hotel & Travel",H30," ") | L30: =IF(E30="Vehicle or Mileage",H30," ") | M30: =IF(E30="Other Expenses",H30," ")
F31: =SUM(F10:F30) -> 0 | G31: =SUM(G10:G30) -> 0 | H31: =SUM(H10:H30) -> 0 | J31: =SUM(J10:J30) -> 0 | K31: =SUM(K10:K30) -> 0 | L31: =SUM(L10:L30) -> 0 | M31: =SUM(M10:M30) -> 0
C33: TOTAL AMOUNT PAYABLE | E33: £ | F33: =F31 -> 0
A35: I confirm the amount claimed has been incurred solely on business and does not include travel expenses from
A36: home to normal place of work, personal or third party expenses
A38: Signed | B38: ……………………………………………………………. | D38: Date | E38: …………………………….
A40: Payment Authorised By | C40: ………………………… | D40: Date | E40: …………………………….
A42: OFFICE USE: Accounting Summary | C42: Reference | D42: Exp01 | G42: Entry Code Letter
A44: =IF(G7>0,G7," ") -> 45504 | B44: =IF(B5>0,B5," ") | D44: Total Purchases | F44: =IF(F31>0,F31," ")
D45: Vat Input | F45: =IF(G31>0,G31," ")
D46: Expense analysis
D47: General Admin | F47: =IF(J31>0,J31," ") | G47: G
D48: Hotel & Travel | F48: =IF(K31>0,K31," ") | G48: H
D49: Vehicle or Mileage | F49: =IF(L31>0,L31," ") | G49: V
B50: Manual analysis required of Other Expenses for accounts | D50: Other Expenses | F50: =IF(M31>0,M31," ") | G50: To be allocated manually

Sheet Month 05
A1: EXPENSES CLAIM FORM
A2: Attach all receipts to support the claim for re-imbursement of business expenses incurred
A3: Enter X if vat registered leave blank if not registered or flat rate scheme | G3: x
A5: Name | B5: =IF('Month 04'!B5:D5>0,'Month 04'!B5:D5,"") | F5: Vat rate applied | H5: ='Month 04'!H5 -> 20
A6: Address | B6: =IF('Month 04'!B6:D6>0,'Month 04'!B6:D6,"") | F6: Date From: | G6: =DATE(YEAR('Month 04'!G6),MONTH('Month 04'!G6)+1,1) -> 45505
B7: =IF('Month 04'!B7>0,'Month 04'!B7,"") | C7: Post Code | D7: =IF('Month 04'!D7>0,'Month 04'!D7,"") | F7: Date To: | G7: =DATE(YEAR(G6),MONTH(G6),DAY(DATE(YEAR(G6),MONTH(G6)+1,1)-1)) -> 45535
A9: Date | B9: Description of Expense | C9: Destination and Purpose | D9: Mileage | E9: Expense Type | F9: Total Claimed | G9: Vat | H9: Net Expense | J9: General Admin | K9: Hotel & Travel | L9: Vehicle or Mileage | M9: Other Expenses
G10: =IF(F10>0,IF(G$3="X",F10*H$5/100/(1+H$5/100)," ")," ") | H10: =IF(F10>0,IF(G10=" ",F10,F10-G10)," ") | J10: =IF(E10="General Admin",H10," ") | K10: =IF(E10="Hotel & Travel",H10," ") | L10: =IF(E10="Vehicle or Mileage",H10," ") | M10: =IF(E10="Other Expenses",H10," ")
G11: =IF(F11>0,IF(G$3="X",F11*H$5/100/(1+H$5/100)," ")," ") | H11: =IF(F11>0,IF(G11=" ",F11,F11-G11)," ") | J11: =IF(E11="General Admin",H11," ") | K11: =IF(E11="Hotel & Travel",H11," ") | L11: =IF(E11="Vehicle or Mileage",H11," ") | M11: =IF(E11="Other Expenses",H11," ")
G12: =IF(F12>0,IF(G$3="X",F12*H$5/100/(1+H$5/100)," ")," ") | H12: =IF(F12>0,IF(G12=" ",F12,F12-G12)," ") | J12: =IF(E12="General Admin",H12," ") | K12: =IF(E12="Hotel & Travel",H12," ") | L12: =IF(E12="Vehicle or Mileage",H12," ") | M12: =IF(E12="Other Expenses",H12," ")
G13: =IF(F13>0,IF(G$3="X",F13*H$5/100/(1+H$5/100)," ")," ") | H13: =IF(F13>0,IF(G13=" ",F13,F13-G13)," ") | J13: =IF(E13="General Admin",H13," ") | K13: =IF(E13="Hotel & Travel",H13," ") | L13: =IF(E13="Vehicle or Mileage",H13," ") | M13: =IF(E13="Other Expenses",H13," ")
G14: =IF(F14>0,IF(G$3="X",F14*H$5/100/(1+H$5/100)," ")," ") | H14: =IF(F14>0,IF(G14=" ",F14,F14-G14)," ") | J14: =IF(E14="General Admin",H14," ") | K14: =IF(E14="Hotel & Travel",H14," ") | L14: =IF(E14="Vehicle or Mileage",H14," ") | M14: =IF(E14="Other Expenses",H14," ")
G15: =IF(F15>0,IF(G$3="X",F15*H$5/100/(1+H$5/100)," ")," ") | H15: =IF(F15>0,IF(G15=" ",F15,F15-G15)," ") | J15: =IF(E15="General Admin",H15," ") | K15: =IF(E15="Hotel & Travel",H15," ") | L15: =IF(E15="Vehicle or Mileage",H15," ") | M15: =IF(E15="Other Expenses",H15," ")
G16: =IF(F16>0,IF(G$3="X",F16*H$5/100/(1+H$5/100)," ")," ") | H16: =IF(F16>0,IF(G16=" ",F16,F16-G16)," ") | J16: =IF(E16="General Admin",H16," ") | K16: =IF(E16="Hotel & Travel",H16," ") | L16: =IF(E16="Vehicle or Mileage",H16," ") | M16: =IF(E16="Other Expenses",H16," ")
G17: =IF(F17>0,IF(G$3="X",F17*H$5/100/(1+H$5/100)," ")," ") | H17: =IF(F17>0,IF(G17=" ",F17,F17-G17)," ") | J17: =IF(E17="General Admin",H17," ") | K17: =IF(E17="Hotel & Travel",H17," ") | L17: =IF(E17="Vehicle or Mileage",H17," ") | M17: =IF(E17="Other Expenses",H17," ")
G18: =IF(F18>0,IF(G$3="X",F18*H$5/100/(1+H$5/100)," ")," ") | H18: =IF(F18>0,IF(G18=" ",F18,F18-G18)," ") | J18: =IF(E18="General Admin",H18," ") | K18: =IF(E18="Hotel & Travel",H18," ") | L18: =IF(E18="Vehicle or Mileage",H18," ") | M18: =IF(E18="Other Expenses",H18," ")
G19: =IF(F19>0,IF(G$3="X",F19*H$5/100/(1+H$5/100)," ")," ") | H19: =IF(F19>0,IF(G19=" ",F19,F19-G19)," ") | J19: =IF(E19="General Admin",H19," ") | K19: =IF(E19="Hotel & Travel",H19," ") | L19: =IF(E19="Vehicle or Mileage",H19," ") | M19: =IF(E19="Other Expenses",H19," ")
G20: =IF(F20>0,IF(G$3="X",F20*H$5/100/(1+H$5/100)," ")," ") | H20: =IF(F20>0,IF(G20=" ",F20,F20-G20)," ") | J20: =IF(E20="General Admin",H20," ") | K20: =IF(E20="Hotel & Travel",H20," ") | L20: =IF(E20="Vehicle or Mileage",H20," ") | M20: =IF(E20="Other Expenses",H20," ")
G21: =IF(F21>0,IF(G$3="X",F21*H$5/100/(1+H$5/100)," ")," ") | H21: =IF(F21>0,IF(G21=" ",F21,F21-G21)," ") | J21: =IF(E21="General Admin",H21," ") | K21: =IF(E21="Hotel & Travel",H21," ") | L21: =IF(E21="Vehicle or Mileage",H21," ") | M21: =IF(E21="Other Expenses",H21," ")
... G29: =IF(F29>0,IF(G$3="X",F29*H$5/100/(1+H$5/100)," ")," ") | H29: =IF(F29>0,IF(G29=" ",F29,F29-G29)," ") | J29: =IF(E29="General Admin",H29," ") | K29: =IF(E29="Hotel & Travel",H29," ") | L29: =IF(E29="Vehicle or Mileage",H29," ") | M29: =IF(E29="Other Expenses",H29," ")
B30: ="Mileage Claim @ "&TEXT(C30*100,0)&"p" -> Mileage Claim @ 45p | C30: ='Month 04'!C30 -> 0.45 | D30: =SUM(D10:D29) -> 0 | E30: Vehicle or Mileage | F30: =IF(D30>0,D30*C30," ") | H30: =IF(D30>0,F30-G30," ") | J30: =IF(E30="General Admin",H30," ") | K30: =IF(E30="Hotel & Travel",H30," ") | L30: =IF(E30="Vehicle or Mileage",H30," ") | M30: =IF(E30="Other Expenses",H30," ")
F31: =SUM(F10:F30) -> 0 | G31: =SUM(G10:G30) -> 0 | H31: =SUM(H10:H30) -> 0 | J31: =SUM(J10:J30) -> 0 | K31: =SUM(K10:K30) -> 0 | L31: =SUM(L10:L30) -> 0 | M31: =SUM(M10:M30) -> 0
C33: TOTAL AMOUNT PAYABLE | E33: £ | F33: =F31 -> 0
A35: I confirm the amount claimed has been incurred solely on business and does not include travel expenses from
A36: home to normal place of work, personal or third party expenses
A38: Signed | B38: ……………………………………………………………. | D38: Date | E38: …………………………….
A40: Payment Authorised By | C40: ………………………… | D40: Date | E40: …………………………….
A42: OFFICE USE: Accounting Summary | C42: Reference | D42: Exp01 | G42: Entry Code Letter
A44: =IF(G7>0,G7," ") -> 45535 | B44: =IF(B5>0,B5," ") | D44: Total Purchases | F44: =IF(F31>0,F31," ")
D45: Vat Input | F45: =IF(G31>0,G31," ")
D46: Expense analysis
D47: General Admin | F47: =IF(J31>0,J31," ") | G47: G
D48: Hotel & Travel | F48: =IF(K31>0,K31," ") | G48: H
D49: Vehicle or Mileage | F49: =IF(L31>0,L31," ") | G49: V
B50: Manual analysis required of Other Expenses for accounts | D50: Other Expenses | F50: =IF(M31>0,M31," ") | G50: To be allocated manually

Sheet Month 06
A1: EXPENSES CLAIM FORM
A2: Attach all receipts to support the claim for re-imbursement of business expenses incurred
A3: Enter X if vat registered leave blank if not registered or flat rate scheme | G3: x
A5: Name | B5: =IF('Month 05'!B5:D5>0,'Month 05'!B5:D5,"") | F5: Vat rate applied | H5: ='Month 05'!H5 -> 20
A6: Address | B6: =IF('Month 05'!B6:D6>0,'Month 05'!B6:D6,"") | F6: Date From: | G6: =DATE(YEAR('Month 05'!G6),MONTH('Month 05'!G6)+1,1) -> 45536
B7: =IF('Month 05'!B7>0,'Month 05'!B7,"") | C7: Post Code | D7: =IF('Month 05'!D7>0,'Month 05'!D7,"") | F7: Date To: | G7: =DATE(YEAR(G6),MONTH(G6),DAY(DATE(YEAR(G6),MONTH(G6)+1,1)-1)) -> 45565
A9: Date | B9: Description of Expense | C9: Destination and Purpose | D9: Mileage | E9: Expense Type | F9: Total Claimed | G9: Vat | H9: Net Expense | J9: General Admin | K9: Hotel & Travel | L9: Vehicle or Mileage | M9: Other Expenses
G10: =IF(F10>0,IF(G$3="X",F10*H$5/100/(1+H$5/100)," ")," ") | H10: =IF(F10>0,IF(G10=" ",F10,F10-G10)," ") | J10: =IF(E10="General Admin",H10," ") | K10: =IF(E10="Hotel & Travel",H10," ") | L10: =IF(E10="Vehicle or Mileage",H10," ") | M10: =IF(E10="Other Expenses",H10," ")
G11: =IF(F11>0,IF(G$3="X",F11*H$5/100/(1+H$5/100)," ")," ") | H11: =IF(F11>0,IF(G11=" ",F11,F11-G11)," ") | J11: =IF(E11="General Admin",H11," ") | K11: =IF(E11="Hotel & Travel",H11," ") | L11: =IF(E11="Vehicle or Mileage",H11," ") | M11: =IF(E11="Other Expenses",H11," ")
G12: =IF(F12>0,IF(G$3="X",F12*H$5/100/(1+H$5/100)," ")," ") | H12: =IF(F12>0,IF(G12=" ",F12,F12-G12)," ") | J12: =IF(E12="General Admin",H12," ") | K12: =IF(E12="Hotel & Travel",H12," ") | L12: =IF(E12="Vehicle or Mileage",H12," ") | M12: =IF(E12="Other Expenses",H12," ")
G13: =IF(F13>0,IF(G$3="X",F13*H$5/100/(1+H$5/100)," ")," ") | H13: =IF(F13>0,IF(G13=" ",F13,F13-G13)," ") | J13: =IF(E13="General Admin",H13," ") | K13: =IF(E13="Hotel & Travel",H13," ") | L13: =IF(E13="Vehicle or Mileage",H13," ") | M13: =IF(E13="Other Expenses",H13," ")
G14: =IF(F14>0,IF(G$3="X",F14*H$5/100/(1+H$5/100)," ")," ") | H14: =IF(F14>0,IF(G14=" ",F14,F14-G14)," ") | J14: =IF(E14="General Admin",H14," ") | K14: =IF(E14="Hotel & Travel",H14," ") | L14: =IF(E14="Vehicle or Mileage",H14," ") | M14: =IF(E14="Other Expenses",H14," ")
G15: =IF(F15>0,IF(G$3="X",F15*H$5/100/(1+H$5/100)," ")," ") | H15: =IF(F15>0,IF(G15=" ",F15,F15-G15)," ") | J15: =IF(E15="General Admin",H15," ") | K15: =IF(E15="Hotel & Travel",H15," ") | L15: =IF(E15="Vehicle or Mileage",H15," ") | M15: =IF(E15="Other Expenses",H15," ")
G16: =IF(F16>0,IF(G$3="X",F16*H$5/100/(1+H$5/100)," ")," ") | H16: =IF(F16>0,IF(G16=" ",F16,F16-G16)," ") | J16: =IF(E16="General Admin",H16," ") | K16: =IF(E16="Hotel & Travel",H16," ") | L16: =IF(E16="Vehicle or Mileage",H16," ") | M16: =IF(E16="Other Expenses",H16," ")
G17: =IF(F17>0,IF(G$3="X",F17*H$5/100/(1+H$5/100)," ")," ") | H17: =IF(F17>0,IF(G17=" ",F17,F17-G17)," ") | J17: =IF(E17="General Admin",H17," ") | K17: =IF(E17="Hotel & Travel",H17," ") | L17: =IF(E17="Vehicle or Mileage",H17," ") | M17: =IF(E17="Other Expenses",H17," ")
G18: =IF(F18>0,IF(G$3="X",F18*H$5/100/(1+H$5/100)," ")," ") | H18: =IF(F18>0,IF(G18=" ",F18,F18-G18)," ") | J18: =IF(E18="General Admin",H18," ") | K18: =IF(E18="Hotel & Travel",H18," ") | L18: =IF(E18="Vehicle or Mileage",H18," ") | M18: =IF(E18="Other Expenses",H18," ")
G19: =IF(F19>0,IF(G$3="X",F19*H$5/100/(1+H$5/100)," ")," ") | H19: =IF(F19>0,IF(G19=" ",F19,F19-G19)," ") | J19: =IF(E19="General Admin",H19," ") | K19: =IF(E19="Hotel & Travel",H19," ") | L19: =IF(E19="Vehicle or Mileage",H19," ") | M19: =IF(E19="Other Expenses",H19," ")
G20: =IF(F20>0,IF(G$3="X",F20*H$5/100/(1+H$5/100)," ")," ") | H20: =IF(F20>0,IF(G20=" ",F20,F20-G20)," ") | J20: =IF(E20="General Admin",H20," ") | K20: =IF(E20="Hotel & Travel",H20," ") | L20: =IF(E20="Vehicle or Mileage",H20," ") | M20: =IF(E20="Other Expenses",H20," ")
G21: =IF(F21>0,IF(G$3="X",F21*H$5/100/(1+H$5/100)," ")," ") | H21: =IF(F21>0,IF(G21=" ",F21,F21-G21)," ") | J21: =IF(E21="General Admin",H21," ") | K21: =IF(E21="Hotel & Travel",H21," ") | L21: =IF(E21="Vehicle or Mileage",H21," ") | M21: =IF(E21="Other Expenses",H21," ")
... G29: =IF(F29>0,IF(G$3="X",F29*H$5/100/(1+H$5/100)," ")," ") | H29: =IF(F29>0,IF(G29=" ",F29,F29-G29)," ") | J29: =IF(E29="General Admin",H29," ") | K29: =IF(E29="Hotel & Travel",H29," ") | L29: =IF(E29="Vehicle or Mileage",H29," ") | M29: =IF(E29="Other Expenses",H29," ")
B30: ="Mileage Claim @ "&TEXT(C30*100,0)&"p" -> Mileage Claim @ 45p | C30: ='Month 05'!C30 -> 0.45 | D30: =SUM(D10:D29) -> 0 | E30: Vehicle or Mileage | F30: =IF(D30>0,D30*C30," ") | H30: =IF(D30>0,F30-G30," ") | J30: =IF(E30="General Admin",H30," ") | K30: =IF(E30="Hotel & Travel",H30," ") | L30: =IF(E30="Vehicle or Mileage",H30," ") | M30: =IF(E30="Other Expenses",H30," ")
F31: =SUM(F10:F30) -> 0 | G31: =SUM(G10:G30) -> 0 | H31: =SUM(H10:H30) -> 0 | J31: =SUM(J10:J30) -> 0 | K31: =SUM(K10:K30) -> 0 | L31: =SUM(L10:L30) -> 0 | M31: =SUM(M10:M30) -> 0
C33: TOTAL AMOUNT PAYABLE | E33: £ | F33: =F31 -> 0
A35: I confirm the amount claimed has been incurred solely on business and does not include travel expenses from
A36: home to normal place of work, personal or third party expenses
A38: Signed | B38: ……………………………………………………………. | D38: Date | E38: …………………………….
A40: Payment Authorised By | C40: ………………………… | D40: Date | E40: …………………………….
A42: OFFICE USE: Accounting Summary | C42: Reference | D42: Exp01 | G42: Entry Code Letter
A44: =IF(G7>0,G7," ") -> 45565 | B44: =IF(B5>0,B5," ") | D44: Total Purchases | F44: =IF(F31>0,F31," ")
D45: Vat Input | F45: =IF(G31>0,G31," ")
D46: Expense analysis
D47: General Admin | F47: =IF(J31>0,J31," ") | G47: G
D48: Hotel & Travel | F48: =IF(K31>0,K31," ") | G48: H
D49: Vehicle or Mileage | F49: =IF(L31>0,L31," ") | G49: V
B50: Manual analysis required of Other Expenses for accounts | D50: Other Expenses | F50: =IF(M31>0,M31," ") | G50: To be allocated manually

Sheet Month 07
A1: EXPENSES CLAIM FORM
A2: Attach all receipts to support the claim for re-imbursement of business expenses incurred
A3: Enter X if vat registered leave blank if not registered or flat rate scheme | G3: x
A5: Name | B5: =IF('Month 06'!B5:D5>0,'Month 06'!B5:D5,"") | F5: Vat rate applied | H5: ='Month 06'!H5 -> 20
A6: Address | B6: =IF('Month 06'!B6:D6>0,'Month 06'!B6:D6,"") | F6: Date From: | G6: =DATE(YEAR('Month 06'!G6),MONTH('Month 06'!G6)+1,1) -> 45566
B7: =IF('Month 06'!B7>0,'Month 06'!B7,"") | C7: Post Code | D7: =IF('Month 06'!D7>0,'Month 06'!D7,"") | F7: Date To: | G7: =DATE(YEAR(G6),MONTH(G6),DAY(DATE(YEAR(G6),MONTH(G6)+1,1)-1)) -> 45596
A9: Date | B9: Description of Expense | C9: Destination and Purpose | D9: Mileage | E9: Expense Type | F9: Total Claimed | G9: Vat | H9: Net Expense | J9: General Admin | K9: Hotel & Travel | L9: Vehicle or Mileage | M9: Other Expenses
G10: =IF(F10>0,IF(G$3="X",F10*H$5/100/(1+H$5/100)," ")," ") | H10: =IF(F10>0,IF(G10=" ",F10,F10-G10)," ") | J10: =IF(E10="General Admin",H10," ") | K10: =IF(E10="Hotel & Travel",H10," ") | L10: =IF(E10="Vehicle or Mileage",H10," ") | M10: =IF(E10="Other Expenses",H10," ")
G11: =IF(F11>0,IF(G$3="X",F11*H$5/100/(1+H$5/100)," ")," ") | H11: =IF(F11>0,IF(G11=" ",F11,F11-G11)," ") | J11: =IF(E11="General Admin",H11," ") | K11: =IF(E11="Hotel & Travel",H11," ") | L11: =IF(E11="Vehicle or Mileage",H11," ") | M11: =IF(E11="Other Expenses",H11," ")
G12: =IF(F12>0,IF(G$3="X",F12*H$5/100/(1+H$5/100)," ")," ") | H12: =IF(F12>0,IF(G12=" ",F12,F12-G12)," ") | J12: =IF(E12="General Admin",H12," ") | K12: =IF(E12="Hotel & Travel",H12," ") | L12: =IF(E12="Vehicle or Mileage",H12," ") | M12: =IF(E12="Other Expenses",H12," ")
G13: =IF(F13>0,IF(G$3="X",F13*H$5/100/(1+H$5/100)," ")," ") | H13: =IF(F13>0,IF(G13=" ",F13,F13-G13)," ") | J13: =IF(E13="General Admin",H13," ") | K13: =IF(E13="Hotel & Travel",H13," ") | L13: =IF(E13="Vehicle or Mileage",H13," ") | M13: =IF(E13="Other Expenses",H13," ")
G14: =IF(F14>0,IF(G$3="X",F14*H$5/100/(1+H$5/100)," ")," ") | H14: =IF(F14>0,IF(G14=" ",F14,F14-G14)," ") | J14: =IF(E14="General Admin",H14," ") | K14: =IF(E14="Hotel & Travel",H14," ") | L14: =IF(E14="Vehicle or Mileage",H14," ") | M14: =IF(E14="Other Expenses",H14," ")
G15: =IF(F15>0,IF(G$3="X",F15*H$5/100/(1+H$5/100)," ")," ") | H15: =IF(F15>0,IF(G15=" ",F15,F15-G15)," ") | J15: =IF(E15="General Admin",H15," ") | K15: =IF(E15="Hotel & Travel",H15," ") | L15: =IF(E15="Vehicle or Mileage",H15," ") | M15: =IF(E15="Other Expenses",H15," ")
G16: =IF(F16>0,IF(G$3="X",F16*H$5/100/(1+H$5/100)," ")," ") | H16: =IF(F16>0,IF(G16=" ",F16,F16-G16)," ") | J16: =IF(E16="General Admin",H16," ") | K16: =IF(E16="Hotel & Travel",H16," ") | L16: =IF(E16="Vehicle or Mileage",H16," ") | M16: =IF(E16="Other Expenses",H16," ")
G17: =IF(F17>0,IF(G$3="X",F17*H$5/100/(1+H$5/100)," ")," ") | H17: =IF(F17>0,IF(G17=" ",F17,F17-G17)," ") | J17: =IF(E17="General Admin",H17," ") | K17: =IF(E17="Hotel & Travel",H17," ") | L17: =IF(E17="Vehicle or Mileage",H17," ") | M17: =IF(E17="Other Expenses",H17," ")
G18: =IF(F18>0,IF(G$3="X",F18*H$5/100/(1+H$5/100)," ")," ") | H18: =IF(F18>0,IF(G18=" ",F18,F18-G18)," ") | J18: =IF(E18="General Admin",H18," ") | K18: =IF(E18="Hotel & Travel",H18," ") | L18: =IF(E18="Vehicle or Mileage",H18," ") | M18: =IF(E18="Other Expenses",H18," ")
G19: =IF(F19>0,IF(G$3="X",F19*H$5/100/(1+H$5/100)," ")," ") | H19: =IF(F19>0,IF(G19=" ",F19,F19-G19)," ") | J19: =IF(E19="General Admin",H19," ") | K19: =IF(E19="Hotel & Travel",H19," ") | L19: =IF(E19="Vehicle or Mileage",H19," ") | M19: =IF(E19="Other Expenses",H19," ")
G20: =IF(F20>0,IF(G$3="X",F20*H$5/100/(1+H$5/100)," ")," ") | H20: =IF(F20>0,IF(G20=" ",F20,F20-G20)," ") | J20: =IF(E20="General Admin",H20," ") | K20: =IF(E20="Hotel & Travel",H20," ") | L20: =IF(E20="Vehicle or Mileage",H20," ") | M20: =IF(E20="Other Expenses",H20," ")
G21: =IF(F21>0,IF(G$3="X",F21*H$5/100/(1+H$5/100)," ")," ") | H21: =IF(F21>0,IF(G21=" ",F21,F21-G21)," ") | J21: =IF(E21="General Admin",H21," ") | K21: =IF(E21="Hotel & Travel",H21," ") | L21: =IF(E21="Vehicle or Mileage",H21," ") | M21: =IF(E21="Other Expenses",H21," ")
... G29: =IF(F29>0,IF(G$3="X",F29*H$5/100/(1+H$5/100)," ")," ") | H29: =IF(F29>0,IF(G29=" ",F29,F29-G29)," ") | J29: =IF(E29="General Admin",H29," ") | K29: =IF(E29="Hotel & Travel",H29," ") | L29: =IF(E29="Vehicle or Mileage",H29," ") | M29: =IF(E29="Other Expenses",H29," ")
B30: ="Mileage Claim @ "&TEXT(C30*100,0)&"p" -> Mileage Claim @ 45p | C30: ='Month 06'!C30 -> 0.45 | D30: =SUM(D10:D29) -> 0 | E30: Vehicle or Mileage | F30: =IF(D30>0,D30*C30," ") | H30: =IF(D30>0,F30-G30," ") | J30: =IF(E30="General Admin",H30," ") | K30: =IF(E30="Hotel & Travel",H30," ") | L30: =IF(E30="Vehicle or Mileage",H30," ") | M30: =IF(E30="Other Expenses",H30," ")
F31: =SUM(F10:F30) -> 0 | G31: =SUM(G10:G30) -> 0 | H31: =SUM(H10:H30) -> 0 | J31: =SUM(J10:J30) -> 0 | K31: =SUM(K10:K30) -> 0 | L31: =SUM(L10:L30) -> 0 | M31: =SUM(M10:M30) -> 0
C33: TOTAL AMOUNT PAYABLE | E33: £ | F33: =F31 -> 0
A35: I confirm the amount claimed has been incurred solely on business and does not include travel expenses from
A36: home to normal place of work, personal or third party expenses
A38: Signed | B38: ……………………………………………………………. | D38: Date | E38: …………………………….
A40: Payment Authorised By | C40: ………………………… | D40: Date | E40: …………………………….
A42: OFFICE USE: Accounting Summary | C42: Reference | D42: Exp01 | G42: Entry Code Letter
A44: =IF(G7>0,G7," ") -> 45596 | B44: =IF(B5>0,B5," ") | D44: Total Purchases | F44: =IF(F31>0,F31," ")
D45: Vat Input | F45: =IF(G31>0,G31," ")
D46: Expense analysis
D47: General Admin | F47: =IF(J31>0,J31," ") | G47: G
D48: Hotel & Travel | F48: =IF(K31>0,K31," ") | G48: H
D49: Vehicle or Mileage | F49: =IF(L31>0,L31," ") | G49: V
B50: Manual analysis required of Other Expenses for accounts | D50: Other Expenses | F50: =IF(M31>0,M31," ") | G50: To be allocated manually

Sheet Month 08
A1: EXPENSES CLAIM FORM
A2: Attach all receipts to support the claim for re-imbursement of business expenses incurred
A3: Enter X if vat registered leave blank if not registered or flat rate scheme | G3: x
A5: Name | B5: =IF('Month 07'!B5:D5>0,'Month 07'!B5:D5,"") | F5: Vat rate applied | H5: ='Month 07'!H5 -> 20
A6: Address | B6: =IF('Month 07'!B6:D6>0,'Month 07'!B6:D6,"") | F6: Date From: | G6: =DATE(YEAR('Month 07'!G6),MONTH('Month 07'!G6)+1,1) -> 45597
B7: =IF('Month 07'!B7>0,'Month 07'!B7,"") | C7: Post Code | D7: =IF('Month 07'!D7>0,'Month 07'!D7,"") | F7: Date To: | G7: =DATE(YEAR(G6),MONTH(G6),DAY(DATE(YEAR(G6),MONTH(G6)+1,1)-1)) -> 45626
A9: Date | B9: Description of Expense | C9: Destination and Purpose | D9: Mileage | E9: Expense Type | F9: Total Claimed | G9: Vat | H9: Net Expense | J9: General Admin | K9: Hotel & Travel | L9: Vehicle or Mileage | M9: Other Expenses
G10: =IF(F10>0,IF(G$3="X",F10*H$5/100/(1+H$5/100)," ")," ") | H10: =IF(F10>0,IF(G10=" ",F10,F10-G10)," ") | J10: =IF(E10="General Admin",H10," ") | K10: =IF(E10="Hotel & Travel",H10," ") | L10: =IF(E10="Vehicle or Mileage",H10," ") | M10: =IF(E10="Other Expenses",H10," ")
G11: =IF(F11>0,IF(G$3="X",F11*H$5/100/(1+H$5/100)," ")," ") | H11: =IF(F11>0,IF(G11=" ",F11,F11-G11)," ") | J11: =IF(E11="General Admin",H11," ") | K11: =IF(E11="Hotel & Travel",H11," ") | L11: =IF(E11="Vehicle or Mileage",H11," ") | M11: =IF(E11="Other Expenses",H11," ")
G12: =IF(F12>0,IF(G$3="X",F12*H$5/100/(1+H$5/100)," ")," ") | H12: =IF(F12>0,IF(G12=" ",F12,F12-G12)," ") | J12: =IF(E12="General Admin",H12," ") | K12: =IF(E12="Hotel & Travel",H12," ") | L12: =IF(E12="Vehicle or Mileage",H12," ") | M12: =IF(E12="Other Expenses",H12," ")
G13: =IF(F13>0,IF(G$3="X",F13*H$5/100/(1+H$5/100)," ")," ") | H13: =IF(F13>0,IF(G13=" ",F13,F13-G13)," ") | J13: =IF(E13="General Admin",H13," ") | K13: =IF(E13="Hotel & Travel",H13," ") | L13: =IF(E13="Vehicle or Mileage",H13," ") | M13: =IF(E13="Other Expenses",H13," ")
G14: =IF(F14>0,IF(G$3="X",F14*H$5/100/(1+H$5/100)," ")," ") | H14: =IF(F14>0,IF(G14=" ",F14,F14-G14)," ") | J14: =IF(E14="General Admin",H14," ") | K14: =IF(E14="Hotel & Travel",H14," ") | L14: =IF(E14="Vehicle or Mileage",H14," ") | M14: =IF(E14="Other Expenses",H14," ")
G15: =IF(F15>0,IF(G$3="X",F15*H$5/100/(1+H$5/100)," ")," ") | H15: =IF(F15>0,IF(G15=" ",F15,F15-G15)," ") | J15: =IF(E15="General Admin",H15," ") | K15: =IF(E15="Hotel & Travel",H15," ") | L15: =IF(E15="Vehicle or Mileage",H15," ") | M15: =IF(E15="Other Expenses",H15," ")
G16: =IF(F16>0,IF(G$3="X",F16*H$5/100/(1+H$5/100)," ")," ") | H16: =IF(F16>0,IF(G16=" ",F16,F16-G16)," ") | J16: =IF(E16="General Admin",H16," ") | K16: =IF(E16="Hotel & Travel",H16," ") | L16: =IF(E16="Vehicle or Mileage",H16," ") | M16: =IF(E16="Other Expenses",H16," ")
G17: =IF(F17>0,IF(G$3="X",F17*H$5/100/(1+H$5/100)," ")," ") | H17: =IF(F17>0,IF(G17=" ",F17,F17-G17)," ") | J17: =IF(E17="General Admin",H17," ") | K17: =IF(E17="Hotel & Travel",H17," ") | L17: =IF(E17="Vehicle or Mileage",H17," ") | M17: =IF(E17="Other Expenses",H17," ")
G18: =IF(F18>0,IF(G$3="X",F18*H$5/100/(1+H$5/100)," ")," ") | H18: =IF(F18>0,IF(G18=" ",F18,F18-G18)," ") | J18: =IF(E18="General Admin",H18," ") | K18: =IF(E18="Hotel & Travel",H18," ") | L18: =IF(E18="Vehicle or Mileage",H18," ") | M18: =IF(E18="Other Expenses",H18," ")
G19: =IF(F19>0,IF(G$3="X",F19*H$5/100/(1+H$5/100)," ")," ") | H19: =IF(F19>0,IF(G19=" ",F19,F19-G19)," ") | J19: =IF(E19="General Admin",H19," ") | K19: =IF(E19="Hotel & Travel",H19," ") | L19: =IF(E19="Vehicle or Mileage",H19," ") | M19: =IF(E19="Other Expenses",H19," ")
G20: =IF(F20>0,IF(G$3="X",F20*H$5/100/(1+H$5/100)," ")," ") | H20: =IF(F20>0,IF(G20=" ",F20,F20-G20)," ") | J20: =IF(E20="General Admin",H20," ") | K20: =IF(E20="Hotel & Travel",H20," ") | L20: =IF(E20="Vehicle or Mileage",H20," ") | M20: =IF(E20="Other Expenses",H20," ")
G21: =IF(F21>0,IF(G$3="X",F21*H$5/100/(1+H$5/100)," ")," ") | H21: =IF(F21>0,IF(G21=" ",F21,F21-G21)," ") | J21: =IF(E21="General Admin",H21," ") | K21: =IF(E21="Hotel & Travel",H21," ") | L21: =IF(E21="Vehicle or Mileage",H21," ") | M21: =IF(E21="Other Expenses",H21," ")
... G29: =IF(F29>0,IF(G$3="X",F29*H$5/100/(1+H$5/100)," ")," ") | H29: =IF(F29>0,IF(G29=" ",F29,F29-G29)," ") | J29: =IF(E29="General Admin",H29," ") | K29: =IF(E29="Hotel & Travel",H29," ") | L29: =IF(E29="Vehicle or Mileage",H29," ") | M29: =IF(E29="Other Expenses",H29," ")
B30: ="Mileage Claim @ "&TEXT(C30*100,0)&"p" -> Mileage Claim @ 45p | C30: ='Month 07'!C30 -> 0.45 | D30: =SUM(D10:D29) -> 0 | E30: Vehicle or Mileage | F30: =IF(D30>0,D30*C30," ") | H30: =IF(D30>0,F30-G30," ") | J30: =IF(E30="General Admin",H30," ") | K30: =IF(E30="Hotel & Travel",H30," ") | L30: =IF(E30="Vehicle or Mileage",H30," ") | M30: =IF(E30="Other Expenses",H30," ")
F31: =SUM(F10:F30) -> 0 | G31: =SUM(G10:G30) -> 0 | H31: =SUM(H10:H30) -> 0 | J31: =SUM(J10:J30) -> 0 | K31: =SUM(K10:K30) -> 0 | L31: =SUM(L10:L30) -> 0 | M31: =SUM(M10:M30) -> 0
C33: TOTAL AMOUNT PAYABLE | E33: £ | F33: =F31 -> 0
A35: I confirm the amount claimed has been incurred solely on business and does not include travel expenses from
A36: home to normal place of work, personal or third party expenses
A38: Signed | B38: ……………………………………………………………. | D38: Date | E38: …………………………….
A40: Payment Authorised By | C40: ………………………… | D40: Date | E40: …………………………….
A42: OFFICE USE: Accounting Summary | C42: Reference | D42: Exp01 | G42: Entry Code Letter
A44: =IF(G7>0,G7," ") -> 45626 | B44: =IF(B5>0,B5," ") | D44: Total Purchases | F44: =IF(F31>0,F31," ")
D45: Vat Input | F45: =IF(G31>0,G31," ")
D46: Expense analysis
D47: General Admin | F47: =IF(J31>0,J31," ") | G47: G
D48: Hotel & Travel | F48: =IF(K31>0,K31," ") | G48: H
D49: Vehicle or Mileage | F49: =IF(L31>0,L31," ") | G49: V
B50: Manual analysis required of Other Expenses for accounts | D50: Other Expenses | F50: =IF(M31>0,M31," ") | G50: To be allocated manually

Sheet Month 09
A1: EXPENSES CLAIM FORM
A2: Attach all receipts to support the claim for re-imbursement of business expenses incurred
A3: Enter X if vat registered leave blank if not registered or flat rate scheme | G3: x
A5: Name | B5: =IF('Month 08'!B5:D5>0,'Month 08'!B5:D5,"") | F5: Vat rate applied | H5: ='Month 08'!H5 -> 20
A6: Address | B6: =IF('Month 08'!B6:D6>0,'Month 08'!B6:D6,"") | F6: Date From: | G6: =DATE(YEAR('Month 08'!G6),MONTH('Month 08'!G6)+1,1) -> 45627
B7: =IF('Month 08'!B7>0,'Month 08'!B7,"") | C7: Post Code | D7: =IF('Month 08'!D7>0,'Month 08'!D7,"") | F7: Date To: | G7: =DATE(YEAR(G6),MONTH(G6),DAY(DATE(YEAR(G6),MONTH(G6)+1,1)-1)) -> 45657
A9: Date | B9: Description of Expense | C9: Destination and Purpose | D9: Mileage | E9: Expense Type | F9: Total Claimed | G9: Vat | H9: Net Expense | J9: General Admin | K9: Hotel & Travel | L9: Vehicle or Mileage | M9: Other Expenses
G10: =IF(F10>0,IF(G$3="X",F10*H$5/100/(1+H$5/100)," ")," ") | H10: =IF(F10>0,IF(G10=" ",F10,F10-G10)," ") | J10: =IF(E10="General Admin",H10," ") | K10: =IF(E10="Hotel & Travel",H10," ") | L10: =IF(E10="Vehicle or Mileage",H10," ") | M10: =IF(E10="Other Expenses",H10," ")
G11: =IF(F11>0,IF(G$3="X",F11*H$5/100/(1+H$5/100)," ")," ") | H11: =IF(F11>0,IF(G11=" ",F11,F11-G11)," ") | J11: =IF(E11="General Admin",H11," ") | K11: =IF(E11="Hotel & Travel",H11," ") | L11: =IF(E11="Vehicle or Mileage",H11," ") | M11: =IF(E11="Other Expenses",H11," ")
G12: =IF(F12>0,IF(G$3="X",F12*H$5/100/(1+H$5/100)," ")," ") | H12: =IF(F12>0,IF(G12=" ",F12,F12-G12)," ") | J12: =IF(E12="General Admin",H12," ") | K12: =IF(E12="Hotel & Travel",H12," ") | L12: =IF(E12="Vehicle or Mileage",H12," ") | M12: =IF(E12="Other Expenses",H12," ")
G13: =IF(F13>0,IF(G$3="X",F13*H$5/100/(1+H$5/100)," ")," ") | H13: =IF(F13>0,IF(G13=" ",F13,F13-G13)," ") | J13: =IF(E13="General Admin",H13," ") | K13: =IF(E13="Hotel & Travel",H13," ") | L13: =IF(E13="Vehicle or Mileage",H13," ") | M13: =IF(E13="Other Expenses",H13," ")
G14: =IF(F14>0,IF(G$3="X",F14*H$5/100/(1+H$5/100)," ")," ") | H14: =IF(F14>0,IF(G14=" ",F14,F14-G14)," ") | J14: =IF(E14="General Admin",H14," ") | K14: =IF(E14="Hotel & Travel",H14," ") | L14: =IF(E14="Vehicle or Mileage",H14," ") | M14: =IF(E14="Other Expenses",H14," ")
G15: =IF(F15>0,IF(G$3="X",F15*H$5/100/(1+H$5/100)," ")," ") | H15: =IF(F15>0,IF(G15=" ",F15,F15-G15)," ") | J15: =IF(E15="General Admin",H15," ") | K15: =IF(E15="Hotel & Travel",H15," ") | L15: =IF(E15="Vehicle or Mileage",H15," ") | M15: =IF(E15="Other Expenses",H15," ")
G16: =IF(F16>0,IF(G$3="X",F16*H$5/100/(1+H$5/100)," ")," ") | H16: =IF(F16>0,IF(G16=" ",F16,F16-G16)," ") | J16: =IF(E16="General Admin",H16," ") | K16: =IF(E16="Hotel & Travel",H16," ") | L16: =IF(E16="Vehicle or Mileage",H16," ") | M16: =IF(E16="Other Expenses",H16," ")
G17: =IF(F17>0,IF(G$3="X",F17*H$5/100/(1+H$5/100)," ")," ") | H17: =IF(F17>0,IF(G17=" ",F17,F17-G17)," ") | J17: =IF(E17="General Admin",H17," ") | K17: =IF(E17="Hotel & Travel",H17," ") | L17: =IF(E17="Vehicle or Mileage",H17," ") | M17: =IF(E17="Other Expenses",H17," ")
G18: =IF(F18>0,IF(G$3="X",F18*H$5/100/(1+H$5/100)," ")," ") | H18: =IF(F18>0,IF(G18=" ",F18,F18-G18)," ") | J18: =IF(E18="General Admin",H18," ") | K18: =IF(E18="Hotel & Travel",H18," ") | L18: =IF(E18="Vehicle or Mileage",H18," ") | M18: =IF(E18="Other Expenses",H18," ")
G19: =IF(F19>0,IF(G$3="X",F19*H$5/100/(1+H$5/100)," ")," ") | H19: =IF(F19>0,IF(G19=" ",F19,F19-G19)," ") | J19: =IF(E19="General Admin",H19," ") | K19: =IF(E19="Hotel & Travel",H19," ") | L19: =IF(E19="Vehicle or Mileage",H19," ") | M19: =IF(E19="Other Expenses",H19," ")
G20: =IF(F20>0,IF(G$3="X",F20*H$5/100/(1+H$5/100)," ")," ") | H20: =IF(F20>0,IF(G20=" ",F20,F20-G20)," ") | J20: =IF(E20="General Admin",H20," ") | K20: =IF(E20="Hotel & Travel",H20," ") | L20: =IF(E20="Vehicle or Mileage",H20," ") | M20: =IF(E20="Other Expenses",H20," ")
G21: =IF(F21>0,IF(G$3="X",F21*H$5/100/(1+H$5/100)," ")," ") | H21: =IF(F21>0,IF(G21=" ",F21,F21-G21)," ") | J21: =IF(E21="General Admin",H21," ") | K21: =IF(E21="Hotel & Travel",H21," ") | L21: =IF(E21="Vehicle or Mileage",H21," ") | M21: =IF(E21="Other Expenses",H21," ")
... G29: =IF(F29>0,IF(G$3="X",F29*H$5/100/(1+H$5/100)," ")," ") | H29: =IF(F29>0,IF(G29=" ",F29,F29-G29)," ") | J29: =IF(E29="General Admin",H29," ") | K29: =IF(E29="Hotel & Travel",H29," ") | L29: =IF(E29="Vehicle or Mileage",H29," ") | M29: =IF(E29="Other Expenses",H29," ")
B30: ="Mileage Claim @ "&TEXT(C30*100,0)&"p" -> Mileage Claim @ 45p | C30: ='Month 08'!C30 -> 0.45 | D30: =SUM(D10:D29) -> 0 | E30: Vehicle or Mileage | F30: =IF(D30>0,D30*C30," ") | H30: =IF(D30>0,F30-G30," ") | J30: =IF(E30="General Admin",H30," ") | K30: =IF(E30="Hotel & Travel",H30," ") | L30: =IF(E30="Vehicle or Mileage",H30," ") | M30: =IF(E30="Other Expenses",H30," ")
F31: =SUM(F10:F30) -> 0 | G31: =SUM(G10:G30) -> 0 | H31: =SUM(H10:H30) -> 0 | J31: =SUM(J10:J30) -> 0 | K31: =SUM(K10:K30) -> 0 | L31: =SUM(L10:L30) -> 0 | M31: =SUM(M10:M30) -> 0
C33: TOTAL AMOUNT PAYABLE | E33: £ | F33: =F31 -> 0
A35: I confirm the amount claimed has been incurred solely on business and does not include travel expenses from
A36: home to normal place of work, personal or third party expenses
A38: Signed | B38: ……………………………………………………………. | D38: Date | E38: …………………………….
A40: Payment Authorised By | C40: ………………………… | D40: Date | E40: …………………………….
A42: OFFICE USE: Accounting Summary | C42: Reference | D42: Exp01 | G42: Entry Code Letter
A44: =IF(G7>0,G7," ") -> 45657 | B44: =IF(B5>0,B5," ") | D44: Total Purchases | F44: =IF(F31>0,F31," ")
D45: Vat Input | F45: =IF(G31>0,G31," ")
D46: Expense analysis
D47: General Admin | F47: =IF(J31>0,J31," ") | G47: G
D48: Hotel & Travel | F48: =IF(K31>0,K31," ") | G48: H
D49: Vehicle or Mileage | F49: =IF(L31>0,L31," ") | G49: V
B50: Manual analysis required of Other Expenses for accounts | D50: Other Expenses | F50: =IF(M31>0,M31," ") | G50: To be allocated manually

Sheet Month 10
A1: EXPENSES CLAIM FORM
A2: Attach all receipts to support the claim for re-imbursement of business expenses incurred
A3: Enter X if vat registered leave blank if not registered or flat rate scheme | G3: x
A5: Name | B5: =IF('Month 09'!B5:D5>0,'Month 09'!B5:D5,"") | F5: Vat rate applied | H5: ='Month 09'!H5 -> 20
A6: Address | B6: =IF('Month 09'!B6:D6>0,'Month 09'!B6:D6,"") | F6: Date From: | G6: =DATE(YEAR('Month 09'!G6),MONTH('Month 09'!G6)+1,1) -> 45658
B7: =IF('Month 09'!B7>0,'Month 09'!B7,"") | C7: Post Code | D7: =IF('Month 09'!D7>0,'Month 09'!D7,"") | F7: Date To: | G7: =DATE(YEAR(G6),MONTH(G6),DAY(DATE(YEAR(G6),MONTH(G6)+1,1)-1)) -> 45688
A9: Date | B9: Description of Expense | C9: Destination and Purpose | D9: Mileage | E9: Expense Type | F9: Total Claimed | G9: Vat | H9: Net Expense | J9: General Admin | K9: Hotel & Travel | L9: Vehicle or Mileage | M9: Other Expenses
G10: =IF(F10>0,IF(G$3="X",F10*H$5/100/(1+H$5/100)," ")," ") | H10: =IF(F10>0,IF(G10=" ",F10,F10-G10)," ") | J10: =IF(E10="General Admin",H10," ") | K10: =IF(E10="Hotel & Travel",H10," ") | L10: =IF(E10="Vehicle or Mileage",H10," ") | M10: =IF(E10="Other Expenses",H10," ")
G11: =IF(F11>0,IF(G$3="X",F11*H$5/100/(1+H$5/100)," ")," ") | H11: =IF(F11>0,IF(G11=" ",F11,F11-G11)," ") | J11: =IF(E11="General Admin",H11," ") | K11: =IF(E11="Hotel & Travel",H11," ") | L11: =IF(E11="Vehicle or Mileage",H11," ") | M11: =IF(E11="Other Expenses",H11," ")
G12: =IF(F12>0,IF(G$3="X",F12*H$5/100/(1+H$5/100)," ")," ") | H12: =IF(F12>0,IF(G12=" ",F12,F12-G12)," ") | J12: =IF(E12="General Admin",H12," ") | K12: =IF(E12="Hotel & Travel",H12," ") | L12: =IF(E12="Vehicle or Mileage",H12," ") | M12: =IF(E12="Other Expenses",H12," ")
G13: =IF(F13>0,IF(G$3="X",F13*H$5/100/(1+H$5/100)," ")," ") | H13: =IF(F13>0,IF(G13=" ",F13,F13-G13)," ") | J13: =IF(E13="General Admin",H13," ") | K13: =IF(E13="Hotel & Travel",H13," ") | L13: =IF(E13="Vehicle or Mileage",H13," ") | M13: =IF(E13="Other Expenses",H13," ")
G14: =IF(F14>0,IF(G$3="X",F14*H$5/100/(1+H$5/100)," ")," ") | H14: =IF(F14>0,IF(G14=" ",F14,F14-G14)," ") | J14: =IF(E14="General Admin",H14," ") | K14: =IF(E14="Hotel & Travel",H14," ") | L14: =IF(E14="Vehicle or Mileage",H14," ") | M14: =IF(E14="Other Expenses",H14," ")
G15: =IF(F15>0,IF(G$3="X",F15*H$5/100/(1+H$5/100)," ")," ") | H15: =IF(F15>0,IF(G15=" ",F15,F15-G15)," ") | J15: =IF(E15="General Admin",H15," ") | K15: =IF(E15="Hotel & Travel",H15," ") | L15: =IF(E15="Vehicle or Mileage",H15," ") | M15: =IF(E15="Other Expenses",H15," ")
G16: =IF(F16>0,IF(G$3="X",F16*H$5/100/(1+H$5/100)," ")," ") | H16: =IF(F16>0,IF(G16=" ",F16,F16-G16)," ") | J16: =IF(E16="General Admin",H16," ") | K16: =IF(E16="Hotel & Travel",H16," ") | L16: =IF(E16="Vehicle or Mileage",H16," ") | M16: =IF(E16="Other Expenses",H16," ")
G17: =IF(F17>0,IF(G$3="X",F17*H$5/100/(1+H$5/100)," ")," ") | H17: =IF(F17>0,IF(G17=" ",F17,F17-G17)," ") | J17: =IF(E17="General Admin",H17," ") | K17: =IF(E17="Hotel & Travel",H17," ") | L17: =IF(E17="Vehicle or Mileage",H17," ") | M17: =IF(E17="Other Expenses",H17," ")
G18: =IF(F18>0,IF(G$3="X",F18*H$5/100/(1+H$5/100)," ")," ") | H18: =IF(F18>0,IF(G18=" ",F18,F18-G18)," ") | J18: =IF(E18="General Admin",H18," ") | K18: =IF(E18="Hotel & Travel",H18," ") | L18: =IF(E18="Vehicle or Mileage",H18," ") | M18: =IF(E18="Other Expenses",H18," ")
G19: =IF(F19>0,IF(G$3="X",F19*H$5/100/(1+H$5/100)," ")," ") | H19: =IF(F19>0,IF(G19=" ",F19,F19-G19)," ") | J19: =IF(E19="General Admin",H19," ") | K19: =IF(E19="Hotel & Travel",H19," ") | L19: =IF(E19="Vehicle or Mileage",H19," ") | M19: =IF(E19="Other Expenses",H19," ")
G20: =IF(F20>0,IF(G$3="X",F20*H$5/100/(1+H$5/100)," ")," ") | H20: =IF(F20>0,IF(G20=" ",F20,F20-G20)," ") | J20: =IF(E20="General Admin",H20," ") | K20: =IF(E20="Hotel & Travel",H20," ") | L20: =IF(E20="Vehicle or Mileage",H20," ") | M20: =IF(E20="Other Expenses",H20," ")
G21: =IF(F21>0,IF(G$3="X",F21*H$5/100/(1+H$5/100)," ")," ") | H21: =IF(F21>0,IF(G21=" ",F21,F21-G21)," ") | J21: =IF(E21="General Admin",H21," ") | K21: =IF(E21="Hotel & Travel",H21," ") | L21: =IF(E21="Vehicle or Mileage",H21," ") | M21: =IF(E21="Other Expenses",H21," ")
... G29: =IF(F29>0,IF(G$3="X",F29*H$5/100/(1+H$5/100)," ")," ") | H29: =IF(F29>0,IF(G29=" ",F29,F29-G29)," ") | J29: =IF(E29="General Admin",H29," ") | K29: =IF(E29="Hotel & Travel",H29," ") | L29: =IF(E29="Vehicle or Mileage",H29," ") | M29: =IF(E29="Other Expenses",H29," ")
B30: ="Mileage Claim @ "&TEXT(C30*100,0)&"p" -> Mileage Claim @ 45p | C30: ='Month 09'!C30 -> 0.45 | D30: =SUM(D10:D29) -> 0 | E30: Vehicle or Mileage | F30: =IF(D30>0,D30*C30," ") | H30: =IF(D30>0,F30-G30," ") | J30: =IF(E30="General Admin",H30," ") | K30: =IF(E30="Hotel & Travel",H30," ") | L30: =IF(E30="Vehicle or Mileage",H30," ") | M30: =IF(E30="Other Expenses",H30," ")
F31: =SUM(F10:F30) -> 0 | G31: =SUM(G10:G30) -> 0 | H31: =SUM(H10:H30) -> 0 | J31: =SUM(J10:J30) -> 0 | K31: =SUM(K10:K30) -> 0 | L31: =SUM(L10:L30) -> 0 | M31: =SUM(M10:M30) -> 0
C33: TOTAL AMOUNT PAYABLE | E33: £ | F33: =F31 -> 0
A35: I confirm the amount claimed has been incurred solely on business and does not include travel expenses from
A36: home to normal place of work, personal or third party expenses
A38: Signed | B38: ……………………………………………………………. | D38: Date | E38: …………………………….
A40: Payment Authorised By | C40: ………………………… | D40: Date | E40: …………………………….
A42: OFFICE USE: Accounting Summary | C42: Reference | D42: Exp01 | G42: Entry Code Letter
A44: =IF(G7>0,G7," ") -> 45688 | B44: =IF(B5>0,B5," ") | D44: Total Purchases | F44: =IF(F31>0,F31," ")
D45: Vat Input | F45: =IF(G31>0,G31," ")
D46: Expense analysis
D47: General Admin | F47: =IF(J31>0,J31," ") | G47: G
D48: Hotel & Travel | F48: =IF(K31>0,K31," ") | G48: H
D49: Vehicle or Mileage | F49: =IF(L31>0,L31," ") | G49: V
B50: Manual analysis required of Other Expenses for accounts | D50: Other Expenses | F50: =IF(M31>0,M31," ") | G50: To be allocated manually

Sheet Month 11
A1: EXPENSES CLAIM FORM
A2: Attach all receipts to support the claim for re-imbursement of business expenses incurred
A3: Enter X if vat registered leave blank if not registered or flat rate scheme | G3: x
A5: Name | B5: =IF('Month 10'!B5:D5>0,'Month 10'!B5:D5,"") | F5: Vat rate applied | H5: ='Month 10'!H5 -> 20
A6: Address | B6: =IF('Month 10'!B6:D6>0,'Month 10'!B6:D6,"") | F6: Date From: | G6: =DATE(YEAR('Month 10'!G6),MONTH('Month 10'!G6)+1,1) -> 45689
