Workbook

Sheet OpeningDebtors
A1: Opening Debtors Balance | C1: =IF([1]OpenAccounts!$E$16>0,[1]OpenAccounts!$E$16,0) -> 0 | D1: Total in C1 should equal F1 | F1: =SUM(F5:F300) -> 0 | G1: =SUM(G5:G300) -> 0 | H1: =SUM(H5:H300) -> 10800 | J1: For your information only. Enter How Paid e.g. Cash, Cheque etc., | K1: =SUM(K5:K300) -> 0 | L1: =SUM(L5:L300) -> 0 | M1: =TODAY() -> 46131 | O1: =SUM(O5:O300) -> 0
A2: Sales Date | B2: Customer Name | C2: Sales Invoice Number or reference | D2: Sales Description | F2: Sales Value including Vat | G2: =Jun!G2 -> 20 | H2: Sales Net of Vat | K2: Receipts from Customers | O2: Sub contractors only
G3: Vat Output | K3: Actual amount received | L3: Sales Value not yet received | M3: Number of Days Outstanding | O3: CIS Tax Deducted | P3: CIS Certificate reference
G4: =Jun!G4 -> 0
B5: Acme Corp | C5: INV-0901 | G5: =IF(G$4>0,(IF(F5<>0,F5*G$4/100," ")),IF(F5<>0,F5*G$2/(100+G$2)," ")) | H5: 7200 | L5: =IF(F5<>0,F5-K5," ") | M5: =IF((F5-K5)<>0,M$1-A5," ")
B6: Beta Systems | C6: INV-0902 | G6: =IF(G$4>0,(IF(F6<>0,F6*G$4/100," ")),IF(F6<>0,F6*G$2/(100+G$2)," ")) | H6: 1200 | L6: =IF(F6<>0,F6-K6," ") | M6: =IF((F6-K6)<>0,M$1-A6," ")
B7: Gamma Ltd | C7: INV-0903 | G7: =IF(G$4>0,(IF(F7<>0,F7*G$4/100," ")),IF(F7<>0,F7*G$2/(100+G$2)," ")) | H7: 2400 | L7: =IF(F7<>0,F7-K7," ") | M7: =IF((F7-K7)<>0,M$1-A7," ")
G8: =IF(G$4>0,(IF(F8<>0,F8*G$4/100," ")),IF(F8<>0,F8*G$2/(100+G$2)," ")) | L8: =IF(F8<>0,F8-K8," ") | M8: =IF((F8-K8)<>0,M$1-A8," ")
G9: =IF(G$4>0,(IF(F9<>0,F9*G$4/100," ")),IF(F9<>0,F9*G$2/(100+G$2)," ")) | L9: =IF(F9<>0,F9-K9," ") | M9: =IF((F9-K9)<>0,M$1-A9," ")
G10: =IF(G$4>0,(IF(F10<>0,F10*G$4/100," ")),IF(F10<>0,F10*G$2/(100+G$2)," ")) | L10: =IF(F10<>0,F10-K10," ") | M10: =IF((F10-K10)<>0,M$1-A10," ")
G11: =IF(G$4>0,(IF(F11<>0,F11*G$4/100," ")),IF(F11<>0,F11*G$2/(100+G$2)," ")) | L11: =IF(F11<>0,F11-K11," ") | M11: =IF((F11-K11)<>0,M$1-A11," ")
G12: =IF(G$4>0,(IF(F12<>0,F12*G$4/100," ")),IF(F12<>0,F12*G$2/(100+G$2)," ")) | L12: =IF(F12<>0,F12-K12," ") | M12: =IF((F12-K12)<>0,M$1-A12," ")
G13: =IF(G$4>0,(IF(F13<>0,F13*G$4/100," ")),IF(F13<>0,F13*G$2/(100+G$2)," ")) | L13: =IF(F13<>0,F13-K13," ") | M13: =IF((F13-K13)<>0,M$1-A13," ")
G14: =IF(G$4>0,(IF(F14<>0,F14*G$4/100," ")),IF(F14<>0,F14*G$2/(100+G$2)," ")) | L14: =IF(F14<>0,F14-K14," ") | M14: =IF((F14-K14)<>0,M$1-A14," ")
G15: =IF(G$4>0,(IF(F15<>0,F15*G$4/100," ")),IF(F15<>0,F15*G$2/(100+G$2)," ")) | L15: =IF(F15<>0,F15-K15," ") | M15: =IF((F15-K15)<>0,M$1-A15," ")
G16: =IF(G$4>0,(IF(F16<>0,F16*G$4/100," ")),IF(F16<>0,F16*G$2/(100+G$2)," ")) | L16: =IF(F16<>0,F16-K16," ") | M16: =IF((F16-K16)<>0,M$1-A16," ")
G17: =IF(G$4>0,(IF(F17<>0,F17*G$4/100," ")),IF(F17<>0,F17*G$2/(100+G$2)," ")) | L17: =IF(F17<>0,F17-K17," ") | M17: =IF((F17-K17)<>0,M$1-A17," ")
G18: =IF(G$4>0,(IF(F18<>0,F18*G$4/100," ")),IF(F18<>0,F18*G$2/(100+G$2)," ")) | L18: =IF(F18<>0,F18-K18," ") | M18: =IF((F18-K18)<>0,M$1-A18," ")
G19: =IF(G$4>0,(IF(F19<>0,F19*G$4/100," ")),IF(F19<>0,F19*G$2/(100+G$2)," ")) | L19: =IF(F19<>0,F19-K19," ") | M19: =IF((F19-K19)<>0,M$1-A19," ")
... G69: =IF(G$4>0,(IF(F69<>0,F69*G$4/100," ")),IF(F69<>0,F69*G$2/(100+G$2)," ")) | L69: =IF(F69<>0,F69-K69," ") | M69: =IF((F69-K69)<>0,M$1-A69," ")
G70: =IF(G$4>0,(IF(F70<>0,F70*G$4/100," ")),IF(F70<>0,F70*G$2/(100+G$2)," ")) | H70: =IF((F70<>0),F70-G70," ") | L70: =IF(F70<>0,F70-K70," ") | M70: =IF((F70-K70)<>0,M$1-A70," ")
G71: =IF(G$4>0,(IF(F71<>0,F71*G$4/100," ")),IF(F71<>0,F71*G$2/(100+G$2)," ")) | H71: =IF((F71<>0),F71-G71," ") | L71: =IF(F71<>0,F71-K71," ") | M71: =IF((F71-K71)<>0,M$1-A71," ")
G72: =IF(G$4>0,(IF(F72<>0,F72*G$4/100," ")),IF(F72<>0,F72*G$2/(100+G$2)," ")) | H72: =IF((F72<>0),F72-G72," ") | L72: =IF(F72<>0,F72-K72," ") | M72: =IF((F72-K72)<>0,M$1-A72," ")
G73: =IF(G$4>0,(IF(F73<>0,F73*G$4/100," ")),IF(F73<>0,F73*G$2/(100+G$2)," ")) | H73: =IF((F73<>0),F73-G73," ") | L73: =IF(F73<>0,F73-K73," ") | M73: =IF((F73-K73)<>0,M$1-A73," ")
G74: =IF(G$4>0,(IF(F74<>0,F74*G$4/100," ")),IF(F74<>0,F74*G$2/(100+G$2)," ")) | H74: =IF((F74<>0),F74-G74," ") | L74: =IF(F74<>0,F74-K74," ") | M74: =IF((F74-K74)<>0,M$1-A74," ")
G75: =IF(G$4>0,(IF(F75<>0,F75*G$4/100," ")),IF(F75<>0,F75*G$2/(100+G$2)," ")) | H75: =IF((F75<>0),F75-G75," ") | L75: =IF(F75<>0,F75-K75," ") | M75: =IF((F75-K75)<>0,M$1-A75," ")
G76: =IF(G$4>0,(IF(F76<>0,F76*G$4/100," ")),IF(F76<>0,F76*G$2/(100+G$2)," ")) | H76: =IF((F76<>0),F76-G76," ") | L76: =IF(F76<>0,F76-K76," ") | M76: =IF((F76-K76)<>0,M$1-A76," ")
G77: =IF(G$4>0,(IF(F77<>0,F77*G$4/100," ")),IF(F77<>0,F77*G$2/(100+G$2)," ")) | H77: =IF((F77<>0),F77-G77," ") | L77: =IF(F77<>0,F77-K77," ") | M77: =IF((F77-K77)<>0,M$1-A77," ")
G78: =IF(G$4>0,(IF(F78<>0,F78*G$4/100," ")),IF(F78<>0,F78*G$2/(100+G$2)," ")) | H78: =IF((F78<>0),F78-G78," ") | L78: =IF(F78<>0,F78-K78," ") | M78: =IF((F78-K78)<>0,M$1-A78," ")
G79: =IF(G$4>0,(IF(F79<>0,F79*G$4/100," ")),IF(F79<>0,F79*G$2/(100+G$2)," ")) | H79: =IF((F79<>0),F79-G79," ") | L79: =IF(F79<>0,F79-K79," ") | M79: =IF((F79-K79)<>0,M$1-A79," ")
G80: =IF(G$4>0,(IF(F80<>0,F80*G$4/100," ")),IF(F80<>0,F80*G$2/(100+G$2)," ")) | H80: =IF((F80<>0),F80-G80," ") | L80: =IF(F80<>0,F80-K80," ") | M80: =IF((F80-K80)<>0,M$1-A80," ")
G81: =IF(G$4>0,(IF(F81<>0,F81*G$4/100," ")),IF(F81<>0,F81*G$2/(100+G$2)," ")) | H81: =IF((F81<>0),F81-G81," ") | L81: =IF(F81<>0,F81-K81," ") | M81: =IF((F81-K81)<>0,M$1-A81," ")
... G300: =IF(G$4>0,(IF(F300<>0,F300*G$4/100," ")),IF(F300<>0,F300*G$2/(100+G$2)," ")) | H300: =IF((F300<>0),F300-G300," ") | L300: =IF(F300<>0,F300-K300," ") | M300: =IF((F300-K300)<>0,M$1-A300," ")

Sheet Jun
A1: =F1-G1-SUM(O1:U1) -> 0 | B1: Check Total | C1: Sales Invoice Number or reference | D1: Total for Month | F1: =SUM(F5:F300) -> 33400 | G1: =SUM(G5:G300) -> 5566.6667 | H1: =SUM(H5:H300) -> 27833.333 | J1: For your information only. Enter How Paid e.g. Cash, Cheque etc., | K1: =SUM(K5:K300) -> 0 | L1: =SUM(L5:L300) -> 33400 | M1: =TODAY() -> 46131 | O1: =SUM(O5:O300) -> 25333.333 | P1: =SUM(P5:P300) -> 1800 | Q1: =SUM(Q5:Q300) -> 0 | R1: =SUM(R5:R300) -> 700 | S1: =SUM(S5:S300) -> 0 | T1: =SUM(T5:T300) -> 0 | U1: =SUM(U5:U300) -> 0 | V1: =SUM(V5:V300) -> 0
A2: Sales Date | B2: Customer Name | D2: Sales Description | E2: Enter Expense Code Letter | F2: Sales Value including Vat | G2: =[1]Admin!$M$19 -> 20 | H2: Sales Net of Vat | K2: Receipts from Customers | O2: Sales Net of Vat | R2: Other Income | S2: Investment Grants | T2: Bad Debts written off | U2: Sale of Fixed Assets | V2: Sub contractors only
G3: Vat Output | K3: Actual amount received | L3: Sales Value not yet received | M3: Number of Days Outstanding | O3: Product A | P3: Product B | Q3: Product C | V3: CIS Tax Deducted | W3: CIS Certificate reference
O4: A | P4: B | Q4: C | R4: D | S4: G | T4: O | U4: FS
A5: 45809 | B5: Beta Systems | E5: b | F5: 1200 | G5: =IF(G$4>0,(IF(F5<>0,F5*G$4/100," ")),IF(F5<>0,F5*G$2/(100+G$2)," ")) -> 200 | H5: =IF((F5<>0),F5-G5," ") -> 1000 | L5: =IF(F5<>0,F5-K5," ") -> 1200 | M5: =IF((F5-K5)<>0,M$1-A5," ") -> 322 | O5: =IF((E5="a"),H5," ") | P5: =IF((E5="b"),H5," ") -> 1000 | Q5: =IF((E5="c"),H5," ") | R5: =IF((E5="d"),H5," ") | S5: =IF((E5="g"),H5," ") | T5: =IF((E5="o"),H5," ") | U5: =IF((E5="FS"),H5," ")
A6: 45811 | B6: FreshField Ltd | E6: b | F6: 360 | G6: =IF(G$4>0,(IF(F6<>0,F6*G$4/100," ")),IF(F6<>0,F6*G$2/(100+G$2)," ")) -> 60 | H6: =IF((F6<>0),F6-G6," ") -> 300 | L6: =IF(F6<>0,F6-K6," ") -> 360 | M6: =IF((F6-K6)<>0,M$1-A6," ") -> 320 | O6: =IF((E6="a"),H6," ") | P6: =IF((E6="b"),H6," ") -> 300 | Q6: =IF((E6="c"),H6," ") | R6: =IF((E6="d"),H6," ") | S6: =IF((E6="g"),H6," ") | T6: =IF((E6="o"),H6," ") | U6: =IF((E6="FS"),H6," ")
A7: 45813 | B7: CloudNine Ltd | E7: b | F7: 600 | G7: =IF(G$4>0,(IF(F7<>0,F7*G$4/100," ")),IF(F7<>0,F7*G$2/(100+G$2)," ")) -> 100 | H7: =IF((F7<>0),F7-G7," ") -> 500 | L7: =IF(F7<>0,F7-K7," ") -> 600 | M7: =IF((F7-K7)<>0,M$1-A7," ") -> 318 | O7: =IF((E7="a"),H7," ") | P7: =IF((E7="b"),H7," ") -> 500 | Q7: =IF((E7="c"),H7," ") | R7: =IF((E7="d"),H7," ") | S7: =IF((E7="g"),H7," ") | T7: =IF((E7="o"),H7," ") | U7: =IF((E7="FS"),H7," ")
A8: 45816 | B8: Cedar Systems | E8: a | F8: 480 | G8: =IF(G$4>0,(IF(F8<>0,F8*G$4/100," ")),IF(F8<>0,F8*G$2/(100+G$2)," ")) -> 80 | H8: =IF((F8<>0),F8-G8," ") -> 400 | L8: =IF(F8<>0,F8-K8," ") -> 480 | M8: =IF((F8-K8)<>0,M$1-A8," ") -> 315 | O8: =IF((E8="a"),H8," ") -> 400 | P8: =IF((E8="b"),H8," ") | Q8: =IF((E8="c"),H8," ") | R8: =IF((E8="d"),H8," ") | S8: =IF((E8="g"),H8," ") | T8: =IF((E8="o"),H8," ") | U8: =IF((E8="FS"),H8," ")
A9: 45818 | B9: Pinnacle Group | E9: a | F9: 720 | G9: =IF(G$4>0,(IF(F9<>0,F9*G$4/100," ")),IF(F9<>0,F9*G$2/(100+G$2)," ")) -> 120 | H9: =IF((F9<>0),F9-G9," ") -> 600 | L9: =IF(F9<>0,F9-K9," ") -> 720 | M9: =IF((F9-K9)<>0,M$1-A9," ") -> 313 | O9: =IF((E9="a"),H9," ") -> 600 | P9: =IF((E9="b"),H9," ") | Q9: =IF((E9="c"),H9," ") | R9: =IF((E9="d"),H9," ") | S9: =IF((E9="g"),H9," ") | T9: =IF((E9="o"),H9," ") | U9: =IF((E9="FS"),H9," ")
A10: 45823 | B10: Acme Corp | E10: a | F10: 25000 | G10: =IF(G$4>0,(IF(F10<>0,F10*G$4/100," ")),IF(F10<>0,F10*G$2/(100+G$2)," ")) -> 4166.6667 | H10: =IF((F10<>0),F10-G10," ") -> 20833.333 | L10: =IF(F10<>0,F10-K10," ") -> 25000 | M10: =IF((F10-K10)<>0,M$1-A10," ") -> 308 | O10: =IF((E10="a"),H10," ") -> 20833.333 | P10: =IF((E10="b"),H10," ") | Q10: =IF((E10="c"),H10," ") | R10: =IF((E10="d"),H10," ") | S10: =IF((E10="g"),H10," ") | T10: =IF((E10="o"),H10," ") | U10: =IF((E10="FS"),H10," ")
A11: 45826 | B11: TechStart Ltd | E11: a | F11: 2400 | G11: =IF(G$4>0,(IF(F11<>0,F11*G$4/100," ")),IF(F11<>0,F11*G$2/(100+G$2)," ")) -> 400 | H11: =IF((F11<>0),F11-G11," ") -> 2000 | L11: =IF(F11<>0,F11-K11," ") -> 2400 | M11: =IF((F11-K11)<>0,M$1-A11," ") -> 305 | O11: =IF((E11="a"),H11," ") -> 2000 | P11: =IF((E11="b"),H11," ") | Q11: =IF((E11="c"),H11," ") | R11: =IF((E11="d"),H11," ") | S11: =IF((E11="g"),H11," ") | T11: =IF((E11="o"),H11," ") | U11: =IF((E11="FS"),H11," ")
A12: 45828 | B12: DataFlow Inc | E12: a | F12: 1800 | G12: =IF(G$4>0,(IF(F12<>0,F12*G$4/100," ")),IF(F12<>0,F12*G$2/(100+G$2)," ")) -> 300 | H12: =IF((F12<>0),F12-G12," ") -> 1500 | L12: =IF(F12<>0,F12-K12," ") -> 1800 | M12: =IF((F12-K12)<>0,M$1-A12," ") -> 303 | O12: =IF((E12="a"),H12," ") -> 1500 | P12: =IF((E12="b"),H12," ") | Q12: =IF((E12="c"),H12," ") | R12: =IF((E12="d"),H12," ") | S12: =IF((E12="g"),H12," ") | T12: =IF((E12="o"),H12," ") | U12: =IF((E12="FS"),H12," ")
A13: 45836 | B13: Horizon Analytics | E13: d | F13: 840 | G13: =IF(G$4>0,(IF(F13<>0,F13*G$4/100," ")),IF(F13<>0,F13*G$2/(100+G$2)," ")) -> 140 | H13: =IF((F13<>0),F13-G13," ") -> 700 | L13: =IF(F13<>0,F13-K13," ") -> 840 | M13: =IF((F13-K13)<>0,M$1-A13," ") -> 295 | O13: =IF((E13="a"),H13," ") | P13: =IF((E13="b"),H13," ") | Q13: =IF((E13="c"),H13," ") | R13: =IF((E13="d"),H13," ") -> 700 | S13: =IF((E13="g"),H13," ") | T13: =IF((E13="o"),H13," ") | U13: =IF((E13="FS"),H13," ")
G14: =IF(G$4>0,(IF(F14<>0,F14*G$4/100," ")),IF(F14<>0,F14*G$2/(100+G$2)," ")) | H14: =IF((F14<>0),F14-G14," ") | L14: =IF(F14<>0,F14-K14," ") | M14: =IF((F14-K14)<>0,M$1-A14," ") | O14: =IF((E14="a"),H14," ") | P14: =IF((E14="b"),H14," ") | Q14: =IF((E14="c"),H14," ") | R14: =IF((E14="d"),H14," ") | S14: =IF((E14="g"),H14," ") | T14: =IF((E14="o"),H14," ") | U14: =IF((E14="FS"),H14," ")
G15: =IF(G$4>0,(IF(F15<>0,F15*G$4/100," ")),IF(F15<>0,F15*G$2/(100+G$2)," ")) | H15: =IF((F15<>0),F15-G15," ") | L15: =IF(F15<>0,F15-K15," ") | M15: =IF((F15-K15)<>0,M$1-A15," ") | O15: =IF((E15="a"),H15," ") | P15: =IF((E15="b"),H15," ") | Q15: =IF((E15="c"),H15," ") | R15: =IF((E15="d"),H15," ") | S15: =IF((E15="g"),H15," ") | T15: =IF((E15="o"),H15," ") | U15: =IF((E15="FS"),H15," ")
G16: =IF(G$4>0,(IF(F16<>0,F16*G$4/100," ")),IF(F16<>0,F16*G$2/(100+G$2)," ")) | H16: =IF((F16<>0),F16-G16," ") | L16: =IF(F16<>0,F16-K16," ") | M16: =IF((F16-K16)<>0,M$1-A16," ") | O16: =IF((E16="a"),H16," ") | P16: =IF((E16="b"),H16," ") | Q16: =IF((E16="c"),H16," ") | R16: =IF((E16="d"),H16," ") | S16: =IF((E16="g"),H16," ") | T16: =IF((E16="o"),H16," ") | U16: =IF((E16="FS"),H16," ")
G17: =IF(G$4>0,(IF(F17<>0,F17*G$4/100," ")),IF(F17<>0,F17*G$2/(100+G$2)," ")) | H17: =IF((F17<>0),F17-G17," ") | L17: =IF(F17<>0,F17-K17," ") | M17: =IF((F17-K17)<>0,M$1-A17," ") | O17: =IF((E17="a"),H17," ") | P17: =IF((E17="b"),H17," ") | Q17: =IF((E17="c"),H17," ") | R17: =IF((E17="d"),H17," ") | S17: =IF((E17="g"),H17," ") | T17: =IF((E17="o"),H17," ") | U17: =IF((E17="FS"),H17," ")
G18: =IF(G$4>0,(IF(F18<>0,F18*G$4/100," ")),IF(F18<>0,F18*G$2/(100+G$2)," ")) | H18: =IF((F18<>0),F18-G18," ") | L18: =IF(F18<>0,F18-K18," ") | M18: =IF((F18-K18)<>0,M$1-A18," ") | O18: =IF((E18="a"),H18," ") | P18: =IF((E18="b"),H18," ") | Q18: =IF((E18="c"),H18," ") | R18: =IF((E18="d"),H18," ") | S18: =IF((E18="g"),H18," ") | T18: =IF((E18="o"),H18," ") | U18: =IF((E18="FS"),H18," ")
G19: =IF(G$4>0,(IF(F19<>0,F19*G$4/100," ")),IF(F19<>0,F19*G$2/(100+G$2)," ")) | H19: =IF((F19<>0),F19-G19," ") | L19: =IF(F19<>0,F19-K19," ") | M19: =IF((F19-K19)<>0,M$1-A19," ") | O19: =IF((E19="a"),H19," ") | P19: =IF((E19="b"),H19," ") | Q19: =IF((E19="c"),H19," ") | R19: =IF((E19="d"),H19," ") | S19: =IF((E19="g"),H19," ") | T19: =IF((E19="o"),H19," ") | U19: =IF((E19="FS"),H19," ")
G20: =IF(G$4>0,(IF(F20<>0,F20*G$4/100," ")),IF(F20<>0,F20*G$2/(100+G$2)," ")) | H20: =IF((F20<>0),F20-G20," ") | L20: =IF(F20<>0,F20-K20," ") | M20: =IF((F20-K20)<>0,M$1-A20," ") | O20: =IF((E20="a"),H20," ") | P20: =IF((E20="b"),H20," ") | Q20: =IF((E20="c"),H20," ") | R20: =IF((E20="d"),H20," ") | S20: =IF((E20="g"),H20," ") | T20: =IF((E20="o"),H20," ") | U20: =IF((E20="FS"),H20," ")
G21: =IF(G$4>0,(IF(F21<>0,F21*G$4/100," ")),IF(F21<>0,F21*G$2/(100+G$2)," ")) | H21: =IF((F21<>0),F21-G21," ") | L21: =IF(F21<>0,F21-K21," ") | M21: =IF((F21-K21)<>0,M$1-A21," ") | O21: =IF((E21="a"),H21," ") | P21: =IF((E21="b"),H21," ") | Q21: =IF((E21="c"),H21," ") | R21: =IF((E21="d"),H21," ") | S21: =IF((E21="g"),H21," ") | T21: =IF((E21="o"),H21," ") | U21: =IF((E21="FS"),H21," ")
G22: =IF(G$4>0,(IF(F22<>0,F22*G$4/100," ")),IF(F22<>0,F22*G$2/(100+G$2)," ")) | H22: =IF((F22<>0),F22-G22," ") | L22: =IF(F22<>0,F22-K22," ") | M22: =IF((F22-K22)<>0,M$1-A22," ") | O22: =IF((E22="a"),H22," ") | P22: =IF((E22="b"),H22," ") | Q22: =IF((E22="c"),H22," ") | R22: =IF((E22="d"),H22," ") | S22: =IF((E22="g"),H22," ") | T22: =IF((E22="o"),H22," ") | U22: =IF((E22="FS"),H22," ")
G23: =IF(G$4>0,(IF(F23<>0,F23*G$4/100," ")),IF(F23<>0,F23*G$2/(100+G$2)," ")) | H23: =IF((F23<>0),F23-G23," ") | L23: =IF(F23<>0,F23-K23," ") | M23: =IF((F23-K23)<>0,M$1-A23," ") | O23: =IF((E23="a"),H23," ") | P23: =IF((E23="b"),H23," ") | Q23: =IF((E23="c"),H23," ") | R23: =IF((E23="d"),H23," ") | S23: =IF((E23="g"),H23," ") | T23: =IF((E23="o"),H23," ") | U23: =IF((E23="FS"),H23," ")
G24: =IF(G$4>0,(IF(F24<>0,F24*G$4/100," ")),IF(F24<>0,F24*G$2/(100+G$2)," ")) | H24: =IF((F24<>0),F24-G24," ") | L24: =IF(F24<>0,F24-K24," ") | M24: =IF((F24-K24)<>0,M$1-A24," ") | O24: =IF((E24="a"),H24," ") | P24: =IF((E24="b"),H24," ") | Q24: =IF((E24="c"),H24," ") | R24: =IF((E24="d"),H24," ") | S24: =IF((E24="g"),H24," ") | T24: =IF((E24="o"),H24," ") | U24: =IF((E24="FS"),H24," ")
G25: =IF(G$4>0,(IF(F25<>0,F25*G$4/100," ")),IF(F25<>0,F25*G$2/(100+G$2)," ")) | H25: =IF((F25<>0),F25-G25," ") | L25: =IF(F25<>0,F25-K25," ") | M25: =IF((F25-K25)<>0,M$1-A25," ") | O25: =IF((E25="a"),H25," ") | P25: =IF((E25="b"),H25," ") | Q25: =IF((E25="c"),H25," ") | R25: =IF((E25="d"),H25," ") | S25: =IF((E25="g"),H25," ") | T25: =IF((E25="o"),H25," ") | U25: =IF((E25="FS"),H25," ")
... G69: =IF(G$4>0,(IF(F69<>0,F69*G$4/100," ")),IF(F69<>0,F69*G$2/(100+G$2)," ")) | H69: =IF((F69<>0),F69-G69," ") | L69: =IF(F69<>0,F69-K69," ") | M69: =IF((F69-K69)<>0,M$1-A69," ") | O69: =IF((E69="a"),H69," ") | P69: =IF((E69="b"),H69," ") | Q69: =IF((E69="c"),H69," ") | R69: =IF((E69="d"),H69," ") | S69: =IF((E69="g"),H69," ") | T69: =IF((E69="o"),H69," ") | U69: =IF((E69="FS"),H69," ")
E70: =IF((F70<>0),"Enter Letter"," ") | G70: =IF(G$4>0,(IF(F70<>0,F70*G$4/100," ")),IF(F70<>0,F70*G$2/(100+G$2)," ")) | H70: =IF((F70<>0),F70-G70," ") | L70: =IF(F70<>0,F70-K70," ") | M70: =IF((F70-K70)<>0,M$1-A70," ") | O70: =IF((E70="a"),H70," ") | P70: =IF((E70="b"),H70," ") | Q70: =IF((E70="c"),H70," ") | R70: =IF((E70="d"),H70," ") | S70: =IF((E70="g"),H70," ") | T70: =IF((E70="o"),H70," ") | U70: =IF((E70="FS"),H70," ")
E71: =IF((F71<>0),"Enter Letter"," ") | G71: =IF(G$4>0,(IF(F71<>0,F71*G$4/100," ")),IF(F71<>0,F71*G$2/(100+G$2)," ")) | H71: =IF((F71<>0),F71-G71," ") | L71: =IF(F71<>0,F71-K71," ") | M71: =IF((F71-K71)<>0,M$1-A71," ") | O71: =IF((E71="a"),H71," ") | P71: =IF((E71="b"),H71," ") | Q71: =IF((E71="c"),H71," ") | R71: =IF((E71="d"),H71," ") | S71: =IF((E71="g"),H71," ") | T71: =IF((E71="o"),H71," ") | U71: =IF((E71="FS"),H71," ")
E72: =IF((F72<>0),"Enter Letter"," ") | G72: =IF(G$4>0,(IF(F72<>0,F72*G$4/100," ")),IF(F72<>0,F72*G$2/(100+G$2)," ")) | H72: =IF((F72<>0),F72-G72," ") | L72: =IF(F72<>0,F72-K72," ") | M72: =IF((F72-K72)<>0,M$1-A72," ") | O72: =IF((E72="a"),H72," ") | P72: =IF((E72="b"),H72," ") | Q72: =IF((E72="c"),H72," ") | R72: =IF((E72="d"),H72," ") | S72: =IF((E72="g"),H72," ") | T72: =IF((E72="o"),H72," ") | U72: =IF((E72="FS"),H72," ")
E73: =IF((F73<>0),"Enter Letter"," ") | G73: =IF(G$4>0,(IF(F73<>0,F73*G$4/100," ")),IF(F73<>0,F73*G$2/(100+G$2)," ")) | H73: =IF((F73<>0),F73-G73," ") | L73: =IF(F73<>0,F73-K73," ") | M73: =IF((F73-K73)<>0,M$1-A73," ") | O73: =IF((E73="a"),H73," ") | P73: =IF((E73="b"),H73," ") | Q73: =IF((E73="c"),H73," ") | R73: =IF((E73="d"),H73," ") | S73: =IF((E73="g"),H73," ") | T73: =IF((E73="o"),H73," ") | U73: =IF((E73="FS"),H73," ")
E74: =IF((F74<>0),"Enter Letter"," ") | G74: =IF(G$4>0,(IF(F74<>0,F74*G$4/100," ")),IF(F74<>0,F74*G$2/(100+G$2)," ")) | H74: =IF((F74<>0),F74-G74," ") | L74: =IF(F74<>0,F74-K74," ") | M74: =IF((F74-K74)<>0,M$1-A74," ") | O74: =IF((E74="a"),H74," ") | P74: =IF((E74="b"),H74," ") | Q74: =IF((E74="c"),H74," ") | R74: =IF((E74="d"),H74," ") | S74: =IF((E74="g"),H74," ") | T74: =IF((E74="o"),H74," ") | U74: =IF((E74="FS"),H74," ")
E75: =IF((F75<>0),"Enter Letter"," ") | G75: =IF(G$4>0,(IF(F75<>0,F75*G$4/100," ")),IF(F75<>0,F75*G$2/(100+G$2)," ")) | H75: =IF((F75<>0),F75-G75," ") | L75: =IF(F75<>0,F75-K75," ") | M75: =IF((F75-K75)<>0,M$1-A75," ") | O75: =IF((E75="a"),H75," ") | P75: =IF((E75="b"),H75," ") | Q75: =IF((E75="c"),H75," ") | R75: =IF((E75="d"),H75," ") | S75: =IF((E75="g"),H75," ") | T75: =IF((E75="o"),H75," ") | U75: =IF((E75="FS"),H75," ")
E76: =IF((F76<>0),"Enter Letter"," ") | G76: =IF(G$4>0,(IF(F76<>0,F76*G$4/100," ")),IF(F76<>0,F76*G$2/(100+G$2)," ")) | H76: =IF((F76<>0),F76-G76," ") | L76: =IF(F76<>0,F76-K76," ") | M76: =IF((F76-K76)<>0,M$1-A76," ") | O76: =IF((E76="a"),H76," ") | P76: =IF((E76="b"),H76," ") | Q76: =IF((E76="c"),H76," ") | R76: =IF((E76="d"),H76," ") | S76: =IF((E76="g"),H76," ") | T76: =IF((E76="o"),H76," ") | U76: =IF((E76="FS"),H76," ")
E77: =IF((F77<>0),"Enter Letter"," ") | G77: =IF(G$4>0,(IF(F77<>0,F77*G$4/100," ")),IF(F77<>0,F77*G$2/(100+G$2)," ")) | H77: =IF((F77<>0),F77-G77," ") | L77: =IF(F77<>0,F77-K77," ") | M77: =IF((F77-K77)<>0,M$1-A77," ") | O77: =IF((E77="a"),H77," ") | P77: =IF((E77="b"),H77," ") | Q77: =IF((E77="c"),H77," ") | R77: =IF((E77="d"),H77," ") | S77: =IF((E77="g"),H77," ") | T77: =IF((E77="o"),H77," ") | U77: =IF((E77="FS"),H77," ")
E78: =IF((F78<>0),"Enter Letter"," ") | G78: =IF(G$4>0,(IF(F78<>0,F78*G$4/100," ")),IF(F78<>0,F78*G$2/(100+G$2)," ")) | H78: =IF((F78<>0),F78-G78," ") | L78: =IF(F78<>0,F78-K78," ") | M78: =IF((F78-K78)<>0,M$1-A78," ") | O78: =IF((E78="a"),H78," ") | P78: =IF((E78="b"),H78," ") | Q78: =IF((E78="c"),H78," ") | R78: =IF((E78="d"),H78," ") | S78: =IF((E78="g"),H78," ") | T78: =IF((E78="o"),H78," ") | U78: =IF((E78="FS"),H78," ")
E79: =IF((F79<>0),"Enter Letter"," ") | G79: =IF(G$4>0,(IF(F79<>0,F79*G$4/100," ")),IF(F79<>0,F79*G$2/(100+G$2)," ")) | H79: =IF((F79<>0),F79-G79," ") | L79: =IF(F79<>0,F79-K79," ") | M79: =IF((F79-K79)<>0,M$1-A79," ") | O79: =IF((E79="a"),H79," ") | P79: =IF((E79="b"),H79," ") | Q79: =IF((E79="c"),H79," ") | R79: =IF((E79="d"),H79," ") | S79: =IF((E79="g"),H79," ") | T79: =IF((E79="o"),H79," ") | U79: =IF((E79="FS"),H79," ")
E80: =IF((F80<>0),"Enter Letter"," ") | G80: =IF(G$4>0,(IF(F80<>0,F80*G$4/100," ")),IF(F80<>0,F80*G$2/(100+G$2)," ")) | H80: =IF((F80<>0),F80-G80," ") | L80: =IF(F80<>0,F80-K80," ") | M80: =IF((F80-K80)<>0,M$1-A80," ") | O80: =IF((E80="a"),H80," ") | P80: =IF((E80="b"),H80," ") | Q80: =IF((E80="c"),H80," ") | R80: =IF((E80="d"),H80," ") | S80: =IF((E80="g"),H80," ") | T80: =IF((E80="o"),H80," ") | U80: =IF((E80="FS"),H80," ")
E81: =IF((F81<>0),"Enter Letter"," ") | G81: =IF(G$4>0,(IF(F81<>0,F81*G$4/100," ")),IF(F81<>0,F81*G$2/(100+G$2)," ")) | H81: =IF((F81<>0),F81-G81," ") | L81: =IF(F81<>0,F81-K81," ") | M81: =IF((F81-K81)<>0,M$1-A81," ") | O81: =IF((E81="a"),H81," ") | P81: =IF((E81="b"),H81," ") | Q81: =IF((E81="c"),H81," ") | R81: =IF((E81="d"),H81," ") | S81: =IF((E81="g"),H81," ") | T81: =IF((E81="o"),H81," ") | U81: =IF((E81="FS"),H81," ")
... E300: =IF((F300<>0),"Enter Letter"," ") | G300: =IF(G$4>0,(IF(F300<>0,F300*G$4/100," ")),IF(F300<>0,F300*G$2/(100+G$2)," ")) | H300: =IF((F300<>0),F300-G300," ") | L300: =IF(F300<>0,F300-K300," ") | M300: =IF((F300-K300)<>0,M$1-A300," ") | O300: =IF((E300="a"),H300," ") | P300: =IF((E300="b"),H300," ") | Q300: =IF((E300="c"),H300," ") | R300: =IF((E300="d"),H300," ") | S300: =IF((E300="g"),H300," ") | T300: =IF((E300="o"),H300," ") | U300: =IF((E300="FS"),H300," ")

Sheet Jul
A1: =F1-G1-SUM(O1:U1) -> 0 | B1: Check Total | C1: Sales Invoice Number or reference | D1: Total for Month | F1: =SUM(F5:F300) -> 32920 | G1: =SUM(G5:G300) -> 5486.6667 | H1: =SUM(H5:H300) -> 27433.333 | J1: For your information only. Enter How Paid e.g. Cash, Cheque etc., | K1: =SUM(K5:K300) -> 0 | L1: =SUM(L5:L300) -> 32920 | M1: =TODAY() -> 46131 | O1: =SUM(O5:O300) -> 25633.333 | P1: =SUM(P5:P300) -> 800 | Q1: =SUM(Q5:Q300) -> 1000 | R1: =SUM(R5:R300) -> 0 | S1: =SUM(S5:S300) -> 0 | T1: =SUM(T5:T300) -> 0 | U1: =SUM(U5:U300) -> 0 | V1: =SUM(V5:V300) -> 0
A2: Sales Date | B2: Customer Name | D2: Sales Description | E2: Enter Expense Code Letter | F2: Sales Value including Vat | G2: =Jun!G2 -> 20 | H2: Sales Net of Vat | K2: Receipts from Customers | O2: Sales Net of Vat | R2: Other Income | S2: Investment Grants | T2: Bad Debts written off | U2: Sale of Fixed Assets | V2: Sub contractors only
G3: Vat Output | K3: Actual amount received | L3: Sales Value not yet received | M3: Number of Days Outstanding | O3: Product A | P3: Product B | Q3: Product C | V3: CIS Tax Deducted | W3: CIS Certificate reference
G4: =Jun!G4 -> 0 | O4: A | P4: B | Q4: C | R4: D | S4: G | T4: O | U4: FS
A5: 45841 | B5: FreshField Ltd | E5: b | F5: 360 | G5: =IF(G$4>0,(IF(F5<>0,F5*G$4/100," ")),IF(F5<>0,F5*G$2/(100+G$2)," ")) -> 60 | H5: =IF((F5<>0),F5-G5," ") -> 300 | L5: =IF(F5<>0,F5-K5," ") -> 360 | M5: =IF((F5-K5)<>0,M$1-A5," ") -> 290 | O5: =IF((E5="a"),H5," ") | P5: =IF((E5="b"),H5," ") -> 300 | Q5: =IF((E5="c"),H5," ") | R5: =IF((E5="d"),H5," ") | S5: =IF((E5="g"),H5," ") | T5: =IF((E5="o"),H5," ") | U5: =IF((E5="FS"),H5," ")
A6: 45843 | B6: CloudNine Ltd | E6: b | F6: 600 | G6: =IF(G$4>0,(IF(F6<>0,F6*G$4/100," ")),IF(F6<>0,F6*G$2/(100+G$2)," ")) -> 100 | H6: =IF((F6<>0),F6-G6," ") -> 500 | L6: =IF(F6<>0,F6-K6," ") -> 600 | M6: =IF((F6-K6)<>0,M$1-A6," ") -> 288 | O6: =IF((E6="a"),H6," ") | P6: =IF((E6="b"),H6," ") -> 500 | Q6: =IF((E6="c"),H6," ") | R6: =IF((E6="d"),H6," ") | S6: =IF((E6="g"),H6," ") | T6: =IF((E6="o"),H6," ") | U6: =IF((E6="FS"),H6," ")
A7: 45846 | B7: Cedar Systems | E7: a | F7: 480 | G7: =IF(G$4>0,(IF(F7<>0,F7*G$4/100," ")),IF(F7<>0,F7*G$2/(100+G$2)," ")) -> 80 | H7: =IF((F7<>0),F7-G7," ") -> 400 | L7: =IF(F7<>0,F7-K7," ") -> 480 | M7: =IF((F7-K7)<>0,M$1-A7," ") -> 285 | O7: =IF((E7="a"),H7," ") -> 400 | P7: =IF((E7="b"),H7," ") | Q7: =IF((E7="c"),H7," ") | R7: =IF((E7="d"),H7," ") | S7: =IF((E7="g"),H7," ") | T7: =IF((E7="o"),H7," ") | U7: =IF((E7="FS"),H7," ")
A8: 45848 | B8: Pinnacle Group | E8: a | F8: 720 | G8: =IF(G$4>0,(IF(F8<>0,F8*G$4/100," ")),IF(F8<>0,F8*G$2/(100+G$2)," ")) -> 120 | H8: =IF((F8<>0),F8-G8," ") -> 600 | L8: =IF(F8<>0,F8-K8," ") -> 720 | M8: =IF((F8-K8)<>0,M$1-A8," ") -> 283 | O8: =IF((E8="a"),H8," ") -> 600 | P8: =IF((E8="b"),H8," ") | Q8: =IF((E8="c"),H8," ") | R8: =IF((E8="d"),H8," ") | S8: =IF((E8="g"),H8," ") | T8: =IF((E8="o"),H8," ") | U8: =IF((E8="FS"),H8," ")
A9: 45850 | B9: QuickFix IT | E9: a | F9: 960 | G9: =IF(G$4>0,(IF(F9<>0,F9*G$4/100," ")),IF(F9<>0,F9*G$2/(100+G$2)," ")) -> 160 | H9: =IF((F9<>0),F9-G9," ") -> 800 | L9: =IF(F9<>0,F9-K9," ") -> 960 | M9: =IF((F9-K9)<>0,M$1-A9," ") -> 281 | O9: =IF((E9="a"),H9," ") -> 800 | P9: =IF((E9="b"),H9," ") | Q9: =IF((E9="c"),H9," ") | R9: =IF((E9="d"),H9," ") | S9: =IF((E9="g"),H9," ") | T9: =IF((E9="o"),H9," ") | U9: =IF((E9="FS"),H9," ")
A10: 45853 | B10: Acme Corp | E10: a | F10: 25000 | G10: =IF(G$4>0,(IF(F10<>0,F10*G$4/100," ")),IF(F10<>0,F10*G$2/(100+G$2)," ")) -> 4166.6667 | H10: =IF((F10<>0),F10-G10," ") -> 20833.333 | L10: =IF(F10<>0,F10-K10," ") -> 25000 | M10: =IF((F10-K10)<>0,M$1-A10," ") -> 278 | O10: =IF((E10="a"),H10," ") -> 20833.333 | P10: =IF((E10="b"),H10," ") | Q10: =IF((E10="c"),H10," ") | R10: =IF((E10="d"),H10," ") | S10: =IF((E10="g"),H10," ") | T10: =IF((E10="o"),H10," ") | U10: =IF((E10="FS"),H10," ")
A11: 45854 | B11: Summit Training | E11: c | F11: 1200 | G11: =IF(G$4>0,(IF(F11<>0,F11*G$4/100," ")),IF(F11<>0,F11*G$2/(100+G$2)," ")) -> 200 | H11: =IF((F11<>0),F11-G11," ") -> 1000 | L11: =IF(F11<>0,F11-K11," ") -> 1200 | M11: =IF((F11-K11)<>0,M$1-A11," ") -> 277 | O11: =IF((E11="a"),H11," ") | P11: =IF((E11="b"),H11," ") | Q11: =IF((E11="c"),H11," ") -> 1000 | R11: =IF((E11="d"),H11," ") | S11: =IF((E11="g"),H11," ") | T11: =IF((E11="o"),H11," ") | U11: =IF((E11="FS"),H11," ")
A12: 45856 | B12: TechStart Ltd | E12: a | F12: 2400 | G12: =IF(G$4>0,(IF(F12<>0,F12*G$4/100," ")),IF(F12<>0,F12*G$2/(100+G$2)," ")) -> 400 | H12: =IF((F12<>0),F12-G12," ") -> 2000 | L12: =IF(F12<>0,F12-K12," ") -> 2400 | M12: =IF((F12-K12)<>0,M$1-A12," ") -> 275 | O12: =IF((E12="a"),H12," ") -> 2000 | P12: =IF((E12="b"),H12," ") | Q12: =IF((E12="c"),H12," ") | R12: =IF((E12="d"),H12," ") | S12: =IF((E12="g"),H12," ") | T12: =IF((E12="o"),H12," ") | U12: =IF((E12="FS"),H12," ")
A13: 45863 | B13: Oakridge Partners | E13: a | F13: 1200 | G13: =IF(G$4>0,(IF(F13<>0,F13*G$4/100," ")),IF(F13<>0,F13*G$2/(100+G$2)," ")) -> 200 | H13: =IF((F13<>0),F13-G13," ") -> 1000 | L13: =IF(F13<>0,F13-K13," ") -> 1200 | M13: =IF((F13-K13)<>0,M$1-A13," ") -> 268 | O13: =IF((E13="a"),H13," ") -> 1000 | P13: =IF((E13="b"),H13," ") | Q13: =IF((E13="c"),H13," ") | R13: =IF((E13="d"),H13," ") | S13: =IF((E13="g"),H13," ") | T13: =IF((E13="o"),H13," ") | U13: =IF((E13="FS"),H13," ")
G14: =IF(G$4>0,(IF(F14<>0,F14*G$4/100," ")),IF(F14<>0,F14*G$2/(100+G$2)," ")) | H14: =IF((F14<>0),F14-G14," ") | L14: =IF(F14<>0,F14-K14," ") | M14: =IF((F14-K14)<>0,M$1-A14," ") | O14: =IF((E14="a"),H14," ") | P14: =IF((E14="b"),H14," ") | Q14: =IF((E14="c"),H14," ") | R14: =IF((E14="d"),H14," ") | S14: =IF((E14="g"),H14," ") | T14: =IF((E14="o"),H14," ") | U14: =IF((E14="FS"),H14," ")
G15: =IF(G$4>0,(IF(F15<>0,F15*G$4/100," ")),IF(F15<>0,F15*G$2/(100+G$2)," ")) | H15: =IF((F15<>0),F15-G15," ") | L15: =IF(F15<>0,F15-K15," ") | M15: =IF((F15-K15)<>0,M$1-A15," ") | O15: =IF((E15="a"),H15," ") | P15: =IF((E15="b"),H15," ") | Q15: =IF((E15="c"),H15," ") | R15: =IF((E15="d"),H15," ") | S15: =IF((E15="g"),H15," ") | T15: =IF((E15="o"),H15," ") | U15: =IF((E15="FS"),H15," ")
G16: =IF(G$4>0,(IF(F16<>0,F16*G$4/100," ")),IF(F16<>0,F16*G$2/(100+G$2)," ")) | H16: =IF((F16<>0),F16-G16," ") | L16: =IF(F16<>0,F16-K16," ") | M16: =IF((F16-K16)<>0,M$1-A16," ") | O16: =IF((E16="a"),H16," ") | P16: =IF((E16="b"),H16," ") | Q16: =IF((E16="c"),H16," ") | R16: =IF((E16="d"),H16," ") | S16: =IF((E16="g"),H16," ") | T16: =IF((E16="o"),H16," ") | U16: =IF((E16="FS"),H16," ")
G17: =IF(G$4>0,(IF(F17<>0,F17*G$4/100," ")),IF(F17<>0,F17*G$2/(100+G$2)," ")) | H17: =IF((F17<>0),F17-G17," ") | L17: =IF(F17<>0,F17-K17," ") | M17: =IF((F17-K17)<>0,M$1-A17," ") | O17: =IF((E17="a"),H17," ") | P17: =IF((E17="b"),H17," ") | Q17: =IF((E17="c"),H17," ") | R17: =IF((E17="d"),H17," ") | S17: =IF((E17="g"),H17," ") | T17: =IF((E17="o"),H17," ") | U17: =IF((E17="FS"),H17," ")
G18: =IF(G$4>0,(IF(F18<>0,F18*G$4/100," ")),IF(F18<>0,F18*G$2/(100+G$2)," ")) | H18: =IF((F18<>0),F18-G18," ") | L18: =IF(F18<>0,F18-K18," ") | M18: =IF((F18-K18)<>0,M$1-A18," ") | O18: =IF((E18="a"),H18," ") | P18: =IF((E18="b"),H18," ") | Q18: =IF((E18="c"),H18," ") | R18: =IF((E18="d"),H18," ") | S18: =IF((E18="g"),H18," ") | T18: =IF((E18="o"),H18," ") | U18: =IF((E18="FS"),H18," ")
G19: =IF(G$4>0,(IF(F19<>0,F19*G$4/100," ")),IF(F19<>0,F19*G$2/(100+G$2)," ")) | H19: =IF((F19<>0),F19-G19," ") | L19: =IF(F19<>0,F19-K19," ") | M19: =IF((F19-K19)<>0,M$1-A19," ") | O19: =IF((E19="a"),H19," ") | P19: =IF((E19="b"),H19," ") | Q19: =IF((E19="c"),H19," ") | R19: =IF((E19="d"),H19," ") | S19: =IF((E19="g"),H19," ") | T19: =IF((E19="o"),H19," ") | U19: =IF((E19="FS"),H19," ")
G20: =IF(G$4>0,(IF(F20<>0,F20*G$4/100," ")),IF(F20<>0,F20*G$2/(100+G$2)," ")) | H20: =IF((F20<>0),F20-G20," ") | L20: =IF(F20<>0,F20-K20," ") | M20: =IF((F20-K20)<>0,M$1-A20," ") | O20: =IF((E20="a"),H20," ") | P20: =IF((E20="b"),H20," ") | Q20: =IF((E20="c"),H20," ") | R20: =IF((E20="d"),H20," ") | S20: =IF((E20="g"),H20," ") | T20: =IF((E20="o"),H20," ") | U20: =IF((E20="FS"),H20," ")
G21: =IF(G$4>0,(IF(F21<>0,F21*G$4/100," ")),IF(F21<>0,F21*G$2/(100+G$2)," ")) | H21: =IF((F21<>0),F21-G21," ") | L21: =IF(F21<>0,F21-K21," ") | M21: =IF((F21-K21)<>0,M$1-A21," ") | O21: =IF((E21="a"),H21," ") | P21: =IF((E21="b"),H21," ") | Q21: =IF((E21="c"),H21," ") | R21: =IF((E21="d"),H21," ") | S21: =IF((E21="g"),H21," ") | T21: =IF((E21="o"),H21," ") | U21: =IF((E21="FS"),H21," ")
G22: =IF(G$4>0,(IF(F22<>0,F22*G$4/100," ")),IF(F22<>0,F22*G$2/(100+G$2)," ")) | H22: =IF((F22<>0),F22-G22," ") | L22: =IF(F22<>0,F22-K22," ") | M22: =IF((F22-K22)<>0,M$1-A22," ") | O22: =IF((E22="a"),H22," ") | P22: =IF((E22="b"),H22," ") | Q22: =IF((E22="c"),H22," ") | R22: =IF((E22="d"),H22," ") | S22: =IF((E22="g"),H22," ") | T22: =IF((E22="o"),H22," ") | U22: =IF((E22="FS"),H22," ")
G23: =IF(G$4>0,(IF(F23<>0,F23*G$4/100," ")),IF(F23<>0,F23*G$2/(100+G$2)," ")) | H23: =IF((F23<>0),F23-G23," ") | L23: =IF(F23<>0,F23-K23," ") | M23: =IF((F23-K23)<>0,M$1-A23," ") | O23: =IF((E23="a"),H23," ") | P23: =IF((E23="b"),H23," ") | Q23: =IF((E23="c"),H23," ") | R23: =IF((E23="d"),H23," ") | S23: =IF((E23="g"),H23," ") | T23: =IF((E23="o"),H23," ") | U23: =IF((E23="FS"),H23," ")
G24: =IF(G$4>0,(IF(F24<>0,F24*G$4/100," ")),IF(F24<>0,F24*G$2/(100+G$2)," ")) | H24: =IF((F24<>0),F24-G24," ") | L24: =IF(F24<>0,F24-K24," ") | M24: =IF((F24-K24)<>0,M$1-A24," ") | O24: =IF((E24="a"),H24," ") | P24: =IF((E24="b"),H24," ") | Q24: =IF((E24="c"),H24," ") | R24: =IF((E24="d"),H24," ") | S24: =IF((E24="g"),H24," ") | T24: =IF((E24="o"),H24," ") | U24: =IF((E24="FS"),H24," ")
G25: =IF(G$4>0,(IF(F25<>0,F25*G$4/100," ")),IF(F25<>0,F25*G$2/(100+G$2)," ")) | H25: =IF((F25<>0),F25-G25," ") | L25: =IF(F25<>0,F25-K25," ") | M25: =IF((F25-K25)<>0,M$1-A25," ") | O25: =IF((E25="a"),H25," ") | P25: =IF((E25="b"),H25," ") | Q25: =IF((E25="c"),H25," ") | R25: =IF((E25="d"),H25," ") | S25: =IF((E25="g"),H25," ") | T25: =IF((E25="o"),H25," ") | U25: =IF((E25="FS"),H25," ")
... G69: =IF(G$4>0,(IF(F69<>0,F69*G$4/100," ")),IF(F69<>0,F69*G$2/(100+G$2)," ")) | H69: =IF((F69<>0),F69-G69," ") | L69: =IF(F69<>0,F69-K69," ") | M69: =IF((F69-K69)<>0,M$1-A69," ") | O69: =IF((E69="a"),H69," ") | P69: =IF((E69="b"),H69," ") | Q69: =IF((E69="c"),H69," ") | R69: =IF((E69="d"),H69," ") | S69: =IF((E69="g"),H69," ") | T69: =IF((E69="o"),H69," ") | U69: =IF((E69="FS"),H69," ")
E70: =IF((F70<>0),"Enter Letter"," ") | G70: =IF(G$4>0,(IF(F70<>0,F70*G$4/100," ")),IF(F70<>0,F70*G$2/(100+G$2)," ")) | H70: =IF((F70<>0),F70-G70," ") | L70: =IF(F70<>0,F70-K70," ") | M70: =IF((F70-K70)<>0,M$1-A70," ") | O70: =IF((E70="a"),H70," ") | P70: =IF((E70="b"),H70," ") | Q70: =IF((E70="c"),H70," ") | R70: =IF((E70="d"),H70," ") | S70: =IF((E70="g"),H70," ") | T70: =IF((E70="o"),H70," ") | U70: =IF((E70="FS"),H70," ")
E71: =IF((F71<>0),"Enter Letter"," ") | G71: =IF(G$4>0,(IF(F71<>0,F71*G$4/100," ")),IF(F71<>0,F71*G$2/(100+G$2)," ")) | H71: =IF((F71<>0),F71-G71," ") | L71: =IF(F71<>0,F71-K71," ") | M71: =IF((F71-K71)<>0,M$1-A71," ") | O71: =IF((E71="a"),H71," ") | P71: =IF((E71="b"),H71," ") | Q71: =IF((E71="c"),H71," ") | R71: =IF((E71="d"),H71," ") | S71: =IF((E71="g"),H71," ") | T71: =IF((E71="o"),H71," ") | U71: =IF((E71="FS"),H71," ")
E72: =IF((F72<>0),"Enter Letter"," ") | G72: =IF(G$4>0,(IF(F72<>0,F72*G$4/100," ")),IF(F72<>0,F72*G$2/(100+G$2)," ")) | H72: =IF((F72<>0),F72-G72," ") | L72: =IF(F72<>0,F72-K72," ") | M72: =IF((F72-K72)<>0,M$1-A72," ") | O72: =IF((E72="a"),H72," ") | P72: =IF((E72="b"),H72," ") | Q72: =IF((E72="c"),H72," ") | R72: =IF((E72="d"),H72," ") | S72: =IF((E72="g"),H72," ") | T72: =IF((E72="o"),H72," ") | U72: =IF((E72="FS"),H72," ")
E73: =IF((F73<>0),"Enter Letter"," ") | G73: =IF(G$4>0,(IF(F73<>0,F73*G$4/100," ")),IF(F73<>0,F73*G$2/(100+G$2)," ")) | H73: =IF((F73<>0),F73-G73," ") | L73: =IF(F73<>0,F73-K73," ") | M73: =IF((F73-K73)<>0,M$1-A73," ") | O73: =IF((E73="a"),H73," ") | P73: =IF((E73="b"),H73," ") | Q73: =IF((E73="c"),H73," ") | R73: =IF((E73="d"),H73," ") | S73: =IF((E73="g"),H73," ") | T73: =IF((E73="o"),H73," ") | U73: =IF((E73="FS"),H73," ")
E74: =IF((F74<>0),"Enter Letter"," ") | G74: =IF(G$4>0,(IF(F74<>0,F74*G$4/100," ")),IF(F74<>0,F74*G$2/(100+G$2)," ")) | H74: =IF((F74<>0),F74-G74," ") | L74: =IF(F74<>0,F74-K74," ") | M74: =IF((F74-K74)<>0,M$1-A74," ") | O74: =IF((E74="a"),H74," ") | P74: =IF((E74="b"),H74," ") | Q74: =IF((E74="c"),H74," ") | R74: =IF((E74="d"),H74," ") | S74: =IF((E74="g"),H74," ") | T74: =IF((E74="o"),H74," ") | U74: =IF((E74="FS"),H74," ")
E75: =IF((F75<>0),"Enter Letter"," ") | G75: =IF(G$4>0,(IF(F75<>0,F75*G$4/100," ")),IF(F75<>0,F75*G$2/(100+G$2)," ")) | H75: =IF((F75<>0),F75-G75," ") | L75: =IF(F75<>0,F75-K75," ") | M75: =IF((F75-K75)<>0,M$1-A75," ") | O75: =IF((E75="a"),H75," ") | P75: =IF((E75="b"),H75," ") | Q75: =IF((E75="c"),H75," ") | R75: =IF((E75="d"),H75," ") | S75: =IF((E75="g"),H75," ") | T75: =IF((E75="o"),H75," ") | U75: =IF((E75="FS"),H75," ")
E76: =IF((F76<>0),"Enter Letter"," ") | G76: =IF(G$4>0,(IF(F76<>0,F76*G$4/100," ")),IF(F76<>0,F76*G$2/(100+G$2)," ")) | H76: =IF((F76<>0),F76-G76," ") | L76: =IF(F76<>0,F76-K76," ") | M76: =IF((F76-K76)<>0,M$1-A76," ") | O76: =IF((E76="a"),H76," ") | P76: =IF((E76="b"),H76," ") | Q76: =IF((E76="c"),H76," ") | R76: =IF((E76="d"),H76," ") | S76: =IF((E76="g"),H76," ") | T76: =IF((E76="o"),H76," ") | U76: =IF((E76="FS"),H76," ")
E77: =IF((F77<>0),"Enter Letter"," ") | G77: =IF(G$4>0,(IF(F77<>0,F77*G$4/100," ")),IF(F77<>0,F77*G$2/(100+G$2)," ")) | H77: =IF((F77<>0),F77-G77," ") | L77: =IF(F77<>0,F77-K77," ") | M77: =IF((F77-K77)<>0,M$1-A77," ") | O77: =IF((E77="a"),H77," ") | P77: =IF((E77="b"),H77," ") | Q77: =IF((E77="c"),H77," ") | R77: =IF((E77="d"),H77," ") | S77: =IF((E77="g"),H77," ") | T77: =IF((E77="o"),H77," ") | U77: =IF((E77="FS"),H77," ")
E78: =IF((F78<>0),"Enter Letter"," ") | G78: =IF(G$4>0,(IF(F78<>0,F78*G$4/100," ")),IF(F78<>0,F78*G$2/(100+G$2)," ")) | H78: =IF((F78<>0),F78-G78," ") | L78: =IF(F78<>0,F78-K78," ") | M78: =IF((F78-K78)<>0,M$1-A78," ") | O78: =IF((E78="a"),H78," ") | P78: =IF((E78="b"),H78," ") | Q78: =IF((E78="c"),H78," ") | R78: =IF((E78="d"),H78," ") | S78: =IF((E78="g"),H78," ") | T78: =IF((E78="o"),H78," ") | U78: =IF((E78="FS"),H78," ")
E79: =IF((F79<>0),"Enter Letter"," ") | G79: =IF(G$4>0,(IF(F79<>0,F79*G$4/100," ")),IF(F79<>0,F79*G$2/(100+G$2)," ")) | H79: =IF((F79<>0),F79-G79," ") | L79: =IF(F79<>0,F79-K79," ") | M79: =IF((F79-K79)<>0,M$1-A79," ") | O79: =IF((E79="a"),H79," ") | P79: =IF((E79="b"),H79," ") | Q79: =IF((E79="c"),H79," ") | R79: =IF((E79="d"),H79," ") | S79: =IF((E79="g"),H79," ") | T79: =IF((E79="o"),H79," ") | U79: =IF((E79="FS"),H79," ")
E80: =IF((F80<>0),"Enter Letter"," ") | G80: =IF(G$4>0,(IF(F80<>0,F80*G$4/100," ")),IF(F80<>0,F80*G$2/(100+G$2)," ")) | H80: =IF((F80<>0),F80-G80," ") | L80: =IF(F80<>0,F80-K80," ") | M80: =IF((F80-K80)<>0,M$1-A80," ") | O80: =IF((E80="a"),H80," ") | P80: =IF((E80="b"),H80," ") | Q80: =IF((E80="c"),H80," ") | R80: =IF((E80="d"),H80," ") | S80: =IF((E80="g"),H80," ") | T80: =IF((E80="o"),H80," ") | U80: =IF((E80="FS"),H80," ")
E81: =IF((F81<>0),"Enter Letter"," ") | G81: =IF(G$4>0,(IF(F81<>0,F81*G$4/100," ")),IF(F81<>0,F81*G$2/(100+G$2)," ")) | H81: =IF((F81<>0),F81-G81," ") | L81: =IF(F81<>0,F81-K81," ") | M81: =IF((F81-K81)<>0,M$1-A81," ") | O81: =IF((E81="a"),H81," ") | P81: =IF((E81="b"),H81," ") | Q81: =IF((E81="c"),H81," ") | R81: =IF((E81="d"),H81," ") | S81: =IF((E81="g"),H81," ") | T81: =IF((E81="o"),H81," ") | U81: =IF((E81="FS"),H81," ")
... E300: =IF((F300<>0),"Enter Letter"," ") | G300: =IF(G$4>0,(IF(F300<>0,F300*G$4/100," ")),IF(F300<>0,F300*G$2/(100+G$2)," ")) | H300: =IF((F300<>0),F300-G300," ") | L300: =IF(F300<>0,F300-K300," ") | M300: =IF((F300-K300)<>0,M$1-A300," ") | O300: =IF((E300="a"),H300," ") | P300: =IF((E300="b"),H300," ") | Q300: =IF((E300="c"),H300," ") | R300: =IF((E300="d"),H300," ") | S300: =IF((E300="g"),H300," ") | T300: =IF((E300="o"),H300," ") | U300: =IF((E300="FS"),H300," ")

Sheet Aug
A1: =F1-G1-SUM(O1:U1) -> 0 | B1: Check Total | C1: Sales Invoice Number or reference | D1: Total for Month | F1: =SUM(F5:F300) -> 35200 | G1: =SUM(G5:G300) -> 5866.6667 | H1: =SUM(H5:H300) -> 29333.333 | J1: For your information only. Enter How Paid e.g. Cash, Cheque etc., | K1: =SUM(K5:K300) -> 0 | L1: =SUM(L5:L300) -> 35200 | M1: =TODAY() -> 46131 | O1: =SUM(O5:O300) -> 26533.333 | P1: =SUM(P5:P300) -> 800 | Q1: =SUM(Q5:Q300) -> 2000 | R1: =SUM(R5:R300) -> 0 | S1: =SUM(S5:S300) -> 0 | T1: =SUM(T5:T300) -> 0 | U1: =SUM(U5:U300) -> 0 | V1: =SUM(V5:V300) -> 0
A2: Sales Date | B2: Customer Name | D2: Sales Description | E2: Enter Expense Code Letter | F2: Sales Value including Vat | G2: =Jul!G2 -> 20 | H2: Sales Net of Vat | K2: Receipts from Customers | O2: Sales Net of Vat | R2: Other Income | S2: Investment Grants | T2: Bad Debts written off | U2: Sale of Fixed Assets | V2: Sub contractors only
G3: Vat Output | K3: Actual amount received | L3: Sales Value not yet received | M3: Number of Days Outstanding | O3: Product A | P3: Product B | Q3: Product C | V3: CIS Tax Deducted | W3: CIS Certificate reference
G4: =Jul!G4 -> 0 | O4: A | P4: B | Q4: C | R4: D | S4: G | T4: O | U4: FS
A5: 45872 | B5: FreshField Ltd | E5: b | F5: 360 | G5: =IF(G$4>0,(IF(F5<>0,F5*G$4/100," ")),IF(F5<>0,F5*G$2/(100+G$2)," ")) -> 60 | H5: =IF((F5<>0),F5-G5," ") -> 300 | L5: =IF(F5<>0,F5-K5," ") -> 360 | M5: =IF((F5-K5)<>0,M$1-A5," ") -> 259 | O5: =IF((E5="a"),H5," ") | P5: =IF((E5="b"),H5," ") -> 300 | Q5: =IF((E5="c"),H5," ") | R5: =IF((E5="d"),H5," ") | S5: =IF((E5="g"),H5," ") | T5: =IF((E5="o"),H5," ") | U5: =IF((E5="FS"),H5," ")
A6: 45874 | B6: CloudNine Ltd | E6: b | F6: 600 | G6: =IF(G$4>0,(IF(F6<>0,F6*G$4/100," ")),IF(F6<>0,F6*G$2/(100+G$2)," ")) -> 100 | H6: =IF((F6<>0),F6-G6," ") -> 500 | L6: =IF(F6<>0,F6-K6," ") -> 600 | M6: =IF((F6-K6)<>0,M$1-A6," ") -> 257 | O6: =IF((E6="a"),H6," ") | P6: =IF((E6="b"),H6," ") -> 500 | Q6: =IF((E6="c"),H6," ") | R6: =IF((E6="d"),H6," ") | S6: =IF((E6="g"),H6," ") | T6: =IF((E6="o"),H6," ") | U6: =IF((E6="FS"),H6," ")
A7: 45877 | B7: Cedar Systems | E7: a | F7: 480 | G7: =IF(G$4>0,(IF(F7<>0,F7*G$4/100," ")),IF(F7<>0,F7*G$2/(100+G$2)," ")) -> 80 | H7: =IF((F7<>0),F7-G7," ") -> 400 | L7: =IF(F7<>0,F7-K7," ") -> 480 | M7: =IF((F7-K7)<>0,M$1-A7," ") -> 254 | O7: =IF((E7="a"),H7," ") -> 400 | P7: =IF((E7="b"),H7," ") | Q7: =IF((E7="c"),H7," ") | R7: =IF((E7="d"),H7," ") | S7: =IF((E7="g"),H7," ") | T7: =IF((E7="o"),H7," ") | U7: =IF((E7="FS"),H7," ")
A8: 45879 | B8: Pinnacle Group | E8: a | F8: 720 | G8: =IF(G$4>0,(IF(F8<>0,F8*G$4/100," ")),IF(F8<>0,F8*G$2/(100+G$2)," ")) -> 120 | H8: =IF((F8<>0),F8-G8," ") -> 600 | L8: =IF(F8<>0,F8-K8," ") -> 720 | M8: =IF((F8-K8)<>0,M$1-A8," ") -> 252 | O8: =IF((E8="a"),H8," ") -> 600 | P8: =IF((E8="b"),H8," ") | Q8: =IF((E8="c"),H8," ") | R8: =IF((E8="d"),H8," ") | S8: =IF((E8="g"),H8," ") | T8: =IF((E8="o"),H8," ") | U8: =IF((E8="FS"),H8," ")
A9: 45884 | B9: Acme Corp | E9: a | F9: 25000 | G9: =IF(G$4>0,(IF(F9<>0,F9*G$4/100," ")),IF(F9<>0,F9*G$2/(100+G$2)," ")) -> 4166.6667 | H9: =IF((F9<>0),F9-G9," ") -> 20833.333 | L9: =IF(F9<>0,F9-K9," ") -> 25000 | M9: =IF((F9-K9)<>0,M$1-A9," ") -> 247 | O9: =IF((E9="a"),H9," ") -> 20833.333 | P9: =IF((E9="b"),H9," ") | Q9: =IF((E9="c"),H9," ") | R9: =IF((E9="d"),H9," ") | S9: =IF((E9="g"),H9," ") | T9: =IF((E9="o"),H9," ") | U9: =IF((E9="FS"),H9," ")
A10: 45887 | B10: TechStart Ltd | E10: a | F10: 2400 | G10: =IF(G$4>0,(IF(F10<>0,F10*G$4/100," ")),IF(F10<>0,F10*G$2/(100+G$2)," ")) -> 400 | H10: =IF((F10<>0),F10-G10," ") -> 2000 | L10: =IF(F10<>0,F10-K10," ") -> 2400 | M10: =IF((F10-K10)<>0,M$1-A10," ") -> 244 | O10: =IF((E10="a"),H10," ") -> 2000 | P10: =IF((E10="b"),H10," ") | Q10: =IF((E10="c"),H10," ") | R10: =IF((E10="d"),H10," ") | S10: =IF((E10="g"),H10," ") | T10: =IF((E10="o"),H10," ") | U10: =IF((E10="FS"),H10," ")
A11: 45889 | B11: DataFlow Inc | E11: a | F11: 1800 | G11: =IF(G$4>0,(IF(F11<>0,F11*G$4/100," ")),IF(F11<>0,F11*G$2/(100+G$2)," ")) -> 300 | H11: =IF((F11<>0),F11-G11," ") -> 1500 | L11: =IF(F11<>0,F11-K11," ") -> 1800 | M11: =IF((F11-K11)<>0,M$1-A11," ") -> 242 | O11: =IF((E11="a"),H11," ") -> 1500 | P11: =IF((E11="b"),H11," ") | Q11: =IF((E11="c"),H11," ") | R11: =IF((E11="d"),H11," ") | S11: =IF((E11="g"),H11," ") | T11: =IF((E11="o"),H11," ") | U11: =IF((E11="FS"),H11," ")
A12: 45889 | B12: Gamma Ltd | E12: c | F12: 2400 | G12: =IF(G$4>0,(IF(F12<>0,F12*G$4/100," ")),IF(F12<>0,F12*G$2/(100+G$2)," ")) -> 400 | H12: =IF((F12<>0),F12-G12," ") -> 2000 | L12: =IF(F12<>0,F12-K12," ") -> 2400 | M12: =IF((F12-K12)<>0,M$1-A12," ") -> 242 | O12: =IF((E12="a"),H12," ") | P12: =IF((E12="b"),H12," ") | Q12: =IF((E12="c"),H12," ") -> 2000 | R12: =IF((E12="d"),H12," ") | S12: =IF((E12="g"),H12," ") | T12: =IF((E12="o"),H12," ") | U12: =IF((E12="FS"),H12," ")
A13: 45891 | B13: WidgetWorks | E13: a | F13: 1440 | G13: =IF(G$4>0,(IF(F13<>0,F13*G$4/100," ")),IF(F13<>0,F13*G$2/(100+G$2)," ")) -> 240 | H13: =IF((F13<>0),F13-G13," ") -> 1200 | L13: =IF(F13<>0,F13-K13," ") -> 1440 | M13: =IF((F13-K13)<>0,M$1-A13," ") -> 240 | O13: =IF((E13="a"),H13," ") -> 1200 | P13: =IF((E13="b"),H13," ") | Q13: =IF((E13="c"),H13," ") | R13: =IF((E13="d"),H13," ") | S13: =IF((E13="g"),H13," ") | T13: =IF((E13="o"),H13," ") | U13: =IF((E13="FS"),H13," ")
G14: =IF(G$4>0,(IF(F14<>0,F14*G$4/100," ")),IF(F14<>0,F14*G$2/(100+G$2)," ")) | H14: =IF((F14<>0),F14-G14," ") | L14: =IF(F14<>0,F14-K14," ") | M14: =IF((F14-K14)<>0,M$1-A14," ") | O14: =IF((E14="a"),H14," ") | P14: =IF((E14="b"),H14," ") | Q14: =IF((E14="c"),H14," ") | R14: =IF((E14="d"),H14," ") | S14: =IF((E14="g"),H14," ") | T14: =IF((E14="o"),H14," ") | U14: =IF((E14="FS"),H14," ")
G15: =IF(G$4>0,(IF(F15<>0,F15*G$4/100," ")),IF(F15<>0,F15*G$2/(100+G$2)," ")) | H15: =IF((F15<>0),F15-G15," ") | L15: =IF(F15<>0,F15-K15," ") | M15: =IF((F15-K15)<>0,M$1-A15," ") | O15: =IF((E15="a"),H15," ") | P15: =IF((E15="b"),H15," ") | Q15: =IF((E15="c"),H15," ") | R15: =IF((E15="d"),H15," ") | S15: =IF((E15="g"),H15," ") | T15: =IF((E15="o"),H15," ") | U15: =IF((E15="FS"),H15," ")
G16: =IF(G$4>0,(IF(F16<>0,F16*G$4/100," ")),IF(F16<>0,F16*G$2/(100+G$2)," ")) | H16: =IF((F16<>0),F16-G16," ") | L16: =IF(F16<>0,F16-K16," ") | M16: =IF((F16-K16)<>0,M$1-A16," ") | O16: =IF((E16="a"),H16," ") | P16: =IF((E16="b"),H16," ") | Q16: =IF((E16="c"),H16," ") | R16: =IF((E16="d"),H16," ") | S16: =IF((E16="g"),H16," ") | T16: =IF((E16="o"),H16," ") | U16: =IF((E16="FS"),H16," ")
G17: =IF(G$4>0,(IF(F17<>0,F17*G$4/100," ")),IF(F17<>0,F17*G$2/(100+G$2)," ")) | H17: =IF((F17<>0),F17-G17," ") | L17: =IF(F17<>0,F17-K17," ") | M17: =IF((F17-K17)<>0,M$1-A17," ") | O17: =IF((E17="a"),H17," ") | P17: =IF((E17="b"),H17," ") | Q17: =IF((E17="c"),H17," ") | R17: =IF((E17="d"),H17," ") | S17: =IF((E17="g"),H17," ") | T17: =IF((E17="o"),H17," ") | U17: =IF((E17="FS"),H17," ")
G18: =IF(G$4>0,(IF(F18<>0,F18*G$4/100," ")),IF(F18<>0,F18*G$2/(100+G$2)," ")) | H18: =IF((F18<>0),F18-G18," ") | L18: =IF(F18<>0,F18-K18," ") | M18: =IF((F18-K18)<>0,M$1-A18," ") | O18: =IF((E18="a"),H18," ") | P18: =IF((E18="b"),H18," ") | Q18: =IF((E18="c"),H18," ") | R18: =IF((E18="d"),H18," ") | S18: =IF((E18="g"),H18," ") | T18: =IF((E18="o"),H18," ") | U18: =IF((E18="FS"),H18," ")
G19: =IF(G$4>0,(IF(F19<>0,F19*G$4/100," ")),IF(F19<>0,F19*G$2/(100+G$2)," ")) | H19: =IF((F19<>0),F19-G19," ") | L19: =IF(F19<>0,F19-K19," ") | M19: =IF((F19-K19)<>0,M$1-A19," ") | O19: =IF((E19="a"),H19," ") | P19: =IF((E19="b"),H19," ") | Q19: =IF((E19="c"),H19," ") | R19: =IF((E19="d"),H19," ") | S19: =IF((E19="g"),H19," ") | T19: =IF((E19="o"),H19," ") | U19: =IF((E19="FS"),H19," ")
G20: =IF(G$4>0,(IF(F20<>0,F20*G$4/100," ")),IF(F20<>0,F20*G$2/(100+G$2)," ")) | H20: =IF((F20<>0),F20-G20," ") | L20: =IF(F20<>0,F20-K20," ") | M20: =IF((F20-K20)<>0,M$1-A20," ") | O20: =IF((E20="a"),H20," ") | P20: =IF((E20="b"),H20," ") | Q20: =IF((E20="c"),H20," ") | R20: =IF((E20="d"),H20," ") | S20: =IF((E20="g"),H20," ") | T20: =IF((E20="o"),H20," ") | U20: =IF((E20="FS"),H20," ")
G21: =IF(G$4>0,(IF(F21<>0,F21*G$4/100," ")),IF(F21<>0,F21*G$2/(100+G$2)," ")) | H21: =IF((F21<>0),F21-G21," ") | L21: =IF(F21<>0,F21-K21," ") | M21: =IF((F21-K21)<>0,M$1-A21," ") | O21: =IF((E21="a"),H21," ") | P21: =IF((E21="b"),H21," ") | Q21: =IF((E21="c"),H21," ") | R21: =IF((E21="d"),H21," ") | S21: =IF((E21="g"),H21," ") | T21: =IF((E21="o"),H21," ") | U21: =IF((E21="FS"),H21," ")
G22: =IF(G$4>0,(IF(F22<>0,F22*G$4/100," ")),IF(F22<>0,F22*G$2/(100+G$2)," ")) | H22: =IF((F22<>0),F22-G22," ") | L22: =IF(F22<>0,F22-K22," ") | M22: =IF((F22-K22)<>0,M$1-A22," ") | O22: =IF((E22="a"),H22," ") | P22: =IF((E22="b"),H22," ") | Q22: =IF((E22="c"),H22," ") | R22: =IF((E22="d"),H22," ") | S22: =IF((E22="g"),H22," ") | T22: =IF((E22="o"),H22," ") | U22: =IF((E22="FS"),H22," ")
G23: =IF(G$4>0,(IF(F23<>0,F23*G$4/100," ")),IF(F23<>0,F23*G$2/(100+G$2)," ")) | H23: =IF((F23<>0),F23-G23," ") | L23: =IF(F23<>0,F23-K23," ") | M23: =IF((F23-K23)<>0,M$1-A23," ") | O23: =IF((E23="a"),H23," ") | P23: =IF((E23="b"),H23," ") | Q23: =IF((E23="c"),H23," ") | R23: =IF((E23="d"),H23," ") | S23: =IF((E23="g"),H23," ") | T23: =IF((E23="o"),H23," ") | U23: =IF((E23="FS"),H23," ")
G24: =IF(G$4>0,(IF(F24<>0,F24*G$4/100," ")),IF(F24<>0,F24*G$2/(100+G$2)," ")) | H24: =IF((F24<>0),F24-G24," ") | L24: =IF(F24<>0,F24-K24," ") | M24: =IF((F24-K24)<>0,M$1-A24," ") | O24: =IF((E24="a"),H24," ") | P24: =IF((E24="b"),H24," ") | Q24: =IF((E24="c"),H24," ") | R24: =IF((E24="d"),H24," ") | S24: =IF((E24="g"),H24," ") | T24: =IF((E24="o"),H24," ") | U24: =IF((E24="FS"),H24," ")
G25: =IF(G$4>0,(IF(F25<>0,F25*G$4/100," ")),IF(F25<>0,F25*G$2/(100+G$2)," ")) | H25: =IF((F25<>0),F25-G25," ") | L25: =IF(F25<>0,F25-K25," ") | M25: =IF((F25-K25)<>0,M$1-A25," ") | O25: =IF((E25="a"),H25," ") | P25: =IF((E25="b"),H25," ") | Q25: =IF((E25="c"),H25," ") | R25: =IF((E25="d"),H25," ") | S25: =IF((E25="g"),H25," ") | T25: =IF((E25="o"),H25," ") | U25: =IF((E25="FS"),H25," ")
... G69: =IF(G$4>0,(IF(F69<>0,F69*G$4/100," ")),IF(F69<>0,F69*G$2/(100+G$2)," ")) | H69: =IF((F69<>0),F69-G69," ") | L69: =IF(F69<>0,F69-K69," ") | M69: =IF((F69-K69)<>0,M$1-A69," ") | O69: =IF((E69="a"),H69," ") | P69: =IF((E69="b"),H69," ") | Q69: =IF((E69="c"),H69," ") | R69: =IF((E69="d"),H69," ") | S69: =IF((E69="g"),H69," ") | T69: =IF((E69="o"),H69," ") | U69: =IF((E69="FS"),H69," ")
E70: =IF((F70<>0),"Enter Letter"," ") | G70: =IF(G$4>0,(IF(F70<>0,F70*G$4/100," ")),IF(F70<>0,F70*G$2/(100+G$2)," ")) | H70: =IF((F70<>0),F70-G70," ") | L70: =IF(F70<>0,F70-K70," ") | M70: =IF((F70-K70)<>0,M$1-A70," ") | O70: =IF((E70="a"),H70," ") | P70: =IF((E70="b"),H70," ") | Q70: =IF((E70="c"),H70," ") | R70: =IF((E70="d"),H70," ") | S70: =IF((E70="g"),H70," ") | T70: =IF((E70="o"),H70," ") | U70: =IF((E70="FS"),H70," ")
E71: =IF((F71<>0),"Enter Letter"," ") | G71: =IF(G$4>0,(IF(F71<>0,F71*G$4/100," ")),IF(F71<>0,F71*G$2/(100+G$2)," ")) | H71: =IF((F71<>0),F71-G71," ") | L71: =IF(F71<>0,F71-K71," ") | M71: =IF((F71-K71)<>0,M$1-A71," ") | O71: =IF((E71="a"),H71," ") | P71: =IF((E71="b"),H71," ") | Q71: =IF((E71="c"),H71," ") | R71: =IF((E71="d"),H71," ") | S71: =IF((E71="g"),H71," ") | T71: =IF((E71="o"),H71," ") | U71: =IF((E71="FS"),H71," ")
E72: =IF((F72<>0),"Enter Letter"," ") | G72: =IF(G$4>0,(IF(F72<>0,F72*G$4/100," ")),IF(F72<>0,F72*G$2/(100+G$2)," ")) | H72: =IF((F72<>0),F72-G72," ") | L72: =IF(F72<>0,F72-K72," ") | M72: =IF((F72-K72)<>0,M$1-A72," ") | O72: =IF((E72="a"),H72," ") | P72: =IF((E72="b"),H72," ") | Q72: =IF((E72="c"),H72," ") | R72: =IF((E72="d"),H72," ") | S72: =IF((E72="g"),H72," ") | T72: =IF((E72="o"),H72," ") | U72: =IF((E72="FS"),H72," ")
E73: =IF((F73<>0),"Enter Letter"," ") | G73: =IF(G$4>0,(IF(F73<>0,F73*G$4/100," ")),IF(F73<>0,F73*G$2/(100+G$2)," ")) | H73: =IF((F73<>0),F73-G73," ") | L73: =IF(F73<>0,F73-K73," ") | M73: =IF((F73-K73)<>0,M$1-A73," ") | O73: =IF((E73="a"),H73," ") | P73: =IF((E73="b"),H73," ") | Q73: =IF((E73="c"),H73," ") | R73: =IF((E73="d"),H73," ") | S73: =IF((E73="g"),H73," ") | T73: =IF((E73="o"),H73," ") | U73: =IF((E73="FS"),H73," ")
E74: =IF((F74<>0),"Enter Letter"," ") | G74: =IF(G$4>0,(IF(F74<>0,F74*G$4/100," ")),IF(F74<>0,F74*G$2/(100+G$2)," ")) | H74: =IF((F74<>0),F74-G74," ") | L74: =IF(F74<>0,F74-K74," ") | M74: =IF((F74-K74)<>0,M$1-A74," ") | O74: =IF((E74="a"),H74," ") | P74: =IF((E74="b"),H74," ") | Q74: =IF((E74="c"),H74," ") | R74: =IF((E74="d"),H74," ") | S74: =IF((E74="g"),H74," ") | T74: =IF((E74="o"),H74," ") | U74: =IF((E74="FS"),H74," ")
E75: =IF((F75<>0),"Enter Letter"," ") | G75: =IF(G$4>0,(IF(F75<>0,F75*G$4/100," ")),IF(F75<>0,F75*G$2/(100+G$2)," ")) | H75: =IF((F75<>0),F75-G75," ") | L75: =IF(F75<>0,F75-K75," ") | M75: =IF((F75-K75)<>0,M$1-A75," ") | O75: =IF((E75="a"),H75," ") | P75: =IF((E75="b"),H75," ") | Q75: =IF((E75="c"),H75," ") | R75: =IF((E75="d"),H75," ") | S75: =IF((E75="g"),H75," ") | T75: =IF((E75="o"),H75," ") | U75: =IF((E75="FS"),H75," ")
E76: =IF((F76<>0),"Enter Letter"," ") | G76: =IF(G$4>0,(IF(F76<>0,F76*G$4/100," ")),IF(F76<>0,F76*G$2/(100+G$2)," ")) | H76: =IF((F76<>0),F76-G76," ") | L76: =IF(F76<>0,F76-K76," ") | M76: =IF((F76-K76)<>0,M$1-A76," ") | O76: =IF((E76="a"),H76," ") | P76: =IF((E76="b"),H76," ") | Q76: =IF((E76="c"),H76," ") | R76: =IF((E76="d"),H76," ") | S76: =IF((E76="g"),H76," ") | T76: =IF((E76="o"),H76," ") | U76: =IF((E76="FS"),H76," ")
E77: =IF((F77<>0),"Enter Letter"," ") | G77: =IF(G$4>0,(IF(F77<>0,F77*G$4/100," ")),IF(F77<>0,F77*G$2/(100+G$2)," ")) | H77: =IF((F77<>0),F77-G77," ") | L77: =IF(F77<>0,F77-K77," ") | M77: =IF((F77-K77)<>0,M$1-A77," ") | O77: =IF((E77="a"),H77," ") | P77: =IF((E77="b"),H77," ") | Q77: =IF((E77="c"),H77," ") | R77: =IF((E77="d"),H77," ") | S77: =IF((E77="g"),H77," ") | T77: =IF((E77="o"),H77," ") | U77: =IF((E77="FS"),H77," ")
E78: =IF((F78<>0),"Enter Letter"," ") | G78: =IF(G$4>0,(IF(F78<>0,F78*G$4/100," ")),IF(F78<>0,F78*G$2/(100+G$2)," ")) | H78: =IF((F78<>0),F78-G78," ") | L78: =IF(F78<>0,F78-K78," ") | M78: =IF((F78-K78)<>0,M$1-A78," ") | O78: =IF((E78="a"),H78," ") | P78: =IF((E78="b"),H78," ") | Q78: =IF((E78="c"),H78," ") | R78: =IF((E78="d"),H78," ") | S78: =IF((E78="g"),H78," ") | T78: =IF((E78="o"),H78," ") | U78: =IF((E78="FS"),H78," ")
E79: =IF((F79<>0),"Enter Letter"," ") | G79: =IF(G$4>0,(IF(F79<>0,F79*G$4/100," ")),IF(F79<>0,F79*G$2/(100+G$2)," ")) | H79: =IF((F79<>0),F79-G79," ") | L79: =IF(F79<>0,F79-K79," ") | M79: =IF((F79-K79)<>0,M$1-A79," ") | O79: =IF((E79="a"),H79," ") | P79: =IF((E79="b"),H79," ") | Q79: =IF((E79="c"),H79," ") | R79: =IF((E79="d"),H79," ") | S79: =IF((E79="g"),H79," ") | T79: =IF((E79="o"),H79," ") | U79: =IF((E79="FS"),H79," ")
E80: =IF((F80<>0),"Enter Letter"," ") | G80: =IF(G$4>0,(IF(F80<>0,F80*G$4/100," ")),IF(F80<>0,F80*G$2/(100+G$2)," ")) | H80: =IF((F80<>0),F80-G80," ") | L80: =IF(F80<>0,F80-K80," ") | M80: =IF((F80-K80)<>0,M$1-A80," ") | O80: =IF((E80="a"),H80," ") | P80: =IF((E80="b"),H80," ") | Q80: =IF((E80="c"),H80," ") | R80: =IF((E80="d"),H80," ") | S80: =IF((E80="g"),H80," ") | T80: =IF((E80="o"),H80," ") | U80: =IF((E80="FS"),H80," ")
E81: =IF((F81<>0),"Enter Letter"," ") | G81: =IF(G$4>0,(IF(F81<>0,F81*G$4/100," ")),IF(F81<>0,F81*G$2/(100+G$2)," ")) | H81: =IF((F81<>0),F81-G81," ") | L81: =IF(F81<>0,F81-K81," ") | M81: =IF((F81-K81)<>0,M$1-A81," ") | O81: =IF((E81="a"),H81," ") | P81: =IF((E81="b"),H81," ") | Q81: =IF((E81="c"),H81," ") | R81: =IF((E81="d"),H81," ") | S81: =IF((E81="g"),H81," ") | T81: =IF((E81="o"),H81," ") | U81: =IF((E81="FS"),H81," ")
... E300: =IF((F300<>0),"Enter Letter"," ") | G300: =IF(G$4>0,(IF(F300<>0,F300*G$4/100," ")),IF(F300<>0,F300*G$2/(100+G$2)," ")) | H300: =IF((F300<>0),F300-G300," ") | L300: =IF(F300<>0,F300-K300," ") | M300: =IF((F300-K300)<>0,M$1-A300," ") | O300: =IF((E300="a"),H300," ") | P300: =IF((E300="b"),H300," ") | Q300: =IF((E300="c"),H300," ") | R300: =IF((E300="d"),H300," ") | S300: =IF((E300="g"),H300," ") | T300: =IF((E300="o"),H300," ") | U300: =IF((E300="FS"),H300," ")

Sheet Sep
A1: =F1-G1-SUM(O1:U1) -> 0 | B1: Check Total | C1: Sales Invoice Number or reference | D1: Total for Month | F1: =SUM(F5:F300) -> 33760 | G1: =SUM(G5:G300) -> 5626.6667 | H1: =SUM(H5:H300) -> 28133.333 | J1: For your information only. Enter How Paid e.g. Cash, Cheque etc., | K1: =SUM(K5:K300) -> 0 | L1: =SUM(L5:L300) -> 33760 | M1: =TODAY() -> 46131 | O1: =SUM(O5:O300) -> 25633.333 | P1: =SUM(P5:P300) -> 1800 | Q1: =SUM(Q5:Q300) -> 0 | R1: =SUM(R5:R300) -> 700 | S1: =SUM(S5:S300) -> 0 | T1: =SUM(T5:T300) -> 0 | U1: =SUM(U5:U300) -> 0 | V1: =SUM(V5:V300) -> 0
A2: Sales Date | B2: Customer Name | D2: Sales Description | E2: Enter Expense Code Letter | F2: Sales Value including Vat | G2: =Aug!G2 -> 20 | H2: Sales Net of Vat | K2: Receipts from Customers | O2: Sales Net of Vat | R2: Other Income | S2: Investment Grants | T2: Bad Debts written off | U2: Sale of Fixed Assets | V2: Sub contractors only
G3: Vat Output | K3: Actual amount received | L3: Sales Value not yet received | M3: Number of Days Outstanding | O3: Product A | P3: Product B | Q3: Product C | V3: CIS Tax Deducted | W3: CIS Certificate reference
G4: =Aug!G4 -> 0 | O4: A | P4: B | Q4: C | R4: D | S4: G | T4: O | U4: FS
A5: 45901 | B5: Beta Systems | E5: b | F5: 1200 | G5: =IF(G$4>0,(IF(F5<>0,F5*G$4/100," ")),IF(F5<>0,F5*G$2/(100+G$2)," ")) -> 200 | H5: =IF((F5<>0),F5-G5," ") -> 1000 | L5: =IF(F5<>0,F5-K5," ") -> 1200 | M5: =IF((F5-K5)<>0,M$1-A5," ") -> 230 | O5: =IF((E5="a"),H5," ") | P5: =IF((E5="b"),H5," ") -> 1000 | Q5: =IF((E5="c"),H5," ") | R5: =IF((E5="d"),H5," ") | S5: =IF((E5="g"),H5," ") | T5: =IF((E5="o"),H5," ") | U5: =IF((E5="FS"),H5," ")
A6: 45903 | B6: FreshField Ltd | E6: b | F6: 360 | G6: =IF(G$4>0,(IF(F6<>0,F6*G$4/100," ")),IF(F6<>0,F6*G$2/(100+G$2)," ")) -> 60 | H6: =IF((F6<>0),F6-G6," ") -> 300 | L6: =IF(F6<>0,F6-K6," ") -> 360 | M6: =IF((F6-K6)<>0,M$1-A6," ") -> 228 | O6: =IF((E6="a"),H6," ") | P6: =IF((E6="b"),H6," ") -> 300 | Q6: =IF((E6="c"),H6," ") | R6: =IF((E6="d"),H6," ") | S6: =IF((E6="g"),H6," ") | T6: =IF((E6="o"),H6," ") | U6: =IF((E6="FS"),H6," ")
A7: 45905 | B7: CloudNine Ltd | E7: b | F7: 600 | G7: =IF(G$4>0,(IF(F7<>0,F7*G$4/100," ")),IF(F7<>0,F7*G$2/(100+G$2)," ")) -> 100 | H7: =IF((F7<>0),F7-G7," ") -> 500 | L7: =IF(F7<>0,F7-K7," ") -> 600 | M7: =IF((F7-K7)<>0,M$1-A7," ") -> 226 | O7: =IF((E7="a"),H7," ") | P7: =IF((E7="b"),H7," ") -> 500 | Q7: =IF((E7="c"),H7," ") | R7: =IF((E7="d"),H7," ") | S7: =IF((E7="g"),H7," ") | T7: =IF((E7="o"),H7," ") | U7: =IF((E7="FS"),H7," ")
A8: 45908 | B8: Cedar Systems | E8: a | F8: 480 | G8: =IF(G$4>0,(IF(F8<>0,F8*G$4/100," ")),IF(F8<>0,F8*G$2/(100+G$2)," ")) -> 80 | H8: =IF((F8<>0),F8-G8," ") -> 400 | L8: =IF(F8<>0,F8-K8," ") -> 480 | M8: =IF((F8-K8)<>0,M$1-A8," ") -> 223 | O8: =IF((E8="a"),H8," ") -> 400 | P8: =IF((E8="b"),H8," ") | Q8: =IF((E8="c"),H8," ") | R8: =IF((E8="d"),H8," ") | S8: =IF((E8="g"),H8," ") | T8: =IF((E8="o"),H8," ") | U8: =IF((E8="FS"),H8," ")
A9: 45910 | B9: Pinnacle Group | E9: a | F9: 720 | G9: =IF(G$4>0,(IF(F9<>0,F9*G$4/100," ")),IF(F9<>0,F9*G$2/(100+G$2)," ")) -> 120 | H9: =IF((F9<>0),F9-G9," ") -> 600 | L9: =IF(F9<>0,F9-K9," ") -> 720 | M9: =IF((F9-K9)<>0,M$1-A9," ") -> 221 | O9: =IF((E9="a"),H9," ") -> 600 | P9: =IF((E9="b"),H9," ") | Q9: =IF((E9="c"),H9," ") | R9: =IF((E9="d"),H9," ") | S9: =IF((E9="g"),H9," ") | T9: =IF((E9="o"),H9," ") | U9: =IF((E9="FS"),H9," ")
A10: 45914 | B10: NorthStar Digital | E10: a | F10: 2160 | G10: =IF(G$4>0,(IF(F10<>0,F10*G$4/100," ")),IF(F10<>0,F10*G$2/(100+G$2)," ")) -> 360 | H10: =IF((F10<>0),F10-G10," ") -> 1800 | L10: =IF(F10<>0,F10-K10," ") -> 2160 | M10: =IF((F10-K10)<>0,M$1-A10," ") -> 217 | O10: =IF((E10="a"),H10," ") -> 1800 | P10: =IF((E10="b"),H10," ") | Q10: =IF((E10="c"),H10," ") | R10: =IF((E10="d"),H10," ") | S10: =IF((E10="g"),H10," ") | T10: =IF((E10="o"),H10," ") | U10: =IF((E10="FS"),H10," ")
A11: 45915 | B11: Acme Corp | E11: a | F11: 25000 | G11: =IF(G$4>0,(IF(F11<>0,F11*G$4/100," ")),IF(F11<>0,F11*G$2/(100+G$2)," ")) -> 4166.6667 | H11: =IF((F11<>0),F11-G11," ") -> 20833.333 | L11: =IF(F11<>0,F11-K11," ") -> 25000 | M11: =IF((F11-K11)<>0,M$1-A11," ") -> 216 | O11: =IF((E11="a"),H11," ") -> 20833.333 | P11: =IF((E11="b"),H11," ") | Q11: =IF((E11="c"),H11," ") | R11: =IF((E11="d"),H11," ") | S11: =IF((E11="g"),H11," ") | T11: =IF((E11="o"),H11," ") | U11: =IF((E11="FS"),H11," ")
A12: 45918 | B12: TechStart Ltd | E12: a | F12: 2400 | G12: =IF(G$4>0,(IF(F12<>0,F12*G$4/100," ")),IF(F12<>0,F12*G$2/(100+G$2)," ")) -> 400 | H12: =IF((F12<>0),F12-G12," ") -> 2000 | L12: =IF(F12<>0,F12-K12," ") -> 2400 | M12: =IF((F12-K12)<>0,M$1-A12," ") -> 213 | O12: =IF((E12="a"),H12," ") -> 2000 | P12: =IF((E12="b"),H12," ") | Q12: =IF((E12="c"),H12," ") | R12: =IF((E12="d"),H12," ") | S12: =IF((E12="g"),H12," ") | T12: =IF((E12="o"),H12," ") | U12: =IF((E12="FS"),H12," ")
A13: 45928 | B13: Horizon Analytics | E13: d | F13: 840 | G13: =IF(G$4>0,(IF(F13<>0,F13*G$4/100," ")),IF(F13<>0,F13*G$2/(100+G$2)," ")) -> 140 | H13: =IF((F13<>0),F13-G13," ") -> 700 | L13: =IF(F13<>0,F13-K13," ") -> 840 | M13: =IF((F13-K13)<>0,M$1-A13," ") -> 203 | O13: =IF((E13="a"),H13," ") | P13: =IF((E13="b"),H13," ") | Q13: =IF((E13="c"),H13," ") | R13: =IF((E13="d"),H13," ") -> 700 | S13: =IF((E13="g"),H13," ") | T13: =IF((E13="o"),H13," ") | U13: =IF((E13="FS"),H13," ")
G14: =IF(G$4>0,(IF(F14<>0,F14*G$4/100," ")),IF(F14<>0,F14*G$2/(100+G$2)," ")) | H14: =IF((F14<>0),F14-G14," ") | L14: =IF(F14<>0,F14-K14," ") | M14: =IF((F14-K14)<>0,M$1-A14," ") | O14: =IF((E14="a"),H14," ") | P14: =IF((E14="b"),H14," ") | Q14: =IF((E14="c"),H14," ") | R14: =IF((E14="d"),H14," ") | S14: =IF((E14="g"),H14," ") | T14: =IF((E14="o"),H14," ") | U14: =IF((E14="FS"),H14," ")
G15: =IF(G$4>0,(IF(F15<>0,F15*G$4/100," ")),IF(F15<>0,F15*G$2/(100+G$2)," ")) | H15: =IF((F15<>0),F15-G15," ") | L15: =IF(F15<>0,F15-K15," ") | M15: =IF((F15-K15)<>0,M$1-A15," ") | O15: =IF((E15="a"),H15," ") | P15: =IF((E15="b"),H15," ") | Q15: =IF((E15="c"),H15," ") | R15: =IF((E15="d"),H15," ") | S15: =IF((E15="g"),H15," ") | T15: =IF((E15="o"),H15," ") | U15: =IF((E15="FS"),H15," ")
