Workbook
Name Annual_ConsolidatedExpenses: VitalTax!$G$29
Name Annual_ExpenseAdminCosts: VitalTax!$G$15
Name Annual_ExpenseAdminCostsDisallowable: VitalTax!$G$42
Name Annual_ExpenseAdvertisingCosts: VitalTax!$G$18
Name Annual_ExpenseAdvertisingCostsDisallowable: VitalTax!$G$43
Name Annual_ExpenseBadDebt: VitalTax!$G$20
Name Annual_ExpenseBadDebtDisallowable: VitalTax!$G$47
Name Annual_ExpenseBusinessEntertainmentCosts: VitalTax!$G$25
Name Annual_ExpenseBusinessEntertainmentCostsDisallowable: VitalTax!$G$44
Name Annual_ExpenseCisPaymentsToSubcontractors: VitalTax!$G$24
Name Annual_ExpenseCisPaymentsToSubcontractorsDisallowable: VitalTax!$G$37
Name Annual_ExpenseCostOfGoodsBought: VitalTax!$G$7
Name Annual_ExpenseCostOfGoodsBoughtDisallowable: VitalTax!$G$36
Name Annual_ExpenseDepreciation: VitalTax!$G$26
Name Annual_ExpenseDepreciationDisallowable: VitalTax!$G$49
Name Annual_ExpenseFinancialCharges: VitalTax!$G$16
Name Annual_ExpenseFinancialChargesDisallowable: VitalTax!$G$46
Name Annual_ExpenseInterest: VitalTax!$G$21
Name Annual_ExpenseInterestDisallowable: VitalTax!$G$45
Name Annual_ExpenseMaintenanceCosts: VitalTax!$G$14
Name Annual_ExpenseMaintenanceCostsDisallowable: VitalTax!$G$41
Name Annual_ExpenseOther: VitalTax!$G$22
Name Annual_ExpenseOtherDisallowable: VitalTax!$G$50
Name Annual_ExpensePremisesRunningCosts: VitalTax!$G$13
Name Annual_ExpensePremisesRunningCostsDisallowable: VitalTax!$G$40
Name Annual_ExpenseProfessionalFees: VitalTax!$G$19
Name Annual_ExpenseProfessionalFeesDisallowable: VitalTax!$G$48
Name Annual_ExpenseStaffCosts: VitalTax!$G$12
Name Annual_ExpenseStaffCostsDisallowable: VitalTax!$G$38
Name Annual_ExpenseTravelCosts: VitalTax!$G$17
Name Annual_ExpenseTravelCostsDisallowable: VitalTax!$G$39
Name Annual_IncomeOther: VitalTax!$G$6
Name Annual_IncomeTurnover: VitalTax!$G$5
Name Q1_ConsolidatedExpenses: VitalTax!$C$29
Name Q1_ExpenseAdminCosts: VitalTax!$C$15
Name Q1_ExpenseAdminCostsDisallowable: VitalTax!$C$42
Name Q1_ExpenseAdvertisingCosts: VitalTax!$C$18
Name Q1_ExpenseAdvertisingCostsDisallowable: VitalTax!$C$43
Name Q1_ExpenseBadDebt: VitalTax!$C$20
Name Q1_ExpenseBadDebtDisallowable: VitalTax!$C$47
Name Q1_ExpenseBusinessEntertainmentCosts: VitalTax!$C$25
Name Q1_ExpenseBusinessEntertainmentCostsDisallowable: VitalTax!$C$44
Name Q1_ExpenseCisPaymentsToSubcontractors: VitalTax!$C$24
Name Q1_ExpenseCisPaymentsToSubcontractorsDisallowable: VitalTax!$C$37
Name Q1_ExpenseCostOfGoodsBought: VitalTax!$C$7
Name Q1_ExpenseCostOfGoodsBoughtDisallowable: VitalTax!$C$36
Name Q1_ExpenseDepreciation: VitalTax!$C$26
Name Q1_ExpenseDepreciationDisallowable: VitalTax!$C$49
Name Q1_ExpenseFinancialCharges: VitalTax!$C$16
Name Q1_ExpenseFinancialChargesDisallowable: VitalTax!$C$46
Name Q1_ExpenseInterest: VitalTax!$C$21
Name Q1_ExpenseInterestDisallowable: VitalTax!$C$45
Name Q1_ExpenseMaintenanceCosts: VitalTax!$C$14
Name Q1_ExpenseMaintenanceCostsDisallowable: VitalTax!$C$41
Name Q1_ExpenseOther: VitalTax!$C$22
Name Q1_ExpenseOtherDisallowable: VitalTax!$C$50
Name Q1_ExpensePremisesRunningCosts: VitalTax!$C$13
Name Q1_ExpensePremisesRunningCostsDisallowable: VitalTax!$C$40
Name Q1_ExpenseProfessionalFees: VitalTax!$C$19
Name Q1_ExpenseProfessionalFeesDisallowable: VitalTax!$C$48

Sheet Business Details
A1: ENTER YOUR BUSINESS DETAILS - which are then transferred to the Self-employment Tax Return
C3: Your name | N3: Your unique taxpayer reference (UTR)
A9: Business details
A11: 1 | C11: Business name - unless it is in your own name | L11: 5 | N11: If the details in boxes 1,2,3 or 4 have changed in the
N12: 12 months put 'X' in the box and give details in the
N13: 'Any other information' box
A16: 2 | C16: Description of business | L16: 6 | N16: If your business started after | S16: =Admin!B4 -> 45753
N17: enter the start date DD/MM/YYYY
L21: 7 | N21: If your business ceased before | S21: =Admin!B17 -> 46117
N22: enter the final date of trading
A23: 3 | C23: First line of your business address - unless you work
C24: from home
L25: 8 | N25: Date your books or accounts start - the beginning of
N26: your accounting period
A29: 4 | C29: Postcode of your business | L29: 9 | N29: Date your books or accounts are made up to or the end
N30: of your accounting period - read page SEFN 3 of the
N31: notes if you have filled in box 6 or 7
N32: =Admin!B17 -> 46117
A34: Other information
A36: 10 | C36: If your accounting period has changed permanently | L36: 12 | N36: If special arrangements apply put 'X' in the box - read
C37: put 'X' in the box | N37: page SEFN 3 of the notes
A41: 11 | C41: If your accounting period has changed more than once | L41: 13 | N41: ="If you have provided the information about your " & Admin!G2 -> If you have provided the information about your 2025-26
C42: since 2002 put 'X' in the box | N42: profit on last year's Tax Return put 'X' in the box - read
N43: page SEFN 3 of the notes
A48: 26 | C48: ENTER: Total losses brought forward from earlier years | L48: 24 | N48: ENTER: Value of goods and services for your own use
N49: - read page SESN 7 of the notes
C50: £ | D50: 0 | G50: . | H50: 0 | I50: 0 | N50: £ | R50: . | S50: 0 | T50: 0
C52: Loss used this year | N52: Total loss carried forward to future years
C53: Calculated no entry required | N53: Calculated no entry required
C55: £ | D55: ='SE Short'!O94 -> 0 | G55: . | H55: 0 | I55: 0 | N55: £ | O55: =D50-D55+'SE Short'!O106 -> 0 | R55: . | S55: 0 | T55: 0

Sheet SE Short
A1: HM Revenue & Customs | G1: COPY DETAILS TO HMRC FORM Submit HMRC RETURN ONLINE by 31st January 2027 | O1: Self-employment (short)
O2: Tax year | Q2: =Admin!B4 -> 45753 | U2: to | V2: =Admin!B17 -> 46117
C6: Your name | N6: Your unique taxpayer reference (UTR)
C8: =IF('Business Details'!C5>0,'Business Details'!C5:J5," ") | O8: =IF('Business Details'!O5>0,'Business Details'!O5," ") | R8: =IF('Business Details'!R5>0,'Business Details'!R5," ")
A10: Business details
A12: 1 | C12: Description of business | L12: 4 | N12: If you are a foster carer or adult placement carer, put 'X'
C13: =IF('Business Details'!C17>0,'Business Details'!C17," ") | N13: in the box - read page SESN 2 of the notes
C15: =IF('Business Details'!C19>0,'Business Details'!C19," ") | N15: =IF('Business Details'!N14="X","X"," ")
C17: =IF('Business Details'!C21>0,'Business Details'!C21," ") | L17: 5 | N17: If your business started after | S17: =Q2 -> 45753
N18: enter the start date DD/MM/YYYY
A20: 2 | C20: Postcode of your business | N20: =IF('Business Details'!N19>0,'Business Details'!N19," ")
C22: =IF('Business Details'!C30>0,'Business Details'!C30," ") | F22: =IF('Business Details'!F30>0,'Business Details'!F30," ")
L23: 6 | N23: If your business ceased before | S23: =V2 -> 46117
A24: 3 | C24: If your business name, description, address or postcode | N24: enter the final date of trading
C25: have changed in the last 12 months, put 'X' in the box
C26: and give details in the 'Any other information' box of | N26: =IF('Business Details'!N24>0,'Business Details'!N24," ")
C27: of your Tax Return
L28: 7 | N28: Date your books or accounts are made up to - read
N29: page SESN 2 of the notes
N31: =Admin!B17 -> 46117
A33: =IF(D38>67000,"SELF-EMPLOYMENT FULL RETURN REQUIRED AS TURNOVER EXCEEDS £"&Admin!F26&" VAT threshold","Business income - if your annual turnover was below £"&Admin!F26&" VAT threshold") -> Business income - if your annual turnover was below £90000 VAT threshold
A35: 8 | C35: Your turnover - the takings, fees, sales or money earned | L35: 9 | N35: Any other business income not included in box 8
C36: by your business | N36: - excluding Business Start-up Allowance
C38: £ | D38: ='Profit & Loss Account'!B9 -> 0 | G38: . | H38: 0 | I38: 0 | N38: £ | O38: ='Profit & Loss Account'!B38 -> 0 | R38: . | S38: 0 | T38: 0
A40: Allowable business expenses
A41: Read pages SESN 3 of the notes to see which expenses are allowed for tax purposes. If your annual turnover was below £30,000
A42: you may just put your total expenses in box 19, rather than filling in the whole section.
A44: 10 | C44: Cost of goods bought for re-sale or goods used | L44: 15 | N44: Accountancy, legal and other professional fees
C46: £ | D46: =IF('Profit & Loss Account'!B9>30000,'Profit & Loss Account'!B17," ") | G46: . | H46: 0 | I46: 0 | N46: £ | O46: =IF('Profit & Loss Account'!B9>30000,'Profit & Loss Account'!B28," ") | R46: . | S46: 0 | T46: 0
A48: 11 | C48: Car, van and other travel expenses - after private | L48: 16 | N48: Interest and bank and credit card etc. financial charges
C49: use proportion
C51: £ | D51: =IF('Profit & Loss Account'!B9>30000,'Profit & Loss Account'!B25+'Profit & Loss Account'!B26," ") | G51: . | H51: 0 | I51: 0 | N51: £ | O51: =IF('Profit & Loss Account'!B9>30000,'Profit & Loss Account'!B30+'Profit & Loss Account'!B31," ") | R51: . | S51: 0 | T51: 0
A53: 12 | C53: Wages, salaries and other staff costs | L53: 17 | N53: Telephone, fax, stationery and other office costs
C55: £ | D55: =IF('Profit & Loss Account'!B9>30000,'Profit & Loss Account'!B21," ") | G55: . | H55: 0 | I55: 0 | N55: £ | O55: =IF('Profit & Loss Account'!B9>30000,'Profit & Loss Account'!B24," ") | R55: . | S55: 0 | T55: 0
A57: 13 | C57: Rent, rates, power and insurance costs | L57: 18 | N57: Other allowable business expenses - client entertaining
N58: costs are not an allowable expense
C60: £ | D60: =IF('Profit & Loss Account'!B9>30000,'Profit & Loss Account'!B22," ") | G60: . | H60: 0 | I60: 0 | N60: £ | O60: =IF('Profit & Loss Account'!B9>30000,'Profit & Loss Account'!B27+'Profit & Loss Account'!B29+'Profit & Loss Account'!B32+'Profit & Loss Account'!B33," ") | R60: . | S60: 0 | T60: 0
A62: 14 | C62: Repairs and renewals of property and equipment | L62: 19 | N62: Total allowable expenses - total of boxes 10 to 18
C64: £ | D64: =IF('Profit & Loss Account'!B9>30000,'Profit & Loss Account'!B23," ") | G64: . | H64: 0 | I64: 0 | N64: £ | O64: ='Profit & Loss Account'!B17+'Profit & Loss Account'!B35-'Profit & Loss Account'!B34 -> 0 | R64: . | S64: 0 | T64: 0
A66: Net profit or loss
...

Sheet SE Full
A1: HM Revenue & Customs | G1: COPY DETAILS TO HMRC FORM Submit HMRC RETURN ONLINE by 31st January 2027 | N1: Self-employment (full)
N2: Tax year | Q2: =Admin!B4 -> 45753 | U2: to | V2: =Admin!B17 -> 46117
C6: Your name | N6: Your unique taxpayer reference (UTR)
C8: =IF('Business Details'!C5>0,'Business Details'!C5," ") | O8: =IF('Business Details'!O5>0,'Business Details'!O5," ") | R8: =IF('Business Details'!R5>0,'Business Details'!R5," ")
C10: =IF('Business Details'!C7>0,'Business Details'!C7," ")
A12: Business details
A14: 1 | C14: Business name - unless it is in your own name | L14: 5 | N14: If the details in boxes 1,2,3 or 4 have changed in the
C15: =IF('Business Details'!C12>0,'Business Details'!C12," ") | N15: 12 months put 'X' in the box and give details in the
N16: 'Any other information' box
C17: =IF('Business Details'!C14>0,'Business Details'!C14," ") | N17: =IF('Business Details'!N14="X","X"," ")
A19: 2 | C19: Description of business | L19: 6 | N19: If your business started after | S19: =Admin!B4 -> 45753
C20: =IF('Business Details'!C17>0,'Business Details'!C17," ") | N20: enter the start date DD/MM/YYYY
C22: =IF('Business Details'!C19>0,'Business Details'!C19," ") | N22: =IF('Business Details'!N10>0,'Business Details'!N19," ")
C24: =IF('Business Details'!C21>0,'Business Details'!C21," ") | L24: 7 | N24: If your business ceased before | S24: =Admin!B17 -> 46117
N25: enter the final date of trading
A26: 3 | C26: First line of your business address - unless you work
C27: from home | N27: =IF('Business Details'!N24>0,'Business Details'!N24," ")
C28: =IF('Business Details'!C25>0,'Business Details'!C25," ") | L28: 8 | N28: Date your books or accounts start - the beginning of
N29: your accounting period
C30: =IF('Business Details'!C27>0,'Business Details'!C27," ") | N30: =IF('Business Details'!N27>0,'Business Details'!N27," ")
A32: 4 | C32: Postcode of your business | L32: 9 | N32: Date your books or accounts are made up to or the end
C33: =IF('Business Details'!C30>0,'Business Details'!C30," ") | F33: =IF('Business Details'!F30>0,'Business Details'!F30," ") | N33: of your accounting period - read page SEFN 3 of the
N34: notes if you have filled in box 6 or 7
N35: =Admin!B17 -> 46117
A37: Other information
A39: 10 | C39: If your accounting period has changed permanently | L39: 12 | N39: If special arrangements apply put 'X' in the box - read
C40: put 'X' in the box | N40: page SEFN 3 of the notes
C42: =IF('Business Details'!C39="x","x"," ") | N42: =IF('Business Details'!N39="x","x"," ")
A44: 11 | C44: If your accounting period has changed more than once | L44: 13 | N44: If you have provided the information about your 2007-08
C45: since 2002 put 'X' in the box | N45: profit on last year's Tax Return put 'X' in the box - read
N46: page SEFN 3 of the notes
C48: =IF('Business Details'!C45="x","x"," ") | N48: =IF('Business Details'!N45="x","x"," ")
A50: Business income
A52: 14 | C52: Your turnover - the takings, fees, sales or money earned | L52: 15 | N52: Any other business income not included in box 14
C53: by your business | N53: - excluding Business Start-up Allowance
C55: £ | D55: ='Profit & Loss Account'!B9 -> 0 | G55: . | H55: 0 | I55: 0 | N55: £ | O55: ='Profit & Loss Account'!B38 -> 0 | R55: . | S55: 0 | T55: 0
A57: Business expenses
A58: Read pages SEFN 5 to SEFN 7 of the notes to see what expenses are allowed for tax purposes.
C60: Total expenses | N60: Disallowable expenses
C61: If your annual turnover was below £30,000 you may | N61: Use this column if the figures in boxes 16 to 29
...

Sheet Profit & Loss Account
A2: Monthly Management Accounts Profit and Loss Account | B2: Total Year | C2: =Admin!B5 -> 45777 | D2: =Admin!B6 -> 45808 | E2: =Admin!B7 -> 45838 | F2: =Admin!B8 -> 45869 | G2: =Admin!B9 -> 45900 | H2: =Admin!B10 -> 45930 | I2: =Admin!B11 -> 45961 | J2: =Admin!B12 -> 45991 | K2: =Admin!B13 -> 46022 | L2: =Admin!B14 -> 46053 | M2: =Admin!B15 -> 46081 | N2: =Admin!B16 -> 46112
B3: =Admin!B$17 -> 46117
B4: £ | C4: £ | D4: £ | E4: £ | F4: £ | G4: £ | H4: £ | I4: £ | J4: £ | K4: £ | L4: £ | M4: £ | N4: £
A5: Sales Product A | B5: =SUM(C5:N5) -> 0 | C5: =[2]Apr!$P$1 -> 0 | D5: =[2]May!$P$1 -> 0 | E5: =[2]Jun!$P$1 -> 0 | F5: =[2]Jul!$P$1 -> 0 | G5: =[2]Aug!$P$1 -> 0 | H5: =[2]Sep!$P$1 -> 0 | I5: =[2]Oct!$P$1 -> 0 | J5: =[2]Nov!$P$1 -> 0 | K5: =[2]Dec!$P$1 -> 0 | L5: =[2]Jan!$P$1 -> 0 | M5: =[2]Feb!$P$1 -> 0 | N5: =[2]Mar!$P$1 -> 0
A6: Sales Product B | B6: =SUM(C6:N6) -> 0 | C6: =[2]Apr!$Q$1 -> 0 | D6: =[2]May!$Q$1 -> 0 | E6: =[2]Jun!$Q$1 -> 0 | F6: =[2]Jul!$Q$1 -> 0 | G6: =[2]Aug!$Q$1 -> 0 | H6: =[2]Sep!$Q$1 -> 0 | I6: =[2]Oct!$Q$1 -> 0 | J6: =[2]Nov!$Q$1 -> 0 | K6: =[2]Dec!$Q$1 -> 0 | L6: =[2]Jan!$Q$1 -> 0 | M6: =[2]Feb!$Q$1 -> 0 | N6: =[2]Mar!$Q$1 -> 0
A7: Sales Product C | B7: =SUM(C7:N7) -> 0 | C7: =[2]Apr!$R$1 -> 0 | D7: =[2]May!$R$1 -> 0 | E7: =[2]Jun!$R$1 -> 0 | F7: =[2]Jul!$R$1 -> 0 | G7: =[2]Aug!$R$1 -> 0 | H7: =[2]Sep!$R$1 -> 0 | I7: =[2]Oct!$R$1 -> 0 | J7: =[2]Nov!$R$1 -> 0 | K7: =[2]Dec!$R$1 -> 0 | L7: =[2]Jan!$R$1 -> 0 | M7: =[2]Feb!$R$1 -> 0 | N7: =[2]Mar!$R$1 -> 0
A8: Other Income | B8: =SUM(C8:N8) -> 0 | C8: =[2]Apr!$S$1 -> 0 | D8: =[2]May!$S$1 -> 0 | E8: =[2]Jun!$S$1 -> 0 | F8: =[2]Jul!$S$1 -> 0 | G8: =[2]Aug!$S$1 -> 0 | H8: =[2]Sep!$S$1 -> 0 | I8: =[2]Oct!$S$1 -> 0 | J8: =[2]Nov!$S$1 -> 0 | K8: =[2]Dec!$S$1 -> 0 | L8: =[2]Jan!$S$1 -> 0 | M8: =[2]Feb!$S$1 -> 0 | N8: =[2]Mar!$S$1 -> 0
A9: Sales Turnover | B9: =SUM(B5:B8) -> 0 | C9: =SUM(C5:C8) -> 0 | D9: =SUM(D5:D8) -> 0 | E9: =SUM(E5:E8) -> 0 | F9: =SUM(F5:F8) -> 0 | G9: =SUM(G5:G8) -> 0 | H9: =SUM(H5:H8) -> 0 | I9: =SUM(I5:I8) -> 0 | ... N9: =SUM(N5:N8) -> 0
A11: Investment Grants received | B11: =SUM(C11:N11) -> 0 | C11: =[2]Apr!$T$1 -> 0 | D11: =[2]May!$T$1 -> 0 | E11: =[2]Jun!$T$1 -> 0 | F11: =[2]Jul!$T$1 -> 0 | G11: =[2]Aug!$T$1 -> 0 | H11: =[2]Sep!$T$1 -> 0 | I11: =[2]Oct!$T$1 -> 0 | J11: =[2]Nov!$T$1 -> 0 | K11: =[2]Dec!$T$1 -> 0 | L11: =[2]Jan!$T$1 -> 0 | M11: =[2]Feb!$T$1 -> 0 | N11: =[2]Mar!$T$1 -> 0
A13: Direct Costs
A14: Purchases after stock adjustment | B14: =SUM(C14:N14) -> 0 | C14: =[3]Apr!$P$1+StockControl!AB6-StockControl!AB8 -> 0 | D14: =[3]May!$P$1+StockControl!AB8-StockControl!AB10 -> 0 | E14: =[3]Jun!$P$1+StockControl!AB10-StockControl!AB12 -> 0 | F14: =[3]Jul!$P$1+StockControl!AB12-StockControl!AB14 -> 0 | G14: =[3]Aug!$P$1+StockControl!AB14-StockControl!AB16 -> 0 | H14: =[3]Sep!$P$1+StockControl!AB16-StockControl!AB18 -> 0 | I14: =[3]Oct!$P$1+StockControl!AB18-StockControl!AB20 -> 0 | J14: =[3]Nov!$P$1+StockControl!AB20-StockControl!AB22 -> 0 | K14: =[3]Dec!$P$1+StockControl!AB22-StockControl!AB24 -> 0 | L14: =[3]Jan!$P$1+StockControl!AB24-StockControl!AB26 -> 0 | M14: =[3]Feb!$P$1+StockControl!AB26-StockControl!AB28 -> 0 | N14: =[3]Mar!$P$1+StockControl!AB28-StockControl!AB30 -> 0
A15: Sub contractors | B15: =SUM(C15:N15) -> 0 | C15: =[3]Apr!$Q$1 -> 0 | D15: =[3]May!$Q$1 -> 0 | E15: =[3]Jun!$Q$1 -> 0 | F15: =[3]Jul!$Q$1 -> 0 | G15: =[3]Aug!$Q$1 -> 0 | H15: =[3]Sep!$Q$1 -> 0 | I15: =[3]Oct!$Q$1 -> 0 | J15: =[3]Nov!$Q$1 -> 0 | K15: =[3]Dec!$Q$1 -> 0 | L15: =[3]Jan!$Q$1 -> 0 | M15: =[3]Feb!$Q$1 -> 0 | N15: =[3]Mar!$Q$1 -> 0
A16: Other Direct Cost of Sales | B16: =SUM(C16:N16) -> 0 | C16: =[3]Apr!$R$1 -> 0 | D16: =[3]May!$R$1 -> 0 | E16: =[3]Jun!$R$1 -> 0 | F16: =[3]Jul!$R$1 -> 0 | G16: =[3]Aug!$R$1 -> 0 | H16: =[3]Sep!$R$1 -> 0 | I16: =[3]Oct!$R$1 -> 0 | J16: =[3]Nov!$R$1 -> 0 | K16: =[3]Dec!$R$1 -> 0 | L16: =[3]Jan!$R$1 -> 0 | M16: =[3]Feb!$R$1 -> 0 | N16: =[3]Mar!$R$1 -> 0
A17: Cost of Sales | B17: =SUM(B14:B16) -> 0 | C17: =SUM(C14:C16) -> 0 | D17: =SUM(D14:D16) -> 0 | E17: =SUM(E14:E16) -> 0 | F17: =SUM(F14:F16) -> 0 | G17: =SUM(G14:G16) -> 0 | H17: =SUM(H14:H16) -> 0 | I17: =SUM(I14:I16) -> 0 | ... N17: =SUM(N14:N16) -> 0
A19: Gross Profit | B19: =B9+B11-B17 -> 0 | C19: =C9+C11-C17 -> 0 | D19: =D9+D11-D17 -> 0 | E19: =E9+E11-E17 -> 0 | F19: =F9+F11-F17 -> 0 | G19: =G9+G11-G17 -> 0 | H19: =H9+H11-H17 -> 0 | I19: =I9+I11-I17 -> 0 | ... N19: =N9+N11-N17 -> 0
A20: Administrative Expenses
A21: Wages and Salaries | B21: =SUM(C21:N21) -> 0 | C21: =[3]Apr!$S$1+Wagesinterface!C4+Wagesinterface!H4-Wagesinterface!I4 -> 0 | D21: =[3]May!$S$1+Wagesinterface!C5+Wagesinterface!H5-Wagesinterface!I5 -> 0 | E21: =[3]Jun!$S$1+Wagesinterface!C6+Wagesinterface!H6-Wagesinterface!I6 -> 0 | F21: =[3]Jul!$S$1+Wagesinterface!C7+Wagesinterface!H7-Wagesinterface!I7 -> 0 | G21: =[3]Aug!$S$1+Wagesinterface!C8+Wagesinterface!H8-Wagesinterface!I8 -> 0 | H21: =[3]Sep!$S$1+Wagesinterface!C9+Wagesinterface!H9-Wagesinterface!I9 -> 0 | I21: =[3]Oct!$S$1+Wagesinterface!C10+Wagesinterface!H10-Wagesinterface!I10 -> 0 | J21: =[3]Nov!$S$1+Wagesinterface!C11+Wagesinterface!H11-Wagesinterface!I11 -> 0 | K21: =[3]Dec!$S$1+Wagesinterface!C12+Wagesinterface!H12-Wagesinterface!I12 -> 0 | L21: =[3]Jan!$S$1+Wagesinterface!C13+Wagesinterface!H13-Wagesinterface!I13 -> 0 | M21: =[3]Feb!$S$1+Wagesinterface!C14+Wagesinterface!H14-Wagesinterface!I14 -> 0 | N21: =[3]Mar!$S$1+Wagesinterface!C15+Wagesinterface!H15-Wagesinterface!I15 -> 0
A22: Premises Rent Rates Power | B22: =SUM(C22:N22) -> 0 | C22: =[3]Apr!$T$1 -> 0 | D22: =[3]May!$T$1 -> 0 | E22: =[3]Jun!$T$1 -> 0 | F22: =[3]Jul!$T$1 -> 0 | G22: =[3]Aug!$T$1 -> 0 | H22: =[3]Sep!$T$1 -> 0 | I22: =[3]Oct!$T$1 -> 0 | J22: =[3]Nov!$T$1 -> 0 | K22: =[3]Dec!$T$1 -> 0 | L22: =[3]Jan!$T$1 -> 0 | M22: =[3]Feb!$T$1 -> 0 | N22: =[3]Mar!$T$1 -> 0
A23: Repairs & Maintenance | B23: =SUM(C23:N23) -> 0 | C23: =[3]Apr!$U$1 -> 0 | D23: =[3]May!$U$1 -> 0 | E23: =[3]Jun!$U$1 -> 0 | F23: =[3]Jul!$U$1 -> 0 | G23: =[3]Aug!$U$1 -> 0 | H23: =[3]Sep!$U$1 -> 0 | I23: =[3]Oct!$U$1 -> 0 | J23: =[3]Nov!$U$1 -> 0 | K23: =[3]Dec!$U$1 -> 0 | L23: =[3]Jan!$U$1 -> 0 | M23: =[3]Feb!$U$1 -> 0 | N23: =[3]Mar!$U$1 -> 0
A24: General Administrative Expenses | B24: =SUM(C24:N24) -> 0 | C24: =[3]Apr!$V$1 -> 0 | D24: =[3]May!$V$1 -> 0 | E24: =[3]Jun!$V$1 -> 0 | F24: =[3]Jul!$V$1 -> 0 | G24: =[3]Aug!$V$1 -> 0 | H24: =[3]Sep!$V$1 -> 0 | I24: =[3]Oct!$V$1 -> 0 | J24: =[3]Nov!$V$1 -> 0 | K24: =[3]Dec!$V$1 -> 0 | L24: =[3]Jan!$V$1 -> 0 | M24: =[3]Feb!$V$1 -> 0 | N24: =[3]Mar!$V$1 -> 0
A25: Motor Expenses | B25: =SUM(C25:N25) -> 0 | C25: =[3]Apr!$W$1 -> 0 | D25: =[3]May!$W$1 -> 0 | E25: =[3]Jun!$W$1 -> 0 | F25: =[3]Jul!$W$1 -> 0 | G25: =[3]Aug!$W$1 -> 0 | H25: =[3]Sep!$W$1 -> 0 | I25: =[3]Oct!$W$1 -> 0 | J25: =[3]Nov!$W$1 -> 0 | K25: =[3]Dec!$W$1 -> 0 | L25: =[3]Jan!$W$1 -> 0 | M25: =[3]Feb!$W$1 -> 0 | N25: =[3]Mar!$W$1 -> 0
A26: Travel Hotel & Subsistence | B26: =SUM(C26:N26) -> 0 | C26: =[3]Apr!$X$1 -> 0 | D26: =[3]May!$X$1 -> 0 | E26: =[3]Jun!$X$1 -> 0 | F26: =[3]Jul!$X$1 -> 0 | G26: =[3]Aug!$X$1 -> 0 | H26: =[3]Sep!$X$1 -> 0 | I26: =[3]Oct!$X$1 -> 0 | J26: =[3]Nov!$X$1 -> 0 | K26: =[3]Dec!$X$1 -> 0 | L26: =[3]Jan!$X$1 -> 0 | M26: =[3]Feb!$X$1 -> 0 | N26: =[3]Mar!$X$1 -> 0
A27: Advertising & Promotion | B27: =SUM(C27:N27) -> 0 | C27: =[3]Apr!$Y$1 -> 0 | D27: =[3]May!$Y$1 -> 0 | E27: =[3]Jun!$Y$1 -> 0 | F27: =[3]Jul!$Y$1 -> 0 | G27: =[3]Aug!$Y$1 -> 0 | H27: =[3]Sep!$Y$1 -> 0 | I27: =[3]Oct!$Y$1 -> 0 | J27: =[3]Nov!$Y$1 -> 0 | K27: =[3]Dec!$Y$1 -> 0 | L27: =[3]Jan!$Y$1 -> 0 | M27: =[3]Feb!$Y$1 -> 0 | N27: =[3]Mar!$Y$1 -> 0
A28: Legal & Professional Fees | B28: =SUM(C28:N28) -> 0 | C28: =[3]Apr!$Z$1 -> 0 | D28: =[3]May!$Z$1 -> 0 | E28: =[3]Jun!$Z$1 -> 0 | F28: =[3]Jul!$Z$1 -> 0 | G28: =[3]Aug!$Z$1 -> 0 | H28: =[3]Sep!$Z$1 -> 0 | I28: =[3]Oct!$Z$1 -> 0 | J28: =[3]Nov!$Z$1 -> 0 | K28: =[3]Dec!$Z$1 -> 0 | L28: =[3]Jan!$Z$1 -> 0 | M28: =[3]Feb!$Z$1 -> 0 | N28: =[3]Mar!$Z$1 -> 0
A29: Bad Debts written off | B29: =SUM(C29:N29) -> 0 | C29: =-[2]Apr!$U$1 -> 0 | D29: =-[2]May!$U$1 -> 0 | E29: =-[2]Jun!$U$1 -> 0 | F29: =-[2]Jul!$U$1 -> 0 | G29: =-[2]Aug!$U$1 -> 0 | H29: =-[2]Sep!$U$1 -> 0 | I29: =-[2]Oct!$U$1 -> 0 | J29: =-[2]Nov!$U$1 -> 0 | K29: =-[2]Dec!$U$1 -> 0 | L29: =-[2]Jan!$U$1 -> 0 | M29: =-[2]Feb!$U$1 -> 0 | N29: =-[2]Mar!$U$1 -> 0
A30: Bank Interest Paid | B30: =SUM(C30:N30) -> 0 | C30: =[4]Apr!$Z$1 -> 0 | D30: =[4]May!$Z$1 -> 0 | E30: =[4]Jun!$Z$1 -> 0 | F30: =[4]Jul!$Z$1 -> 0 | G30: =[4]Aug!$Z$1 -> 0 | H30: =[4]Sep!$Z$1 -> 0 | I30: =[4]Oct!$Z$1 -> 0 | J30: =[4]Nov!$Z$1 -> 0 | K30: =[4]Dec!$Z$1 -> 0 | L30: =[4]Jan!$Z$1 -> 0 | M30: =[4]Feb!$Z$1 -> 0 | N30: =[4]Mar!$Z$1 -> 0
A31: HP Interest Lease Bank Charges | B31: =SUM(C31:N31) -> 0 | C31: =[5]Apr!$V$1+[4]Apr!$Y$1 -> 0 | D31: =[5]May!$V$1+[4]May!$Y$1 -> 0 | E31: =[5]Jun!$V$1+[4]Jun!$Y$1 -> 0 | F31: =[5]Jul!$V$1+[4]Jul!$Y$1 -> 0 | G31: =[5]Aug!$V$1+[4]Aug!$Y$1 -> 0 | H31: =[5]Sep!$V$1+[4]Sep!$Y$1 -> 0 | I31: =[5]Oct!$V$1+[4]Oct!$Y$1 -> 0 | J31: =[5]Nov!$V$1+[4]Nov!$Y$1 -> 0 | K31: =[5]Dec!$V$1+[4]Dec!$Y$1 -> 0 | L31: =[5]Jan!$V$1+[4]Jan!$Y$1 -> 0 | M31: =[5]Feb!$V$1+[4]Feb!$Y$1 -> 0 | N31: =[5]Mar!$V$1+[4]Mar!$Y$1 -> 0
A32: Other Expenses | B32: =SUM(C32:N32) -> 0 | C32: =[3]Apr!$AA$1 -> 0 | D32: =[3]May!$AA$1 -> 0 | E32: =[3]Jun!$AA$1 -> 0 | F32: =[3]Jul!$AA$1 -> 0 | G32: =[3]Aug!$AA$1 -> 0 | H32: =[3]Sep!$AA$1 -> 0 | I32: =[3]Oct!$AA$1 -> 0 | J32: =[3]Nov!$AA$1 -> 0 | K32: =[3]Dec!$AA$1 -> 0 | L32: =[3]Jan!$AA$1 -> 0 | M32: =[3]Feb!$AA$1 -> 0 | N32: =[3]Mar!$AA$1 -> 0
A33: Loss (profit) disposal of assets | B33: =SUM(C33:N33) -> 0 | C33: =-([1]Schedule!$V$1-[1]Schedule!$W$1+[1]Schedule!$X$1)/12 -> 0 | D33: =-([1]Schedule!$V$1-[1]Schedule!$W$1+[1]Schedule!$X$1)/12 -> 0 | E33: =-([1]Schedule!$V$1-[1]Schedule!$W$1+[1]Schedule!$X$1)/12 -> 0 | F33: =-([1]Schedule!$V$1-[1]Schedule!$W$1+[1]Schedule!$X$1)/12 -> 0 | G33: =-([1]Schedule!$V$1-[1]Schedule!$W$1+[1]Schedule!$X$1)/12 -> 0 | H33: =-([1]Schedule!$V$1-[1]Schedule!$W$1+[1]Schedule!$X$1)/12 -> 0 | I33: =-([1]Schedule!$V$1-[1]Schedule!$W$1+[1]Schedule!$X$1)/12 -> 0 | J33: =-([1]Schedule!$V$1-[1]Schedule!$W$1+[1]Schedule!$X$1)/12 -> 0 | ... N33: =-([1]Schedule!$V$1-[1]Schedule!$W$1+[1]Schedule!$X$1)/12 -> 0
A34: Depreciation | B34: =SUM(C34:N34) -> 0 | C34: =([1]Schedule!$I$1)/12 -> 0 | D34: =([1]Schedule!$I$1)/12 -> 0 | E34: =([1]Schedule!$I$1)/12 -> 0 | F34: =([1]Schedule!$I$1)/12 -> 0 | G34: =([1]Schedule!$I$1)/12 -> 0 | H34: =([1]Schedule!$I$1)/12 -> 0 | I34: =([1]Schedule!$I$1)/12 -> 0 | J34: =([1]Schedule!$I$1)/12 -> 0 | ... N34: =([1]Schedule!$I$1)/12 -> 0
A35: Administrative Expenses | B35: =SUM(B21:B34) -> 0 | C35: =SUM(C21:C34) -> 0 | D35: =SUM(D21:D34) -> 0 | E35: =SUM(E21:E34) -> 0 | F35: =SUM(F21:F34) -> 0 | G35: =SUM(G21:G34) -> 0 | H35: =SUM(H21:H34) -> 0 | I35: =SUM(I21:I34) -> 0 | ... N35: =SUM(N21:N34) -> 0
A37: Operating Profit | B37: =B19-B35 -> 0 | C37: =C19-C35 -> 0 | D37: =D19-D35 -> 0 | E37: =E19-E35 -> 0 | F37: =F19-F35 -> 0 | G37: =G19-G35 -> 0 | H37: =H19-H35 -> 0 | I37: =I19-I35 -> 0 | ... N37: =N19-N35 -> 0
A38: Interest received | B38: =SUM(C38:N38) -> 0 | C38: =[4]Apr!$J$1 -> 0 | D38: =[4]May!$J$1 -> 0 | E38: =[4]Jun!$J$1 -> 0 | F38: =[4]Jul!$J$1 -> 0 | G38: =[4]Aug!$J$1 -> 0 | H38: =[4]Sep!$J$1 -> 0 | I38: =[4]Oct!$J$1 -> 0 | J38: =[4]Nov!$J$1 -> 0 | K38: =[4]Dec!$J$1 -> 0 | L38: =[4]Jan!$J$1 -> 0 | M38: =[4]Feb!$J$1 -> 0 | N38: =[4]Mar!$J$1 -> 0
A39: Profit (Loss) before Tax | B39: =B37+B38 -> 0 | C39: =C37+C38 -> 0 | D39: =D37+D38 -> 0 | E39: =E37+E38 -> 0 | F39: =F37+F38 -> 0 | G39: =G37+G38 -> 0 | H39: =H37+H38 -> 0 | I39: =I37+I38 -> 0 | ... N39: =N37+N38 -> 0
A41: Financial Business Health Check
A42: Self Employed Drawings | B42: =SUM(C42:N42) -> 0 | C42: =[5]Apr!$X$1+[4]Apr!$AB$1 -> 0 | D42: =[5]May!$X$1+[4]May!$AB$1 -> 0 | E42: =[5]Jun!$X$1+[4]Jun!$AB$1 -> 0 | F42: =[5]Jul!$X$1+[4]Jul!$AB$1 -> 0 | G42: =[5]Aug!$X$1+[4]Aug!$AB$1 -> 0 | H42: =[5]Sep!$X$1+[4]Sep!$AB$1 -> 0 | I42: =[5]Oct!$X$1+[4]Oct!$AB$1 -> 0 | J42: =[5]Nov!$X$1+[4]Nov!$AB$1 -> 0 | K42: =[5]Dec!$X$1+[4]Dec!$AB$1 -> 0 | L42: =[5]Jan!$X$1+[4]Jan!$AB$1 -> 0 | M42: =[5]Feb!$X$1+[4]Feb!$AB$1 -> 0 | N42: =[5]Mar!$X$1+[4]Mar!$AB$1 -> 0
A43: CIS Tax deducted | B43: =SUM(C43:N43) -> 0 | C43: =-[2]Apr!$W$1 -> 0 | D43: =-[2]May!$W$1 -> 0 | E43: =-[2]Jun!$W$1 -> 0 | F43: =-[2]Jul!$W$1 -> 0 | G43: =-[2]Aug!$W$1 -> 0 | H43: =-[2]Sep!$W$1 -> 0 | I43: =-[2]Oct!$W$1 -> 0 | J43: =-[2]Nov!$W$1 -> 0 | K43: =-[2]Dec!$W$1 -> 0 | L43: =-[2]Jan!$W$1 -> 0 | M43: =-[2]Feb!$W$1 -> 0 | N43: =-[2]Mar!$W$1 -> 0
A44: Income Tax & NI Liability | B44: =SUM(C44:N44) -> 0 | C44: =IF(C9>0,'Profit Forecast'!C$46/12,0) -> 0 | D44: =IF(D9>0,'Profit Forecast'!C$46/12,0) -> 0 | E44: =IF(E9>0,'Profit Forecast'!C$46/12,0) -> 0 | F44: =IF(F9>0,'Profit Forecast'!C$46/12,0) -> 0 | G44: =IF(G9>0,'Profit Forecast'!C$46/12,0) -> 0 | H44: =IF(H9>0,'Profit Forecast'!C$46/12,0) -> 0 | I44: =IF(I9>0,'Profit Forecast'!C$46/12,0) -> 0 | J44: =IF(J9>0,'Profit Forecast'!C$46/12,0) -> 0 | K44: =IF(K9>0,'Profit Forecast'!C$46/12,0) -> 0 | L44: =IF(L9>0,'Profit Forecast'!C$46/12,0) -> 0 | M44: =IF(M9>0,'Profit Forecast'!C$46/12,0) -> 0 | N44: =IF(N9>0,'Profit Forecast'!C$46/12,0) -> 0
A45: Financial Health Check | B45: =SUM(C45:N45) -> 0 | C45: =C39-C42-C44 -> 0 | D45: =D39-D42-D44 -> 0 | E45: =E39-E42-E44 -> 0 | F45: =F39-F42-F44 -> 0 | G45: =G39-G42-G44 -> 0 | H45: =H39-H42-H44 -> 0 | I45: =I39-I42-I44 -> 0 | J45: =J39-J42-J44 -> 0 | ... N45: =N39-N42-N44 -> 0
A46: Capital introduced | B46: =SUM(C46:N46) -> 0 | C46: =[5]Apr!$J$1+[4]Apr!$L$1 -> 0 | D46: =[5]May!$J$1+[4]May!$L$1 -> 0 | E46: =[5]Jun!$J$1+[4]Jun!$L$1 -> 0 | F46: =[5]Jul!$J$1+[4]Jul!$L$1 -> 0 | G46: =[5]Aug!$J$1+[4]Aug!$L$1 -> 0 | H46: =[5]Sep!$J$1+[4]Sep!$L$1 -> 0 | I46: =[5]Oct!$J$1+[4]Oct!$L$1 -> 0 | J46: =[5]Nov!$J$1+[4]Nov!$L$1 -> 0 | K46: =[5]Dec!$J$1+[4]Dec!$L$1 -> 0 | L46: =[5]Jan!$J$1+[4]Jan!$L$1 -> 0 | M46: =[5]Feb!$J$1+[4]Feb!$L$1 -> 0 | N46: =[5]Mar!$J$1+[4]Mar!$L$1 -> 0

Sheet VitalTax
B2: VitalTax summary | C2: Q1 | D2: Q2 | E2: Q3 | F2: Q4 | G2: Annual | H2: Notes
B5: Turnover | C5: =SUM('Profit & Loss Account'!C5:E7) -> 0 | D5: =SUM('Profit & Loss Account'!F5:H7) -> 0 | E5: =SUM('Profit & Loss Account'!I5:K7) -> 0 | F5: =SUM('Profit & Loss Account'!L5:N7) -> 0 | G5: =SUM(C5:F5) -> 0
B6: Other income | C6: =SUM('Profit & Loss Account'!C8:E8)+SUM('Profit & Loss Account'!C11:E11)+SUM('Profit & Loss Account'!C38:E38) -> 0 | D6: =SUM('Profit & Loss Account'!F8:H8)+SUM('Profit & Loss Account'!F11:H11)+SUM('Profit & Loss Account'!F38:H38) -> 0 | E6: =SUM('Profit & Loss Account'!I8:K8)+SUM('Profit & Loss Account'!I11:K11)+SUM('Profit & Loss Account'!I38:K38) -> 0 | F6: =SUM('Profit & Loss Account'!L8:N8)+SUM('Profit & Loss Account'!L11:N11)+SUM('Profit & Loss Account'!L38:N38) -> 0 | G6: =SUM(C6:F6) -> 0
B7: Cost of goods bought | C7: =SUM('Profit & Loss Account'!C14:E14)+SUM('Profit & Loss Account'!C16:E16) -> 0 | D7: =SUM('Profit & Loss Account'!F14:H14)+SUM('Profit & Loss Account'!F16:H16) -> 0 | E7: =SUM('Profit & Loss Account'!I14:K14)+SUM('Profit & Loss Account'!I16:K16) -> 0 | F7: =SUM('Profit & Loss Account'!L14:N14)+SUM('Profit & Loss Account'!L16:N16) -> 0 | G7: =SUM(C7:F7) -> 0
B10: Allowable expenses
B12: Staff costs | C12: =SUM('Profit & Loss Account'!C21:E21) -> 0 | D12: =SUM('Profit & Loss Account'!F21:H21) -> 0 | E12: =SUM('Profit & Loss Account'!I21:K21) -> 0 | F12: =SUM('Profit & Loss Account'!L21:N21) -> 0 | G12: =SUM(C12:F12) -> 0
B13: Premises running costs | C13: =SUM('Profit & Loss Account'!C22:E22) -> 0 | D13: =SUM('Profit & Loss Account'!F22:H22) -> 0 | E13: =SUM('Profit & Loss Account'!I22:K22) -> 0 | F13: =SUM('Profit & Loss Account'!L22:N22) -> 0 | G13: =SUM(C13:F13) -> 0
B14: Maintenance | C14: =SUM('Profit & Loss Account'!C23:E23) -> 0 | D14: =SUM('Profit & Loss Account'!F23:H23) -> 0 | E14: =SUM('Profit & Loss Account'!I23:K23) -> 0 | F14: =SUM('Profit & Loss Account'!L23:N23) -> 0 | G14: =SUM(C14:F14) -> 0
B15: Admin | C15: =SUM('Profit & Loss Account'!C24:E24) -> 0 | D15: =SUM('Profit & Loss Account'!F24:H24) -> 0 | E15: =SUM('Profit & Loss Account'!I24:K24) -> 0 | F15: =SUM('Profit & Loss Account'!L24:N24) -> 0 | G15: =SUM(C15:F15) -> 0
B16: Financial charges | C16: =SUM('Profit & Loss Account'!C31:E31) -> 0 | D16: =SUM('Profit & Loss Account'!F31:H31) -> 0 | E16: =SUM('Profit & Loss Account'!I31:K31) -> 0 | F16: =SUM('Profit & Loss Account'!L31:N31) -> 0 | G16: =SUM(C16:F16) -> 0
B17: Travel | C17: =SUM('Profit & Loss Account'!C25:E26) -> 0 | D17: =SUM('Profit & Loss Account'!F25:H26) -> 0 | E17: =SUM('Profit & Loss Account'!I25:K26) -> 0 | F17: =SUM('Profit & Loss Account'!L25:N26) -> 0 | G17: =SUM(C17:F17) -> 0
B18: Advertising | C18: =SUM('Profit & Loss Account'!C27:E27) -> 0 | D18: =SUM('Profit & Loss Account'!F27:H27) -> 0 | E18: =SUM('Profit & Loss Account'!I27:K27) -> 0 | F18: =SUM('Profit & Loss Account'!L27:N27) -> 0 | G18: =SUM(C18:F18) -> 0
B19: Professional | C19: =SUM('Profit & Loss Account'!C28:E28) -> 0 | D19: =SUM('Profit & Loss Account'!F28:H28) -> 0 | E19: =SUM('Profit & Loss Account'!I28:K28) -> 0 | F19: =SUM('Profit & Loss Account'!L28:N28) -> 0 | G19: =SUM(C19:F19) -> 0
B20: Bad debt | C20: =SUM('Profit & Loss Account'!C29:E29) -> 0 | D20: =SUM('Profit & Loss Account'!F29:H29) -> 0 | E20: =SUM('Profit & Loss Account'!I29:K29) -> 0 | F20: =SUM('Profit & Loss Account'!L29:N29) -> 0 | G20: =SUM(C20:F20) -> 0
B21: Interest | C21: =SUM('Profit & Loss Account'!C30:E30) -> 0 | D21: =SUM('Profit & Loss Account'!F30:H30) -> 0 | E21: =SUM('Profit & Loss Account'!I30:K30) -> 0 | F21: =SUM('Profit & Loss Account'!L30:N30) -> 0 | G21: =SUM(C21:F21) -> 0
B22: Other | C22: =SUM('Profit & Loss Account'!C32:E32) -> 0 | D22: =SUM('Profit & Loss Account'!F32:H32) -> 0 | E22: =SUM('Profit & Loss Account'!I32:K32) -> 0 | F22: =SUM('Profit & Loss Account'!L32:N32) -> 0 | G22: =SUM(C22:F22) -> 0
B24: CIS payment to subcontractors | C24: =SUM('Profit & Loss Account'!C15:E15) -> 0 | D24: =SUM('Profit & Loss Account'!F15:H15) -> 0 | E24: =SUM('Profit & Loss Account'!I15:K15) -> 0 | F24: =SUM('Profit & Loss Account'!L15:N15) -> 0 | G24: =SUM(C24:F24) -> 0
B25: Business entertainment | C25: 0 | D25: 0 | E25: 0 | F25: 0 | G25: =SUM(C25:F25) -> 0 | H25: Not captured in DIY Accounting
B26: Depreciation | C26: =SUM('Profit & Loss Account'!C33:E34) -> 0 | D26: =SUM('Profit & Loss Account'!F33:H34) -> 0 | E26: =SUM('Profit & Loss Account'!I33:K34) -> 0 | F26: =SUM('Profit & Loss Account'!L33:N34) -> 0 | G26: =SUM(C26:F26) -> 0
B29: Total allowable expenses | C29: =SUM(C7,C12,C13,C14,C15,C16,C17,C18,C19,C20,C21,C22,C24,C25,C26) -> 0 | D29: =SUM(D7,D12,D13,D14,D15,D16,D17,D18,D19,D20,D21,D22,D24,D25,D26) -> 0 | E29: =SUM(E7,E12,E13,E14,E15,E16,E17,E18,E19,E20,E21,E22,E24,E25,E26) -> 0 | F29: =SUM(F7,F12,F13,F14,F15,F16,F17,F18,F19,F20,F21,F22,F24,F25,F26) -> 0 | G29: =SUM(G7,G12,G13,G14,G15,G16,G17,G18,G19,G20,G21,G22,G24,G25,G26) -> 0
B34: Disallowable expenses
B36: Cost of goods bought | C36: 0 | D36: 0 | E36: 0 | F36: 0 | G36: =SUM(C36:F36) -> 0 | H36: Not captured in DIY Accounting
B37: CIS payment to subcontractors | C37: 0 | D37: 0 | E37: 0 | F37: 0 | G37: =SUM(C37:F37) -> 0 | H37: Not captured in DIY Accounting
B38: Staff costs | C38: 0 | D38: 0 | E38: 0 | F38: 0 | G38: =SUM(C38:F38) -> 0 | H38: Not captured in DIY Accounting
B39: Travel | C39: 0 | D39: 0 | E39: 0 | F39: 0 | G39: =SUM(C39:F39) -> 0 | H39: Not captured in DIY Accounting
B40: Premises running costs | C40: 0 | D40: 0 | E40: 0 | F40: 0 | G40: =SUM(C40:F40) -> 0 | H40: Not captured in DIY Accounting
B41: Maintenance | C41: 0 | D41: 0 | E41: 0 | F41: 0 | G41: =SUM(C41:F41) -> 0 | H41: Not captured in DIY Accounting
B42: Admin | C42: 0 | D42: 0 | E42: 0 | F42: 0 | G42: =SUM(C42:F42) -> 0 | H42: Not captured in DIY Accounting
B43: Advertising | C43: 0 | D43: 0 | E43: 0 | F43: 0 | G43: =SUM(C43:F43) -> 0 | H43: Not captured in DIY Accounting
B44: Business entertainment | C44: 0 | D44: 0 | E44: 0 | F44: 0 | G44: =SUM(C44:F44) -> 0 | H44: Not captured in DIY Accounting
B45: Interest | C45: 0 | D45: 0 | E45: 0 | F45: 0 | G45: =SUM(C45:F45) -> 0 | H45: Not captured in DIY Accounting
B46: Financial charges | C46: 0 | D46: 0 | E46: 0 | F46: 0 | G46: =SUM(C46:F46) -> 0 | H46: Not captured in DIY Accounting
B47: Bad debt | C47: 0 | D47: 0 | E47: 0 | F47: 0 | G47: =SUM(C47:F47) -> 0 | H47: Not captured in DIY Accounting
... B50: Other | C50: 0 | D50: 0 | E50: 0 | F50: 0 | G50: =SUM(C50:F50) -> 0 | H50: Not captured in DIY Accounting

Sheet Income Tax
B2: TAXATION CALCULATION | C2: =Admin!L2 -> 2025-26 | D2: This section an indication and for your information only
B5: Profit from Self employment | E5: ='SE Full'!O210 -> 0
B6: Minus Personal Allowance | C6: =C2 -> 2025-26 | E6: =IF((E5>0),Admin!N$4,0) -> 0
B7: Total income on which tax is due | E7: =IF((E5>E6),(E5-E6),0) -> 0
B8: Income Tax first band | C8: =Admin!N$11 -> 0 | D8: =Admin!N$6 -> 0.2 | E8: =IF((E7>0),(IF((E7<C9),E7*D8,C9*D8)),0) -> 0
B9: Income Tax second band | C9: =Admin!N$12 -> 37701 | D9: =Admin!N$7 -> 0.4 | E9: =IF((E7>C9),((E7-C9)*D9),0) -> 0
B10: Income Tax payable | E10: =SUM(E8:E9) -> 0
B11: Deductions by contractors | E11: =-[2]Mar!$X$1 -> 0
B13: Amounts Payable by | C13: =Admin!B21 -> 46418
B15: Class 4 NI Contribution Lower - Upper profits | D15: =Admin!L20 -> 0.06 | E15: =IF(E5>Admin!N20,IF(E5<Admin!N$23,(E5-Admin!N20)*D15,(Admin!N$23-Admin!N20)*D15),0) -> 0
B16: Class 4 NI Contribution Upper profits | D16: =Admin!L23 -> 0.02 | E16: =IF((E5>Admin!N$23),((E5-Admin!N$23)*D16),0) -> 0
B18: TOTAL Income Tax & NI Liability | E18: =SUM(E10:E17) -> 0
B21: FUTURE TAX LIABILITY (if over £500) | D21: This section for your information only
D23: Due Date | E23: Amount Payable
B25: Tax & NI Assessment | C25: =Admin!B24 -> 2026-27 | D25: Previous Year | E25: =E18 -> 0
B26: 50% Payable | D26: =Admin!B21 -> 46418 | E26: =E25/2 -> 0
B27: 50% Payable | D27: =Admin!B22 -> 46599 | E27: =E25/2 -> 0
B29: NOTES:
B30: Working Tax Credit
B31: Not taxable and not added to self employment income for tax purposes
B32: Pension Entitlement
B33: To receive Full Pension entitlement NI has to be paid 44 years out of 49 years (16 - 65)
B34: UK residents aged 60 - 65 get 5 years bonus.
B35: To confirm current NI / Pension entitlement years the helpline number is 0845 3000 168

Sheet Wagesinterface
B2: Month | C2: Gross Wages paid | D2: Income Tax deducted | E2: Employees National Insurance deducted | F2: Other Deductions | G2: Net Wages Paid | H2: Employers National Insurance | I2: Recoverable Statutory Payments | K2: WAGES INTERFACE
B3: EMPLOYEES
B4: =Admin!B5 -> 45777 | C4: =[6]Apr!$M$1 -> 0 | D4: =[6]Apr!$N$1 -> 0 | E4: =[6]Apr!$O$1 -> 0 | F4: =[6]Apr!$P$1+[6]Apr!$Q$1 -> 0 | G4: =C4-SUM(D4:F4) -> 0 | H4: =[6]Apr!$T$1 -> 0 | I4: =[6]Apr!$G$1 -> 0 | K4: 1. If you are using a DIY Accounting payroll package then no action is required for the pay periods during which that payroll package is relevant April to March each year.
B5: =Admin!B6 -> 45808 | C5: =[6]May!$M$1 -> 0 | D5: =[6]May!$N$1 -> 0 | E5: =[6]May!$O$1 -> 0 | F5: =[6]May!$P$1+[6]May!$Q$1 -> 0 | G5: =C5-SUM(D5:F5) -> 0 | H5: =[6]May!$T$1 -> 0 | I5: =[6]May!$G$1 -> 0
B6: =Admin!B7 -> 45838 | C6: =[6]Jun!$M$1 -> 0 | D6: =[6]Jun!$N$1 -> 0 | E6: =[6]Jun!$O$1 -> 0 | F6: =[6]Jun!$P$1+[6]Jun!$Q$1 -> 0 | G6: =C6-SUM(D6:F6) -> 0 | H6: =[6]Jun!$T$1 -> 0 | I6: =[6]Jun!$G$1 -> 0
B7: =Admin!B8 -> 45869 | C7: =[6]Jul!$M$1 -> 0 | D7: =[6]Jul!$N$1 -> 0 | E7: =[6]Jul!$O$1 -> 0 | F7: =[6]Jul!$P$1+[6]Jul!$Q$1 -> 0 | G7: =C7-SUM(D7:F7) -> 0 | H7: =[6]Jul!$T$1 -> 0 | I7: =[6]Jul!$G$1 -> 0
B8: =Admin!B9 -> 45900 | C8: =[6]Aug!$M$1 -> 0 | D8: =[6]Aug!$N$1 -> 0 | E8: =[6]Aug!$O$1 -> 0 | F8: =[6]Aug!$P$1+[6]Aug!$Q$1 -> 0 | G8: =C8-SUM(D8:F8) -> 0 | H8: =[6]Aug!$T$1 -> 0 | I8: =[6]Aug!$G$1 -> 0 | K8: 2. Non DIY Accounting Payroll employers should overwrite the formulae with the actual monthly payroll totals
B9: =Admin!B10 -> 45930 | C9: =[6]Sep!$M$1 -> 0 | D9: =[6]Sep!$N$1 -> 0 | E9: =[6]Sep!$O$1 -> 0 | F9: =[6]Sep!$P$1+[6]Sep!$Q$1 -> 0 | G9: =C9-SUM(D9:F9) -> 0 | H9: =[6]Sep!$T$1 -> 0 | I9: =[6]Sep!$G$1 -> 0
B10: =Admin!B11 -> 45961 | C10: =[6]Oct!$M$1 -> 0 | D10: =[6]Oct!$N$1 -> 0 | E10: =[6]Oct!$O$1 -> 0 | F10: =[6]Oct!$P$1+[6]Oct!$Q$1 -> 0 | G10: =C10-SUM(D10:F10) -> 0 | H10: =[6]Oct!$T$1 -> 0 | I10: =[6]Oct!$G$1 -> 0
B11: =Admin!B12 -> 45991 | C11: =[6]Nov!$M$1 -> 0 | D11: =[6]Nov!$N$1 -> 0 | E11: =[6]Nov!$O$1 -> 0 | F11: =[6]Nov!$P$1+[6]Nov!$Q$1 -> 0 | G11: =C11-SUM(D11:F11) -> 0 | H11: =[6]Nov!$T$1 -> 0 | I11: =[6]Nov!$G$1 -> 0
B12: =Admin!B13 -> 46022 | C12: =[6]Dec!$M$1 -> 0 | D12: =[6]Dec!$N$1 -> 0 | E12: =[6]Dec!$O$1 -> 0 | F12: =[6]Dec!$P$1+[6]Dec!$Q$1 -> 0 | G12: =C12-SUM(D12:F12) -> 0 | H12: =[6]Dec!$T$1 -> 0 | I12: =[6]Dec!$G$1 -> 0
B13: =Admin!B14 -> 46053 | C13: =[6]Jan!$M$1 -> 0 | D13: =[6]Jan!$N$1 -> 0 | E13: =[6]Jan!$O$1 -> 0 | F13: =[6]Jan!$P$1+[6]Jan!$Q$1 -> 0 | G13: =C13-SUM(D13:F13) -> 0 | H13: =[6]Jan!$T$1 -> 0 | I13: =[6]Jan!$G$1 -> 0
B14: =Admin!B15 -> 46081 | C14: =[6]Feb!$M$1 -> 0 | D14: =[6]Feb!$N$1 -> 0 | E14: =[6]Feb!$O$1 -> 0 | F14: =[6]Feb!$P$1+[6]Feb!$Q$1 -> 0 | G14: =C14-SUM(D14:F14) -> 0 | H14: =[6]Feb!$T$1 -> 0 | I14: =[6]Feb!$G$1 -> 0
B15: =Admin!B16 -> 46112 | C15: =[6]Mar!$M$1 -> 0 | D15: =[6]Mar!$N$1 -> 0 | E15: =[6]Mar!$O$1 -> 0 | F15: =[6]Mar!$P$1+[6]Mar!$Q$1 -> 0 | G15: =C15-SUM(D15:F15) -> 0 | H15: =[6]Mar!$T$1 -> 0 | I15: =[6]Mar!$G$1 -> 0

Sheet StockControl
H1: Calculation Of Stock Sold | N1: Calculation Of Stock Sold | T1: Calculation Of Stock Sold
B2: Date | D2: Calculated Stock value | F2: Direct Material BOUGHT | H2: Stock % Prod A | J2: Net Sales Product A | L2: Direct Material SOLD | N2: Stock % Prod B | P2: Net Sales Product B | R2: Direct Material SOLD | T2: Stock % Prod C | V2: Net Sales Product C | X2: Direct Material SOLD | Z2: Stock Loss Adjustment | AB2: ACTUAL STOCK VALUE | AD2: Stock Control User Notes
AD3: 1. Enter the average percentage stock value in cell H4. This is the average % of direct materials included in the net sales value of each product type. The table will repeat this same % for each month unless a new percentage is entered in a specific month which will then overwrite the originally % entered for that and the remaining months
B4: Enter % to change % materials sold | H4: 0 | N4: 0 | T4: 0
B6: =Admin!B4 -> 45753 | D6: =AB6 -> 0
B8: =Admin!B5 -> 45777 | D8: =D6+F8-L8-R8-X8+Z6 -> 0 | F8: =IF((H$4+N$4+T$4)=0,0,[3]Apr!$P$1) -> 0 | H8: =H4 -> 0 | J8: =[2]Apr!$P$1 -> 0 | L8: =J8*H8 -> 0 | N8: =N4 -> 0 | P8: =[2]Apr!$Q$1 -> 0 | R8: =P8*N8 -> 0 | T8: =T4 -> 0 | V8: =[2]Apr!$R$1 -> 0 | X8: =V8*T8 -> 0 | Z8: =IF(AB8<>D8,AB8-D8,0) -> 0 | AB8: =AB6+F8-L8-R8-X8 -> 0
B10: =Admin!B6 -> 45808 | D10: =D8+F10-L10-R10-X10+Z8 -> 0 | F10: =IF((H$4+N$4+T$4)=0,0,[3]May!$P$1) -> 0 | H10: =H8 -> 0 | J10: =[2]May!$P$1 -> 0 | L10: =J10*H10 -> 0 | N10: =N8 -> 0 | P10: =[2]May!$Q$1 -> 0 | R10: =P10*N10 -> 0 | T10: =T8 -> 0 | V10: =[2]May!$R$1 -> 0 | X10: =V10*T10 -> 0 | Z10: =IF(AB10<>D10,AB10-D10,0) -> 0 | AB10: =AB8+F10-L10-R10-X10 -> 0
AD11: 2. Optional: manually calculate the % of direct materials included in net sales value and enter this percentage in Column H against each month
B12: =Admin!B7 -> 45838 | D12: =D10+F12-L12-R12-X12+Z10 -> 0 | F12: =IF((H$4+N$4+T$4)=0,0,[3]Jun!$P$1) -> 0 | H12: =H10 -> 0 | J12: =[2]Jun!$P$1 -> 0 | L12: =J12*H12 -> 0 | N12: =N10 -> 0 | P12: =[2]Jun!$Q$1 -> 0 | R12: =P12*N12 -> 0 | T12: =T10 -> 0 | V12: =[2]Jun!$R$1 -> 0 | X12: =V12*T12 -> 0 | Z12: =IF(AB12<>D12,AB12-D12,0) -> 0 | AB12: =AB10+F12-L12-R12-X12 -> 0
B14: =Admin!B8 -> 45869 | D14: =D12+F14-L14-R14-X14+Z12 -> 0 | F14: =IF((H$4+N$4+T$4)=0,0,[3]Jul!$P$1) -> 0 | H14: =H12 -> 0 | J14: =[2]Jul!$P$1 -> 0 | L14: =J14*H14 -> 0 | N14: =N12 -> 0 | P14: =[2]Jul!$Q$1 -> 0 | R14: =P14*N14 -> 0 | T14: =T12 -> 0 | V14: =[2]Jul!$R$1 -> 0 | X14: =V14*T14 -> 0 | Z14: =IF(AB14<>D14,AB14-D14,0) -> 0 | AB14: =AB12+F14-L14-R14-X14 -> 0
AD15: 3. Column F automatically collects the value of direct material purchased from the monthly purchases worksheet
B16: =Admin!B9 -> 45900 | D16: =D14+F16-L16-R16-X16+Z14 -> 0 | F16: =IF((H$4+N$4+T$4)=0,0,[3]Aug!$P$1) -> 0 | H16: =H14 -> 0 | J16: =[2]Aug!$P$1 -> 0 | L16: =J16*H16 -> 0 | N16: =N14 -> 0 | P16: =[2]Aug!$Q$1 -> 0 | R16: =P16*N16 -> 0 | T16: =T14 -> 0 | V16: =[2]Aug!$R$1 -> 0 | X16: =V16*T16 -> 0 | Z16: =IF(AB16<>D16,AB16-D16,0) -> 0 | AB16: =AB14+F16-L16-R16-X16 -> 0
B18: =Admin!B10 -> 45930 | D18: =D16+F18-L18-R18-X18+Z16 -> 0 | F18: =IF((H$4+N$4+T$4)=0,0,[3]Sep!$P$1) -> 0 | H18: =H16 -> 0 | J18: =[2]Sep!$P$1 -> 0 | L18: =J18*H18 -> 0 | N18: =N16 -> 0 | P18: =[2]Sep!$Q$1 -> 0 | R18: =P18*N18 -> 0 | T18: =T16 -> 0 | V18: =[2]Sep!$R$1 -> 0 | X18: =V18*T18 -> 0 | Z18: =IF(AB18<>D18,AB18-D18,0) -> 0 | AB18: =AB16+F18-L18-R18-X18 -> 0
AD19: 4. Column L automatically calculates the value of direct materials sold by applying the stock sales % to the net sales value from the sales worksheet
B20: =Admin!B11 -> 45961 | D20: =D18+F20-L20-R20-X20+Z18 -> 0 | F20: =IF((H$4+N$4+T$4)=0,0,[3]Oct!$P$1) -> 0 | H20: =H18 -> 0 | J20: =[2]Oct!$P$1 -> 0 | L20: =J20*H20 -> 0 | N20: =N18 -> 0 | P20: =[2]Oct!$Q$1 -> 0 | R20: =P20*N20 -> 0 | T20: =T18 -> 0 | V20: =[2]Oct!$R$1 -> 0 | X20: =V20*T20 -> 0 | Z20: =IF(AB20<>D20,AB20-D20,0) -> 0 | AB20: =AB18+F20-L20-R20-X20 -> 0
B22: =Admin!B12 -> 45991 | D22: =D20+F22-L22-R22-X22+Z20 -> 0 | F22: =IF((H$4+N$4+T$4)=0,0,[3]Nov!$P$1) -> 0 | H22: =H20 -> 0 | J22: =[2]Nov!$P$1 -> 0 | L22: =J22*H22 -> 0 | N22: =N20 -> 0 | P22: =[2]Nov!$Q$1 -> 0 | R22: =P22*N22 -> 0 | T22: =T20 -> 0 | V22: =[2]Nov!$R$1 -> 0 | X22: =V22*T22 -> 0 | Z22: =IF(AB22<>D22,AB22-D22,0) -> 0 | AB22: =AB20+F22-L22-R22-X22 -> 0
AD23: 5. Optional: At the end of each month conduct a physical stock check and value the items counted at cost price. Enter this actual physical value in column P at the appropriate month end date
B24: =Admin!B13 -> 46022 | D24: =D22+F24-L24-R24-X24+Z22 -> 0 | F24: =IF((H$4+N$4+T$4)=0,0,[3]Dec!$P$1) -> 0 | H24: =H22 -> 0 | J24: =[2]Dec!$P$1 -> 0 | L24: =J24*H24 -> 0 | N24: =N22 -> 0 | P24: =[2]Dec!$Q$1 -> 0 | R24: =P24*N24 -> 0 | T24: =T22 -> 0 | V24: =[2]Dec!$R$1 -> 0 | X24: =V24*T24 -> 0 | Z24: =IF(AB24<>D24,AB24-D24,0) -> 0 | AB24: =AB22+F24-L24-R24-X24 -> 0
B26: =Admin!B14 -> 46053 | D26: =D24+F26-L26-R26-X26+Z24 -> 0 | F26: =IF((H$4+N$4+T$4)=0,0,[3]Jan!$P$1) -> 0 | H26: =H24 -> 0 | J26: =[2]Jan!$P$1 -> 0 | L26: =J26*H26 -> 0 | N26: =N24 -> 0 | P26: =[2]Jan!$Q$1 -> 0 | R26: =P26*N26 -> 0 | T26: =T24 -> 0 | V26: =[2]Jan!$R$1 -> 0 | X26: =V26*T26 -> 0 | Z26: =IF(AB26<>D26,AB26-D26,0) -> 0 | AB26: =AB24+F26-L26-R26-X26 -> 0
B28: =Admin!B15 -> 46081 | D28: =D26+F28-L28-R28-X28+Z26 -> 0 | F28: =IF((H$4+N$4+T$4)=0,0,[3]OpeningCreditors!$P$1) -> 0 | H28: =H26 -> 0 | J28: =[2]Feb!$P$1 -> 0 | L28: =J28*H28 -> 0 | N28: =N26 -> 0 | P28: =[2]Feb!$Q$1 -> 0 | R28: =P28*N28 -> 0 | T28: =T26 -> 0 | V28: =[2]Feb!$R$1 -> 0 | X28: =V28*T28 -> 0 | Z28: =IF(AB28<>D28,AB28-D28,0) -> 0 | AB28: =AB26+F28-L28-R28-X28 -> 0 | AD28: 6. If the % of stock sold in net sales is correct then Column Z should be zero unless stock has been lost.. Investigate significant Stock Loss Adjustments
B30: =Admin!B17 -> 46117 | D30: =D28+F30-L30-R30-X30+Z28 -> 0 | F30: =IF((H$4+N$4+T$4)=0,0,[3]Mar!$P$1) -> 0 | H30: =H28 -> 0 | J30: =[2]Mar!$P$1 -> 0 | L30: =J30*H30 -> 0 | N30: =N28 -> 0 | P30: =[2]Mar!$Q$1 -> 0 | R30: =P30*N30 -> 0 | T30: =T28 -> 0 | V30: =[2]Mar!$R$1 -> 0 | X30: =V30*T30 -> 0 | Z30: =IF(AB30<>D30,AB30-D30,0) -> 0 | AB30: =AB28+F30-L30-R30-X30 -> 0

Sheet Profit Forecast
B2: ACTUAL Profit and Loss Account | C2: Total Year | D2: =Admin!B5 -> 45777 | E2: =Admin!B6 -> 45808 | F2: =Admin!B7 -> 45838 | G2: =Admin!B8 -> 45869 | H2: =Admin!B9 -> 45900 | I2: =Admin!B10 -> 45930 | J2: =Admin!B11 -> 45961 | K2: =Admin!B12 -> 45991 | L2: =Admin!B13 -> 46022 | M2: =Admin!B14 -> 46053 | N2: =Admin!B15 -> 46081 | O2: =Admin!B16 -> 46112
C3: =Admin!B$17 -> 46117
C4: £ | D4: £ | E4: £ | F4: £ | G4: £ | H4: £ | I4: £ | J4: £ | K4: £ | L4: £ | M4: £ | N4: £ | O4: £
B5: Sales Turnover | C5: =SUM(D5:O5) -> 0 | D5: ='Profit & Loss Account'!C9 -> 0 | E5: ='Profit & Loss Account'!D9 -> 0 | F5: ='Profit & Loss Account'!E9 -> 0 | G5: ='Profit & Loss Account'!F9 -> 0 | H5: ='Profit & Loss Account'!G9 -> 0 | I5: ='Profit & Loss Account'!H9 -> 0 | J5: ='Profit & Loss Account'!I9 -> 0 | K5: ='Profit & Loss Account'!J9 -> 0 | ... O5: ='Profit & Loss Account'!N9 -> 0
B7: Investment Grants | C7: =SUM(D7:O7) -> 0 | D7: ='Profit & Loss Account'!C11 -> 0 | E7: ='Profit & Loss Account'!D11 -> 0 | F7: ='Profit & Loss Account'!E11 -> 0 | G7: ='Profit & Loss Account'!F11 -> 0 | H7: ='Profit & Loss Account'!G11 -> 0 | I7: ='Profit & Loss Account'!H11 -> 0 | J7: ='Profit & Loss Account'!I11 -> 0 | K7: ='Profit & Loss Account'!J11 -> 0 | ... O7: ='Profit & Loss Account'!N11 -> 0
B9: Cost of Sales | C9: =SUM(D9:O9) -> 0 | D9: ='Profit & Loss Account'!C17 -> 0 | E9: ='Profit & Loss Account'!D17 -> 0 | F9: ='Profit & Loss Account'!E17 -> 0 | G9: ='Profit & Loss Account'!F17 -> 0 | H9: ='Profit & Loss Account'!G17 -> 0 | I9: ='Profit & Loss Account'!H17 -> 0 | J9: ='Profit & Loss Account'!I17 -> 0 | K9: ='Profit & Loss Account'!J17 -> 0 | ... O9: ='Profit & Loss Account'!N17 -> 0
B11: Gross Profit | C11: =SUM(D11:O11) -> 0 | D11: =D5+D7-D9 -> 0 | E11: =E5+E7-E9 -> 0 | F11: =F5+F7-F9 -> 0 | G11: =G5+G7-G9 -> 0 | H11: =H5+H7-H9 -> 0 | I11: =I5+I7-I9 -> 0 | J11: =J5+J7-J9 -> 0 | K11: =K5+K7-K9 -> 0 | ... O11: =O5+O7-O9 -> 0
B13: General Expenses | C13: =SUM(D13:O13) -> 0 | D13: ='Profit & Loss Account'!C35 -> 0 | E13: ='Profit & Loss Account'!D35 -> 0 | F13: ='Profit & Loss Account'!E35 -> 0 | G13: ='Profit & Loss Account'!F35 -> 0 | H13: ='Profit & Loss Account'!G35 -> 0 | I13: ='Profit & Loss Account'!H35 -> 0 | J13: ='Profit & Loss Account'!I35 -> 0 | K13: ='Profit & Loss Account'!J35 -> 0 | ... O13: ='Profit & Loss Account'!N35 -> 0
B15: Operating Profit | C15: =SUM(D15:O15) -> 0 | D15: =D11-D13 -> 0 | E15: =E11-E13 -> 0 | F15: =F11-F13 -> 0 | G15: =G11-G13 -> 0 | H15: =H11-H13 -> 0 | I15: =I11-I13 -> 0 | J15: =J11-J13 -> 0 | K15: =K11-K13 -> 0 | ... O15: =O11-O13 -> 0
B16: Interest received | C16: =SUM(D16:O16) -> 0 | D16: ='Profit & Loss Account'!C38 -> 0 | E16: ='Profit & Loss Account'!D38 -> 0 | F16: ='Profit & Loss Account'!E38 -> 0 | G16: ='Profit & Loss Account'!F38 -> 0 | H16: ='Profit & Loss Account'!G38 -> 0 | I16: ='Profit & Loss Account'!H38 -> 0 | J16: ='Profit & Loss Account'!I38 -> 0 | K16: ='Profit & Loss Account'!J38 -> 0 | ... O16: ='Profit & Loss Account'!N38 -> 0
B17: Profit (Loss) before Tax | C17: =SUM(D17:O17) -> 0 | D17: =D15+D16 -> 0 | E17: =E15+E16 -> 0 | F17: =F15+F16 -> 0 | G17: =G15+G16 -> 0 | H17: =H15+H16 -> 0 | I17: =I15+I16 -> 0 | J17: =J15+J16 -> 0 | K17: =K15+K16 -> 0 | ... O17: =O15+O16 -> 0
B19: FORECAST Profit and Loss Account | C19: Total Year | D19: =D2 -> 45777 | E19: =E2 -> 45808 | F19: =F2 -> 45838 | G19: =G2 -> 45869 | H19: =H2 -> 45900 | I19: =I2 -> 45930 | J19: =J2 -> 45961 | K19: =K2 -> 45991 | ... O19: =O2 -> 46112
C20: =Admin!B$17 -> 46117
C21: =SUM(D21:O21) -> 0 | D21: =IF(D5>0,1," ") | E21: =IF(E5>0,1," ") | F21: =IF(F5>0,1," ") | G21: =IF(G5>0,1," ") | H21: =IF(H5>0,1," ") | I21: =IF(I5>0,1," ") | J21: =IF(J5>0,1," ") | K21: =IF(K5>0,1," ") | ... O21: =IF(O5>0,1," ")
B22: Sales Turnover | C22: =SUM(D22:O22) -> 0 | D22: =IF(C5>0,IF(D5>0,D5,C5/C21),0) -> 0 | E22: =IF(C5>0,IF(E5>0,E5,C5/C21),0) -> 0 | F22: =IF(C5>0,IF(F5>0,F5,C5/C21),0) -> 0 | G22: =IF(C5>0,IF(G5>0,G5,C5/C21),0) -> 0 | H22: =IF(C5>0,IF(H5>0,H5,C5/C21),0) -> 0 | I22: =IF(C5>0,IF(I5>0,I5,C5/C21),0) -> 0 | J22: =IF(C5>0,IF(J5>0,J5,C5/C21),0) -> 0 | K22: =IF(C5>0,IF(K5>0,K5,C5/C21),0) -> 0 | L22: =IF(C5>0,IF(L5>0,L5,C5/C21),0) -> 0 | M22: =IF(C5>0,IF(M5>0,M5,C5/C21),0) -> 0 | N22: =IF(C5>0,IF(N5>0,N5,C5/C21),0) -> 0 | O22: =IF(C5>0,IF(O5>0,O5,C5/C21),0) -> 0
B24: Investment Grants | C24: =SUM(D24:O24) -> 0 | D24: =D7 -> 0 | E24: =E7 -> 0 | F24: =F7 -> 0 | G24: =G7 -> 0 | H24: =H7 -> 0 | I24: =I7 -> 0 | J24: =J7 -> 0 | K24: =K7 -> 0 | ... O24: =O7 -> 0
B26: Cost of Sales | C26: =SUM(D26:O26) -> 0 | D26: =IF(C5>0,IF(D5>0,D9,C9/C21),0) -> 0 | E26: =IF(C5>0,IF(E5>0,E9,C9/C21),0) -> 0 | F26: =IF(C5>0,IF(F5>0,F9,C9/C21),0) -> 0 | G26: =IF(C5>0,IF(G5>0,G9,C9/C21),0) -> 0 | H26: =IF(C5>0,IF(H5>0,H9,C9/C21),0) -> 0 | I26: =IF(C5>0,IF(I5>0,I9,C9/C21),0) -> 0 | J26: =IF(C5>0,IF(J5>0,J9,C9/C21),0) -> 0 | K26: =IF(C5>0,IF(K5>0,K9,C9/C21),0) -> 0 | L26: =IF(C5>0,IF(L5>0,L9,C9/C21),0) -> 0 | M26: =IF(C5>0,IF(M5>0,M9,C9/C21),0) -> 0 | N26: =IF(C5>0,IF(N5>0,N9,C9/C21),0) -> 0 | O26: =IF(C5>0,IF(O5>0,O9,C9/C21),0) -> 0
B28: Gross Profit | C28: =SUM(D28:O28) -> 0 | D28: =D22+D24-D26 -> 0 | E28: =E22+E24-E26 -> 0 | F28: =F22+F24-F26 -> 0 | G28: =G22+G24-G26 -> 0 | H28: =H22+H24-H26 -> 0 | I28: =I22+I24-I26 -> 0 | J28: =J22+J24-J26 -> 0 | K28: =K22+K24-K26 -> 0 | ... O28: =O22+O24-O26 -> 0
B30: General Expenses | C30: =SUM(D30:O30) -> 0 | D30: =IF(C5>0,IF(D5>0,D13,C13/C21),0) -> 0 | E30: =IF(C5>0,IF(E5>0,E13,C13/C21),0) -> 0 | F30: =IF(C5>0,IF(F5>0,F13,C13/C21),0) -> 0 | G30: =IF(C5>0,IF(G5>0,G13,C13/C21),0) -> 0 | H30: =IF(C5>0,IF(H5>0,H13,C13/C21),0) -> 0 | I30: =IF(C5>0,IF(I5>0,I13,C13/C21),0) -> 0 | J30: =IF(C5>0,IF(J5>0,J13,C13/C21),0) -> 0 | K30: =IF(C5>0,IF(K5>0,K13,C13/C21),0) -> 0 | L30: =IF(C5>0,IF(L5>0,L13,C13/C21),0) -> 0 | M30: =IF(C5>0,IF(M5>0,M13,C13/C21),0) -> 0 | N30: =IF(C5>0,IF(N5>0,N13,C13/C21),0) -> 0 | O30: =IF(C5>0,IF(O5>0,O13,C13/C21),0) -> 0
B32: Operating Profit | C32: =SUM(D32:O32) -> 0 | D32: =D28-D30 -> 0 | E32: =E28-E30 -> 0 | F32: =F28-F30 -> 0 | G32: =G28-G30 -> 0 | H32: =H28-H30 -> 0 | I32: =I28-I30 -> 0 | J32: =J28-J30 -> 0 | K32: =K28-K30 -> 0 | ... O32: =O28-O30 -> 0
B33: Interest received | C33: =SUM(D33:O33) -> 0 | D33: =D16 -> 0 | E33: =E16 -> 0 | F33: =F16 -> 0 | G33: =G16 -> 0 | H33: =H16 -> 0 | I33: =I16 -> 0 | J33: =J16 -> 0 | K33: =K16 -> 0 | ... O33: =O16 -> 0
B34: Profit (Loss) before Tax | C34: =SUM(D34:O34) -> 0 | D34: =D32+D33 -> 0 | E34: =E32+E33 -> 0 | F34: =F32+F33 -> 0 | G34: =G32+G33 -> 0 | H34: =H32+H33 -> 0 | I34: =I32+I33 -> 0 | J34: =J32+J33 -> 0 | K34: =K32+K33 -> 0 | ... O34: =O32+O33 -> 0
B36: FORECAST TAX CALCULATION
B37: Add Depreciation | C37: ='Profit & Loss Account'!B33+'Profit & Loss Account'!B34 -> 0
B38: Less Capital Allowances | C38: =[1]Schedule!$Q$1+[1]Schedule!$R$1+[1]Schedule!$Y$1-[1]Schedule!$Z$1 -> 0
B39: Profit before Tax | C39: =C34+C37-C38 -> 0
B40: Personal Allowance | C40: =Admin!N$4 -> 12570
B41: Profit after Allowance | C41: =IF((C39>C40),(C39-C40),0) -> 0
B42: Tax at standard rate | C42: =IF((C41>0),(IF((C41<Admin!N$12),C41*Admin!N$6,Admin!N$12*Admin!N$6)),0) -> 0
B43: Tax at higher rate | C43: =IF((C41>Admin!N$12),((C41-Admin!N$12)*Admin!N$7),0) -> 0
B44: National Insurance | C44: =IF((C41>0),IF(C41>Admin!N12,Admin!N12*Admin!L20+(C41-Admin!N12)*Admin!L23,C41*Admin!L$20),0) -> 0
B46: TAX & NI LIABILITY | C46: =C42+C43+C44 -> 0

Sheet Admin
B1: Dates
B2: 45716 | D2: Capital Tax Allowances | G2: =B23 -> 2025-26 | J2: Income Tax Rates | L2: =G2 -> 2025-26
B3: 45747
B4: 45753 | D4: Annual Investment Allowance | G4: 1 | I4: Personal allowance | N4: 12570 | O4: £
B5: 45777 | D5: Writing down allowance | G5: 0.18
B6: 45808 | I6: Basic rate applicable on taxable income up to higher rate | N6: 0.2 | O6: %
B7: 45838 | D7: Allowances restricted on Motor vehicles | I7: Higher rate applicable on taxable income over higher rate | N7: 0.4 | O7: %
B8: 45869 | D8: Costing over | E8: 12000 | F8: Restricted to | G8: 3000
B9: 45900 | I9: Taxable Bands Allowances | L9: Start Level | M9: End Level | N9: Tax Band
B10: 45930
B11: 45961 | D11: Depreciation Rates Applied | G11: % | I11: Basic rate | K11: 0.2 | L11: =N11 -> 0 | M11: 37700 | N11: 0
B12: 45991 | I12: Higher rate | K12: 0 | L12: 37701 | N12: 37701
B13: 46022 | D13: Land & Property | G13: 0
B14: 46053 | D14: Plant & Machinery | G14: 0.1 | I14: National Insurance rates | L14: =G2 -> 2025-26
B15: 46081 | D15: Fixtures & Fittings | G15: 0.2
B16: 46112 | D16: Computer Equipment | G16: 0.33 | I16: NI Class 2 rate | L16: 0 | M16: Above Lower Profits Threshold (LPT)
B17: 46117 | D17: Motor Vehicles | G17: 0.25
B18: 46142
B19: 46173 | D19: Mileage Allowances | F19: Miles | G19: p per mile | I19: NI Class 4 rate between lower profits and upper profits limit | M19: NIC class 4 lower limit
B20: 46203 | L20: 0.06 | N20: 12570 | O20: £
B21: 46418 | D21: Higher rate allowance up to | F21: 10000 | G21: 0.45
B22: 46599 | D22: Lower rate allowance over | F22: 10001 | G22: 0.25 | I22: NI Class 4 rate above upper profits limit | M22: NIC class 4 upper limit
B23: 2025-26 | L23: 0.02 | N23: 50270 | O23: £
B24: 2026-27 | D24: Mileage Allowances
D26: VAT Threshold | F26: 90000
D27: VAT Rate | F27: 0.2
