Workbook

Sheet Schedule
B1: Date Asset Purchased | C1: FIXED ASSETS | E1: =E57+E110 -> 0 | F1: =F57+F110 -> 0 | G1: =G57+G110 -> 0 | H1: Deprn Rate % | I1: =I57+I110 -> 0 | J1: =J57+J110 -> 0 | K1: =K57+K110 -> 0 | M1: Enter % Personal use of vehicles | O1: =O57+O110 -> 0 | P1: Annual Invest Allow | Q1: =Q57+Q110 -> 0 | R1: =R57+R110 -> 0 | S1: =S57+S110 -> 0 | U1: Date Asset Sold | V1: =V57+V110 -> 0 | W1: =W57+W110 -> 0 | X1: =X57+X110 -> 0 | Y1: =Y57+Y110 -> 0 | Z1: =Z57+Z110 -> 0
C2: Asset Description | D2: Purchase Reference | E2: Original Cost | F2: Accumulated Depreciation | G2: Written Down Book Value | I2: Depreciation Charge current year | J2: Accumulated Depreciation | K2: Written Down Book Value | O2: Written Down Tax Value | Q2: First Year Allowance | R2: W Down Allowance | S2: Written Down Tax Value | V2: Sales Value Assets Sold | W2: Original Cost Assets Sold | X2: Accumulated Depreciation Assets Sold | Y2: Capital Allowance | Z2: Balancing Charge
F4: =[1]Admin!$B$4 -> 45388 | G4: =[1]Admin!$B$4 -> 45388 | J4: =[1]Admin!$B$17 -> 45752 | K4: =[1]Admin!$B$17 -> 45752 | O4: =[1]Admin!$B$4 -> 45388 | P4: =[1]Admin!$G$4 -> 1 | R4: =[1]Admin!$G$5 -> 0.18 | S4: =[1]Admin!$B$17 -> 45752
B6: EXISTING FIXED ASSETS at | D6: =[1]Admin!$B$4 -> 45388
B7: Land & Property | H7: =[1]Admin!$G$13 -> 0
G8: =IF(E8>0,E8-F8," ") | H8: =H$7 -> 0 | I8: =IF(E8>0,MIN(E8*H8,G8)," ") | J8: =IF(E8>0,F8+I8," ") | K8: =IF(E8>0,E8-J8," ") | W8: =IF(V8>0,E8," ") | X8: =IF(V8>0,J8," ")
G9: =IF(E9>0,E9-F9," ") | H9: =H$7 -> 0 | I9: =IF(E9>0,MIN(E9*H9,G9)," ") | J9: =IF(E9>0,F9+I9," ") | K9: =IF(E9>0,E9-J9," ") | W9: =IF(V9>0,E9," ") | X9: =IF(V9>0,J9," ")
G10: =IF(E10>0,E10-F10," ") | H10: =H$7 -> 0 | I10: =IF(E10>0,MIN(E10*H10,G10)," ") | J10: =IF(E10>0,F10+I10," ") | K10: =IF(E10>0,E10-J10," ") | W10: =IF(V10>0,E10," ") | X10: =IF(V10>0,J10," ")
B11: Existing Land & Property | E11: =SUM(E8:E10) -> 0 | F11: =SUM(F8:F10) -> 0 | G11: =SUM(G8:G10) -> 0 | I11: =SUM(I8:I10) -> 0 | J11: =SUM(J8:J10) -> 0 | K11: =SUM(K8:K10) -> 0 | O11: =SUM(O8:O10) -> 0 | Q11: =SUM(Q8:Q10) -> 0 | R11: =SUM(R8:R10) -> 0 | S11: =SUM(S8:S10) -> 0 | V11: =SUM(V8:V10) -> 0 | W11: =SUM(W8:W10) -> 0 | X11: =SUM(X8:X10) -> 0 | Y11: =SUM(Y8:Y10) -> 0 | Z11: =SUM(Z8:Z10) -> 0
B13: Plant & Machinery | H13: =[1]Admin!$G$14 -> 0.1
G14: =IF(E14>0,E14-F14," ") | H14: =H$13 -> 0.1 | I14: =IF(E14>0,MIN(E14*H14,G14)," ") | J14: =IF(E14>0,F14+I14," ") | K14: =IF(E14>0,E14-J14," ") | R14: =IF(O14>0,O14*R$4," ") | S14: =IF(O14>0,O14-R14," ") | W14: =IF(V14>0,E14," ") | X14: =IF(V14>0,J14," ") | Y14: =IF((U14+V14)>0,IF(V14<S14,S14-V14," ")," ") | Z14: =IF((U14+V14)>0,IF(V14>S14,V14-S14," ")," ")
G15: =IF(E15>0,E15-F15," ") | H15: =H$13 -> 0.1 | I15: =IF(E15>0,MIN(E15*H15,G15)," ") | J15: =IF(E15>0,F15+I15," ") | K15: =IF(E15>0,E15-J15," ") | R15: =IF(O15>0,O15*R$4," ") | S15: =IF(O15>0,O15-R15," ") | W15: =IF(V15>0,E15," ") | X15: =IF(V15>0,J15," ") | Y15: =IF((U15+V15)>0,IF(V15<S15,S15-V15," ")," ") | Z15: =IF((U15+V15)>0,IF(V15>S15,V15-S15," ")," ")
G16: =IF(E16>0,E16-F16," ") | H16: =H$13 -> 0.1 | I16: =IF(E16>0,MIN(E16*H16,G16)," ") | J16: =IF(E16>0,F16+I16," ") | K16: =IF(E16>0,E16-J16," ") | R16: =IF(O16>0,O16*R$4," ") | S16: =IF(O16>0,O16-R16," ") | W16: =IF(V16>0,E16," ") | X16: =IF(V16>0,J16," ") | Y16: =IF((U16+V16)>0,IF(V16<S16,S16-V16," ")," ") | Z16: =IF((U16+V16)>0,IF(V16>S16,V16-S16," ")," ")
G17: =IF(E17>0,E17-F17," ") | H17: =H$13 -> 0.1 | I17: =IF(E17>0,MIN(E17*H17,G17)," ") | J17: =IF(E17>0,F17+I17," ") | K17: =IF(E17>0,E17-J17," ") | R17: =IF(O17>0,O17*R$4," ") | S17: =IF(O17>0,O17-R17," ") | W17: =IF(V17>0,E17," ") | X17: =IF(V17>0,J17," ") | Y17: =IF((U17+V17)>0,IF(V17<S17,S17-V17," ")," ") | Z17: =IF((U17+V17)>0,IF(V17>S17,V17-S17," ")," ")
G18: =IF(E18>0,E18-F18," ") | H18: =H$13 -> 0.1 | I18: =IF(E18>0,MIN(E18*H18,G18)," ") | J18: =IF(E18>0,F18+I18," ") | K18: =IF(E18>0,E18-J18," ") | R18: =IF(O18>0,O18*R$4," ") | S18: =IF(O18>0,O18-R18," ") | W18: =IF(V18>0,E18," ") | X18: =IF(V18>0,J18," ") | Y18: =IF((U18+V18)>0,IF(V18<S18,S18-V18," ")," ") | Z18: =IF((U18+V18)>0,IF(V18>S18,V18-S18," ")," ")
B19: Existing Plant & Machinery | E19: =SUM(E14:E18) -> 0 | F19: =SUM(F14:F18) -> 0 | G19: =SUM(G14:G18) -> 0 | I19: =SUM(I14:I18) -> 0 | J19: =SUM(J14:J18) -> 0 | K19: =SUM(K14:K18) -> 0 | O19: =SUM(O14:O18) -> 0 | Q19: =SUM(Q14:Q18) -> 0 | R19: =SUM(R14:R18) -> 0 | S19: =SUM(S14:S18) -> 0 | V19: =SUM(V14:V18) -> 0 | W19: =SUM(W14:W18) -> 0 | X19: =SUM(X14:X18) -> 0 | Y19: =SUM(Y14:Y18) -> 0 | Z19: =SUM(Z14:Z18) -> 0
B21: Fixtures & Fittings | H21: =[1]Admin!$G$15 -> 0.2
G22: =IF(E22>0,E22-F22," ") | H22: =H$21 -> 0.2 | I22: =IF(E22>0,MIN(E22*H22,G22)," ") | J22: =IF(E22>0,F22+I22," ") | K22: =IF(E22>0,E22-J22," ") | R22: =IF(O22>0,O22*R$4," ") | S22: =IF(O22>0,O22-R22," ") | W22: =IF(V22>0,E22," ") | X22: =IF(V22>0,J22," ") | Y22: =IF((U22+V22)>0,IF(V22<S22,S22-V22," ")," ") | Z22: =IF((U22+V22)>0,IF(V22>S22,V22-S22," ")," ")
G23: =IF(E23>0,E23-F23," ") | H23: =H$21 -> 0.2 | I23: =IF(E23>0,MIN(E23*H23,G23)," ") | J23: =IF(E23>0,F23+I23," ") | K23: =IF(E23>0,E23-J23," ") | R23: =IF(O23>0,O23*R$4," ") | S23: =IF(O23>0,O23-R23," ") | W23: =IF(V23>0,E23," ") | X23: =IF(V23>0,J23," ") | Y23: =IF((U23+V23)>0,IF(V23<S23,S23-V23," ")," ") | Z23: =IF((U23+V23)>0,IF(V23>S23,V23-S23," ")," ")
G24: =IF(E24>0,E24-F24," ") | H24: =H$21 -> 0.2 | I24: =IF(E24>0,MIN(E24*H24,G24)," ") | J24: =IF(E24>0,F24+I24," ") | K24: =IF(E24>0,E24-J24," ") | R24: =IF(O24>0,O24*R$4," ") | S24: =IF(O24>0,O24-R24," ") | W24: =IF(V24>0,E24," ") | X24: =IF(V24>0,J24," ") | Y24: =IF((U24+V24)>0,IF(V24<S24,S24-V24," ")," ") | Z24: =IF((U24+V24)>0,IF(V24>S24,V24-S24," ")," ")
G25: =IF(E25>0,E25-F25," ") | H25: =H$21 -> 0.2 | I25: =IF(E25>0,MIN(E25*H25,G25)," ") | J25: =IF(E25>0,F25+I25," ") | K25: =IF(E25>0,E25-J25," ") | R25: =IF(O25>0,O25*R$4," ") | S25: =IF(O25>0,O25-R25," ") | W25: =IF(V25>0,E25," ") | X25: =IF(V25>0,J25," ") | Y25: =IF((U25+V25)>0,IF(V25<S25,S25-V25," ")," ") | Z25: =IF((U25+V25)>0,IF(V25>S25,V25-S25," ")," ")
G26: =IF(E26>0,E26-F26," ") | H26: =H$21 -> 0.2 | I26: =IF(E26>0,MIN(E26*H26,G26)," ") | J26: =IF(E26>0,F26+I26," ") | K26: =IF(E26>0,E26-J26," ") | R26: =IF(O26>0,O26*R$4," ") | S26: =IF(O26>0,O26-R26," ") | W26: =IF(V26>0,E26," ") | X26: =IF(V26>0,J26," ") | Y26: =IF((U26+V26)>0,IF(V26<S26,S26-V26," ")," ") | Z26: =IF((U26+V26)>0,IF(V26>S26,V26-S26," ")," ")
B27: Existing Fixtures & Fittings | E27: =SUM(E22:E26) -> 0 | F27: =SUM(F22:F26) -> 0 | G27: =SUM(G22:G26) -> 0 | I27: =SUM(I22:I26) -> 0 | J27: =SUM(J22:J26) -> 0 | K27: =SUM(K22:K26) -> 0 | O27: =SUM(O22:O26) -> 0 | Q27: =SUM(Q22:Q26) -> 0 | R27: =SUM(R22:R26) -> 0 | S27: =SUM(S22:S26) -> 0 | V27: =SUM(V22:V26) -> 0 | W27: =SUM(W22:W26) -> 0 | X27: =SUM(X22:X26) -> 0 | Y27: =SUM(Y22:Y26) -> 0 | Z27: =SUM(Z22:Z26) -> 0
B29: Computers | H29: =[1]Admin!$G$16 -> 0.33
G30: =IF(E30>0,E30-F30," ") | H30: =H$29 -> 0.33 | I30: =IF(E30>0,MIN(E30*H30,G30)," ") | J30: =IF(E30>0,F30+I30," ") | K30: =IF(E30>0,E30-J30," ") | R30: =IF(O30>0,O30*R$4," ") | S30: =IF(O30>0,O30-R30," ") | W30: =IF(V30>0,E30," ") | X30: =IF(V30>0,J30," ") | Y30: =IF((U30+V30)>0,IF(V30<S30,S30-V30," ")," ") | Z30: =IF((U30+V30)>0,IF(V30>S30,V30-S30," ")," ")
G31: =IF(E31>0,E31-F31," ") | H31: =H$29 -> 0.33 | I31: =IF(E31>0,MIN(E31*H31,G31)," ") | J31: =IF(E31>0,F31+I31," ") | K31: =IF(E31>0,E31-J31," ") | R31: =IF(O31>0,O31*R$4," ") | S31: =IF(O31>0,O31-R31," ") | W31: =IF(V31>0,E31," ") | X31: =IF(V31>0,J31," ") | Y31: =IF((U31+V31)>0,IF(V31<S31,S31-V31," ")," ") | Z31: =IF((U31+V31)>0,IF(V31>S31,V31-S31," ")," ")
G32: =IF(E32>0,E32-F32," ") | H32: =H$29 -> 0.33 | I32: =IF(E32>0,MIN(E32*H32,G32)," ") | J32: =IF(E32>0,F32+I32," ") | K32: =IF(E32>0,E32-J32," ") | R32: =IF(O32>0,O32*R$4," ") | S32: =IF(O32>0,O32-R32," ") | W32: =IF(V32>0,E32," ") | X32: =IF(V32>0,J32," ") | Y32: =IF((U32+V32)>0,IF(V32<S32,S32-V32," ")," ") | Z32: =IF((U32+V32)>0,IF(V32>S32,V32-S32," ")," ")
G33: =IF(E33>0,E33-F33," ") | H33: =H$29 -> 0.33 | I33: =IF(E33>0,MIN(E33*H33,G33)," ") | J33: =IF(E33>0,F33+I33," ") | K33: =IF(E33>0,E33-J33," ") | R33: =IF(O33>0,O33*R$4," ") | S33: =IF(O33>0,O33-R33," ") | W33: =IF(V33>0,E33," ") | X33: =IF(V33>0,J33," ") | Y33: =IF((U33+V33)>0,IF(V33<S33,S33-V33," ")," ") | Z33: =IF((U33+V33)>0,IF(V33>S33,V33-S33," ")," ")
G34: =IF(E34>0,E34-F34," ") | H34: =H$29 -> 0.33 | I34: =IF(E34>0,MIN(E34*H34,G34)," ") | J34: =IF(E34>0,F34+I34," ") | K34: =IF(E34>0,E34-J34," ") | R34: =IF(O34>0,O34*R$4," ") | S34: =IF(O34>0,O34-R34," ") | W34: =IF(V34>0,E34," ") | X34: =IF(V34>0,J34," ") | Y34: =IF((U34+V34)>0,IF(V34<S34,S34-V34," ")," ") | Z34: =IF((U34+V34)>0,IF(V34>S34,V34-S34," ")," ")
B35: Existing Computers | E35: =SUM(E30:E34) -> 0 | F35: =SUM(F30:F34) -> 0 | G35: =SUM(G30:G34) -> 0 | I35: =SUM(I30:I34) -> 0 | J35: =SUM(J30:J34) -> 0 | K35: =SUM(K30:K34) -> 0 | O35: =SUM(O30:O34) -> 0 | Q35: =SUM(Q30:Q34) -> 0 | R35: =SUM(R30:R34) -> 0 | S35: =SUM(S30:S34) -> 0 | V35: =SUM(V30:V34) -> 0 | W35: =SUM(W30:W34) -> 0 | X35: =SUM(X30:X34) -> 0 | Y35: =SUM(Y30:Y34) -> 0 | Z35: =SUM(Z30:Z34) -> 0
B37: Motor Vehicles - costing over £ | D37: =[1]Admin!$E$8 -> 12000 | H37: =[1]Admin!$G$17 -> 0.25
G38: =IF(E38>0,E38-F38," ") | H38: =H$37 -> 0.25 | I38: =IF(E38>0,MIN(E38*H38,G38)," ") | J38: =IF(E38>0,F38+I38," ") | K38: =IF(E38>0,E38-J38," ") | M38: 0 | R38: =IF(O38>0,MIN(O38*R$4*(1-M38),[1]Admin!$G$8*(1-M38))," ") | S38: =IF(O38>0,O38-R38," ") | W38: =IF(V38>0,E38," ") | X38: =IF(V38>0,J38," ") | Y38: =IF((U38+V38)>0,IF(V38<S38,(S38-V38)*(1-M38)," ")," ") | Z38: =IF((U38+V38)>0,IF(V38>S38,(V38-S38)*(1-M38)," ")," ")
G39: =IF(E39>0,E39-F39," ") | H39: =H$37 -> 0.25 | I39: =IF(E39>0,MIN(E39*H39,G39)," ") | J39: =IF(E39>0,F39+I39," ") | K39: =IF(E39>0,E39-J39," ") | M39: 0 | R39: =IF(O39>0,MIN(O39*R$4*(1-M39),[1]Admin!$G$8*(1-M39))," ") | S39: =IF(O39>0,O39-R39," ") | W39: =IF(V39>0,E39," ") | X39: =IF(V39>0,J39," ") | Y39: =IF((U39+V39)>0,IF(V39<S39,(S39-V39)*(1-M39)," ")," ") | Z39: =IF((U39+V39)>0,IF(V39>S39,(V39-S39)*(1-M39)," ")," ")
G40: =IF(E40>0,E40-F40," ") | H40: =H$37 -> 0.25 | I40: =IF(E40>0,MIN(E40*H40,G40)," ") | J40: =IF(E40>0,F40+I40," ") | K40: =IF(E40>0,E40-J40," ") | M40: 0 | R40: =IF(O40>0,MIN(O40*R$4*(1-M40),[1]Admin!$G$8*(1-M40))," ") | S40: =IF(O40>0,O40-R40," ") | W40: =IF(V40>0,E40," ") | X40: =IF(V40>0,J40," ") | Y40: =IF((U40+V40)>0,IF(V40<S40,(S40-V40)*(1-M40)," ")," ") | Z40: =IF((U40+V40)>0,IF(V40>S40,(V40-S40)*(1-M40)," ")," ")
G41: =IF(E41>0,E41-F41," ") | H41: =H$37 -> 0.25 | I41: =IF(E41>0,MIN(E41*H41,G41)," ") | J41: =IF(E41>0,F41+I41," ") | K41: =IF(E41>0,E41-J41," ") | M41: 0 | R41: =IF(O41>0,MIN(O41*R$4*(1-M41),[1]Admin!$G$8*(1-M41))," ") | S41: =IF(O41>0,O41-R41," ") | W41: =IF(V41>0,E41," ") | X41: =IF(V41>0,J41," ") | Y41: =IF((U41+V41)>0,IF(V41<S41,(S41-V41)*(1-M41)," ")," ") | Z41: =IF((U41+V41)>0,IF(V41>S41,(V41-S41)*(1-M41)," ")," ")
G42: =IF(E42>0,E42-F42," ") | H42: =H$37 -> 0.25 | I42: =IF(E42>0,MIN(E42*H42,G42)," ") | J42: =IF(E42>0,F42+I42," ") | K42: =IF(E42>0,E42-J42," ") | M42: 0 | R42: =IF(O42>0,MIN(O42*R$4*(1-M42),[1]Admin!$G$8*(1-M42))," ") | S42: =IF(O42>0,O42-R42," ") | W42: =IF(V42>0,E42," ") | X42: =IF(V42>0,J42," ") | Y42: =IF((U42+V42)>0,IF(V42<S42,(S42-V42)*(1-M42)," ")," ") | Z42: =IF((U42+V42)>0,IF(V42>S42,(V42-S42)*(1-M42)," ")," ")
B43: Motor Vehicles - costing under £ | D43: =[1]Admin!$E$8 -> 12000
G44: =IF(E44>0,E44-F44," ") | H44: =H$37 -> 0.25 | I44: =IF(E44>0,MIN(E44*H44,G44)," ") | J44: =IF(E44>0,F44+I44," ") | K44: =IF(E44>0,E44-J44," ") | M44: 0 | R44: =IF(O44>0,MIN(O44*R$4*(1-M44),[1]Admin!$G$8*(1-M44))," ") | S44: =IF(O44>0,O44-R44," ") | W44: =IF(V44>0,E44," ") | X44: =IF(V44>0,J44," ") | Y44: =IF((U44+V44)>0,IF(V44<S44,(S44-V44)*(1-M44)," ")," ") | Z44: =IF((U44+V44)>0,IF(V44>S44,(V44-S44)*(1-M44)," ")," ")
G45: =IF(E45>0,E45-F45," ") | H45: =H$37 -> 0.25 | I45: =IF(E45>0,MIN(E45*H45,G45)," ") | J45: =IF(E45>0,F45+I45," ") | K45: =IF(E45>0,E45-J45," ") | M45: 0 | R45: =IF(O45>0,MIN(O45*R$4*(1-M45),[1]Admin!$G$8*(1-M45))," ") | S45: =IF(O45>0,O45-R45," ") | W45: =IF(V45>0,E45," ") | X45: =IF(V45>0,J45," ") | Y45: =IF((U45+V45)>0,IF(V45<S45,(S45-V45)*(1-M45)," ")," ") | Z45: =IF((U45+V45)>0,IF(V45>S45,(V45-S45)*(1-M45)," ")," ")
G46: =IF(E46>0,E46-F46," ") | H46: =H$37 -> 0.25 | I46: =IF(E46>0,MIN(E46*H46,G46)," ") | J46: =IF(E46>0,F46+I46," ") | K46: =IF(E46>0,E46-J46," ") | M46: 0 | R46: =IF(O46>0,MIN(O46*R$4*(1-M46),[1]Admin!$G$8*(1-M46))," ") | S46: =IF(O46>0,O46-R46," ") | W46: =IF(V46>0,E46," ") | X46: =IF(V46>0,J46," ") | Y46: =IF((U46+V46)>0,IF(V46<S46,(S46-V46)*(1-M46)," ")," ") | Z46: =IF((U46+V46)>0,IF(V46>S46,(V46-S46)*(1-M46)," ")," ")
...

Sheet FAreconciliation
E2: FIXED ASSET RECONCILIATION
B4: FIXED ASSET PURCHASES | E4: Original Cost | G4: FIXED ASSET SALES | K4: Sales Value | M4: Reconciliation totals on Row 15 should be zero. If Row 15 not zero check all Fixed Assets entered on Purhases and Sales Spreadsheets have been recorded on the Fixed Asset Schedule.
B5: Fixed Asset Schedule New Additions | G5: Fixed Asset Schedule Assets Sold
B6: New Land & Property | E6: =Schedule!E64 -> 0 | G6: Land & Property Sold | K6: =Schedule!V11+Schedule!V64 -> 0
B7: New Plant & Machinery | E7: =Schedule!E72 -> 0 | G7: Plant & Machinery Sold | K7: =Schedule!V19+Schedule!V72 -> 0
B8: New Fixtures & Fittings | E8: =Schedule!E80 -> 0 | G8: Fixtures & Fittings Sold | K8: =Schedule!V27+Schedule!V80 -> 0
B9: New Computers | E9: =Schedule!E88 -> 0 | G9: Computers Sold | K9: =Schedule!V35+Schedule!V88 -> 0
B10: New Motor Vehicles | E10: =Schedule!E108 -> 0 | G10: Motor Vehicles Sold | K10: =Schedule!V55+Schedule!V108 -> 0
B11: FIXED ASSETS SCHEDULE | E11: =SUM(E6:E10) -> 0 | G11: FIXED ASSETS SCHEDULE | K11: =SUM(K6:K10) -> 0
B13: PURCHASE SHEET FIXED ASSETS PURCHASES | E13: =[2]Mar!$AB$2 -> 0 | G13: SALES SHEET FIXED ASSETS SALES | K13: =[3]Mar!$V$2 -> 0
B15: =IF(E15>0,"Purchases exceed Assets listed on Schedule",IF(E15<0,"Assets listed on Schedule exceed Purchase values","Purchases reconcile with Fixed asset Schedule")) -> Purchases reconcile with Fixed asset Schedule | E15: =E13-E11 -> 0 | G15: =IF(K15>0,"Sales exceed Assets listed on Schedule",IF(K15<0,"Assets listed on Schedule exceed Sales values","Sales reconcile with Fixed asset Schedule")) -> Sales reconcile with Fixed asset Schedule | K15: =K13-K11 -> 0

Sheet HPfinance
C2: YEAR END LONG TERM CREDITORS | E2: =SUM(E8:E14) -> 0 | G2: Enter Finance Agreements due to end more than 12 months after the financial year end or leave blank
B3: New Hire Purchase Agreements
B5: Agreement Date | C5: Finance Company | D5: Agreement Refernce | E5: Total Amount Financed excluding Admin & Interest | F5: Admin Charges | G5: Total Interest Charged | H5: Number of Months | I5: BANK ANALYSIS PURPOSES | L5: Enter Supplier Name as entered on Purchase Spreadsheet
I6: Monthly Payment | J6: Net Capital Repayment | K6: Monthly Interest
I8: =IF(E8>0,(E8+F8+G8)/H8," ") | J8: =IF(H8>0,I8-K8," ") | K8: =IF(H8>0,G8/H8," ")
I10: =IF(H10>0,#REF!/H10," ") | J10: =IF(H10>0,I10-K10," ") | K10: =IF(H10>0,G10/H10," ")
I12: =IF(H12>0,#REF!/H12," ") | J12: =IF(H12>0,I12-K12," ") | K12: =IF(H12>0,G12/H12," ")
I14: =IF(H14>0,#REF!/H14," ") | J14: =IF(H14>0,I14-K14," ") | K14: =IF(H14>0,G14/H14," ")
B17: Hire Purchase Agreements existing at start of financial year | H17: Required to calculate monthly interest liability
B19: Agreement Date | C19: Finance Company | D19: Agreement Refernce | E19: Total Amount Financed excluding Admin & Interest | F19: Admin Charges | G19: Total Interest Charged | H19: Number of Months | I19: BANK ANALYSIS PURPOSES | L19: Enter Supplier Name as entered on Purchase Spreadsheet
I20: Monthly Payment | J20: Net Capital Repayment | K20: Monthly Interest
I22: =IF(E22>0,(E22+F22+G22)/H22," ") | J22: =IF(H22>0,I22-K22," ") | K22: =IF(H22>0,G22/H22," ")
I24: =IF(H24>0,#REF!/H24," ") | J24: =IF(H24>0,I24-K24," ") | K24: =IF(H24>0,G24/H24," ")
I26: =IF(H26>0,#REF!/H26," ") | J26: =IF(H26>0,I26-K26," ") | K26: =IF(H26>0,G26/H26," ")
I28: =IF(H28>0,#REF!/H28," ") | J28: =IF(H28>0,I28-K28," ") | K28: =IF(H28>0,G28/H28," ")
