Workbook

Sheet Home
B2: Basic Sole Trader Accounts
B4: Click a link below to navigate to the desired page. To return to the home page click the Home tab. If you can't see the Home tab, you can scroll to it by clicking the |< symbol (bottom left).
B6: Preparation | C6: Sales | D6: Purchases | E6: Results
B8: =HYPERLINK("#'Business Details'!C5","Business Details") -> Business Details | C8: =HYPERLINK("#'SalesApr'!A4","SalesApr") -> SalesApr | D8: =HYPERLINK("#'PurchasesApr'!A5","PurchasesApr") -> PurchasesApr | E8: =HYPERLINK("#'SE Short'!C8","SE Short") -> SE Short
B9: =HYPERLINK("#'Fixed Assets'!B8","Fixed Assets") -> Fixed Assets | C9: =HYPERLINK("#'SalesMay'!A4","SalesMay") -> SalesMay | D9: =HYPERLINK("#'PurchasesMay'!A5","PurchasesMay") -> PurchasesMay | E9: =HYPERLINK("#'Profit & Loss Acc'!A1","Profit & Loss Acc") -> Profit & Loss Acc
B10: =HYPERLINK("#'Debtors & Creditors'!C3","Debtors & Creditors") -> Debtors & Creditors | C10: =HYPERLINK("#'SalesJun'!A4","SalesJun") -> SalesJun | D10: =HYPERLINK("#'PurchasesJun'!A5","PurchasesJun") -> PurchasesJun | E10: =HYPERLINK("#'Income Tax'!D2","Income Tax") -> Income Tax
C11: =HYPERLINK("#'SalesJul'!A4","SalesJul") -> SalesJul | D11: =HYPERLINK("#'PurchasesJul'!A5","PurchasesJul") -> PurchasesJul
C12: =HYPERLINK("#'SalesAug'!A4","SalesAug") -> SalesAug | D12: =HYPERLINK("#'PurchasesAug'!A5","PurchasesAug") -> PurchasesAug
C13: =HYPERLINK("#'SalesSep'!A4","SalesSep") -> SalesSep | D13: =HYPERLINK("#'PurchasesSep'!A5","PurchasesSep") -> PurchasesSep
C14: =HYPERLINK("#'SalesOct'!A4","SalesOct") -> SalesOct | D14: =HYPERLINK("#'PurchasesOct'!A5","PurchasesOct") -> PurchasesOct
C15: =HYPERLINK("#'SalesNov'!A4","SalesNov") -> SalesNov | D15: =HYPERLINK("#'PurchasesNov'!A5","PurchasesNov") -> PurchasesNov
C16: =HYPERLINK("#'SalesDec'!A4","SalesDec") -> SalesDec | D16: =HYPERLINK("#'PurchasesDec'!A5","PurchasesDec") -> PurchasesDec
C17: =HYPERLINK("#'SalesJan'!A4","SalesJan") -> SalesJan | D17: =HYPERLINK("#'PurchasesJan'!A5","PurchasesJan") -> PurchasesJan
C18: =HYPERLINK("#'SalesFeb'!A4","SalesFeb") -> SalesFeb | D18: =HYPERLINK("#'PurchasesFeb'!A5","PurchasesFeb") -> PurchasesFeb
C19: =HYPERLINK("#'SalesMar'!A4","SalesMar") -> SalesMar | D19: =HYPERLINK("#'PurchasesMar'!A5","PurchasesMar") -> PurchasesMar

Sheet Business Details
A1: ENTER YOUR BUSINESS DETAILS - which are then transferred to the Self-employment Tax Return
C3: Your name | N3: Your unique taxpayer reference (UTR)
C5: Precision Code Trading
C7: IT consultancy and software development | L7: 4 | N7: If you are a foster carer or adult placement carer, put 'X'
C8: 123 High Street
C10: Manchester
C12: M1 1AA | N12: If your business started sifter | S12: =Admin!B4 -> 46118
N13: enter the start date DD/MM/YYY
A15: 2 | C15: Postcode of your business
L18: 6 | N18: If your business ceased before | S18: =Admin!B17 -> 46482
A19: 3 | C19: If your business name, description, address or postcode | N19: enter the final date of trading
C20: have changed in the last 12 months, put 'X' in the box
C21: and give details in the 'Any other information' box of
C22: of your Tax Return
L23: 7 | N23: Date your books or accounts are made up to - read
N24: page SESN 2 of the notes
N25: =Admin!B17 -> 46482
A27: 26 | C27: ENTER: Total losses brought forward from earlier years | L27: 24 | N27: ENTER: Value of goods and services for your own use
N28: - read page SESN 7 of the notes
C29: £ | D29: 0 | G29: . | H29: 0 | I29: 0 | N29: £ | O29: 0 | R29: . | S29: 0 | T29: 0
C31: Loss used this year | N31: Total loss carried forward to future years
C32: Calculated no entry required | N32: Calculated no entry required
C34: £ | D34: ='SE Short'!O94 -> 0 | G34: . | H34: 0 | I34: 0 | N34: £ | O34: =D29-D34+'SE Short'!O106 -> 0 | R34: . | S34: 0 | T34: 0

Sheet SE Short
A1: HM Revenue & Customs | G1: ="SUBMIT ONLINE RETURN TO HMRC BY 31ST JANUARY "&TEXT(YEAR(Admin!B17)+1,"0000") -> SUBMIT ONLINE RETURN TO HMRC BY 31ST JANUARY 2028 | O1: Self-employment (short)
O2: Tax year | Q2: =Admin!B4 -> 46118 | U2: to | V2: =Admin!B17 -> 46482
C6: Your name | N6: Your unique taxpayer reference (UTR)
C8: =IF('Business Details'!C5>0,'Business Details'!C5," ") -> Precision Code Trading | O8: =IF('Business Details'!O5>0,'Business Details'!O5," ") | R8: =IF('Business Details'!R5>0,'Business Details'!R5," ")
A10: Business details
A12: 1 | C12: Description of business | L12: 4 | N12: If you are a foster carer or adult placement carer, put 'X'
C13: =IF('Business Details'!C8>0,'Business Details'!C8," ") -> 123 High Street | N13: in the box - read page SESN 2 of the notes
C15: =IF('Business Details'!C10>0,'Business Details'!C10," ") -> Manchester | N15: =IF('Business Details'!N10>0,'Business Details'!N10," ")
C17: =IF('Business Details'!C12>0,'Business Details'!C12," ") -> M1 1AA | L17: 5 | N17: If your business started after | S17: =Admin!B4 -> 46118
N18: enter the start date DD/MM/YYY
A20: 2 | C20: Postcode of your business | N20: =IF('Business Details'!N15>0,'Business Details'!N15," ")
C22: =IF('Business Details'!C17>0,'Business Details'!C17," ") | F22: =IF('Business Details'!F17>0,'Business Details'!F17," ")
L23: 6 | N23: If your business ceased before | S23: =Admin!B4 -> 46118
A24: 3 | C24: If your business name, description, address or postcode | N24: enter the final date of trading
C25: have changed in the last 12 months, put 'X' in the box
C26: and give details in the 'Any other information' box of | N26: =IF('Business Details'!N21>0,'Business Details'!N21," ")
C27: of your Tax Return
L28: 7 | N28: Date your books or accounts are made up to - read
C29: =IF('Business Details'!C24>0,'Business Details'!C24," ") | N29: page SESN 2 of the notes
N31: =Admin!B17 -> 46482
A33: ="Business income - if your annual turnover was below £"&Admin!F26&" vat threshold" -> Business income - if your annual turnover was below £90000 vat threshold
A35: 8 | C35: Your turnover - the takings, fees, sales or money earned | L35: 9 | N35: Any other business income not included in box 8
C36: by your business | N36: - excluding Business Start-up Allowance
C38: £ | D38: ='Profit & Loss Acc'!C4 -> 409900 | G38: . | H38: 0 | I38: 0 | N38: £ | R38: . | S38: 0 | T38: 0
A40: Allowable business expenses
A41: Read pages SESN 3 of the notes to see which expenses are allowed for tax purposes. If your annual turnover was below £30,000
A42: you may just put your total expenses in box 19, rather than filling in the whole section.
A44: 10 | C44: Cost of goods bought for re-sale or goods used | L44: 15 | N44: Accountancy, legal and other professional fees
C46: £ | D46: =IF(('Profit & Loss Acc'!C4<30000)," ",'Profit & Loss Acc'!C6+'Profit & Loss Acc'!C7) -> 18540 | G46: . | H46: 0 | I46: 0 | N46: £ | O46: =IF(('Profit & Loss Acc'!C4<30000)," ",'Profit & Loss Acc'!C18) -> 4560 | R46: . | S46: 0 | T46: 0
A48: 11 | C48: Car, van and other travel expenses - after private | L48: 16 | N48: Interest and bank and credit card etc. financial charges
C49: use proportion
C51: £ | D51: =IF(('Profit & Loss Acc'!C4<30000)," ",'Profit & Loss Acc'!C15+'Profit & Loss Acc'!C16) -> 9458 | G51: . | H51: 0 | I51: 0 | N51: £ | O51: =IF(('Profit & Loss Acc'!C4<30000)," ",'Profit & Loss Acc'!C20) -> 750 | R51: . | S51: 0 | T51: 0
A53: 12 | C53: Wages, salaries and other staff costs | L53: 17 | N53: Telephone, fax, stationery and other office costs
C55: £ | D55: =IF(('Profit & Loss Acc'!C4<30000)," ",'Profit & Loss Acc'!C11) -> 800 | G55: . | H55: 0 | I55: 0 | N55: £ | O55: =IF(('Profit & Loss Acc'!C4<30000)," ",'Profit & Loss Acc'!C14) -> 1962 | R55: . | S55: 0 | T55: 0
A57: 13 | C57: Rent, rates, power and insurance costs | L57: 18 | N57: Other allowable business expenses - client entertaining
N58: costs are not an allowable expense
C60: £ | D60: =IF(('Profit & Loss Acc'!C4<30000)," ",'Profit & Loss Acc'!C12) -> 15840 | G60: . | H60: 0 | I60: 0 | N60: £ | O60: =IF(('Profit & Loss Acc'!C4<30000)," ",'Profit & Loss Acc'!C17+'Profit & Loss Acc'!C19+'Profit & Loss Acc'!C21) -> 22942 | R60: . | S60: 0 | T60: 0
A62: 14 | C62: Repairs and renewals of property and equipment | L62: 19 | N62: Total allowable expenses - total of boxes 10 to 18
C64: £ | D64: =IF(('Profit & Loss Acc'!C4<30000)," ",'Profit & Loss Acc'!C13) -> 1140 | G64: . | H64: 0 | I64: 0 | N64: £ | O64: ='Profit & Loss Acc'!C6+'Profit & Loss Acc'!C7+'Profit & Loss Acc'!C22 -> 75992 | R64: . | S64: 0 | T64: 0
A66: Net profit or loss
...

Sheet Profit & Loss Acc
A1: Profit & Loss Account | B1: Ref | C1: TOTAL | D1: =Admin!B5 -> 46142 | E1: =Admin!B6 -> 46173 | F1: =Admin!B7 -> 46203 | G1: =Admin!B8 -> 46234 | H1: =Admin!B9 -> 46265 | I1: =Admin!B10 -> 46295 | J1: =Admin!B11 -> 46326 | K1: =Admin!B12 -> 46356 | L1: =Admin!B13 -> 46387 | M1: =Admin!B14 -> 46418 | N1: =Admin!B15 -> 46446 | O1: =Admin!B16 -> 46477 | S1: VitalTax summary | T1: Q1 | U1: Q2 | V1: Q3 | W1: Q4 | X1: Annual | Y1: Notes
C2: =Admin!G2 -> 2026-27
A3: =IF(C3=" "," ","Purchase analysis errors") | C3: =IF((SUM(D3:O3)>1),ROUND(SUM(D3:O3),0)," ") | D3: =IF((PurchasesApr!$E$1>1),PurchasesApr!$E$1," ") | E3: =IF((PurchasesMay!$E$1>1),PurchasesMay!$E$1," ") | F3: =IF((PurchasesJun!$E$1>1),PurchasesJun!$E$1," ") | G3: =IF((PurchasesJul!$E$1>1),PurchasesJul!$E$1," ") | H3: =IF((PurchasesAug!$E$1>1),PurchasesAug!$E$1," ") | I3: =IF((PurchasesSep!$E$1>1),PurchasesSep!$E$1," ") | J3: =IF((PurchasesOct!$E$1>1),PurchasesOct!$E$1," ") | K3: =IF((PurchasesNov!$E$1>1),PurchasesNov!$E$1," ") | L3: =IF((PurchasesDec!$E$1>1),PurchasesDec!$E$1," ") | M3: =IF((PurchasesJan!$E$1>1),PurchasesJan!$E$1," ") | N3: =IF((PurchasesFeb!$E$1>1),PurchasesFeb!$E$1," ") | O3: =IF((PurchasesMar!$E$1>1),PurchasesMar!$E$1," ")
A4: Sales Turnover | B4: 3.29 | C4: =ROUND(SUM(D4:O4),0) -> 409900 | D4: =SalesApr!$F$1 -> 33400 | E4: =SalesMay!$F$1 -> 32920 | F4: =SalesJun!$F$1 -> 35200 | G4: =SalesJul!$F$1 -> 33760 | H4: =SalesAug!$F$1 -> 36020 | I4: =SalesSep!$F$1 -> 33760 | J4: =SalesOct!$F$1 -> 35560 | K4: =SalesNov!$F$1 -> 35320 | L4: =SalesDec!$F$1 -> 32800 | M4: =SalesJan!$F$1 -> 35440 | N4: =SalesFeb!$F$1 -> 34360 | O4: =SalesMar!$F$1 -> 31360 | S4: Turnover | T4: =SUM(D4:F4) -> 101520 | U4: =SUM(G4:I4) -> 103540 | V4: =SUM(J4:L4) -> 103680 | W4: =SUM(M4:O4) -> 101160 | X4: =SUM(T4:W4) -> 409900
S5: Other income | T5: =SUM(D30:F30) -> 0 | U5: =SUM(G30:I30) -> 0 | V5: =SUM(J30:L30) -> 0 | W5: =SUM(M30:O30) -> 0 | X5: =SUM(T5:W5) -> 0
A6: Cost of sales | B6: 3.46 | C6: =ROUND(SUM(D6:O6),0) -> 10540 | D6: =PurchasesApr!$J$1+PurchasesStock!$D$5-PurchasesStock!$D$7 -> 600 | E6: =PurchasesMay!$J$1+PurchasesStock!$D$7-PurchasesStock!$D$9 -> 720 | F6: =PurchasesJun!$J$1+PurchasesStock!$D$9-PurchasesStock!$D$11 -> 360 | G6: =PurchasesJul!$J$1+PurchasesStock!$D$11-PurchasesStock!$D$13 -> 720 | H6: =PurchasesAug!$J$1+PurchasesStock!$D$13-PurchasesStock!$D$15 -> 540 | I6: =PurchasesSep!$J$1+PurchasesStock!$D$15-PurchasesStock!$D$17 -> 240 | J6: =PurchasesOct!$J$1+PurchasesStock!$D$17-PurchasesStock!$D$19 -> 480 | K6: =PurchasesNov!$J$1+PurchasesStock!$D$19-PurchasesStock!$D$21 -> 840 | L6: =PurchasesDec!$J$1+PurchasesStock!$D$21-PurchasesStock!$D$23 -> 480 | M6: =PurchasesJan!$J$1+PurchasesStock!$D$23-PurchasesStock!$D$25 -> 600 | N6: =PurchasesFeb!$J$1+PurchasesStock!$D$25-PurchasesStock!$D$27 -> 660 | O6: =PurchasesMar!$J$1+PurchasesStock!$D$27-PurchasesStock!$D$30 -> 4300 | S6: Cost of goods bought | T6: =SUM(D6:F7) -> 6680 | U6: =SUM(G6:I7) -> 1500 | V6: =SUM(J6:L7) -> 4800 | W6: =SUM(M6:O7) -> 5560 | X6: =SUM(T6:W6) -> 18540
A7: Other direct costs | B7: 3.48 | C7: =ROUND(SUM(D7:O7),0) -> 8000 | D7: =PurchasesApr!$K$1 -> 0 | E7: =PurchasesMay!$K$1 -> 0 | F7: =PurchasesJun!$K$1 -> 5000 | G7: =PurchasesJul!$K$1 -> 0 | H7: =PurchasesAug!$K$1 -> 0 | I7: =PurchasesSep!$K$1 -> 0 | J7: =PurchasesOct!$K$1 -> 0 | K7: =PurchasesNov!$K$1 -> 3000 | L7: =PurchasesDec!$K$1 -> 0 | M7: =PurchasesJan!$K$1 -> 0 | N7: =PurchasesFeb!$K$1 -> 0 | O7: =PurchasesMar!$K$1 -> 0
A9: Gross Profit | B9: 3.49 | C9: =ROUND((C4-C6-C7),0) -> 391360 | D9: =D4-D6-D7 -> 32800 | E9: =E4-E6-E7 -> 32200 | F9: =F4-F6-F7 -> 29840 | G9: =G4-G6-G7 -> 33040 | H9: =H4-H6-H7 -> 35480 | I9: =I4-I6-I7 -> 33520 | J9: =J4-J6-J7 -> 35080 | K9: =K4-K6-K7 -> 31480 | ... O9: =O4-O6-O7 -> 27060 | S9: Allowable expenses
A11: Employee costs | B11: 3.51 | C11: =ROUND(SUM(D11:O11),0) -> 800 | D11: =PurchasesApr!$L$1 -> 0 | E11: =PurchasesMay!$L$1 -> 0 | F11: =PurchasesJun!$L$1 -> 0 | G11: =PurchasesJul!$L$1 -> 0 | H11: =PurchasesAug!$L$1 -> 800 | I11: =PurchasesSep!$L$1 -> 0 | J11: =PurchasesOct!$L$1 -> 0 | K11: =PurchasesNov!$L$1 -> 0 | L11: =PurchasesDec!$L$1 -> 0 | M11: =PurchasesJan!$L$1 -> 0 | N11: =PurchasesFeb!$L$1 -> 0 | O11: =PurchasesMar!$L$1 -> 0 | S11: Staff costs | T11: =SUM(D11:F11) -> 0 | U11: =SUM(G11:I11) -> 800 | V11: =SUM(J11:L11) -> 0 | W11: =SUM(M11:O11) -> 0 | X11: =SUM(T11:W11) -> 800
A12: Premises costs | B12: 3.52 | C12: =ROUND(SUM(D12:O12),0) -> 15840 | D12: =PurchasesApr!$M$1 -> 1200 | E12: =PurchasesMay!$M$1 -> 1200 | F12: =PurchasesJun!$M$1 -> 1560 | G12: =PurchasesJul!$M$1 -> 1200 | H12: =PurchasesAug!$M$1 -> 1200 | I12: =PurchasesSep!$M$1 -> 1500 | J12: =PurchasesOct!$M$1 -> 1200 | K12: =PurchasesNov!$M$1 -> 1200 | L12: =PurchasesDec!$M$1 -> 1620 | M12: =PurchasesJan!$M$1 -> 1200 | N12: =PurchasesFeb!$M$1 -> 1200 | O12: =PurchasesMar!$M$1 -> 1560 | S12: Premises running costs | T12: =SUM(D12:F12) -> 3960 | U12: =SUM(G12:I12) -> 3900 | V12: =SUM(J12:L12) -> 4020 | W12: =SUM(M12:O12) -> 3960 | X12: =SUM(T12:W12) -> 15840
A13: Repairs | B13: 3.53 | C13: =ROUND(SUM(D13:O13),0) -> 1140 | D13: =PurchasesApr!$N$1 -> 120 | E13: =PurchasesMay!$N$1 -> 0 | F13: =PurchasesJun!$N$1 -> 0 | G13: =PurchasesJul!$N$1 -> 180 | H13: =PurchasesAug!$N$1 -> 240 | I13: =PurchasesSep!$N$1 -> 0 | J13: =PurchasesOct!$N$1 -> 96 | K13: =PurchasesNov!$N$1 -> 0 | L13: =PurchasesDec!$N$1 -> 0 | M13: =PurchasesJan!$N$1 -> 144 | N13: =PurchasesFeb!$N$1 -> 360 | O13: =PurchasesMar!$N$1 -> 0 | S13: Maintenance | T13: =SUM(D13:F13) -> 120 | U13: =SUM(G13:I13) -> 420 | V13: =SUM(J13:L13) -> 96 | W13: =SUM(M13:O13) -> 504 | X13: =SUM(T13:W13) -> 1140
A14: General admin expenses | B14: 3.54 | C14: =ROUND(SUM(D14:O14),0) -> 1962 | D14: =PurchasesApr!$O$1 -> 135 | E14: =PurchasesMay!$O$1 -> 153 | F14: =PurchasesJun!$O$1 -> 231 | G14: =PurchasesJul!$O$1 -> 159 | H14: =PurchasesAug!$O$1 -> 135 | I14: =PurchasesSep!$O$1 -> 147 | J14: =PurchasesOct!$O$1 -> 135 | K14: =PurchasesNov!$O$1 -> 165 | L14: =PurchasesDec!$O$1 -> 255 | M14: =PurchasesJan!$O$1 -> 153 | N14: =PurchasesFeb!$O$1 -> 135 | O14: =PurchasesMar!$O$1 -> 159 | S14: Admin | T14: =SUM(D14:F14) -> 519 | U14: =SUM(G14:I14) -> 441 | V14: =SUM(J14:L14) -> 555 | W14: =SUM(M14:O14) -> 447 | X14: =SUM(T14:W14) -> 1962
A15: Motor expenses | B15: 3.55 | C15: =ROUND(SUM(D15:O15),0) -> 7598 | D15: =PurchasesApr!$P$1 -> 602.25 | E15: =PurchasesMay!$P$1 -> 666 | F15: =PurchasesJun!$P$1 -> 654 | G15: =PurchasesJul!$P$1 -> 584.25 | H15: =PurchasesAug!$P$1 -> 602.25 | I15: =PurchasesSep!$P$1 -> 708 | J15: =PurchasesOct!$P$1 -> 606.75 | K15: =PurchasesNov!$P$1 -> 645 | L15: =PurchasesDec!$P$1 -> 613.5 | M15: =PurchasesJan!$P$1 -> 638.25 | N15: =PurchasesFeb!$P$1 -> 595.5 | O15: =PurchasesMar!$P$1 -> 682.5 | S15: Financial charges | T15: =SUM(D15:F15) -> 1922.25 | U15: =SUM(G15:I15) -> 1894.5 | V15: =SUM(J15:L15) -> 1865.25 | W15: =SUM(M15:O15) -> 1916.25 | X15: =SUM(T15:W15) -> 7598.25
A16: Travel & subsistence | B16: 3.56 | C16: =ROUND(SUM(D16:O16),0) -> 1860 | D16: =PurchasesApr!$Q$1 -> 92 | E16: =PurchasesMay!$Q$1 -> 152 | F16: =PurchasesJun!$Q$1 -> 272 | G16: =PurchasesJul!$Q$1 -> 92 | H16: =PurchasesAug!$Q$1 -> 140 | I16: =PurchasesSep!$Q$1 -> 92 | J16: =PurchasesOct!$Q$1 -> 212 | K16: =PurchasesNov!$Q$1 -> 164 | L16: =PurchasesDec!$Q$1 -> 92 | M16: =PurchasesJan!$Q$1 -> 92 | N16: =PurchasesFeb!$Q$1 -> 368 | O16: =PurchasesMar!$Q$1 -> 92 | S16: Travel | T16: =SUM(D16:F16) -> 516 | U16: =SUM(G16:I16) -> 324 | V16: =SUM(J16:L16) -> 468 | W16: =SUM(M16:O16) -> 552 | X16: =SUM(T16:W16) -> 1860
A17: Advertising & promotion | B17: 3.57 | C17: =ROUND(SUM(D17:O17),0) -> 4560 | D17: =PurchasesApr!$R$1 -> 0 | E17: =PurchasesMay!$R$1 -> 600 | F17: =PurchasesJun!$R$1 -> 0 | G17: =PurchasesJul!$R$1 -> 480 | H17: =PurchasesAug!$R$1 -> 0 | I17: =PurchasesSep!$R$1 -> 0 | J17: =PurchasesOct!$R$1 -> 3000 | K17: =PurchasesNov!$R$1 -> 0 | L17: =PurchasesDec!$R$1 -> 0 | M17: =PurchasesJan!$R$1 -> 480 | N17: =PurchasesFeb!$R$1 -> 0 | O17: =PurchasesMar!$R$1 -> 0 | S17: Advertising | T17: =SUM(D17:F17) -> 600 | U17: =SUM(G17:I17) -> 480 | V17: =SUM(J17:L17) -> 3000 | W17: =SUM(M17:O17) -> 480 | X17: =SUM(T17:W17) -> 4560
A18: Legal & professional | B18: 3.58 | C18: =ROUND(SUM(D18:O18),0) -> 4560 | D18: =PurchasesApr!$S$1 -> 300 | E18: =PurchasesMay!$S$1 -> 300 | F18: =PurchasesJun!$S$1 -> 300 | G18: =PurchasesJul!$S$1 -> 300 | H18: =PurchasesAug!$S$1 -> 300 | I18: =PurchasesSep!$S$1 -> 1260 | J18: =PurchasesOct!$S$1 -> 300 | K18: =PurchasesNov!$S$1 -> 300 | L18: =PurchasesDec!$S$1 -> 300 | M18: =PurchasesJan!$S$1 -> 300 | N18: =PurchasesFeb!$S$1 -> 300 | O18: =PurchasesMar!$S$1 -> 300 | S18: Professional | T18: =SUM(D18:F18) -> 900 | U18: =SUM(G18:I18) -> 1860 | V18: =SUM(J18:L18) -> 900 | W18: =SUM(M18:O18) -> 900 | X18: =SUM(T18:W18) -> 4560
A19: Bad debts | B19: 3.59 | C19: =ROUND(SUM(D19:O19),0) -> 500 | D19: =PurchasesApr!$T$1 -> 0 | E19: =PurchasesMay!$T$1 -> 0 | F19: =PurchasesJun!$T$1 -> 0 | G19: =PurchasesJul!$T$1 -> 0 | H19: =PurchasesAug!$T$1 -> 0 | I19: =PurchasesSep!$T$1 -> 0 | J19: =PurchasesOct!$T$1 -> 0 | K19: =PurchasesNov!$T$1 -> 0 | L19: =PurchasesDec!$T$1 -> 500 | M19: =PurchasesJan!$T$1 -> 0 | N19: =PurchasesFeb!$T$1 -> 0 | O19: =PurchasesMar!$T$1 -> 0 | S19: Bad debt | T19: =SUM(D19:F19) -> 0 | U19: =SUM(G19:I19) -> 0 | V19: =SUM(J19:L19) -> 500 | W19: =SUM(M19:O19) -> 0 | X19: =SUM(T19:W19) -> 500
A20: Interest, finance charges | B20: 3.6 | C20: =ROUND(SUM(D20:O20),0) -> 750 | D20: =PurchasesApr!$U$1 -> 0 | E20: =PurchasesMay!$U$1 -> 0 | F20: =PurchasesJun!$U$1 -> 250 | G20: =PurchasesJul!$U$1 -> 0 | H20: =PurchasesAug!$U$1 -> 0 | I20: =PurchasesSep!$U$1 -> 208 | J20: =PurchasesOct!$U$1 -> 0 | K20: =PurchasesNov!$U$1 -> 0 | L20: =PurchasesDec!$U$1 -> 167 | M20: =PurchasesJan!$U$1 -> 0 | N20: =PurchasesFeb!$U$1 -> 0 | O20: =PurchasesMar!$U$1 -> 125 | S20: Interest | T20: =SUM(D20:F20) -> 250 | U20: =SUM(G20:I20) -> 208 | V20: =SUM(J20:L20) -> 167 | W20: =SUM(M20:O20) -> 125 | X20: =SUM(T20:W20) -> 750
A21: Other expenses | B21: 3.63 | C21: =ROUND(SUM(D21:O21),0) -> 17882 | D21: =PurchasesApr!$V$1 -> 2062 | E21: =PurchasesMay!$V$1 -> 784 | F21: =PurchasesJun!$V$1 -> 430 | G21: =PurchasesJul!$V$1 -> 4144 | H21: =PurchasesAug!$V$1 -> 448 | I21: =PurchasesSep!$V$1 -> 820 | J21: =PurchasesOct!$V$1 -> 976 | K21: =PurchasesNov!$V$1 -> 604 | L21: =PurchasesDec!$V$1 -> 5424 | M21: =PurchasesJan!$V$1 -> 904 | N21: =PurchasesFeb!$V$1 -> 778 | O21: =PurchasesMar!$V$1 -> 508 | S21: Other | T21: =SUM(D21:F21) -> 3276 | U21: =SUM(G21:I21) -> 5412 | V21: =SUM(J21:L21) -> 7004 | W21: =SUM(M21:O21) -> 2190 | X21: =SUM(T21:W21) -> 17882
A22: Total Expenses | B22: 3.64 | C22: =SUM(C11:C21) -> 57452 | D22: =SUM(D11:D21) -> 4511.25 | E22: =SUM(E11:E21) -> 3855 | F22: =SUM(F11:F21) -> 3697 | G22: =SUM(G11:G21) -> 7139.25 | H22: =SUM(H11:H21) -> 3865.25 | I22: =SUM(I11:I21) -> 4735 | J22: =SUM(J11:J21) -> 6525.75 | ... O22: =SUM(O11:O21) -> 3426.5
S23: CIS payment to subcontractors | T23: 0 | U23: 0 | V23: 0 | W23: 0 | X23: =SUM(T23:W23) -> 0 | Y23: Not captured in DIY Accounting
A24: Net Profit/Loss | B24: 3.65 | C24: =ROUND((C9-C22),0) -> 333908 | D24: =D9-D22 -> 28288.75 | E24: =E9-E22 -> 28345 | F24: =F9-F22 -> 26143 | G24: =G9-G22 -> 25900.75 | H24: =H9-H22 -> 31614.75 | I24: =I9-I22 -> 28785 | J24: =J9-J22 -> 28554.25 | K24: =K9-K22 -> 28402 | ... O24: =O9-O22 -> 23633.5 | S24: Business entertainment | T24: 0 | U24: 0 | V24: 0 | W24: 0 | X24: =SUM(T24:W24) -> 0 | Y24: Not captured in DIY Accounting
S25: Depreciation | T25: 0 | U25: 0 | V25: 0 | W25: 0 | X25: =SUM(T25:W25) -> 0 | Y25: Not captured in DIY Accounting
A26: Less Capital Allowances | C26: =-'SE Short'!O85+'SE Short'!D80+'SE Short'!D85+'SE Short'!O80 -> 0
A28: NET TAXABLE PROFIT | C28: =C24-C26 -> 333908 | S28: Total allowable expenses | T28: =SUM(T6,T11,T12,T13,T14,T15,T16,T17,T18,T19,T20,T21,T23,T24,T25) -> 18743.25 | U28: =SUM(U6,U11,U12,U13,U14,U15,U16,U17,U18,U19,U20,U21,U23,U24,U25) -> 17239.5 | V28: =SUM(V6,V11,V12,V13,V14,V15,V16,V17,V18,V19,V20,V21,V23,V24,V25) -> 23375.25 | W28: =SUM(W6,W11,W12,W13,W14,W15,W16,W17,W18,W19,W20,W21,W23,W24,W25) -> 16634.25 | X28: =SUM(X6,X11,X12,X13,X14,X15,X16,X17,X18,X19,X20,X21,X23,X24,X25) -> 75992.25
A30: Any Other Business Income | C30: =ROUND(SUM(D30:O30),0) -> 0 | D30: =SalesApr!$G$1 -> 0 | E30: =SalesMay!$G$1 -> 0 | F30: =SalesJun!$G$1 -> 0 | G30: =SalesJul!$G$1 -> 0 | H30: =SalesAug!$G$1 -> 0 | I30: =SalesSep!$G$1 -> 0 | J30: =SalesOct!$G$1 -> 0 | K30: =SalesNov!$G$1 -> 0 | L30: =SalesDec!$G$1 -> 0 | M30: =SalesJan!$G$1 -> 0 | N30: =SalesFeb!$G$1 -> 0 | O30: =SalesMar!$G$1 -> 0
A32: Income Tax | C32: ='Income Tax'!E10-'Income Tax'!E11 -> 120995
A33: National Insurance | C33: ='Income Tax'!E15+'Income Tax'!E16 -> 7934.76 | S33: Disallowable expenses
A35: Net Income after Tax | C35: =C28+C30-C32-C33 -> 204978.24 | S35: Cost of goods bought | T35: 0 | U35: 0 | V35: 0 | W35: 0 | X35: =SUM(T35:W35) -> 0 | Y35: Not captured in DIY Accounting
S36: CIS payment to subcontractors | T36: 0 | U36: 0 | V36: 0 | W36: 0 | X36: =SUM(T36:W36) -> 0 | Y36: Not captured in DIY Accounting
A37: Enter Drawings (optional) | C37: =ROUND(SUM(D37:O37),0) -> 0 | S37: Staff costs | T37: 0 | U37: 0 | V37: 0 | W37: 0 | X37: =SUM(T37:W37) -> 0 | Y37: Not captured in DIY Accounting
S38: Travel | T38: 0 | U38: 0 | V38: 0 | W38: 0 | X38: =SUM(T38:W38) -> 0 | Y38: Not captured in DIY Accounting
S39: Premises running costs | T39: 0 | U39: 0 | V39: 0 | W39: 0 | X39: =SUM(T39:W39) -> 0 | Y39: Not captured in DIY Accounting
S40: Maintenance | T40: 0 | U40: 0 | V40: 0 | W40: 0 | X40: =SUM(T40:W40) -> 0 | Y40: Not captured in DIY Accounting
S41: Admin | T41: 0 | U41: 0 | V41: 0 | W41: 0 | X41: =SUM(T41:W41) -> 0 | Y41: Not captured in DIY Accounting
S42: Advertising | T42: 0 | U42: 0 | V42: 0 | W42: 0 | X42: =SUM(T42:W42) -> 0 | Y42: Not captured in DIY Accounting
S43: Business entertainment | T43: 0 | U43: 0 | V43: 0 | W43: 0 | X43: =SUM(T43:W43) -> 0 | Y43: Not captured in DIY Accounting
S44: Interest | T44: 0 | U44: 0 | V44: 0 | W44: 0 | X44: =SUM(T44:W44) -> 0 | Y44: Not captured in DIY Accounting
S45: Financial charges | T45: 0 | U45: 0 | V45: 0 | W45: 0 | X45: =SUM(T45:W45) -> 0 | Y45: Not captured in DIY Accounting
S46: Bad debt | T46: 0 | U46: 0 | V46: 0 | W46: 0 | X46: =SUM(T46:W46) -> 0 | Y46: Not captured in DIY Accounting
...

Sheet Income Tax
B2: TAXATION CALCULATION | C2: =Admin!L2 -> 2026-27 | D2: This section an indication and for your information only
B5: Profit from Self employment | E5: ='SE Short'!D106 -> 333908
B6: Minus Personal Allowance | C6: =C2 -> 2026-27 | E6: =IF((E5>0),Admin!N$4,0) -> 12570
B7: Total income on which tax is due | E7: =IF((E5>Admin!N4),(E5-E6),0) -> 321338
B8: Income Tax first band | C8: =Admin!N12 -> 0 | D8: =Admin!N7 -> 0.2 | E8: =IF((E7>0),(IF((E7<C9),E7*D8,C9*D8)),0) -> 7540.2
B9: Income Tax second band | C9: =Admin!N13 -> 37701 | D9: =Admin!N8 -> 0.4 | E9: =IF((E7>C9),((E7-C9)*D9),0) -> 113454.8
B10: Income Tax payable | E10: =SUM(E8:E9) -> 120995
B11: Deductions by contractors | E11: =-SalesMar!$K$1 -> 0
B13: Amounts Payable by | C13: =Admin!B21 -> 46783
B15: Class 4 NI Contribution Lower - Upper profits | D15: =Admin!L$20 -> 0.06 | E15: =IF(E5>Admin!N20,IF(E5<Admin!N$23,(E5-Admin!N20)*D15,(Admin!N$23-Admin!N20)*D15),0) -> 2262
B16: Class 4 NI Contribution Upper profits | D16: =Admin!L$23 -> 0.02 | E16: =IF((E5>Admin!N$23),((E5-Admin!N$23)*D16),0) -> 5672.76
B18: TOTAL Income Tax & NI Liability | E18: =SUM(E10:E17) -> 128929.76
B21: FUTURE TAX LIABILITY (if over £500) | D21: This section for your information only
D23: Due Date | E23: Amount Payable
B25: Tax & NI Assessment | C25: =Admin!B24 -> 2027-28 | D25: Previous Year | E25: =E18 -> 128929.76
B26: 50% Payable | D26: =Admin!B21 -> 46783 | E26: =E25/2 -> 64464.88
B27: 50% Payable | D27: =Admin!B22 -> 46965 | E27: =E25/2 -> 64464.88
B29: NOTES:
B30: Working Tax Credit
B31: Not taxable and not added to self employment income for tax purposes
B32: Pension Entitlement
B33: To receive Full Pension entitlement NI has to be paid 44 years out of 49 years (16 - 65)
B34: UK residents aged 60 - 65 get 5 years bonus.
B35: To confirm current NI / Pension entitlement years the helpline number is 0845 3000 168

Sheet Fixed Assets
B1: Date Asset Purchased | C1: FIXED ASSETS | E1: =E57+E110 -> 0 | G1: Enter % Personal use of vehicles | I1: =I57+I110 -> 0 | J1: First Year Allow | K1: =K57+K110 -> 0 | L1: =L57+L110 -> 0 | M1: =M57+M110 -> 0 | O1: Date Asset Sold | P1: =P57+P110 -> 0 | Q1: =Q57+Q110 -> 0 | R1: =R57+R110 -> 0
C2: Asset Description | D2: Purchase Reference | E2: Original Cost | I2: Written Down Tax Value | K2: First Year Allowance | L2: W Down Allowance | M2: Written Down Tax Value | P2: Sales Value Assets Sold | Q2: Capital Allowance | R2: Balancing Charge
I4: =Admin!B4 -> 46118 | J4: =Admin!G4 -> 1 | L4: =Admin!G5 -> 0.14 | M4: =Admin!B17 -> 46482
B6: EXISTING FIXED ASSETS at | D6: =Admin!B$4 -> 46118
B7: Land & Property
B11: Existing Land & Property | E11: =SUM(E8:E10) -> 0 | I11: =SUM(I8:I10) -> 0 | K11: =SUM(K8:K10) -> 0 | L11: =SUM(L8:L10) -> 0 | M11: =SUM(M8:M10) -> 0 | P11: =SUM(P8:P10) -> 0 | Q11: =SUM(Q8:Q10) -> 0 | R11: =SUM(R8:R10) -> 0
B13: Plant & Machinery
L14: =IF(I14>0,I14*L$4," ") | M14: =IF(I14>0,I14-L14," ") | Q14: =IF((O14+P14)>0,IF(P14<M14,M14-P14," ")," ") | R14: =IF((O14+P14)>0,IF(P14>M14,P14-M14," ")," ")
L15: =IF(I15>0,I15*L$4," ") | M15: =IF(I15>0,I15-L15," ") | Q15: =IF((O15+P15)>0,IF(P15<M15,M15-P15," ")," ") | R15: =IF((O15+P15)>0,IF(P15>M15,P15-M15," ")," ")
L16: =IF(I16>0,I16*L$4," ") | M16: =IF(I16>0,I16-L16," ") | Q16: =IF((O16+P16)>0,IF(P16<M16,M16-P16," ")," ") | R16: =IF((O16+P16)>0,IF(P16>M16,P16-M16," ")," ")
L17: =IF(I17>0,I17*L$4," ") | M17: =IF(I17>0,I17-L17," ") | Q17: =IF((O17+P17)>0,IF(P17<M17,M17-P17," ")," ") | R17: =IF((O17+P17)>0,IF(P17>M17,P17-M17," ")," ")
L18: =IF(I18>0,I18*L$4," ") | M18: =IF(I18>0,I18-L18," ") | Q18: =IF((O18+P18)>0,IF(P18<M18,M18-P18," ")," ") | R18: =IF((O18+P18)>0,IF(P18>M18,P18-M18," ")," ")
B19: Existing Plant & Machinery | E19: =SUM(E14:E18) -> 0 | I19: =SUM(I14:I18) -> 0 | K19: =SUM(K14:K18) -> 0 | L19: =SUM(L14:L18) -> 0 | M19: =SUM(M14:M18) -> 0 | P19: =SUM(P14:P18) -> 0 | Q19: =SUM(Q14:Q18) -> 0 | R19: =SUM(R14:R18) -> 0
B21: Fixtures & Fittings
L22: =IF(I22>0,I22*L$4," ") | M22: =IF(I22>0,I22-L22," ") | Q22: =IF((O22+P22)>0,IF(P22<M22,M22-P22," ")," ") | R22: =IF((O22+P22)>0,IF(P22>M22,P22-M22," ")," ")
L23: =IF(I23>0,I23*L$4," ") | M23: =IF(I23>0,I23-L23," ") | Q23: =IF((O23+P23)>0,IF(P23<M23,M23-P23," ")," ") | R23: =IF((O23+P23)>0,IF(P23>M23,P23-M23," ")," ")
L24: =IF(I24>0,I24*L$4," ") | M24: =IF(I24>0,I24-L24," ") | Q24: =IF((O24+P24)>0,IF(P24<M24,M24-P24," ")," ") | R24: =IF((O24+P24)>0,IF(P24>M24,P24-M24," ")," ")
L25: =IF(I25>0,I25*L$4," ") | M25: =IF(I25>0,I25-L25," ") | Q25: =IF((O25+P25)>0,IF(P25<M25,M25-P25," ")," ") | R25: =IF((O25+P25)>0,IF(P25>M25,P25-M25," ")," ")
L26: =IF(I26>0,I26*L$4," ") | M26: =IF(I26>0,I26-L26," ") | Q26: =IF((O26+P26)>0,IF(P26<M26,M26-P26," ")," ") | R26: =IF((O26+P26)>0,IF(P26>M26,P26-M26," ")," ")
B27: Existing Fixtures & Fittings | E27: =SUM(E22:E26) -> 0 | I27: =SUM(I22:I26) -> 0 | K27: =SUM(K22:K26) -> 0 | L27: =SUM(L22:L26) -> 0 | M27: =SUM(M22:M26) -> 0 | P27: =SUM(P22:P26) -> 0 | Q27: =SUM(Q22:Q26) -> 0 | R27: =SUM(R22:R26) -> 0
B29: Computers
L30: =IF(I30>0,I30*L$4," ") | M30: =IF(I30>0,I30-L30," ") | Q30: =IF((O30+P30)>0,IF(P30<M30,M30-P30," ")," ") | R30: =IF((O30+P30)>0,IF(P30>M30,P30-M30," ")," ")
L31: =IF(I31>0,I31*L$4," ") | M31: =IF(I31>0,I31-L31," ") | Q31: =IF((O31+P31)>0,IF(P31<M31,M31-P31," ")," ") | R31: =IF((O31+P31)>0,IF(P31>M31,P31-M31," ")," ")
L32: =IF(I32>0,I32*L$4," ") | M32: =IF(I32>0,I32-L32," ") | Q32: =IF((O32+P32)>0,IF(P32<M32,M32-P32," ")," ") | R32: =IF((O32+P32)>0,IF(P32>M32,P32-M32," ")," ")
L33: =IF(I33>0,I33*L$4," ") | M33: =IF(I33>0,I33-L33," ") | Q33: =IF((O33+P33)>0,IF(P33<M33,M33-P33," ")," ") | R33: =IF((O33+P33)>0,IF(P33>M33,P33-M33," ")," ")
L34: =IF(I34>0,I34*L$4," ") | M34: =IF(I34>0,I34-L34," ") | Q34: =IF((O34+P34)>0,IF(P34<M34,M34-P34," ")," ") | R34: =IF((O34+P34)>0,IF(P34>M34,P34-M34," ")," ")
B35: Existing Computers | E35: =SUM(E30:E34) -> 0 | I35: =SUM(I30:I34) -> 0 | K35: =SUM(K30:K34) -> 0 | L35: =SUM(L30:L34) -> 0 | M35: =SUM(M30:M34) -> 0 | P35: =SUM(P30:P34) -> 0 | Q35: =SUM(Q30:Q34) -> 0 | R35: =SUM(R30:R34) -> 0
B37: Motor Vehicles - costing over £ | D37: =Admin!E8 -> 12000
G38: 0 | L38: =IF(I38>0,MIN(I38*L$4*(1-G38),Admin!G$8*(1-G38))," ") | M38: =IF(I38>0,I38-L38," ") | Q38: =IF((O38+P38)>0,IF(P38<M38,(M38-P38)*(1-G38)," ")," ") | R38: =IF((O38+P38)>0,IF(P38>M38,(P38-M38)*(1-G38)," ")," ")
G39: 0 | L39: =IF(I39>0,MIN(I39*L$4*(1-G39),Admin!G$8*(1-G39))," ") | M39: =IF(I39>0,I39-L39," ") | Q39: =IF((O39+P39)>0,IF(P39<M39,(M39-P39)*(1-G39)," ")," ") | R39: =IF((O39+P39)>0,IF(P39>M39,(P39-M39)*(1-G39)," ")," ")
G40: 0 | L40: =IF(I40>0,MIN(I40*L$4*(1-G40),Admin!G$8*(1-G40))," ") | M40: =IF(I40>0,I40-L40," ") | Q40: =IF((O40+P40)>0,IF(P40<M40,(M40-P40)*(1-G40)," ")," ") | R40: =IF((O40+P40)>0,IF(P40>M40,(P40-M40)*(1-G40)," ")," ")
G41: 0 | L41: =IF(I41>0,MIN(I41*L$4*(1-G41),Admin!G$8*(1-G41))," ") | M41: =IF(I41>0,I41-L41," ") | Q41: =IF((O41+P41)>0,IF(P41<M41,(M41-P41)*(1-G41)," ")," ") | R41: =IF((O41+P41)>0,IF(P41>M41,(P41-M41)*(1-G41)," ")," ")
G42: 0 | L42: =IF(I42>0,MIN(I42*L$4*(1-G42),Admin!G$8*(1-G42))," ") | M42: =IF(I42>0,I42-L42," ") | Q42: =IF((O42+P42)>0,IF(P42<M42,(M42-P42)*(1-G42)," ")," ") | R42: =IF((O42+P42)>0,IF(P42>M42,(P42-M42)*(1-G42)," ")," ")
B43: Motor Vehicles - costing under £ | D43: =Admin!E8 -> 12000
G44: 0 | L44: =IF(I44>0,MIN(I44*L$4*(1-G44),Admin!G$8*(1-G44))," ") | M44: =IF(I44>0,I44-L44," ") | Q44: =IF((O44+P44)>0,IF(P44<M44,(M44-P44)*(1-G44)," ")," ") | R44: =IF((O44+P44)>0,IF(P44>M44,(P44-M44)*(1-G44)," ")," ")
G45: 0 | L45: =IF(I45>0,MIN(I45*L$4*(1-G45),Admin!G$8*(1-G45))," ") | M45: =IF(I45>0,I45-L45," ") | Q45: =IF((O45+P45)>0,IF(P45<M45,(M45-P45)*(1-G45)," ")," ") | R45: =IF((O45+P45)>0,IF(P45>M45,(P45-M45)*(1-G45)," ")," ")
G46: 0 | L46: =IF(I46>0,MIN(I46*L$4*(1-G46),Admin!G$8*(1-G46))," ") | M46: =IF(I46>0,I46-L46," ") | Q46: =IF((O46+P46)>0,IF(P46<M46,(M46-P46)*(1-G46)," ")," ") | R46: =IF((O46+P46)>0,IF(P46>M46,(P46-M46)*(1-G46)," ")," ")
G47: 0 | L47: =IF(I47>0,MIN(I47*L$4*(1-G47),Admin!G$8*(1-G47))," ") | M47: =IF(I47>0,I47-L47," ") | Q47: =IF((O47+P47)>0,IF(P47<M47,(M47-P47)*(1-G47)," ")," ") | R47: =IF((O47+P47)>0,IF(P47>M47,(P47-M47)*(1-G47)," ")," ")
G48: 0 | L48: =IF(I48>0,MIN(I48*L$4*(1-G48),Admin!G$8*(1-G48))," ") | M48: =IF(I48>0,I48-L48," ") | Q48: =IF((O48+P48)>0,IF(P48<M48,(M48-P48)*(1-G48)," ")," ") | R48: =IF((O48+P48)>0,IF(P48>M48,(P48-M48)*(1-G48)," ")," ")
B49: Motor Vehicles - Vans & Lorries
...

Sheet PurchasesStock
B2: Month end Date | D2: Physical Stock Value
B4: Opening Stock
B5: =Admin!$B$4 -> 46118 | D5: 10000
B7: =Admin!$B$5 -> 46142 | D7: =D5 -> 10000
B9: =Admin!$B$6 -> 46173 | D9: =D7 -> 10000
B11: =Admin!$B$7 -> 46203 | D11: =D9 -> 10000
B13: =Admin!$B$8 -> 46234 | D13: =D11 -> 10000
B15: =Admin!$B$9 -> 46265 | D15: =D13 -> 10000
B17: =Admin!$B$10 -> 46295 | D17: =D15 -> 10000
B19: =Admin!$B$11 -> 46326 | D19: =D17 -> 10000
B21: =Admin!$B$12 -> 46356 | D21: =D19 -> 10000
B23: =Admin!$B$13 -> 46387 | D23: =D21 -> 10000
B25: =Admin!$B$14 -> 46418 | D25: =D23 -> 10000
B27: =Admin!$B$15 -> 46446 | D27: =D25 -> 10000
B29: Closing Stock
B30: =Admin!$B$17 -> 46482 | D30: 6000

Sheet Debtors & Creditors
B1: Sales Month | C1: Sales not yet received | E1: Purchase Month | F1: Purchases still to be paid
B3: Owed start year | E3: Owed start year
B5: Acme Corp | C5: 7200 | E5: Acme Corp | F5: 8000
B6: Beta Systems | C6: 1200 | E6: TechStart Ltd | F6: 2400
B7: Gamma Ltd | C7: 2400 | E7: =B7 -> Gamma Ltd | F7: =IF((PurchasesMay!$H$1>0),PurchasesMay!$H$1," ") -> 420
B9: =Admin!B$7 -> 46203 | C9: =IF((SalesJun!$H$1>0),SalesJun!$H$1," ") | E9: =B9 -> 46203 | F9: =IF((PurchasesJun!$H$1>0),PurchasesJun!$H$1," ") -> 9057
B11: =Admin!B$8 -> 46234 | C11: =IF((SalesJul!$H$1>0),SalesJul!$H$1," ") | E11: =B11 -> 46234 | F11: =IF((PurchasesJul!$H$1>0),PurchasesJul!$H$1," ") -> 9059.25
B12: WorkSpace Ltd | C12: 1200 | E12: WorkSpace Ltd | F12: 1200
B13: Smith & Co | C13: 300 | E13: Smith & Co | F13: 300
B14: TechParts Ltd | C14: 600 | E14: BT Business | F14: 60
B15: Shell | C15: 120 | E15: Shell | F15: 150
B17: =Admin!B$11 -> 46326 | C17: =IF((SalesOct!$H$1>0),SalesOct!$H$1," ") | E17: =B17 -> 46326 | F17: =IF((PurchasesOct!$H$1>0),PurchasesOct!$H$1," ") -> 43005.75
B19: =Admin!B$12 -> 46356 | C19: =IF((SalesNov!$H$1>0),SalesNov!$H$1," ") | E19: =B19 -> 46356 | F19: =IF((PurchasesNov!$H$1>0),PurchasesNov!$H$1," ") -> 6918
B21: =Admin!B$13 -> 46387 | C21: =IF((SalesDec!$H$1>0),SalesDec!$H$1," ") | E21: =B21 -> 46387 | F21: =IF((PurchasesDec!$H$1>0),PurchasesDec!$H$1," ") -> 9451.5
B23: =Admin!B$14 -> 46418 | C23: =IF((SalesJan!$H$1>0),SalesJan!$H$1," ") | E23: =B23 -> 46418 | F23: =IF((PurchasesJan!$H$1>0),PurchasesJan!$H$1," ") -> 4511.25
B25: =Admin!B$15 -> 46446 | C25: =IF((SalesFeb!$H$1>0),SalesFeb!$H$1," ") | E25: =B25 -> 46446 | F25: =IF((PurchasesFeb!$H$1>0),PurchasesFeb!$H$1," ") -> 4396.5
B27: =Admin!B$16 -> 46477 | C27: =IF((SalesMar!$H$1>0),SalesMar!$H$1," ") | E27: =B27 -> 46477 | F27: =IF((PurchasesMar!$H$1>0),PurchasesMar!$H$1," ") -> 3726.5
B29: Amount owed by customers | C29: =SUM(C3:C28) -> 13020 | E29: Amount owed to suppliers | F29: =SUM(F3:F28) -> 102655.75

Sheet SalesApr
A1: Sales Date | B1: Customer Name | D1: Total for Month | E1: =SUM(E4:E300) -> 0 | F1: =SUM(F4:F300) -> 33400 | G1: =SUM(G4:G300) -> 0 | H1: =SUM(H4:H300) -> 0 | I1: =TODAY() -> 46138 | J1: =SUM(J4:J300) -> 0 | K1: =J1 -> 0
C2: Sales Invoice or reference | D2: Receipt record Cash, Bank deposit, Dr Cr Card | E2: Sales Mileage | F2: Gross Sales Value | G2: Other Income (start up grants) | H2: Sales Value not yet received | I2: Number of Days Outstanding | J2: Sub contractors only
J3: CIS Tax Deducted | K3: CIS Certificate reference
A4: 45748 | B4: Beta Systems | F4: 1200 | I4: =IF((F4<>0),IF((D4>0)," ",(I$1-A4))," ") -> 390
A5: 45750 | B5: FreshField Ltd | F5: 360 | I5: =IF((F5<>0),IF((D5>0)," ",(I$1-A5))," ") -> 388
A6: 45752 | B6: CloudNine Ltd | F6: 600 | I6: =IF((F6<>0),IF((D6>0)," ",(I$1-A6))," ") -> 386
A7: 45755 | B7: Cedar Systems | F7: 480 | I7: =IF((F7<>0),IF((D7>0)," ",(I$1-A7))," ") -> 383
A8: 45757 | B8: Pinnacle Group | F8: 720 | I8: =IF((F8<>0),IF((D8>0)," ",(I$1-A8))," ") -> 381
A9: 45762 | B9: Acme Corp | F9: 25000 | I9: =IF((F9<>0),IF((D9>0)," ",(I$1-A9))," ") -> 376
A10: 45765 | B10: TechStart Ltd | F10: 2400 | I10: =IF((F10<>0),IF((D10>0)," ",(I$1-A10))," ") -> 373
A11: 45767 | B11: DataFlow Inc | F11: 1800 | I11: =IF((F11<>0),IF((D11>0)," ",(I$1-A11))," ") -> 371
A12: 45775 | B12: Horizon Analytics | F12: 840 | I12: =IF((F12<>0),IF((D12>0)," ",(I$1-A12))," ") -> 363
I13: =IF((F13<>0),IF((D13>0)," ",(I$1-A13))," ")
I14: =IF((F14<>0),IF((D14>0)," ",(I$1-A14))," ")
I15: =IF((F15<>0),IF((D15>0)," ",(I$1-A15))," ")
I16: =IF((F16<>0),IF((D16>0)," ",(I$1-A16))," ")
I17: =IF((F17<>0),IF((D17>0)," ",(I$1-A17))," ")
I18: =IF((F18<>0),IF((D18>0)," ",(I$1-A18))," ")
I19: =IF((F19<>0),IF((D19>0)," ",(I$1-A19))," ")
I20: =IF((F20<>0),IF((D20>0)," ",(I$1-A20))," ")
I21: =IF((F21<>0),IF((D21>0)," ",(I$1-A21))," ")
I22: =IF((F22<>0),IF((D22>0)," ",(I$1-A22))," ")
I23: =IF((F23<>0),IF((D23>0)," ",(I$1-A23))," ")
I24: =IF((F24<>0),IF((D24>0)," ",(I$1-A24))," ")
... I67: =IF((F67<>0),IF((D67>0)," ",(I$1-A67))," ")
H68: =IF((F68<>0),IF((D68>0)," ",F68)," ") | I68: =IF((F68<>0),IF((D68>0)," ",(I$1-A68))," ")
H69: =IF((F69<>0),IF((D69>0)," ",F69)," ") | I69: =IF((F69<>0),IF((D69>0)," ",(I$1-A69))," ")
H70: =IF((F70<>0),IF((D70>0)," ",F70)," ") | I70: =IF((F70<>0),IF((D70>0)," ",(I$1-A70))," ")
H71: =IF((F71<>0),IF((D71>0)," ",F71)," ") | I71: =IF((F71<>0),IF((D71>0)," ",(I$1-A71))," ")
H72: =IF((F72<>0),IF((D72>0)," ",F72)," ") | I72: =IF((F72<>0),IF((D72>0)," ",(I$1-A72))," ")
H73: =IF((F73<>0),IF((D73>0)," ",F73)," ") | I73: =IF((F73<>0),IF((D73>0)," ",(I$1-A73))," ")
H74: =IF((F74<>0),IF((D74>0)," ",F74)," ") | I74: =IF((F74<>0),IF((D74>0)," ",(I$1-A74))," ")
H75: =IF((F75<>0),IF((D75>0)," ",F75)," ") | I75: =IF((F75<>0),IF((D75>0)," ",(I$1-A75))," ")
H76: =IF((F76<>0),IF((D76>0)," ",F76)," ") | I76: =IF((F76<>0),IF((D76>0)," ",(I$1-A76))," ")
H77: =IF((F77<>0),IF((D77>0)," ",F77)," ") | I77: =IF((F77<>0),IF((D77>0)," ",(I$1-A77))," ")
H78: =IF((F78<>0),IF((D78>0)," ",F78)," ") | I78: =IF((F78<>0),IF((D78>0)," ",(I$1-A78))," ")
H79: =IF((F79<>0),IF((D79>0)," ",F79)," ") | I79: =IF((F79<>0),IF((D79>0)," ",(I$1-A79))," ")
... H204: =IF((F204<>0),IF((D204>0)," ",F204)," ") | I204: =IF((F204<>0),IF((D204>0)," ",(I$1-A204))," ")
A301: Entries below this line not included in totals

Sheet PurchasesApr
A1: =G4 -> 0 | B1: Mileage to date | C1: =F1+SalesApr!$E$1 -> 0 | D1: Total for Month | E1: =IF((G1-SUM(J1:W1)<>0),(G1-SUM(J1:W1))," ") | F1: =SUM(F5:F300) -> 0 | G1: =SUM(G4:G300) -> 5111.25 | H1: =SUM(H5:H300) -> 0 | I1: =TODAY() -> 46138 | J1: =SUM(J5:J300) -> 600 | K1: =SUM(K5:K300) -> 0 | L1: =SUM(L5:L300) -> 0 | M1: =SUM(M5:M300) -> 1200 | N1: =SUM(N5:N300) -> 120 | O1: =SUM(O5:O300) -> 135 | P1: =SUM(P3:P300) -> 602.25 | Q1: =SUM(Q5:Q300) -> 92 | R1: =SUM(R5:R300) -> 0 | S1: =SUM(S5:S300) -> 300 | T1: =SUM(T5:T300) -> 0 | U1: =SUM(U5:U300) -> 0 | V1: =SUM(V5:V300) -> 2062 | W1: =SUM(W5:W300) -> 0 | X1: =W1 -> 0 | Y1: =SUM(Y5:Y300) -> 0 | Z1: =Y1 -> 0
A2: Purchase Date | B2: =IF((G1-SUM(J1:W1)<>0),"COMPLETE EXPENSE ANALYSIS by inserting expense letter in col E","Supplier") -> Supplier | C2: Purchase Reference / Invoice Number | D2: Payment method Enter cash, cheque no., DD, credit card | E2: Enter Expense Code Letter | F2: Enter Mileage on purchases | G2: Total Purchase Value incl Vat | H2: Purchases waiting payment | I2: Purchases number of days outstanding | J2: Stock Purchases | K2: Direct other costs | L2: Employee Costs | M2: Premises Costs | N2: Repairs & Maintenance | O2: Gen Admin Postage Tel & Stationery | P2: Motor Expenses | Q2: Travel & Subsistence | R2: Advertising & Promotion | S2: Legal & Professional | T2: Bad Debts | U2: Bank Interest Charges | V2: Other Expenses | W2: Fixed Assets (items over £100) | X2: =IF(X1>('Fixed Assets'!$E$110),"FIXED ASSETS requires updating with new additions","Fixed Assets Description (Vehicles: make, model, date reg. and reg. mark)") -> Fixed Assets Description (Vehicles: make, model, date reg. and reg. mark) | Y2: Contractors
P3: =IF((E$4="m"),G$4," ") -> 0 | Y3: CIS Certificates
E4: m | G4: =IF((C1<Admin!$F$22),(C1*Admin!$G$21),(C1*Admin!$G$21-(C1-Admin!$F$21)*(Admin!$G$21-Admin!$G$22))) -> 0 | J4: S | K4: D | L4: E | M4: P | N4: R | O4: G | P4: M | Q4: T | R4: A | S4: L | T4: B | U4: I | V4: O | W4: F | Y4: Tax Paid | Z4: Certificate No
A5: 45748 | B5: WorkSpace Ltd | E5: p | G5: 1200 | I5: =IF((G5<>0),IF((D5>0)," ",(I$1-A5))," ") -> 390 | J5: =IF((E5="s"),G5," ") | K5: =IF((E5="d"),G5," ") | L5: =IF((E5="e"),G5," ") | M5: =IF((E5="p"),G5," ") -> 1200 | N5: =IF((E5="r"),G5," ") | O5: =IF((E5="g"),G5," ") | P5: =IF((E5="m"),G5," ") | Q5: =IF((E5="t"),G5," ") | R5: =IF((E5="a"),G5," ") | S5: =IF((E5="l"),G5," ") | T5: =IF((E5="b"),G5," ") | U5: =IF((E5="i"),G5," ") | V5: =IF((E5="o"),G5," ") | W5: =IF((E5="f"),G5," ")
A6: 45748 | B6: Microsoft | E6: g | G6: 30 | I6: =IF((G6<>0),IF((D6>0)," ",(I$1-A6))," ") -> 390 | J6: =IF((E6="s"),G6," ") | K6: =IF((E6="d"),G6," ") | L6: =IF((E6="e"),G6," ") | M6: =IF((E6="p"),G6," ") | N6: =IF((E6="r"),G6," ") | O6: =IF((E6="g"),G6," ") -> 30 | P6: =IF((E6="m"),G6," ") | Q6: =IF((E6="t"),G6," ") | R6: =IF((E6="a"),G6," ") | S6: =IF((E6="l"),G6," ") | T6: =IF((E6="b"),G6," ") | U6: =IF((E6="i"),G6," ") | V6: =IF((E6="o"),G6," ") | W6: =IF((E6="f"),G6," ")
A7: 45748 | B7: Slack | E7: g | G7: 15 | I7: =IF((G7<>0),IF((D7>0)," ",(I$1-A7))," ") -> 390 | J7: =IF((E7="s"),G7," ") | K7: =IF((E7="d"),G7," ") | L7: =IF((E7="e"),G7," ") | M7: =IF((E7="p"),G7," ") | N7: =IF((E7="r"),G7," ") | O7: =IF((E7="g"),G7," ") -> 15 | P7: =IF((E7="m"),G7," ") | Q7: =IF((E7="t"),G7," ") | R7: =IF((E7="a"),G7," ") | S7: =IF((E7="l"),G7," ") | T7: =IF((E7="b"),G7," ") | U7: =IF((E7="i"),G7," ") | V7: =IF((E7="o"),G7," ") | W7: =IF((E7="f"),G7," ")
A8: 45748 | B8: GitHub | E8: o | G8: 45 | I8: =IF((G8<>0),IF((D8>0)," ",(I$1-A8))," ") -> 390 | J8: =IF((E8="s"),G8," ") | K8: =IF((E8="d"),G8," ") | L8: =IF((E8="e"),G8," ") | M8: =IF((E8="p"),G8," ") | N8: =IF((E8="r"),G8," ") | O8: =IF((E8="g"),G8," ") | P8: =IF((E8="m"),G8," ") | Q8: =IF((E8="t"),G8," ") | R8: =IF((E8="a"),G8," ") | S8: =IF((E8="l"),G8," ") | T8: =IF((E8="b"),G8," ") | U8: =IF((E8="i"),G8," ") | V8: =IF((E8="o"),G8," ") -> 45 | W8: =IF((E8="f"),G8," ")
A9: 45748 | B9: Hiscox | E9: o | G9: 1440 | I9: =IF((G9<>0),IF((D9>0)," ",(I$1-A9))," ") -> 390 | J9: =IF((E9="s"),G9," ") | K9: =IF((E9="d"),G9," ") | L9: =IF((E9="e"),G9," ") | M9: =IF((E9="p"),G9," ") | N9: =IF((E9="r"),G9," ") | O9: =IF((E9="g"),G9," ") | P9: =IF((E9="m"),G9," ") | Q9: =IF((E9="t"),G9," ") | R9: =IF((E9="a"),G9," ") | S9: =IF((E9="l"),G9," ") | T9: =IF((E9="b"),G9," ") | U9: =IF((E9="i"),G9," ") | V9: =IF((E9="o"),G9," ") -> 1440 | W9: =IF((E9="f"),G9," ")
A10: 45748 | B10: Cloudflare | E10: o | G10: 24 | I10: =IF((G10<>0),IF((D10>0)," ",(I$1-A10))," ") -> 390 | J10: =IF((E10="s"),G10," ") | K10: =IF((E10="d"),G10," ") | L10: =IF((E10="e"),G10," ") | M10: =IF((E10="p"),G10," ") | N10: =IF((E10="r"),G10," ") | O10: =IF((E10="g"),G10," ") | P10: =IF((E10="m"),G10," ") | Q10: =IF((E10="t"),G10," ") | R10: =IF((E10="a"),G10," ") | S10: =IF((E10="l"),G10," ") | T10: =IF((E10="b"),G10," ") | U10: =IF((E10="i"),G10," ") | V10: =IF((E10="o"),G10," ") -> 24 | W10: =IF((E10="f"),G10," ")
A11: 45748 | B11: Zoom | E11: g | G11: 18 | I11: =IF((G11<>0),IF((D11>0)," ",(I$1-A11))," ") -> 390 | J11: =IF((E11="s"),G11," ") | K11: =IF((E11="d"),G11," ") | L11: =IF((E11="e"),G11," ") | M11: =IF((E11="p"),G11," ") | N11: =IF((E11="r"),G11," ") | O11: =IF((E11="g"),G11," ") -> 18 | P11: =IF((E11="m"),G11," ") | Q11: =IF((E11="t"),G11," ") | R11: =IF((E11="a"),G11," ") | S11: =IF((E11="l"),G11," ") | T11: =IF((E11="b"),G11," ") | U11: =IF((E11="i"),G11," ") | V11: =IF((E11="o"),G11," ") | W11: =IF((E11="f"),G11," ")
A12: 45750 | B12: AWS | E12: o | G12: 180 | I12: =IF((G12<>0),IF((D12>0)," ",(I$1-A12))," ") -> 388 | J12: =IF((E12="s"),G12," ") | K12: =IF((E12="d"),G12," ") | L12: =IF((E12="e"),G12," ") | M12: =IF((E12="p"),G12," ") | N12: =IF((E12="r"),G12," ") | O12: =IF((E12="g"),G12," ") | P12: =IF((E12="m"),G12," ") | Q12: =IF((E12="t"),G12," ") | R12: =IF((E12="a"),G12," ") | S12: =IF((E12="l"),G12," ") | T12: =IF((E12="b"),G12," ") | U12: =IF((E12="i"),G12," ") | V12: =IF((E12="o"),G12," ") -> 180 | W12: =IF((E12="f"),G12," ")
A13: 45750 | B13: Argos | E13: o | G13: 22 | I13: =IF((G13<>0),IF((D13>0)," ",(I$1-A13))," ") -> 388 | J13: =IF((E13="s"),G13," ") | K13: =IF((E13="d"),G13," ") | L13: =IF((E13="e"),G13," ") | M13: =IF((E13="p"),G13," ") | N13: =IF((E13="r"),G13," ") | O13: =IF((E13="g"),G13," ") | P13: =IF((E13="m"),G13," ") | Q13: =IF((E13="t"),G13," ") | R13: =IF((E13="a"),G13," ") | S13: =IF((E13="l"),G13," ") | T13: =IF((E13="b"),G13," ") | U13: =IF((E13="i"),G13," ") | V13: =IF((E13="o"),G13," ") -> 22 | W13: =IF((E13="f"),G13," ")
A14: 45752 | B14: Ryman | E14: o | G14: 24 | I14: =IF((G14<>0),IF((D14>0)," ",(I$1-A14))," ") -> 386 | J14: =IF((E14="s"),G14," ") | K14: =IF((E14="d"),G14," ") | L14: =IF((E14="e"),G14," ") | M14: =IF((E14="p"),G14," ") | N14: =IF((E14="r"),G14," ") | O14: =IF((E14="g"),G14," ") | P14: =IF((E14="m"),G14," ") | Q14: =IF((E14="t"),G14," ") | R14: =IF((E14="a"),G14," ") | S14: =IF((E14="l"),G14," ") | T14: =IF((E14="b"),G14," ") | U14: =IF((E14="i"),G14," ") | V14: =IF((E14="o"),G14," ") -> 24 | W14: =IF((E14="f"),G14," ")
A15: 45752 | B15: BP | E15: m | G15: 180 | I15: =IF((G15<>0),IF((D15>0)," ",(I$1-A15))," ") -> 386 | J15: =IF((E15="s"),G15," ") | K15: =IF((E15="d"),G15," ") | L15: =IF((E15="e"),G15," ") | M15: =IF((E15="p"),G15," ") | N15: =IF((E15="r"),G15," ") | O15: =IF((E15="g"),G15," ") | P15: =IF((E15="m"),G15," ") -> 180 | Q15: =IF((E15="t"),G15," ") | R15: =IF((E15="a"),G15," ") | S15: =IF((E15="l"),G15," ") | T15: =IF((E15="b"),G15," ") | U15: =IF((E15="i"),G15," ") | V15: =IF((E15="o"),G15," ") | W15: =IF((E15="f"),G15," ")
A16: 45752 | B16: DigitalOcean | E16: o | G16: 36 | I16: =IF((G16<>0),IF((D16>0)," ",(I$1-A16))," ") -> 386 | J16: =IF((E16="s"),G16," ") | K16: =IF((E16="d"),G16," ") | L16: =IF((E16="e"),G16," ") | M16: =IF((E16="p"),G16," ") | N16: =IF((E16="r"),G16," ") | O16: =IF((E16="g"),G16," ") | P16: =IF((E16="m"),G16," ") | Q16: =IF((E16="t"),G16," ") | R16: =IF((E16="a"),G16," ") | S16: =IF((E16="l"),G16," ") | T16: =IF((E16="b"),G16," ") | U16: =IF((E16="i"),G16," ") | V16: =IF((E16="o"),G16," ") -> 36 | W16: =IF((E16="f"),G16," ")
... A35: 45777 | B35: Smith & Co | E35: l | G35: 300 | I35: =IF((G35<>0),IF((D35>0)," ",(I$1-A35))," ") -> 361 | J35: =IF((E35="s"),G35," ") | K35: =IF((E35="d"),G35," ") | L35: =IF((E35="e"),G35," ") | M35: =IF((E35="p"),G35," ") | N35: =IF((E35="r"),G35," ") | O35: =IF((E35="g"),G35," ") | P35: =IF((E35="m"),G35," ") | Q35: =IF((E35="t"),G35," ") | R35: =IF((E35="a"),G35," ") | S35: =IF((E35="l"),G35," ") -> 300 | T35: =IF((E35="b"),G35," ") | U35: =IF((E35="i"),G35," ") | V35: =IF((E35="o"),G35," ") | W35: =IF((E35="f"),G35," ")
I36: =IF((G36<>0),IF((D36>0)," ",(I$1-A36))," ") | J36: =IF((E36="s"),G36," ") | K36: =IF((E36="d"),G36," ") | L36: =IF((E36="e"),G36," ") | M36: =IF((E36="p"),G36," ") | N36: =IF((E36="r"),G36," ") | O36: =IF((E36="g"),G36," ") | P36: =IF((E36="m"),G36," ") | Q36: =IF((E36="t"),G36," ") | R36: =IF((E36="a"),G36," ") | S36: =IF((E36="l"),G36," ") | T36: =IF((E36="b"),G36," ") | U36: =IF((E36="i"),G36," ") | V36: =IF((E36="o"),G36," ") | W36: =IF((E36="f"),G36," ")
H37: =IF((G37<>0),IF((D37>0)," ",G37)," ") | I37: =IF((G37<>0),IF((D37>0)," ",(I$1-A37))," ") | J37: =IF((E37="s"),G37," ") | K37: =IF((E37="d"),G37," ") | L37: =IF((E37="e"),G37," ") | M37: =IF((E37="p"),G37," ") | N37: =IF((E37="r"),G37," ") | O37: =IF((E37="g"),G37," ") | P37: =IF((E37="m"),G37," ") | Q37: =IF((E37="t"),G37," ") | R37: =IF((E37="a"),G37," ") | S37: =IF((E37="l"),G37," ") | T37: =IF((E37="b"),G37," ") | U37: =IF((E37="i"),G37," ") | V37: =IF((E37="o"),G37," ") | W37: =IF((E37="f"),G37," ")
H38: =IF((G38<>0),IF((D38>0)," ",G38)," ") | I38: =IF((G38<>0),IF((D38>0)," ",(I$1-A38))," ") | J38: =IF((E38="s"),G38," ") | K38: =IF((E38="d"),G38," ") | L38: =IF((E38="e"),G38," ") | M38: =IF((E38="p"),G38," ") | N38: =IF((E38="r"),G38," ") | O38: =IF((E38="g"),G38," ") | P38: =IF((E38="m"),G38," ") | Q38: =IF((E38="t"),G38," ") | R38: =IF((E38="a"),G38," ") | S38: =IF((E38="l"),G38," ") | T38: =IF((E38="b"),G38," ") | U38: =IF((E38="i"),G38," ") | V38: =IF((E38="o"),G38," ") | W38: =IF((E38="f"),G38," ")
H39: =IF((G39<>0),IF((D39>0)," ",G39)," ") | I39: =IF((G39<>0),IF((D39>0)," ",(I$1-A39))," ") | J39: =IF((E39="s"),G39," ") | K39: =IF((E39="d"),G39," ") | L39: =IF((E39="e"),G39," ") | M39: =IF((E39="p"),G39," ") | N39: =IF((E39="r"),G39," ") | O39: =IF((E39="g"),G39," ") | P39: =IF((E39="m"),G39," ") | Q39: =IF((E39="t"),G39," ") | R39: =IF((E39="a"),G39," ") | S39: =IF((E39="l"),G39," ") | T39: =IF((E39="b"),G39," ") | U39: =IF((E39="i"),G39," ") | V39: =IF((E39="o"),G39," ") | W39: =IF((E39="f"),G39," ")
H40: =IF((G40<>0),IF((D40>0)," ",G40)," ") | I40: =IF((G40<>0),IF((D40>0)," ",(I$1-A40))," ") | J40: =IF((E40="s"),G40," ") | K40: =IF((E40="d"),G40," ") | L40: =IF((E40="e"),G40," ") | M40: =IF((E40="p"),G40," ") | N40: =IF((E40="r"),G40," ") | O40: =IF((E40="g"),G40," ") | P40: =IF((E40="m"),G40," ") | Q40: =IF((E40="t"),G40," ") | R40: =IF((E40="a"),G40," ") | S40: =IF((E40="l"),G40," ") | T40: =IF((E40="b"),G40," ") | U40: =IF((E40="i"),G40," ") | V40: =IF((E40="o"),G40," ") | W40: =IF((E40="f"),G40," ")
H41: =IF((G41<>0),IF((D41>0)," ",G41)," ") | I41: =IF((G41<>0),IF((D41>0)," ",(I$1-A41))," ") | J41: =IF((E41="s"),G41," ") | K41: =IF((E41="d"),G41," ") | L41: =IF((E41="e"),G41," ") | M41: =IF((E41="p"),G41," ") | N41: =IF((E41="r"),G41," ") | O41: =IF((E41="g"),G41," ") | P41: =IF((E41="m"),G41," ") | Q41: =IF((E41="t"),G41," ") | R41: =IF((E41="a"),G41," ") | S41: =IF((E41="l"),G41," ") | T41: =IF((E41="b"),G41," ") | U41: =IF((E41="i"),G41," ") | V41: =IF((E41="o"),G41," ") | W41: =IF((E41="f"),G41," ")
H42: =IF((G42<>0),IF((D42>0)," ",G42)," ") | I42: =IF((G42<>0),IF((D42>0)," ",(I$1-A42))," ") | J42: =IF((E42="s"),G42," ") | K42: =IF((E42="d"),G42," ") | L42: =IF((E42="e"),G42," ") | M42: =IF((E42="p"),G42," ") | N42: =IF((E42="r"),G42," ") | O42: =IF((E42="g"),G42," ") | P42: =IF((E42="m"),G42," ") | Q42: =IF((E42="t"),G42," ") | R42: =IF((E42="a"),G42," ") | S42: =IF((E42="l"),G42," ") | T42: =IF((E42="b"),G42," ") | U42: =IF((E42="i"),G42," ") | V42: =IF((E42="o"),G42," ") | W42: =IF((E42="f"),G42," ")
H43: =IF((G43<>0),IF((D43>0)," ",G43)," ") | I43: =IF((G43<>0),IF((D43>0)," ",(I$1-A43))," ") | J43: =IF((E43="s"),G43," ") | K43: =IF((E43="d"),G43," ") | L43: =IF((E43="e"),G43," ") | M43: =IF((E43="p"),G43," ") | N43: =IF((E43="r"),G43," ") | O43: =IF((E43="g"),G43," ") | P43: =IF((E43="m"),G43," ") | Q43: =IF((E43="t"),G43," ") | R43: =IF((E43="a"),G43," ") | S43: =IF((E43="l"),G43," ") | T43: =IF((E43="b"),G43," ") | U43: =IF((E43="i"),G43," ") | V43: =IF((E43="o"),G43," ") | W43: =IF((E43="f"),G43," ")
H44: =IF((G44<>0),IF((D44>0)," ",G44)," ") | I44: =IF((G44<>0),IF((D44>0)," ",(I$1-A44))," ") | J44: =IF((E44="s"),G44," ") | K44: =IF((E44="d"),G44," ") | L44: =IF((E44="e"),G44," ") | M44: =IF((E44="p"),G44," ") | N44: =IF((E44="r"),G44," ") | O44: =IF((E44="g"),G44," ") | P44: =IF((E44="m"),G44," ") | Q44: =IF((E44="t"),G44," ") | R44: =IF((E44="a"),G44," ") | S44: =IF((E44="l"),G44," ") | T44: =IF((E44="b"),G44," ") | U44: =IF((E44="i"),G44," ") | V44: =IF((E44="o"),G44," ") | W44: =IF((E44="f"),G44," ")
H45: =IF((G45<>0),IF((D45>0)," ",G45)," ") | I45: =IF((G45<>0),IF((D45>0)," ",(I$1-A45))," ") | J45: =IF((E45="s"),G45," ") | K45: =IF((E45="d"),G45," ") | L45: =IF((E45="e"),G45," ") | M45: =IF((E45="p"),G45," ") | N45: =IF((E45="r"),G45," ") | O45: =IF((E45="g"),G45," ") | P45: =IF((E45="m"),G45," ") | Q45: =IF((E45="t"),G45," ") | R45: =IF((E45="a"),G45," ") | S45: =IF((E45="l"),G45," ") | T45: =IF((E45="b"),G45," ") | U45: =IF((E45="i"),G45," ") | V45: =IF((E45="o"),G45," ") | W45: =IF((E45="f"),G45," ")
H46: =IF((G46<>0),IF((D46>0)," ",G46)," ") | I46: =IF((G46<>0),IF((D46>0)," ",(I$1-A46))," ") | J46: =IF((E46="s"),G46," ") | K46: =IF((E46="d"),G46," ") | L46: =IF((E46="e"),G46," ") | M46: =IF((E46="p"),G46," ") | N46: =IF((E46="r"),G46," ") | O46: =IF((E46="g"),G46," ") | P46: =IF((E46="m"),G46," ") | Q46: =IF((E46="t"),G46," ") | R46: =IF((E46="a"),G46," ") | S46: =IF((E46="l"),G46," ") | T46: =IF((E46="b"),G46," ") | U46: =IF((E46="i"),G46," ") | V46: =IF((E46="o"),G46," ") | W46: =IF((E46="f"),G46," ")
H47: =IF((G47<>0),IF((D47>0)," ",G47)," ") | I47: =IF((G47<>0),IF((D47>0)," ",(I$1-A47))," ") | J47: =IF((E47="s"),G47," ") | K47: =IF((E47="d"),G47," ") | L47: =IF((E47="e"),G47," ") | M47: =IF((E47="p"),G47," ") | N47: =IF((E47="r"),G47," ") | O47: =IF((E47="g"),G47," ") | P47: =IF((E47="m"),G47," ") | Q47: =IF((E47="t"),G47," ") | R47: =IF((E47="a"),G47," ") | S47: =IF((E47="l"),G47," ") | T47: =IF((E47="b"),G47," ") | U47: =IF((E47="i"),G47," ") | V47: =IF((E47="o"),G47," ") | W47: =IF((E47="f"),G47," ")
H48: =IF((G48<>0),IF((D48>0)," ",G48)," ") | I48: =IF((G48<>0),IF((D48>0)," ",(I$1-A48))," ") | J48: =IF((E48="s"),G48," ") | K48: =IF((E48="d"),G48," ") | L48: =IF((E48="e"),G48," ") | M48: =IF((E48="p"),G48," ") | N48: =IF((E48="r"),G48," ") | O48: =IF((E48="g"),G48," ") | P48: =IF((E48="m"),G48," ") | Q48: =IF((E48="t"),G48," ") | R48: =IF((E48="a"),G48," ") | S48: =IF((E48="l"),G48," ") | T48: =IF((E48="b"),G48," ") | U48: =IF((E48="i"),G48," ") | V48: =IF((E48="o"),G48," ") | W48: =IF((E48="f"),G48," ")
... H68: =IF((G68<>0),IF((D68>0)," ",G68)," ") | I68: =IF((G68<>0),IF((D68>0)," ",(I$1-A68))," ") | J68: =IF((E68="s"),G68," ") | K68: =IF((E68="d"),G68," ") | L68: =IF((E68="e"),G68," ") | M68: =IF((E68="p"),G68," ") | N68: =IF((E68="r"),G68," ") | O68: =IF((E68="g"),G68," ") | P68: =IF((E68="m"),G68," ") | Q68: =IF((E68="t"),G68," ") | R68: =IF((E68="a"),G68," ") | S68: =IF((E68="l"),G68," ") | T68: =IF((E68="b"),G68," ") | U68: =IF((E68="i"),G68," ") | V68: =IF((E68="o"),G68," ") | W68: =IF((E68="f"),G68," ")
E69: =IF((G69<>0),"Enter Letter"," ") | H69: =IF((G69<>0),IF((D69>0)," ",G69)," ") | I69: =IF((G69<>0),IF((D69>0)," ",(I$1-A69))," ") | J69: =IF((E69="s"),G69," ") | K69: =IF((E69="d"),G69," ") | L69: =IF((E69="e"),G69," ") | M69: =IF((E69="p"),G69," ") | N69: =IF((E69="r"),G69," ") | O69: =IF((E69="g"),G69," ") | P69: =IF((E69="m"),G69," ") | Q69: =IF((E69="t"),G69," ") | R69: =IF((E69="a"),G69," ") | S69: =IF((E69="l"),G69," ") | T69: =IF((E69="b"),G69," ") | U69: =IF((E69="i"),G69," ") | V69: =IF((E69="o"),G69," ") | W69: =IF((E69="f"),G69," ")
E70: =IF((G70<>0),"Enter Letter"," ") | H70: =IF((G70<>0),IF((D70>0)," ",G70)," ") | I70: =IF((G70<>0),IF((D70>0)," ",(I$1-A70))," ") | J70: =IF((E70="s"),G70," ") | K70: =IF((E70="d"),G70," ") | L70: =IF((E70="e"),G70," ") | M70: =IF((E70="p"),G70," ") | N70: =IF((E70="r"),G70," ") | O70: =IF((E70="g"),G70," ") | P70: =IF((E70="m"),G70," ") | Q70: =IF((E70="t"),G70," ") | R70: =IF((E70="a"),G70," ") | S70: =IF((E70="l"),G70," ") | T70: =IF((E70="b"),G70," ") | U70: =IF((E70="i"),G70," ") | V70: =IF((E70="o"),G70," ") | W70: =IF((E70="f"),G70," ")
E71: =IF((G71<>0),"Enter Letter"," ") | H71: =IF((G71<>0),IF((D71>0)," ",G71)," ") | I71: =IF((G71<>0),IF((D71>0)," ",(I$1-A71))," ") | J71: =IF((E71="s"),G71," ") | K71: =IF((E71="d"),G71," ") | L71: =IF((E71="e"),G71," ") | M71: =IF((E71="p"),G71," ") | N71: =IF((E71="r"),G71," ") | O71: =IF((E71="g"),G71," ") | P71: =IF((E71="m"),G71," ") | Q71: =IF((E71="t"),G71," ") | R71: =IF((E71="a"),G71," ") | S71: =IF((E71="l"),G71," ") | T71: =IF((E71="b"),G71," ") | U71: =IF((E71="i"),G71," ") | V71: =IF((E71="o"),G71," ") | W71: =IF((E71="f"),G71," ")
E72: =IF((G72<>0),"Enter Letter"," ") | H72: =IF((G72<>0),IF((D72>0)," ",G72)," ") | I72: =IF((G72<>0),IF((D72>0)," ",(I$1-A72))," ") | J72: =IF((E72="s"),G72," ") | K72: =IF((E72="d"),G72," ") | L72: =IF((E72="e"),G72," ") | M72: =IF((E72="p"),G72," ") | N72: =IF((E72="r"),G72," ") | O72: =IF((E72="g"),G72," ") | P72: =IF((E72="m"),G72," ") | Q72: =IF((E72="t"),G72," ") | R72: =IF((E72="a"),G72," ") | S72: =IF((E72="l"),G72," ") | T72: =IF((E72="b"),G72," ") | U72: =IF((E72="i"),G72," ") | V72: =IF((E72="o"),G72," ") | W72: =IF((E72="f"),G72," ")
E73: =IF((G73<>0),"Enter Letter"," ") | H73: =IF((G73<>0),IF((D73>0)," ",G73)," ") | I73: =IF((G73<>0),IF((D73>0)," ",(I$1-A73))," ") | J73: =IF((E73="s"),G73," ") | K73: =IF((E73="d"),G73," ") | L73: =IF((E73="e"),G73," ") | M73: =IF((E73="p"),G73," ") | N73: =IF((E73="r"),G73," ") | O73: =IF((E73="g"),G73," ") | P73: =IF((E73="m"),G73," ") | Q73: =IF((E73="t"),G73," ") | R73: =IF((E73="a"),G73," ") | S73: =IF((E73="l"),G73," ") | T73: =IF((E73="b"),G73," ") | U73: =IF((E73="i"),G73," ") | V73: =IF((E73="o"),G73," ") | W73: =IF((E73="f"),G73," ")
E74: =IF((G74<>0),"Enter Letter"," ") | H74: =IF((G74<>0),IF((D74>0)," ",G74)," ") | I74: =IF((G74<>0),IF((D74>0)," ",(I$1-A74))," ") | J74: =IF((E74="s"),G74," ") | K74: =IF((E74="d"),G74," ") | L74: =IF((E74="e"),G74," ") | M74: =IF((E74="p"),G74," ") | N74: =IF((E74="r"),G74," ") | O74: =IF((E74="g"),G74," ") | P74: =IF((E74="m"),G74," ") | Q74: =IF((E74="t"),G74," ") | R74: =IF((E74="a"),G74," ") | S74: =IF((E74="l"),G74," ") | T74: =IF((E74="b"),G74," ") | U74: =IF((E74="i"),G74," ") | V74: =IF((E74="o"),G74," ") | W74: =IF((E74="f"),G74," ")
E75: =IF((G75<>0),"Enter Letter"," ") | H75: =IF((G75<>0),IF((D75>0)," ",G75)," ") | I75: =IF((G75<>0),IF((D75>0)," ",(I$1-A75))," ") | J75: =IF((E75="s"),G75," ") | K75: =IF((E75="d"),G75," ") | L75: =IF((E75="e"),G75," ") | M75: =IF((E75="p"),G75," ") | N75: =IF((E75="r"),G75," ") | O75: =IF((E75="g"),G75," ") | P75: =IF((E75="m"),G75," ") | Q75: =IF((E75="t"),G75," ") | R75: =IF((E75="a"),G75," ") | S75: =IF((E75="l"),G75," ") | T75: =IF((E75="b"),G75," ") | U75: =IF((E75="i"),G75," ") | V75: =IF((E75="o"),G75," ") | W75: =IF((E75="f"),G75," ")
E76: =IF((G76<>0),"Enter Letter"," ") | H76: =IF((G76<>0),IF((D76>0)," ",G76)," ") | I76: =IF((G76<>0),IF((D76>0)," ",(I$1-A76))," ") | J76: =IF((E76="s"),G76," ") | K76: =IF((E76="d"),G76," ") | L76: =IF((E76="e"),G76," ") | M76: =IF((E76="p"),G76," ") | N76: =IF((E76="r"),G76," ") | O76: =IF((E76="g"),G76," ") | P76: =IF((E76="m"),G76," ") | Q76: =IF((E76="t"),G76," ") | R76: =IF((E76="a"),G76," ") | S76: =IF((E76="l"),G76," ") | T76: =IF((E76="b"),G76," ") | U76: =IF((E76="i"),G76," ") | V76: =IF((E76="o"),G76," ") | W76: =IF((E76="f"),G76," ")
E77: =IF((G77<>0),"Enter Letter"," ") | H77: =IF((G77<>0),IF((D77>0)," ",G77)," ") | I77: =IF((G77<>0),IF((D77>0)," ",(I$1-A77))," ") | J77: =IF((E77="s"),G77," ") | K77: =IF((E77="d"),G77," ") | L77: =IF((E77="e"),G77," ") | M77: =IF((E77="p"),G77," ") | N77: =IF((E77="r"),G77," ") | O77: =IF((E77="g"),G77," ") | P77: =IF((E77="m"),G77," ") | Q77: =IF((E77="t"),G77," ") | R77: =IF((E77="a"),G77," ") | S77: =IF((E77="l"),G77," ") | T77: =IF((E77="b"),G77," ") | U77: =IF((E77="i"),G77," ") | V77: =IF((E77="o"),G77," ") | W77: =IF((E77="f"),G77," ")
...

Sheet SalesMay
A1: Sales Date | B1: Customer Name | D1: Total for Month | E1: =SUM(E4:E300) -> 0 | F1: =SUM(F4:F300) -> 32920 | G1: =SUM(G4:G300) -> 0 | H1: =SUM(H4:H300) -> 0 | I1: =TODAY() -> 46138 | J1: =SUM(J4:J300) -> 0 | K1: =J1+SalesApr!K1 -> 0
C2: Sales Invoice or reference | D2: Receipt record Cash, Bank deposit, Dr Cr Card | E2: Sales Mileage | F2: Gross Sales Value | G2: Other Income (start up grants) | H2: Sales Value not yet received | I2: Number of Days Outstanding | J2: Sub contractors only
J3: CIS Tax Deducted | K3: CIS Certificate reference
A4: 45780 | B4: FreshField Ltd | F4: 360 | I4: =IF((F4<>0),IF((D4>0)," ",(I$1-A4))," ") -> 358
A5: 45782 | B5: CloudNine Ltd | F5: 600 | I5: =IF((F5<>0),IF((D5>0)," ",(I$1-A5))," ") -> 356
A6: 45785 | B6: Cedar Systems | F6: 480 | I6: =IF((F6<>0),IF((D6>0)," ",(I$1-A6))," ") -> 353
A7: 45787 | B7: Pinnacle Group | F7: 720 | I7: =IF((F7<>0),IF((D7>0)," ",(I$1-A7))," ") -> 351
A8: 45789 | B8: QuickFix IT | F8: 960 | I8: =IF((F8<>0),IF((D8>0)," ",(I$1-A8))," ") -> 349
A9: 45792 | B9: Acme Corp | F9: 25000 | I9: =IF((F9<>0),IF((D9>0)," ",(I$1-A9))," ") -> 346
A10: 45793 | B10: Summit Training | F10: 1200 | I10: =IF((F10<>0),IF((D10>0)," ",(I$1-A10))," ") -> 345
A11: 45795 | B11: TechStart Ltd | F11: 2400 | I11: =IF((F11<>0),IF((D11>0)," ",(I$1-A11))," ") -> 343
A12: 45802 | B12: Oakridge Partners | F12: 1200 | I12: =IF((F12<>0),IF((D12>0)," ",(I$1-A12))," ") -> 336
I13: =IF((F13<>0),IF((D13>0)," ",(I$1-A13))," ")
I14: =IF((F14<>0),IF((D14>0)," ",(I$1-A14))," ")
I15: =IF((F15<>0),IF((D15>0)," ",(I$1-A15))," ")
I16: =IF((F16<>0),IF((D16>0)," ",(I$1-A16))," ")
I17: =IF((F17<>0),IF((D17>0)," ",(I$1-A17))," ")
I18: =IF((F18<>0),IF((D18>0)," ",(I$1-A18))," ")
